Workbook

Sheet About 
J4: Alkem Laboratories is one of India's leading pharmaceutical companies, focused mainly on branded generic medicines. The company has a strong domestic presence, particularly in anti infectives, gastrointestinal, vitamins, neurology, cardiology, and diabetes therapies, while also exporting products to over 40 countries, including the United States. Alkem operates multiple manufacturing facilities and has gradually expanded into specialty and chronic therapies, which generally provide higher margins and more stable growth than acute care medicines. Its well known brands include Clavam, Pan, Taxim, and Gemcal. The company is known for a strong doctor distribution network, consistent profitability, and a healthy balance sheet, making it a significant player in the Indian pharmaceutical sector.
B22: Subsidaries | J22: Units
B24: Alkem Laboratories Corporation, Makati City Philippines, 1229 | J24: Taloja, Navi Mumbai Maharashtra
B25: Ascend GmbH, Frankfurt am Main Germany, 60439 | J25: Mandva, Gujarat
B26: Pharmacor Pty Limited, Manly Vale NSW Australia, 2093 | J26: Baddi, Himachal Pradesh
B27: S & B Holdings B.V., Amsterdam Netherlands, 1043 BW | J27: Daman, Dadra and Nagar Haveli and Daman and Diu
B28: ThePharmaNetwork LLC, Montvale New Jersey USA, 07645 | J28: Sikkim
B29: Ascend Laboratories LLC, Montvale New Jersey USA, 07645 | J29: Indore, Madhya Pradesh
B30: Ascend Laboratories UK Limited, United Kingdom | J30: Ankleshwar, Gujarat
B31: Ascend Laboratories Ltd., Canada | J31: Pune, Maharashtra
B32: Ascend Laboratories SDN BHD., Malaysia | J32: St Louis, Missouri USA
B33: Ascend Laboratories SpA, Chile | J33: California USA
B34: Ascend Laboratories SAS, Colombia
B35: Pharmacor Ltd., Kenya
B36: Alkem Laboratories Korea Inc., South Korea
B37: Enzene Biosciences Limited, India
B38: Cachet Pharmaceuticals Private Limited, India
B39: Indchemie Health Specialities Private Limited, India
B40: The PharmaNetwork LLP, Kazakhstan

Sheet Shareholding 
B3: Category of shareholder | C3: Entity Type | D3: Shareholding %
B6: A7) Indian | D6: 0
B7: Individuals/Hindu undivided Family | D7: 51.2
B8: Sarandhar Singh * (please refer notes) | C8: Promoter | D8: 18.75
B9: Basudeo Narain Singh | C9: Promoter | D9: 7.27
B10: Mritunjay Kumar Singh | C10: Promoter | D10: 6.42
B11: Madhurima Singh& (please refer notes) | C11: Promoter | D11: 6.18
B12: Madhurima Singh@ (please refer notes) | C12: Promoter | D12: 2.59
B13: Seema Singh | C13: Promoter | D13: 2.16
B14: Archana Singh | C14: Promoter | D14: 2
B15: Jayanti Sinha | C15: Promoter Group | D15: 1.04
B16: Aniruddha Singh& (please refer notes) | C16: Promoter | D16: 1.01
B17: Divya Singh& (please refer notes) | C17: Promoter | D17: 1.01
B18: Meghna Singh | C18: Promoter | D18: 1.01
B19: Shrey Shree Anant Singh | C19: Promoter | D19: 1
... B29: Sarvesh Singh # (please refer notes) | C29: Promoter | D29: 0
B30: Sub Total A1 | D30: 51.2
B31: A8) Foreign | D31: 0
B32: A=A1+A2 | D32: 51.2
B33: PROMOTER HOLDING
B34: Category & Name of the Shareholders | C34: No. of shareholder | D34: Total no. shares held | E34: Shareholding %
B37: Institutions | C37: 0 | D37: - | E37: 0
B38: B2) Institutions (Domestic) | C38: 0 | D38: - | E38: 0
B39: Mutual Funds/ | C39: 30 | D39: 1,86,14,487 | E39: 15.57
B40: Dsp Midcap Fund | C40: 1 | D40: 17,33,169 | E40: 1.45
B41: Nippon Life India Trustee Ltd- A/C Nippon India Growth Mid Cap Fund | C41: 1 | D41: 23,04,115 | E41: 1.93
B42: Sbi Large & Midcap Fund | C42: 1 | D42: 28,91,770 | E42: 2.42
B43: Icici Prudential Multi-Asset Fund | C43: 1 | D43: 37,05,808 | E43: 3.1
B44: Hdfc Mutual Fund - Hdfc Mid-Cap Fund | C44: 1 | D44: 48,49,338 | E44: 4.06
B45: Venture Capital Funds | C45: 0 | D45: - | E45: 0
B46: Alternate Investment Funds | C46: 15 | D46: 3,75,893 | E46: 0.31
B47: Banks | C47: 1 | D47: 34 | E47: 0
B48: Insurance Companies | C48: 20 | D48: 50,00,210 | E48: 4.18
B49: Hdfc Life Insurance Company Limited | C49: 1 | D49: 15,95,302 | E49: 1.33
B50: Life Insurance Corporation Of India - P & Gs Fund | C50: 1 | D50: 18,63,018 | E50: 1.56
B51: Provident Funds/ Pension Funds | C51: 1 | D51: 15,94,635 | E51: 1.33
B52: Nps Trust- A/C Hdfc Pension Fund Management Limited Scheme E - Tier I | C52: 1 | D52: 15,94,635 | E52: 1.33
B53: Asset reconstruction companies | C53: 0 | D53: - | E53: 0
B54: Sovereign Wealth Funds | C54: 0 | D54: - | E54: 0
B55: NBFCs registered with RBI | C55: 0 | D55: - | E55: 0
...

Sheet Consolidated Fs
B2: Consolidated Balance Sheet (₹ in Crores) | K2: Consolidated Balance Sheet (₹ in Crores) | S2: Consolidated Statement of Cash Flow (₹ in Crores)
B3: Years ending March 31 | K3: Years ending March 31 | S3: For the year ended March 31
B4: Particulars | C4: 2021 | D4: 2022 | E4: 2023 | F4: 2024 | G4: 2025 | K4: Particulars | L4: 2021 | M4: 2022 | N4: 2023 | O4: 2024 | P4: 2025 | S4: Particulars | T4: FY2021 | U4: FY2022 | V4: FY2023 | W4: FY2024 | X4: FY2025
B5: 1 Income | K5: I. ASSETS | S5: A. CASH FLOW FROM OPERATING ACTIVITIES:
B6: (a) Revenue from operations | C6: 9654.9 | D6: 10732.8 | E6: 11981.4 | F6: 12667.6 | G6: 12964.5 | K6: 1. Non-current assets | S6: Profit before Tax | T6: 1319.1 | U6: 1616.3 | V6: 2099.5 | W6: 2023.1 | X6: 2527
B7: (b) Other income | C7: 264.5 | D7: 320.4 | E7: 353.7 | F7: 310.8 | G7: 493.7 | K7: (a) Property, plant and equipment | L7: 1518.8 | M7: 1654.3 | N7: 1798.4 | O7: 2161.5 | P7: 2063.9 | S7: Adjustments for:
B8: Total income | C8: 9919.4 | D8: 11053.2 | E8: 12335.1 | F8: 12978.4 | G8: 13458.3 | K8: (b) Right of use assets | L8: 167.2 | M8: 189.5 | N8: 215.8 | O8: 247.2 | P8: 322.2 | S8: Depreciation and amortisation expense | T8: 215.9 | U8: 240 | V8: 265 | W8: 299.3 | X8: 357.2
B9: 2 Expenses | K9: (c) Capital work in progress | L9: 89.5 | M9: 102.3 | N9: 145.2 | O9: 148.4 | P9: 476.6 | S9: Liabilities no longer required written back | T9: -1.8 | U9: -2.1 | V9: -2.5 | W9: -1.9 | X9: -15.5
B10: (a) Cost of materials consumed | C10: 2788.3 | D10: 3065.8 | E10: 3300 | F10: 3294.6 | G10: 3440.4 | K10: (d) Goodwill / Goodwill on consolidation | L10: 324.1 | M10: 368.9 | N10: 412.3 | O10: 418.8 | P10: 423 | S10: Profit on sale of investments (net) | T10: -9.2 | U10: -10.5 | V10: -12 | W10: -14.6 | X10: -11
B11: (b) Purchases of stock-in-trade | C11: 1236.8 | D11: 1404.7 | E11: 1550 | F11: 1628.9 | G11: 1514 | K11: (e) Other intangible assets | L11: 27.9 | M11: 31.2 | N11: 35.4 | O11: 37.4 | P11: 43.1 | S11: Unrealised gain on fair valuation of investments (net) | T11: -0.4 | U11: -0.5 | V11: -0.6 | W11: -0.5 | X11: -41.9
B12: (c) Changes in inventories | C12: 85.2 | D12: 42 | E12: 25.6 | F12: 14.1 | G12: -190.1 | K12: (f) Intangible assets under development | L12: 23.4 | M12: 26.8 | N12: 30.2 | O12: 30.4 | P12: 71.5 | S12: (Profit) / Loss on sale / write off of property plant and equipment (net) | T12: 1.5 | U12: 1.7 | V12: 2 | W12: 3.2 | X12: -4.6
B13: (d) Employee benefits expense | C13: 1649.4 | D13: 1814.5 | E13: 1950 | F13: 2201 | G13: 2453.9 | K13: (g) Financial assets | S13: Employee stock compensation expenses | T13: 8.1 | U13: 9.2 | V13: 10.5 | W13: 18.9 | X13: 16.6
B14: (e) Finance costs | C14: 75.8 | D14: 85.4 | E14: 95 | F14: 112.4 | G14: 121.7 | K14: (i) Investments | L14: 1840.2 | M14: 2105.8 | N14: 2380.5 | O14: 2550.3 | P14: 32.4 | S14: Unrealised foreign currency loss on revaluation (net) | T14: 24.2 | U14: 27.6 | V14: 31.5 | W14: 59.4 | X14: 11.2
B15: (f) Depreciation & amortisation | C15: 215.9 | D15: 240 | E15: 265 | F15: 299.3 | G15: 357.2 | K15: (ii) Loans | L15: 98.6 | M15: 112.4 | N15: 128.5 | O15: 134.8 | P15: 910.9 | S15: Dividend income | T15: -0.1 | U15: -0.1 | V15: -0.2 | W15: -0.2 | X15: -0.2
B16: (g) Other expenses | C16: 2548.9 | D16: 2784.6 | E16: 3050 | F16: 3283.5 | G16: 3234.2 | K16: (iii) Other financial assets | L16: 71.3 | M16: 81.6 | N16: 93.2 | O16: 120.2 | P16: 475.4 | S16: Interest Income | T16: -121.2 | U16: -138 | V16: -157 | W16: -215.7 | X16: -358.8
B17: Total expenses | C17: 8600.3 | D17: 9436.9 | E17: 10235.6 | F17: 10833.8 | G17: 10931.2 | K17: (h) Deferred tax assets (net) | L17: 899.7 | M17: 1028.5 | N17: 1175.3 | O17: 1514.8 | P17: 1738.3 | S17: Impairment loss on property, plant and equipment and others | T17: 48.1 | U17: 54.8 | V17: 62.5 | W17: 99.2 | X17: 13.7
B18: 3 Profit before tax & exceptional | C18: 1319.1 | D18: 1616.3 | E18: 2099.5 | F18: 2144.6 | G18: 2527 | K18: (i) Non-current tax assets (net) | L18: 45.1 | M18: 51.7 | N18: 59.3 | O18: 78.2 | P18: 64.7 | S18: Interest expenses | T18: 75.8 | U18: 86.4 | V18: 98.5 | W18: 112.4 | X18: 121.7
B19: 4 Exceptional items | F19: -121.5 | K19: (j) Other non-current assets | L19: 22.6 | M19: 25.9 | N19: 29.8 | O19: 34 | P19: 123.3 | S19: Provision for doubtful advances | T19: 16.1 | U19: 18.3 | V19: 20.9 | W19: 31.8 | X19: 2
B20: 5 Profit before tax | C20: 1319.1 | D20: 1616.3 | E20: 2099.5 | F20: 2023.1 | G20: 2527 | K20: Total non-current assets | L20: 5130.4 | M20: 5779 | N20: 6503.9 | O20: 5163.2 | P20: 6745.3 | S20: Expected credit loss on receivables | T20: 24 | U20: 27.4 | V20: 31.2 | W20: 52.4 | X20: 13.4
B21: 6 Tax expense (Current & Deferred) | C21: 254.6 | D21: 305.9 | E21: 404 | F21: 211.7 | G21: 311 | K21: 2. Current assets | S21: Subtotal of Adjustments | T21: 280 | U21: 314.2 | V21: 349.8 | W21: 383.6 | X21: 103.8
B22: 7 Profit for the year (PAT) | C22: 1064.5 | D22: 1310.4 | E22: 1695.5 | F22: 1811.5 | G22: 2215.4 | K22: (a) Inventories | L22: 1823.9 | M22: 2067.8 | N22: 2341.5 | O22: 2661.2 | P22: 2922.4 | S22: Operating profit before working capital changes | T22: 1599.1 | U22: 1930.5 | V22: 2449.3 | W22: 2406.7 | X22: 2630.8
B23: 8 Other Comprehensive Income | C23: -13.6 | D23: -7 | E23: -8.6 | F23: 27.3 | G23: 18 | K23: (b) Financial assets
B24: 9 Total Comprehensive Income | C24: 1050.9 | D24: 1303.4 | E24: 1686.9 | F24: 1838.8 | G24: 2233.4 | K24: (i) Investments | L24: 92.4 | M24: 105.3 | N24: 120.2 | O24: 148.9 | P24: 902.3 | S24: Adjustments for changes in working capital:
K25: (ii) Trade receivables | L25: 1589.3 | M25: 1805.2 | N25: 2053.7 | O25: 2252.8 | P25: 2466.3 | S25: Increase in trade receivables | T25: -120.8 | U25: -137.6 | V25: -156.8 | W25: -222 | X25: -218.6
K26: (iii) Cash and cash equivalents | L26: 245.1 | M26: 278.9 | N26: 318.2 | O26: 455.1 | P26: 304.1 | S26: Decrease/ (Increase) in loans, other financial assets and other assets | T26: -64.7 | U26: -73.7 | V26: -84 | W26: -135.1 | X26: 25
K27: (iv) Bank balances other than (iii) | L27: 612.8 | M27: 696.7 | N27: 793.8 | O27: 1124.3 | P27: 1258.9 | S27: Increase in inventories | T27: -97.1 | U27: -110.6 | V27: -126 | W27: -73.4 | X27: -261.2
K28: (v) Loans | L28: 18.3 | M28: 20.8 | N28: 23.7 | O28: 30.1 | P28: 9 | S28: Increase in trade payable, other financial liabilities and other liabilities | T28: 176.1 | U28: 200.6 | V28: 228.5 | W28: 525.3 | X28: 216.7
K29: (vi) Other financial assets | L29: 1878.5 | M29: 2136.8 | N29: 2430.5 | O29: 2930.2 | P29: 2115.5 | S29: Increase / (decrease) in provisions | T29: -56.7 | U29: -64.6 | V29: -73.6 | W29: -146.5 | X29: 24.2
K30: (c) Other current assets | L30: 142.8 | M30: 162.7 | N30: 185.3 | O30: 230.3 | P30: 293.7 | S30: Subtotal of adjustments | T30: -163.2 | U30: -185.9 | V30: -212 | W30: -51.7 | X30: -213.9
K31: (d) Non-current assets held for sale | P31: 959.4 | S31: Cash generated from operations | T31: 1435.9 | U31: 1744.6 | V31: 2237.3 | W31: 2355 | X31: 2416.9
K32: Total current assets | L32: 6928.82 | M32: 8435.43 | N32: 8729.68 | O32: 10219.34 | P32: 10945.82 | S32: Less: Income taxes paid (net of refund) | T32: -246.5 | U32: -280.9 | V32: -320 | W32: -406.9 | X32: -504
K33: TOTAL ASSETS | L33: 11533.5 | M33: 13053.2 | N33: 14770.8 | O33: 15576.4 | P33: 17728.9 | S33: Net Cash generated from operating activities | T33: 1189.4 | U33: 1463.7 | V33: 1917.3 | W33: 1948.1 | X33: 1912.9
K35: II. EQUITY AND LIABILITIES | S35: B. CASH FLOW FROM INVESTING ACTIVITIES:
K36: 1. Equity | S36: Purchases of property, plant and equipment (including capital work in progress, other intangible assets and intangible assets under development) | T36: -128.6 | U36: -146.5 | V36: -166.8 | W36: -259.3 | X36: -675.6
K37: (a) Equity share capital | L37: 23.9 | M37: 23.9 | N37: 23.9 | O37: 23.9 | P37: 23.9 | S37: Proceeds from disposal of property, plant and equipment | T37: 31.4 | U37: 35.8 | V37: 40.8 | W37: 72.5 | X37: 40.8
K38: (b) Other equity | L38: 7654.3 | M38: 8712.5 | N38: 9925.8 | O38: 10288.2 | P38: 11960.9 | S38: Investment made in fixed deposits | T38: -2375.1 | U38: -2706.3 | V38: -3082 | W38: -3625.9 | X38: -3755.8
K39: Equity attr. to owners | L39: 7678.2 | M39: 8736.4 | N39: 9949.7 | O39: 10312.1 | P39: 11984.8 | S39: Redemption of fixed deposits | T39: 1918.3 | U39: 2186.3 | V39: 2490 | W39: 2404.2 | X39: 4053.4
K40: (c) Non-controlling interest | L40: 292.8 | M40: 334.2 | N40: 380.7 | O40: 402.3 | P40: 448.8 | S40: Other investments made | T40: -22.1 | U40: -25.2 | V40: -28.7 | W40: -53.4 | X40: -1938.1
K41: Total Equity | L41: 7971 | M41: 9070.6 | N41: 10330.4 | O41: 10714.4 | P41: 12433.6 | S41: Other investments redeemed | T41: 172.9 | U41: 197.2 | V41: 224.6 | W41: 213.9 | X41: 661.6
K42: 2. Liabilities | S42: Investments in associate | X42: -33
...

Sheet Quaterly
B2: Particulars | C2: 45901 | D2: 45992 | E2: 46082
B3: Sales | C3: 4001 | D3: 3737 | E3: 3603
B4: YOY Sales Growth % | C4: 0.1717 | D4: 0.1074 | E4: 0.1462
B5: Material Cost % | C5: 0.3502 | D5: 0.3406 | E5: 0.3463
B6: Employee Cost % | C6: 0.1775 | D6: 0.1931 | E6: 0.1976
B7: Operating Profit | C7: 921 | D7: 828 | E7: 517
B8: OPM % | C8: 0.23 | D8: 0.22 | E8: 0.14
B9: Other Income | C9: 104 | D9: 90 | E9: 65
B10: Exceptional Items | C10: 0 | D10: -53 | E10: -135
B11: Other Income Normal | C11: 104 | D11: 143 | E11: 200
B12: Interest | C12: 35 | D12: 42 | E12: 54
B13: Depreciation | C13: 94 | D13: 95 | E13: 106
... B16: Net Profit | C16: 779 | D16: 653 | E16: 251

Sheet Assumptions 
C2: [ | D2: Suzlon Energy
D3: Consolidated Profit & Loss account
E4: 44256 | F4: 44621 | G4: 44986 | H4: 45352 | I4: Mar 25
C5: Particulars
C6: Revenue From Operations [Net] | E6: ='Consolidated Fs'!C6 -> 9654.9 | F6: ='Consolidated Fs'!D6 -> 10732.8 | G6: ='Consolidated Fs'!E6 -> 11981.4 | H6: ='Consolidated Fs'!F6 -> 12667.6 | I6: ='Consolidated Fs'!G6 -> 12964.5
C7: revenue growth | F7: =(F6-E6)/E6 -> 0.11164279 | G7: =(G6-F6)/F6 -> 0.11633497 | H7: =(H6-G6)/G6 -> 0.057272105 | I7: =(I6-H6)/H6 -> 0.023437747
C9: less: Material Consumed | E9: ='Consolidated Fs'!C10+'Consolidated Fs'!C11+'Consolidated Fs'!C12 -> 4110.3 | F9: ='Consolidated Fs'!D10+'Consolidated Fs'!D11+'Consolidated Fs'!D12 -> 4512.5 | G9: ='Consolidated Fs'!E10+'Consolidated Fs'!E11+'Consolidated Fs'!E12 -> 4875.6 | H9: =SUM('Consolidated Fs'!F10:F12) -> 4937.6 | I9: ='Consolidated Fs'!G10+'Consolidated Fs'!G11+'Consolidated Fs'!G12 -> 4764.3
C10: less: Employee Cost | E10: ='Consolidated Fs'!C13 -> 1649.4 | F10: ='Consolidated Fs'!D13 -> 1814.5 | G10: ='Consolidated Fs'!E13 -> 1950 | H10: ='Consolidated Fs'!F13 -> 2201 | I10: ='Consolidated Fs'!G13 -> 2453.9
C11: less: Other Expenses | E11: ='Consolidated Fs'!C16 -> 2548.9 | F11: ='Consolidated Fs'!D16 -> 2784.6 | G11: ='Consolidated Fs'!E16 -> 3050 | H11: ='Consolidated Fs'!F16 -> 3283.5 | I11: ='Consolidated Fs'!G16 -> 3234.2
C12: Total Expenses | E12: =SUM(E9:E11) -> 8308.6 | F12: =SUM(F9:F11) -> 9111.6 | G12: =SUM(G9:G11) -> 9875.6 | H12: =SUM(H9:H11) -> 10422.1 | I12: =SUM(I9:I11) -> 10452.4
C14: EBITDA | E14: =E6-E12 -> 1346.3 | F14: =F6-F12 -> 1621.2 | G14: =G6-G12 -> 2105.8 | H14: =H6-H12 -> 2245.5 | I14: =I6-I12 -> 2512.1
C16: less: Depreciation & Amortization | E16: ='Consolidated Fs'!C15 -> 215.9 | F16: ='Consolidated Fs'!D15 -> 240 | G16: ='Consolidated Fs'!E15 -> 265 | H16: ='Consolidated Fs'!F15 -> 299.3 | I16: ='Consolidated Fs'!G15 -> 357.2
C18: EBIT | E18: =E14-E16 -> 1130.4 | F18: =F14-F16 -> 1381.2 | G18: =G14-G16 -> 1840.8 | H18: =H14-H16 -> 1946.2 | I18: =I14-I16 -> 2154.9
C20: add: Other income | E20: ='Consolidated Fs'!C7 -> 264.5 | F20: ='Consolidated Fs'!D7 -> 320.4 | G20: ='Consolidated Fs'!E7 -> 353.7 | H20: ='Consolidated Fs'!F7 -> 310.8 | I20: ='Consolidated Fs'!G7 -> 493.7
C21: less: Interest Expense | E21: ='Consolidated Fs'!C14 -> 75.8 | F21: ='Consolidated Fs'!D14 -> 85.4 | G21: ='Consolidated Fs'!E14 -> 95 | H21: ='Consolidated Fs'!F14 -> 112.4 | I21: ='Consolidated Fs'!G14 -> 121.7
C23: EBT | E23: =E18+E20-E21 -> 1319.1 | F23: =F18+F20-F21 -> 1616.2 | G23: =G18+G20-G21 -> 2099.5 | H23: =H18+H20-H21 -> 2144.6 | I23: =I18+I20-I21 -> 2526.9
C25: less: Tax | E25: ='Consolidated Fs'!C21 -> 254.6 | F25: ='Consolidated Fs'!D21 -> 305.9 | G25: ='Consolidated Fs'!E21 -> 404 | H25: ='Consolidated Fs'!F21 -> 211.7 | I25: ='Consolidated Fs'!G21 -> 311
C26: less: Non Controlling interest
C28: PAT | E28: =E23-E25-E26 -> 1064.5 | F28: =F23-F25-F26 -> 1310.3 | G28: =G23-G25-G26 -> 1695.5 | H28: =H23-H25-H26 -> 1932.9 | I28: =I23-I25-I26 -> 2215.9
C30: Historical Growth
C31: Average Growth | E31: =AVERAGE(F7:I7) -> 0.077171904
C32: CAGR | E32: =(I6/E6)^(1/4)-1 -> 0.076470166 | F32: =_xlfn.RRI(4,E6,I6) -> 0.076470166
C34: Margin Analysis
C35: EBITDA Margin | E35: =E14/E6 -> 0.13944215 | F35: =F14/F6 -> 0.15105098 | G35: =G14/G6 -> 0.17575575 | H35: =H14/H6 -> 0.17726325 | I35: =I14/I6 -> 0.1937676
C36: EBIT Margin | E36: =E18/E6 -> 0.11708045 | F36: =F18/F6 -> 0.12868962 | G36: =G18/G6 -> 0.15363814 | H36: =H18/H6 -> 0.15363605 | I36: =I18/I6 -> 0.16621543
C37: EBT Margin | E37: =E23/E6 -> 0.13662493 | F37: =F23/F6 -> 0.15058512 | G37: =G23/G6 -> 0.17522994 | H37: =H23/H6 -> 0.16929805 | I37: =I23/I6 -> 0.19490918
C38: PAT Margin | E38: =E28/E6 -> 0.1102549 | F38: =F28/F6 -> 0.12208371 | G38: =G28/G6 -> 0.14151101 | H38: =H28/H6 -> 0.15258613 | I38: =I28/I6 -> 0.17092059
C40: Tax Rate
C41: Effective Tax Rate | E41: =E25/E23 -> 0.19301039 | F41: =F25/F23 -> 0.18927113 | G41: =G25/G23 -> 0.19242677 | H41: =H25/H23 -> 0.098713047 | I41: =I25/I23 -> 0.12307571
C42: Marginal Tax Rate | E42: 0.25 | F42: 0.25 | G42: 0.25 | H42: 0.25 | I42: 0.25
C44: Return on Capital
C45: EBIT(1-t) | E45: =E18*(1-E42) -> 847.8 | F45: =F18*(1-F42) -> 1035.9 | G45: =G18*(1-G42) -> 1380.6 | H45: =H18*(1-H42) -> 1459.65 | I45: =I18*(1-I42) -> 1616.175
C46: Book Equity | E46: ='Consolidated Fs'!L41 -> 7971 | F46: ='Consolidated Fs'!M41 -> 9070.6 | G46: ='Consolidated Fs'!N41 -> 10330.4 | H46: ='Consolidated Fs'!O41 -> 10714.4 | I46: ='Consolidated Fs'!P41 -> 12433.6
C47: Book Debt | E47: ='Consolidated Fs'!L45+'Consolidated Fs'!L53 -> 935.6 | F47: ='Consolidated Fs'!M45+'Consolidated Fs'!M53 -> 1065.4 | G47: ='Consolidated Fs'!N45+'Consolidated Fs'!N53 -> 1212 | H47: ='Consolidated Fs'!O45+'Consolidated Fs'!O53 -> 1213.1 | I47: ='Consolidated Fs'!P45+'Consolidated Fs'!P53 -> 1062.8
C48: Cash and Cash Equivalent | E48: ='Consolidated Fs'!L26 -> 245.1 | F48: ='Consolidated Fs'!M26 -> 278.9 | G48: ='Consolidated Fs'!N26 -> 318.2 | H48: ='Consolidated Fs'!O26 -> 455.1 | I48: ='Consolidated Fs'!P26 -> 304.1
C49: Capital Employed | E49: =E46+E47-E48 -> 8661.5 | F49: =F46+F47-F48 -> 9857.1 | G49: =G46+G47-G48 -> 11224.2 | H49: =H46+H47-H48 -> 11472.4 | I49: =I46+I47-I48 -> 13192.3
C51: Pre Tax Return on Capital | E51: =E18/E49 -> 0.13050857 | F51: =F18/F49 -> 0.14012235 | G51: =G18/G49 -> 0.16400278 | H51: =H18/H49 -> 0.16964192 | I51: =I18/I49 -> 0.16334528
C52: Post Tax Return on Capital | E52: =E45/E49 -> 0.097881429 | F52: =F45/F49 -> 0.10509176 | G52: =G45/G49 -> 0.12300208 | H52: =H45/H49 -> 0.12723144 | I52: =I45/I49 -> 0.12250896

Sheet BETA
B2: Alkem Labs | F2: NIFTY
B3: Date | C3: Closing Price | F3: Date | G3: Closing Price
B4: 44287 | C4: 2637.8247 | F4: 44287 | G4: 14867.35
B5: 44291 | C5: 2573.1968 | D5: =(C5-C4)/C4 -> -0.024500464 | F5: 44291 | G5: 14637.8 | H5: =(G5-G4)/G4 -> -0.015439861 | K5: =SLOPE(D5:D1237,H5:H1237) -> 0.52092555
B6: 44292 | C6: 2587.833 | D6: =(C6-C5)/C5 -> 0.0056879562 | F6: 44292 | G6: 14683.5 | H6: =(G6-G5)/G5 -> 0.0031220672
B7: 44293 | C7: 2591.8247 | D7: =(C7-C6)/C6 -> 0.0015424872 | F7: 44293 | G7: 14819.05 | H7: =(G7-G6)/G6 -> 0.009231437 | K7: =(_xlfn.COVARIANCE.S(D5:D1237,H5:H1237))/_xlfn.VAR.S(H5:H1237) -> 0.52092555
B8: 44294 | C8: 2572.2461 | D8: =(C8-C7)/C7 -> -0.0075539882 | F8: 44294 | G8: 14873.8 | H8: =(G8-G7)/G7 -> 0.0036945689
B9: 44295 | C9: 2691.8555 | D9: =(C9-C8)/C8 -> 0.046499973 | F9: 44295 | G9: 14834.85 | H9: =(G9-G8)/G8 -> -0.0026187118
B10: 44298 | C10: 2609.4072 | D10: =(C10-C9)/C9 -> -0.030628777 | F10: 44298 | G10: 14310.8 | H10: =(G10-G9)/G9 -> -0.035325589 | K10: SUMMARY OUTPUT
B11: 44299 | C11: 2615.2996 | D11: =(C11-C10)/C10 -> 0.0022581121 | F11: 44299 | G11: 14504.8 | H11: =(G11-G10)/G10 -> 0.013556196
B12: 44301 | C12: 2614.0645 | D12: =(C12-C11)/C11 -> -0.00047226231 | F12: 44301 | G12: 14581.45 | H12: =(G12-G11)/G11 -> 0.0052844846 | K12: Regression Statistics
B13: 44302 | C13: 2652.4136 | D13: =(C13-C12)/C12 -> 0.014670304 | F13: 44302 | G13: 14617.85 | H13: =(G13-G12)/G12 -> 0.0024962822 | K13: Multiple R | L13: 0.30810353
B14: 44305 | C14: 2612.7817 | D14: =(C14-C13)/C13 -> -0.014941801 | F14: 44305 | G14: 14359.45 | H14: =(G14-G13)/G13 -> -0.017676979 | K14: R Square | L14: 0.094927785
B15: 44306 | C15: 2604.7502 | D15: =(C15-C14)/C14 -> -0.0030739246 | F15: 44306 | G15: 14296.4 | H15: =(G15-G14)/G14 -> -0.004390823 | K15: Adjusted R Square | L15: 0.094192552
B16: 44308 | C16: 2658.6387 | D16: =(C16-C15)/C15 -> 0.02068852 | F16: 44308 | G16: 14406.15 | H16: =(G16-G15)/G15 -> 0.0076767576 | K16: Standard Error | L16: 0.013954873
B17: 44309 | C17: 2640.6758 | D17: =(C17-C16)/C16 -> -0.0067564242 | F17: 44309 | G17: 14341.35 | H17: =(G17-G16)/G16 -> -0.0044981331 | K17: Observations | L17: 1233
B18: 44312 | C18: 2659.1614 | D18: =(C18-C17)/C17 -> 0.0070003277 | F18: 44312 | G18: 14485 | H18: =(G18-G17)/G17 -> 0.010016518
B19: 44313 | C19: 2632.2649 | D19: =(C19-C18)/C18 -> -0.010114649 | F19: 44313 | G19: 14653.05 | H19: =(G19-G18)/G18 -> 0.011601643 | K19: ANOVA
B20: 44314 | C20: 2637.1597 | D20: =(C20-C19)/C19 -> 0.0018595299 | F20: 44314 | G20: 14864.55 | H20: =(G20-G19)/G19 -> 0.014433855 | L20: df | M20: SS | N20: MS | O20: F | P20: Significance F
B21: 44315 | C21: 2624.7566 | D21: =(C21-C20)/C20 -> -0.004703195 | F21: 44315 | G21: 14894.9 | H21: =(G21-G20)/G20 -> 0.00204181 | K21: Regression | L21: 1 | M21: 0.025143164 | N21: 0.025143164 | O21: 129.11246 | P21: 1.5968346e-28
B22: 44316 | C22: 2622.2375 | D22: =(C22-C21)/C21 -> -0.00095972441 | F22: 44316 | G22: 14631.1 | H22: =(G22-G21)/G21 -> -0.017710812 | K22: Residual | L22: 1231 | M22: 0.23972306 | N22: 0.00019473847
B23: 44319 | C23: 2625.0415 | D23: =(C23-C22)/C22 -> 0.0010692987 | F23: 44319 | G23: 14634.15 | H23: =(G23-G22)/G22 -> 0.00020851346 | K23: Total | L23: 1232 | M23: 0.26486622
B24: 44320 | C24: 2659.8271 | D24: =(C24-C23)/C23 -> 0.013251465 | F24: 44320 | G24: 14496.5 | H24: =(G24-G23)/G23 -> -0.0094061074
B25: 44321 | C25: 2750.9236 | D25: =(C25-C24)/C24 -> 0.034249006 | F25: 44321 | G25: 14617.85 | H25: =(G25-G24)/G24 -> 0.0083709592 | L25: Coefficients | M25: Standard Error | N25: t Stat | O25: P-value | P25: Lower 95% | Q25: Upper 95% | R25: Lower 95.0% | S25: Upper 95.0%
B26: 44322 | C26: 2720.0354 | D26: =(C26-C25)/C25 -> -0.011228296 | F26: 44322 | G26: 14724.8 | H26: =(G26-G25)/G25 -> 0.007316411 | K26: Intercept | L26: 0.00048184429 | M26: 0.00039777239 | N26: 1.2113568 | O26: 0.22599117 | P26: -0.00029854256 | Q26: 0.0012622312 | R26: -0.00029854256 | S26: 0.0012622312
B27: 44323 | C27: 2763.2793 | D27: =(C27-C26)/C26 -> 0.015898284 | F27: 44323 | G27: 14823.15 | H27: =(G27-G26)/G26 -> 0.0066792477 | K27: X Variable 1 | L27: 0.52092555 | M27: 0.045844957 | N27: 11.362767 | O27: 1.5968346e-28 | P27: 0.43098265 | Q27: 0.61086845 | R27: 0.43098265 | S27: 0.61086845
B28: 44326 | C28: 2880.9407 | D28: =(C28-C27)/C27 -> 0.042580342 | F28: 44326 | G28: 14942.35 | H28: =(G28-G27)/G27 -> 0.0080414227
B29: 44327 | C29: 2888.8289 | D29: =(C29-C28)/C28 -> 0.0027380583 | F29: 44327 | G29: 14850.75 | H29: =(G29-G28)/G28 -> -0.0061302012
B30: 44328 | C30: 2854.6616 | D30: =(C30-C29)/C29 -> -0.011827366 | F30: 44328 | G30: 14696.5 | H30: =(G30-G29)/G29 -> -0.010386681
B31: 44330 | C31: 2844.6821 | D31: =(C31-C30)/C30 -> -0.0034958582 | F31: 44330 | G31: 14677.8 | H31: =(G31-G30)/G30 -> -0.0012724251
B32: 44333 | C32: 2831.9941 | D32: =(C32-C31)/C31 -> -0.0044602482 | F32: 44333 | G32: 14923.15 | H32: =(G32-G31)/G31 -> 0.01671576
B33: 44334 | C33: 2803.1965 | D33: =(C33-C32)/C32 -> -0.010168668 | F33: 44334 | G33: 15108.1 | H33: =(G33-G32)/G32 -> 0.012393443
B34: 44335 | C34: 2826.0063 | D34: =(C34-C33)/C33 -> 0.0081370729 | F34: 44335 | G34: 15030.15 | H34: =(G34-G33)/G33 -> -0.0051594324
B35: 44336 | C35: 2842.0681 | D35: =(C35-C34)/C34 -> 0.0056835568 | F35: 44336 | G35: 14906.05 | H35: =(G35-G34)/G34 -> -0.0082567761
B36: 44337 | C36: 2854.5664 | D36: =(C36-C35)/C35 -> 0.0043976043 | F36: 44337 | G36: 15175.3 | H36: =(G36-G35)/G35 -> 0.018063136
B37: 44340 | C37: 2847.5811 | D37: =(C37-C36)/C36 -> -0.0024470797 | F37: 44340 | G37: 15197.7 | H37: =(G37-G36)/G36 -> 0.0014761086
B38: 44341 | C38: 2760.9507 | D38: =(C38-C37)/C37 -> -0.030422443 | F38: 44341 | G38: 15208.45 | H38: =(G38-G37)/G37 -> 0.00070734387
B39: 44342 | C39: 2790.0334 | D39: =(C39-C38)/C38 -> 0.010533605 | F39: 44342 | G39: 15301.45 | H39: =(G39-G38)/G38 -> 0.0061150215
... B1237: 46111 | C1237: 5299 | D1237: =(C1237-C1236)/C1236 -> -0.008513425 | F1237: 46111 | G1237: 22331.4 | H1237: =(G1237-G1236)/G1236 -> -0.021393856

Sheet Stock
M3: Recommendation
M4: HOLD — Alkem Laboratories trades at ₹5458, valuing the company at ₹65,253 Cr. With FY25 consolidated revenue of ₹12,965 Cr (+2.3% YoY) and PAT of ₹2,215 Cr (+22.3% YoY), the stock offers a balanced risk-reward profile. Current P/E of 27.2x, ROCE of 20.4%, and dividend yield of 0.84% reflect a fairly valued mid-cap pharmaceutical company with steady fundamentals. Suitable for long-term investors with moderate growth expectations.
M13: Alkem Laboratories is India's 5th largest pharmaceutical company by domestic market share (4.1% in 9M FY25), with leadership in anti-infectives and strong presence in GI, pain management, and vitamins segments. The company has demonstrated consistent profit growth with FY21-FY25 PAT CAGR of 8.1%, though revenue growth has moderated to 9.2% CAGR over five years due to market maturity and competitive pressures. Key investment considerations: (1) Domestic formulations business stabilizing with volume recovery; (2) Export momentum gaining from emerging market focus; (3) Specialty and complex generics portfolio contributing to margin expansion; (4) US FDA compliance maintained with no Form 483 in recent inspections. Risk factors include generic price compression in key markets, forex volatility, and regulatory challenges. Management guidance suggests steady execution with EBITDA margin expansion target of 22-25%. The stock is suitable for value-conscious investors seeking stability over aggressive growth.
N22: Financial Year | O22: Revenue (₹ Crore) | P22: Profit After Tax (PAT) (₹ Crore) | Q22: Revenue Change (%) | R22: PAT Change (%) | S22: ROCE (%)
N23: FY 2024-25 | O23: 12965 | P23: 2215 | Q23: 0.023444901 | R23: 0.22308117 | S23: 0.204
N24: FY 2023-24 | O24: 12668 | P24: 1811 | Q24: 0.092163118 | R24: 0.79841112 | S24: 0.204
N25: FY 2022-23 | O25: 11599 | P25: 1007 | Q25: 0.090746662 | R25: -0.40059524 | S25: 0.204
N26: FY 2021-22 | O26: 10634 | P26: 1680 | Q26: 0.19954879 | R26: 0.038318912 | S26: 0.204
B27: Metric | C27: Value | N27: FY 2020-21 | O27: 8865 | P27: 1618 | Q27: - | R27: - | S27: 0.204
B28: Market Cap | C28: ₹ 65,253 Cr.
B29: Current Price | C29: 5458
B30: High / Low | C30: ₹ 5,934 / ₹ 4,716
B31: Stock P/E | C31: 27.2
B32: Book Value | C32: 1116 | M32: Alkem Laboratories posts FY25 revenue of ₹12,965 Cr, PAT up 22% YoY to ₹2,215 Cr; stock trades at ₹5,458
B33: Dividend Yield | C33: 0.0084
B34: ROCE | C34: 0.204
B35: ROE | C35: 0.194
B36: Face Value | C36: 2
B48: Data source: Screener.in | As of May 18, 2026

Sheet WACC
B1: Weighted Average Cost of Capital
B4: Capital Structure
B5: Total Debt | C5: ='Consolidated Fs'!P45+'Consolidated Fs'!P53+'Consolidated Fs'!P46+'Consolidated Fs'!P54 -> 1380.9
B6: Total Equity | C6: ='Consolidated Fs'!P39 -> 11984.8
B7: Total Mix | C7: =SUM(C5:C6) -> 13365.7
B8: % of Debt | C8: =C5/C7 -> 0.1033167
B9: % of Equity | C9: =C6/C7 -> 0.8966833
B10: Debt to Equity | C10: =C5/C6 -> 0.11522095
B14: Cost of Equity | E14: Cost of Debt
B15: Risk free rate(Rf) | C15: 0.066 | E15: Source | F15: Cost
B16: Beta | C16: =BETA!K5 -> 0.52092555 | E16: Cost of debt* | F16: ='Consolidated Fs'!G14/('Consolidated Fs'!P45+'Consolidated Fs'!P46+'Consolidated Fs'!P54+'Consolidated Fs'!P53) -> 0.088130929
B17: Market risk premium | C17: 0.07 | E17: Tax rate | F17: =AVERAGE('Assumptions '!E41:I41) -> 0.15929941
B18: Cost of equity | C18: =C15+C16*C17 -> 0.10246479 | E18: Cost of Debt after tax | F18: =F16*(1-F17) -> 0.074091724
B21: WACC
B22: Source | C22: Weight | D22: Cost | E22: Weighted Cost
B23: Debt | C23: =C8 -> 0.1033167 | D23: =F18 -> 0.074091724 | E23: =C23*D23 -> 0.0076549124
B24: Equity | C24: =C9 -> 0.8966833 | D24: =C18 -> 0.10246479 | E24: =C24*D24 -> 0.091878465
B25: WACC | E25: =SUM(E23:E24) -> 0.099533377

Sheet Fixed Asset Schedule 
B1: Alkem Labs "Fixed Asset Schedule "
B2: Particular | C2: 44256 | D2: 44621 | E2: 44986 | F2: 45352 | G2: 45717
B3: Beginning balance | D3: =C7 -> 1518.8 | E3: =D7 -> 1654.3 | F3: =E7 -> 1798.4 | G3: =F7 -> 2161.5
B4: Add: Net Purchases | D4: =D5-D3 -> 375.5 | E4: =E5-E3 -> 409.1 | F4: =F5-F3 -> 662.4 | G4: =G5-G3 -> 259.6
B5: Total Fixed Assets | C5: =C6+C7 -> 1734.7 | D5: =D6+D7 -> 1894.3 | E5: =E6+E7 -> 2063.4 | F5: =F6+F7 -> 2460.8 | G5: =G6+G7 -> 2421.1
B6: Less: Depreciation | C6: ='Consolidated Fs'!C15 -> 215.9 | D6: ='Consolidated Fs'!D15 -> 240 | E6: ='Consolidated Fs'!E15 -> 265 | F6: ='Consolidated Fs'!F15 -> 299.3 | G6: ='Consolidated Fs'!G15 -> 357.2
B7: Closing Balance(Fixed Asests ) | C7: ='Consolidated Fs'!L7 -> 1518.8 | D7: ='Consolidated Fs'!M7 -> 1654.3 | E7: ='Consolidated Fs'!N7 -> 1798.4 | F7: ='Consolidated Fs'!O7 -> 2161.5 | G7: ='Consolidated Fs'!P7 -> 2063.9
B9: Net Capital expenditure | D9: =D4-D6 -> 135.5 | E9: =E4-E6 -> 144.1 | F9: =F4-F6 -> 363.1 | G9: =G4-G6 -> -97.6
B10: Net Capital expenditure / Sales percentage | D10: =IFERROR(D9/D3,0) -> 0.08921517 | E10: =IFERROR(E9/E3,0) -> 0.087106329 | F10: =IFERROR(F9/F3,0) -> 0.20190169 | G10: =IFERROR(G9/G3,0) -> -0.045153828
B12: Median Capital expenditure /Sales percentage | C12: =MEDIAN(D10:G10) -> 0.088160749
B13: Average Capital expenditure /Sales percentage | C13: =AVERAGE(D10:G10) -> 0.08326734

Sheet Change in Working Capital 
B2: Change in Working Capital
B3: Particular | C3: 44256 | D3: 44621 | E3: 44986 | F3: 45352 | G3: 45717
B4: Inventory | C4: ='Consolidated Fs'!L22 -> 1823.9 | D4: ='Consolidated Fs'!M22 -> 2067.8 | E4: ='Consolidated Fs'!N22 -> 2341.5 | F4: ='Consolidated Fs'!O22 -> 2661.2 | G4: ='Consolidated Fs'!P22 -> 2922.4
B5: Trade Receivables | C5: ='Consolidated Fs'!L25 -> 1589.3 | D5: ='Consolidated Fs'!M25 -> 1805.2 | E5: ='Consolidated Fs'!N25 -> 2053.7 | F5: ='Consolidated Fs'!O25 -> 2252.8 | G5: ='Consolidated Fs'!P25 -> 2466.3
B6: Trade Payable | C6: ='Consolidated Fs'!L55 -> 1069.41 | D6: ='Consolidated Fs'!M55 -> 1173.38 | E6: ='Consolidated Fs'!N55 -> 1165.02 | F6: ='Consolidated Fs'!O55 -> 1748.12 | G6: ='Consolidated Fs'!P55 -> 1839.35
B7: Non Cash working Capital | C7: =C4+C5-C6 -> 2343.79 | D7: =D4+D5-D6 -> 2699.62 | E7: =E4+E5-E6 -> 3230.18 | F7: =F4+F5-F6 -> 3165.88 | G7: =G4+G5-G6 -> 3549.35
B8: Change in Working Capital | D8: =D7-C7 -> 355.83 | E8: =E7-D7 -> 530.56 | F8: =F7-E7 -> -64.3 | G8: =G7-F7 -> 383.47
B9: changein working Capital /percentage of sales | D9: =D8/'Consolidated Fs'!D6 -> 0.033153511 | E9: =E8/'Consolidated Fs'!E6 -> 0.04428197 | F9: =F8/'Consolidated Fs'!F6 -> -0.0050759418 | G9: =G8/'Consolidated Fs'!G6 -> 0.029578464
B11: Median Non Cash working Capital /Sales percentage | C11: =MEDIAN(D9:G9) -> 0.031365988
B12: Average Non Cash working Capital /Sales percentage | C12: =AVERAGE(D9:G9) -> 0.025484501

Sheet FCFF
B2: Alkem Labs "Free Cash Flow "
B3: Particular | C3: 44256 | D3: 44621 | E3: 44986 | F3: 45352 | G3: 45717
B4: EBIT | C4: ='Assumptions '!E18 -> 1130.4 | D4: ='Assumptions '!F18 -> 1381.2 | E4: ='Assumptions '!G18 -> 1840.8 | F4: ='Assumptions '!H18 -> 1946.2 | G4: ='Assumptions '!I18 -> 2154.9
B5: Less: Tax on EBIT | C5: ='Assumptions '!E25/'Assumptions '!E23 -> 0.19301039 | D5: ='Assumptions '!F25/'Assumptions '!F23 -> 0.18927113 | E5: ='Assumptions '!G25/'Assumptions '!G23 -> 0.19242677 | F5: ='Assumptions '!H25/'Assumptions '!H23 -> 0.098713047 | G5: ='Assumptions '!I25/'Assumptions '!I23 -> 0.12307571
B6: EBIT * (1- Tax) | C6: =C4*(1-C5) -> 912.22106 | D6: =D4*(1-D5) -> 1119.7787 | E6: =E4*(1-E5) -> 1486.5808 | F6: =F4*(1-F5) -> 1754.0847 | G6: =G4*(1-G5) -> 1889.6842
B7: Less: Net Capital expenditure | C7: 0 | D7: ='Fixed Asset Schedule '!D9 -> 135.5 | E7: ='Fixed Asset Schedule '!E9 -> 144.1 | F7: ='Fixed Asset Schedule '!F9 -> 363.1 | G7: ='Fixed Asset Schedule '!G9 -> -97.6
B8: Less: Net Change in working Capital | C8: 0 | D8: ='Change in Working Capital '!D8 -> 355.83 | E8: ='Change in Working Capital '!E8 -> 530.56 | F8: ='Change in Working Capital '!F8 -> -64.3 | G8: ='Change in Working Capital '!G8 -> 383.47
B9: Reinvestment | C9: =SUM(C7:C8) -> 0 | D9: =SUM(D7:D8) -> 491.33 | E9: =SUM(E7:E8) -> 674.66 | F9: =SUM(F7:F8) -> 298.8 | G9: =SUM(G7:G8) -> 285.87
B10: Free Cash Flow | C10: =C6-C9 -> 912.22106 | D10: =D6-D9 -> 628.44872 | E10: =E6-E9 -> 811.9208 | F10: =F6-F9 -> 1455.2847 | G10: =G6-G9 -> 1603.8142
B12: Reinvestment Rate | C12: 0 | D12: =D9/D6 -> 0.43877419 | E12: =E9/E6 -> 0.45383339 | F12: =F9/F6 -> 0.17034525 | G12: =G9/G6 -> 0.15127925
B14: Median Reinvestment rate /Sales percentage | C14: =MEDIAN(D12:G12) -> 0.30455972
B15: Average Reinvestment rate /Sales percentage | C15: =AVERAGE(D12:G12) -> 0.30355802

Sheet Growth Scenario
B2: Alkem Labs "Growth Scenarios"
B4: Scenario 1: High Growth
B5: INR Cr. | C5: LTM | D5: Y1E | E5: Y2E | F5: Y3E | G5: Y4W | H5: Y5E | I5: Y6E | J5: Y7E | K5: Y8E | L5: Y9E | M5: Y10E
B6: Sales | C6: ='Consolidated Fs'!G6 -> 12964.5 | D6: =C6*(1+D7) -> 14059.449 | E6: =D6*(1+E7) -> 15218.04 | F6: =E6*(1+F7) -> 16440.898 | G6: =F6*(1+G7) -> 17728.302 | H6: =G6*(1+H7) -> 19080.158 | I6: =H6*(1+I7) -> 20495.969 | J6: =I6*(1+J7) -> 21974.804 | K6: =J6*(1+K7) -> 23515.274 | ... M6: =L6*(1+M7) -> 26773.132 | O6: Risk Free Rate | P6: 0.066
B7: Sales Growth % | D7: =N7 -> 0.084457449 | E7: =D7-$P$9 -> 0.082406621 | F7: =E7-$P$9 -> 0.080355794 | G7: =F7-$P$9 -> 0.078304966 | H7: =G7-$P$9 -> 0.076254138 | I7: =H7-$P$9 -> 0.074203311 | J7: =I7-$P$9 -> 0.072152483 | K7: =J7-$P$9 -> 0.070101655 | L7: =K7-$P$9 -> 0.068050828 | M7: =L7-$P$9 -> 0.066 | N7: =MEDIAN('Assumptions '!F7:I7) -> 0.084457449
B9: Scenario 2: Average Growth | O9: =N7-P6 -> 0.018457449 | P9: =O9/9 -> 0.0020508277
B10: INR Cr. | C10: LTM | D10: Y1E | E10: Y2E | F10: Y3E | G10: Y4W | H10: Y5E | I10: Y6E | J10: Y7E | K10: Y8E | L10: Y9E | M10: Y10E
B11: Sales | C11: =C6 -> 12964.5 | D11: =C11*(1+D12) -> 13964.995 | E11: =D11*(1+E12) -> 15027.693 | F11: =E11*(1+F12) -> 16155.109 | G11: =F11*(1+G12) -> 17349.746 | H11: =G11*(1+H12) -> 18614.079 | I11: =H11*(1+I12) -> 19950.545 | J11: =I11*(1+J12) -> 21361.526 | K11: =J11*(1+K12) -> 22849.342 | ... M11: =L11*(1+M12) -> 26064.323
B12: Sales Growth % | D12: =AVERAGE('Assumptions '!F7:I7) -> 0.077171904 | E12: =D12-O12 -> 0.076097248 | F12: =E12-O12 -> 0.075022592 | G12: =F12-O12 -> 0.073947936 | H12: =G12-O12 -> 0.07287328 | I12: =H12-O12 -> 0.071798624 | J12: =I12-O12 -> 0.070723968 | K12: =J12-O12 -> 0.069649312 | L12: =K12-O12 -> 0.068574656 | M12: 0.0675 | N12: =D12-M12 -> 0.0096719044 | O12: =N12/9 -> 0.001074656
B14: Scenario 3: EBIT Growth
B15: INR Cr. | C15: LTM | D15: Y1E | E15: Y2E | F15: Y3E | G15: Y4W | H15: Y5E | I15: Y6E | J15: Y7E | K15: Y8E | L15: Y9E | M15: Y10E
B16: Sales | C16: =C11 -> 12964.5 | D16: =C16*(1+D17) -> 13448.222 | E16: =D16*(1+E17) -> 13995.102 | F16: =E16*(1+F17) -> 14611.165 | G16: =F16*(1+G17) -> 15303.357 | H16: =G16*(1+H17) -> 16079.674 | I16: =H16*(1+I17) -> 16949.308 | K16: =J16*(1+K17) -> #VALUE! | L16: =K16*(1+L17) -> #VALUE! | M16: =L16*(1+M17) -> #VALUE!
B17: Sales Growth % | D17: ='Assumptions '!I52*FCFF!C14 -> 0.037311296 | E17: =D17-$O$17 -> 0.040665596 | F17: =E17-$O$17 -> 0.044019897 | G17: =F17-$O$17 -> 0.047374197 | H17: =G17-$O$17 -> 0.050728498 | I17: =H17-$O$17 -> 0.054082798 | J17: =I17-$O$17 -> 0.057437099 | K17: =J17-$O$17 -> 0.060791399 | L17: =K17-$O$17 -> 0.0641457 | M17: 0.0675 | N17: =D17-M17 -> -0.030188704 | O17: =N17/9 -> -0.0033543004
B19: Live Scenario | C19: 1
B20: INR Cr. | C20: LTM | D20: Y1E | E20: Y2E | F20: Y3E | G20: Y4W | H20: Y5E | I20: Y6E | J20: Y7E | K20: Y8E | L20: Y9E | M20: Y10E
B21: Sales | C21: =C6 -> 12964.5 | D21: =C21*(1+D22) -> 14059.449 | E21: =D21*(1+E22) -> 15218.04 | F21: =E21*(1+F22) -> 16440.898 | G21: =F21*(1+G22) -> 17728.302 | H21: =G21*(1+H22) -> 19080.158 | I21: =H21*(1+I22) -> 20495.969 | J21: =I21*(1+J22) -> 21974.804 | K21: =J21*(1+K22) -> 23515.274 | ... M21: =L21*(1+M22) -> 26773.132
B22: Sales Growth % | D22: =CHOOSE($C$19,D7,D12,D17) -> 0.084457449 | E22: =CHOOSE($C$19,E7,E12,E17) -> 0.082406621 | F22: =CHOOSE($C$19,F7,F12,F17) -> 0.080355794 | G22: =CHOOSE($C$19,G7,G12,G17) -> 0.078304966 | H22: =CHOOSE($C$19,H7,H12,H17) -> 0.076254138 | I22: =CHOOSE($C$19,I7,I12,I17) -> 0.074203311 | J22: =CHOOSE($C$19,J7,J12,J17) -> 0.072152483 | K22: =CHOOSE($C$19,K7,K12,K17) -> 0.070101655 | ... M22: =CHOOSE($C$19,M7,M12,M17) -> 0.066

Sheet Valuation 
B1: Alkem Labs - "VALUATION"
D2: 1 | E2: 2 | F2: 3 | G2: 4 | H2: 5 | I2: 6 | J2: 7 | K2: 8 | L2: 9 | M2: 10
B3: INR Cr | C3: LTM | D3: Y1E | E3: Y2E | F3: Y3E | G3: Y4W | H3: Y5E | I3: Y6E | J3: Y7E | K3: Y8E | L3: Y9E | M3: Y10E | O3: Terminal Year | Q3: Terminal growth rate % | R3: 0.05
B4: Sales | C4: ='Growth Scenario'!C21 -> 12964.5 | D4: ='Growth Scenario'!D21 -> 14059.449 | E4: ='Growth Scenario'!E21 -> 15218.04 | F4: ='Growth Scenario'!F21 -> 16440.898 | G4: ='Growth Scenario'!G21 -> 17728.302 | H4: ='Growth Scenario'!H21 -> 19080.158 | I4: ='Growth Scenario'!I21 -> 20495.969 | J4: ='Growth Scenario'!J21 -> 21974.804 | ... M4: ='Growth Scenario'!M21 -> 26773.132 | O4: =M4*(1+R3) -> 28111.788 | Q4: Cost of Capital % | R4: =WACC!E25 -> 0.099533377
B5: Sales Growth | D5: ='Growth Scenario'!D22 -> 0.084457449 | E5: ='Growth Scenario'!E22 -> 0.082406621 | F5: ='Growth Scenario'!F22 -> 0.080355794 | G5: ='Growth Scenario'!G22 -> 0.078304966 | H5: ='Growth Scenario'!H22 -> 0.076254138 | I5: ='Growth Scenario'!I22 -> 0.074203311 | J5: ='Growth Scenario'!J22 -> 0.072152483 | K5: ='Growth Scenario'!K22 -> 0.070101655 | ... M5: ='Growth Scenario'!M22 -> 0.066 | O5: =R3 -> 0.05 | Q5: Terminal reinvestment rate % | R5: =R4*R3 -> 0.0049766689
B6: EBIT | D6: =D7*D4 -> 2022.4789 | E6: =E7*E4 -> 2189.1446 | F6: =F7*F4 -> 2365.055 | G6: =G7*G4 -> 2550.2506 | H6: =H7*H4 -> 2744.7178 | I6: =I7*I4 -> 2948.3849 | J6: =J7*J4 -> 3161.1182 | K6: =K7*K4 -> 3382.7178 | ... M6: =M7*M4 -> 3851.3669 | O6: =O7*O4 -> 4043.9353
B7: EBIT Margin % | D7: =AVERAGE('Ratios '!C13:G13) -> 0.14385194 | E7: =D7 -> 0.14385194 | F7: =E7 -> 0.14385194 | G7: =F7 -> 0.14385194 | H7: =G7 -> 0.14385194 | I7: =H7 -> 0.14385194 | J7: =I7 -> 0.14385194 | K7: =J7 -> 0.14385194 | L7: =K7 -> 0.14385194 | M7: =L7 -> 0.14385194 | O7: =M7 -> 0.14385194 | Q7: Enterprise value = Equity Value + Minority interest
B8: Less: Tax on EBIT | D8: =AVERAGE(WACC!$F$17)*D6 -> 322.1797 | E8: =AVERAGE(WACC!$F$17)*E6 -> 348.72944 | F8: =AVERAGE(WACC!$F$17)*F6 -> 376.75187 | G8: =AVERAGE(WACC!$F$17)*G6 -> 406.25341 | H8: =AVERAGE(WACC!$F$17)*H6 -> 437.23191 | I8: =AVERAGE(WACC!$F$17)*I6 -> 469.67597 | J8: =AVERAGE(WACC!$F$17)*J6 -> 503.56425 | K8: =AVERAGE(WACC!$F$17)*K6 -> 538.86494 | ... M8: =AVERAGE(WACC!$F$17)*M6 -> 613.52047 | O8: =WACC!F17*O6 -> 644.19649
B9: EBIT(1-T) | D9: =D6-D8 -> 1700.2992 | E9: =E6-E8 -> 1840.4152 | F9: =F6-F8 -> 1988.3032 | G9: =G6-G8 -> 2143.9972 | H9: =H6-H8 -> 2307.4858 | I9: =I6-I8 -> 2478.7089 | J9: =J6-J8 -> 2657.5539 | K9: =K6-K8 -> 2843.8529 | ... M9: =M6-M8 -> 3237.8464 | O9: =O6-O8 -> 3399.7388
B10: Less: Net Capital Expenditure | D10: ='Fixed Asset Schedule '!$C$13*'Valuation '!D4 -> 1170.6929 | E10: ='Fixed Asset Schedule '!$C$13*'Valuation '!E4 -> 1267.1657 | F10: ='Fixed Asset Schedule '!$C$13*'Valuation '!F4 -> 1368.9898 | G10: ='Fixed Asset Schedule '!$C$13*'Valuation '!G4 -> 1476.1885 | H10: ='Fixed Asset Schedule '!$C$13*'Valuation '!H4 -> 1588.754 | I10: ='Fixed Asset Schedule '!$C$13*'Valuation '!I4 -> 1706.6448 | J10: ='Fixed Asset Schedule '!$C$13*'Valuation '!J4 -> 1829.7835 | K10: ='Fixed Asset Schedule '!$C$13*'Valuation '!K4 -> 1958.0544 | ... M10: ='Fixed Asset Schedule '!$C$13*'Valuation '!M4 -> 2229.3275
B11: Non Cash Working Capital | C11: ='Change in Working Capital '!G7 -> 3549.35 | D11: ='Change in Working Capital '!$C$11*'Valuation '!D4 -> 440.98849 | E11: ='Change in Working Capital '!$C$11*'Valuation '!E4 -> 477.32886 | F11: ='Change in Working Capital '!$C$11*'Valuation '!F4 -> 515.685 | G11: ='Change in Working Capital '!$C$11*'Valuation '!G4 -> 556.0657 | H11: ='Change in Working Capital '!$C$11*'Valuation '!H4 -> 598.46801 | I11: ='Change in Working Capital '!$C$11*'Valuation '!I4 -> 642.87631 | J11: ='Change in Working Capital '!$C$11*'Valuation '!J4 -> 689.26144 | K11: ='Change in Working Capital '!$C$11*'Valuation '!K4 -> 737.5798 | ... M11: ='Change in Working Capital '!$C$11*'Valuation '!M4 -> 839.76572
B12: Less: Change in Working Capital | D12: =D11-C11 -> -3108.3615 | E12: =E11-D11 -> 36.340371 | F12: =F11-E11 -> 38.356139 | G12: =G11-F11 -> 40.380696 | H12: =H11-G11 -> 42.40231 | I12: =I11-H11 -> 44.408307 | J12: =J11-I11 -> 46.385122 | K12: =K11-J11 -> 48.318368 | ... M12: =M11-L11 -> 51.993
B13: Reinvestment | D13: =D10+D12 -> -1937.6686 | E13: =E10+E12 -> 1303.5061 | F13: =F10+F12 -> 1407.346 | G13: =G10+G12 -> 1516.5692 | H13: =H10+H12 -> 1631.1563 | I13: =I10+I12 -> 1751.0531 | J13: =J10+J12 -> 1876.1686 | K13: =K10+K12 -> 2006.3727 | ... M13: =M10+M12 -> 2281.3205 | O13: =O9*O15 -> 16.919374
B14: Free Cash Flow To Firm (FCFF) | D14: =D9-D13 -> 3637.9679 | E14: =E9-E13 -> 536.90905 | F14: =F9-F13 -> 580.95719 | G14: =G9-G13 -> 627.42794 | H14: =H9-H13 -> 676.3295 | I14: =I9-I13 -> 727.65578 | J14: =J9-J13 -> 781.38531 | K14: =K9-K13 -> 837.48014 | ... M14: =M9-M13 -> 956.52597 | O14: =O9-O13 -> 3382.8194
B15: Implied Reinvestment rate % | D15: =D13/D9 -> -1.1396045 | E15: =E13/E9 -> 0.70826743 | F15: =F13/F9 -> 0.70781257 | G15: =G13/G9 -> 0.70735599 | H15: =H13/H9 -> 0.70689766 | I15: =I13/I9 -> 0.70643758 | J15: =J13/J9 -> 0.70597575 | K15: =K13/K9 -> 0.70551214 | ... M15: =M13/M9 -> 0.70457958 | O15: =R5 -> 0.0049766689
B17: Terminal Value | M17: =M14/(R4-R3) -> 19310.736
B19: Present Value Interest Factor(PVIF) | D19: =1/(1+$R$4)^D2 -> 0.90947671 | E19: =1/(1+$R$4)^E2 -> 0.82714789 | F19: =1/(1+$R$4)^F2 -> 0.75227174 | G19: =1/(1+$R$4)^G2 -> 0.68417363 | H19: =1/(1+$R$4)^H2 -> 0.62223998 | I19: =1/(1+$R$4)^I2 -> 0.56591277 | J19: =1/(1+$R$4)^J2 -> 0.51468449 | K19: =1/(1+$R$4)^K2 -> 0.46809356 | ... M19: =1/(1+$R$4)^M2 -> 0.3871826
B21: Present value of FCFF | D21: =SUMPRODUCT(D14:M14,D19:M19) -> 6997.619
B22: Present value of Terminal value | D22: =M17*M19 -> 7476.7809
I23: Calculation of Sensitivity Analysis
B24: Value of operating assets | D24: =D21+D22 -> 14474.4 | I24: =D31 -> 84.664814 | J24: =K24-1% -> 0.089533377 | K24: =R4 -> 0.099533377 | L24: =K24+1% -> 0.10953338 | M24: =L24+1% -> 0.11953338
B25: Add: Cash | D25: ='Consolidated Fs'!P26 -> 304.1 | I25: =I26-1% -> 0.047 | J25: 647.64581 | K25: 647.64581 | L25: 525.46011 | M25: 380.7948
B26: Less: Debt | D26: ='Consolidated Fs'!P45+'Consolidated Fs'!P53 -> 1062.8 | I26: =I27-1% -> 0.057 | J26: 488.12563 | K26: 488.12563 | L26: 411.63691 | M26: 313.33096
B27: Less: Minority Interest | I27: 0.067 | J27: 384.07289 | K27: 384.07289 | L27: 332.97385 | M27: 263.15813
B28: Equity Value | D28: =D24+D25-D26-D27 -> 13715.7 | I28: =I27+1% -> 0.077 | J28: 311.961 | K28: 311.961 | L28: 276.13091 | M28: 224.78524
I29: =I28+1% -> 0.087 | J29: 259.70008 | K29: 259.70008 | L29: 233.60488 | M29: 194.74248
B30: No. of Shares outstanding (Cr) | D30: 162
B31: intrinsic value per share | D31: =D28/D30 -> 84.664814 | F31: Current | G31: 2,658

Sheet Ratios 
B2: Ratio Analysis
B3: Years | C3: 46102 | D3: 46103 | E3: 46104 | F3: 46105 | G3: 46106 | H3: Trend
B5: SalesGrowth | D5: 0.49685044 | E5: 0.21020332 | F5: 0.25273235 | G5: 0.073101585
B6: EBITDA Growth | D6: 0.72078222 | E6: 0.25734024 | F6: 0.30101548 | G6: 0.012083973
B7: EBIT Growth | D7: 1.0358939 | E7: 0.30690577 | F7: 0.27648511 | G7: -0.068395666
B8: Net Profit Growth | D8: 0.57696031 | E8: 0.23950075 | F8: 0.24261558 | G8: 0.017230475
B9: Dividend Growth | D9: =('Consolidated Fs'!U50-'Consolidated Fs'!T50)/'Consolidated Fs'!T50 -> 0.13907496 | E9: =('Consolidated Fs'!V50-'Consolidated Fs'!U50)/'Consolidated Fs'!U50 -> 0.1391767 | F9: =('Consolidated Fs'!W50-'Consolidated Fs'!V50)/'Consolidated Fs'!V50 -> 0.32866273 | G9: =('Consolidated Fs'!X50-'Consolidated Fs'!W50)/'Consolidated Fs'!W50 -> -0.066419981
B11: Gross Margin | C11: 0.53315244 | D11: 0.51543025 | E11: 0.52598814 | F11: 0.54205723 | G11: 0.53368819
B12: EBITDA Margin | C12: 0.17052769 | D12: 0.19627043 | E12: 0.20411555 | F12: 0.21334324 | G12: 0.20152055
B13: EBIT Margin | C13: ='Assumptions '!E18/'Assumptions '!E6 -> 0.11708045 | D13: ='Assumptions '!F18/'Assumptions '!F6 -> 0.12868962 | E13: ='Assumptions '!G18/'Assumptions '!G6 -> 0.15363814 | F13: ='Assumptions '!H18/'Assumptions '!H6 -> 0.15363605 | G13: ='Assumptions '!I18/'Assumptions '!I6 -> 0.16621543
B14: EBT Margin | C14: 0.333709 | D14: 0.35910007 | E14: 0.37263775 | F14: 0.37323226 | G14: 0.36153322
B15: Net Profit Margin | C15: 0.30957668 | D15: 0.32652996 | E15: 0.33476361 | F15: 0.33419148 | G15: 0.31727703
B17: SalesExpenses%Sales | C17: =('Consolidated Fs'!C13+'Consolidated Fs'!C16)/'Consolidated Fs'!C6 -> 0.4348362 | D17: =('Consolidated Fs'!D13+'Consolidated Fs'!D16)/'Consolidated Fs'!D6 -> 0.42850887 | E17: =('Consolidated Fs'!E13+'Consolidated Fs'!E16)/'Consolidated Fs'!E6 -> 0.4173135 | F17: =('Consolidated Fs'!F13+'Consolidated Fs'!F16)/'Consolidated Fs'!F6 -> 0.43295494 | G17: =('Consolidated Fs'!G13+'Consolidated Fs'!G16)/'Consolidated Fs'!G6 -> 0.43874426
B18: Depreciation%Sales | C18: ='Consolidated Fs'!C15/'Consolidated Fs'!C6 -> 0.022361702 | D18: ='Consolidated Fs'!D15/'Consolidated Fs'!D6 -> 0.02236136 | E18: ='Consolidated Fs'!E15/'Consolidated Fs'!E6 -> 0.022117616 | F18: ='Consolidated Fs'!F15/'Consolidated Fs'!F6 -> 0.023627206 | G18: ='Consolidated Fs'!G15/'Consolidated Fs'!G6 -> 0.027552162
B19: OperatingIncome%Sales | C19: ='Assumptions '!E18/'Assumptions '!E6 -> 0.11708045 | D19: ='Assumptions '!F18/'Assumptions '!F6 -> 0.12868962 | E19: ='Assumptions '!G18/'Assumptions '!G6 -> 0.15363814 | F19: ='Assumptions '!H18/'Assumptions '!H6 -> 0.15363605 | G19: ='Assumptions '!I18/'Assumptions '!I6 -> 0.16621543
B21: Return on Capital Employed | C21: 0.21694795 | D21: 0.32834189 | E21: 0.82475654 | F21: 1.1853569 | G21: 1.1042836
B22: Retained Earnings% | C22: =('Consolidated Fs'!C22-ABS('Consolidated Fs'!T50))/'Consolidated Fs'!C22 -> 0.70549554 | D22: =('Consolidated Fs'!D22-ABS('Consolidated Fs'!U50))/'Consolidated Fs'!D22 -> 0.72748779 | E22: =('Consolidated Fs'!E22-ABS('Consolidated Fs'!V50))/'Consolidated Fs'!E22 -> 0.76007078 | F22: =('Consolidated Fs'!F22-ABS('Consolidated Fs'!W50))/'Consolidated Fs'!F22 -> 0.70162848 | G22: =('Consolidated Fs'!G22-ABS('Consolidated Fs'!X50))/'Consolidated Fs'!G22 -> 0.77223075
B23: Return on Equity% | C23: 0.52435726 | D23: 0.60827837 | E23: 0.3148491 | F23: 0.33191477 | G23: 0.33763381
B24: Self Sustained Growth Rate | C24: =('Consolidated Fs'!C22/'Consolidated Fs'!L41)*('Consolidated Fs'!C22-ABS('Consolidated Fs'!T50))/'Consolidated Fs'!C22 -> 0.094216535 | D24: =('Consolidated Fs'!D22/((('Consolidated Fs'!L41+'Consolidated Fs'!M41)/2)))*('Consolidated Fs'!D22-ABS('Consolidated Fs'!U50))/'Consolidated Fs'!D22 -> 0.11187917 | E24: =('Consolidated Fs'!E22/((('Consolidated Fs'!M41+'Consolidated Fs'!N41)/2)))*('Consolidated Fs'!E22-ABS('Consolidated Fs'!V50))/'Consolidated Fs'!E22 -> 0.13284882 | F24: =('Consolidated Fs'!F22/((('Consolidated Fs'!N41+'Consolidated Fs'!O41)/2)))*('Consolidated Fs'!F22-ABS('Consolidated Fs'!W50))/'Consolidated Fs'!F22 -> 0.12078993 | G24: =('Consolidated Fs'!G22/((('Consolidated Fs'!O41+'Consolidated Fs'!P41)/2)))*('Consolidated Fs'!G22-ABS('Consolidated Fs'!X50))/'Consolidated Fs'!G22 -> 0.14781407
B25: Interest Coverage Ratio | C25: 0.19596817 | D25: 0.096996607 | E25: 0.10690944 | F25: 0.14069939 | G25: 0.056865204
B27: Debtor Turnover Ratio | C27: ='Consolidated Fs'!C6/'Consolidated Fs'!L25 -> 6.0749387 | D27: ='Consolidated Fs'!D6/((('Consolidated Fs'!L25+'Consolidated Fs'!M25)/2)) -> 6.3236412 | E27: ='Consolidated Fs'!E6/((('Consolidated Fs'!M25+'Consolidated Fs'!N25)/2)) -> 6.2097489 | F27: ='Consolidated Fs'!F6/((('Consolidated Fs'!N25+'Consolidated Fs'!O25)/2)) -> 5.883014 | G27: ='Consolidated Fs'!G6/((('Consolidated Fs'!O25+'Consolidated Fs'!P25)/2)) -> 5.4944799
B28: Creditor Turnover Ratio | C28: =('Consolidated Fs'!C10+'Consolidated Fs'!C11+'Consolidated Fs'!C12)/'Consolidated Fs'!L55 -> 3.8435212 | D28: =('Consolidated Fs'!D10+'Consolidated Fs'!D11+'Consolidated Fs'!D12)/((('Consolidated Fs'!L55+'Consolidated Fs'!M55)/2)) -> 4.0240058 | E28: =('Consolidated Fs'!E10+'Consolidated Fs'!E11+'Consolidated Fs'!E12)/((('Consolidated Fs'!M55+'Consolidated Fs'!N55)/2)) -> 4.1700308 | F28: =('Consolidated Fs'!F10+'Consolidated Fs'!F11+'Consolidated Fs'!F12)/((('Consolidated Fs'!N55+'Consolidated Fs'!O55)/2)) -> 3.3898817 | G28: =('Consolidated Fs'!G10+'Consolidated Fs'!G11+'Consolidated Fs'!G12)/((('Consolidated Fs'!O55+'Consolidated Fs'!P55)/2)) -> 2.656078
B29: Inventory Turnover | C29: =('Consolidated Fs'!C10+'Consolidated Fs'!C11+'Consolidated Fs'!C12)/'Consolidated Fs'!L22 -> 2.2535775 | D29: =('Consolidated Fs'!D10+'Consolidated Fs'!D11+'Consolidated Fs'!D12)/((('Consolidated Fs'!L22+'Consolidated Fs'!M22)/2)) -> 2.319038 | E29: =('Consolidated Fs'!E10+'Consolidated Fs'!E11+'Consolidated Fs'!E12)/((('Consolidated Fs'!M22+'Consolidated Fs'!N22)/2)) -> 2.2115075 | F29: =('Consolidated Fs'!F10+'Consolidated Fs'!F11+'Consolidated Fs'!F12)/((('Consolidated Fs'!N22+'Consolidated Fs'!O22)/2)) -> 1.9739741 | G29: =('Consolidated Fs'!G10+'Consolidated Fs'!G11+'Consolidated Fs'!G12)/((('Consolidated Fs'!O22+'Consolidated Fs'!P22)/2)) -> 1.7065334
B30: Fixed Asset Turnover | C30: ='Consolidated Fs'!C6/'Consolidated Fs'!L20 -> 1.8819 | D30: ='Consolidated Fs'!D6/((('Consolidated Fs'!L20+'Consolidated Fs'!M20)/2)) -> 1.9676243 | E30: ='Consolidated Fs'!E6/((('Consolidated Fs'!M20+'Consolidated Fs'!N20)/2)) -> 1.9509074 | F30: ='Consolidated Fs'!F6/((('Consolidated Fs'!N20+'Consolidated Fs'!O20)/2)) -> 2.1715079 | G30: ='Consolidated Fs'!G6/((('Consolidated Fs'!O20+'Consolidated Fs'!P20)/2)) -> 2.1773523
B31: Capital Turnover Ratio | C31: ='Consolidated Fs'!C6/('Consolidated Fs'!L41+'Consolidated Fs'!L50) -> 1.1219192 | D31: ='Consolidated Fs'!D6/(((('Consolidated Fs'!L41+'Consolidated Fs'!L50)+('Consolidated Fs'!M41+'Consolidated Fs'!M50))/2)) -> 1.1666594 | E31: ='Consolidated Fs'!E6/(((('Consolidated Fs'!M41+'Consolidated Fs'!M50)+('Consolidated Fs'!N41+'Consolidated Fs'!N50))/2)) -> 1.143951 | F31: ='Consolidated Fs'!F6/(((('Consolidated Fs'!N41+'Consolidated Fs'!N50)+('Consolidated Fs'!O41+'Consolidated Fs'!O50))/2)) -> 1.1144091 | G31: ='Consolidated Fs'!G6/(((('Consolidated Fs'!O41+'Consolidated Fs'!O50)+('Consolidated Fs'!P41+'Consolidated Fs'!P50))/2)) -> 1.0246025
B33: Debtor Days | C33: =365/C27 -> 60.082911 | D33: =365/D27 -> 57.71991 | E33: =365/E27 -> 58.778544 | F33: =365/F27 -> 62.043027 | G33: =365/G27 -> 66.43031
B34: Payable Days | C34: =365/C28 -> 94.965003 | D34: =365/D28 -> 90.705634 | E34: =365/E28 -> 87.52933 | F34: =365/F28 -> 107.67337 | G34: =365/G28 -> 137.42067
B35: Inventory Days | C35: =365/C29 -> 161.9647 | D35: =365/D29 -> 157.39285 | E35: =365/E29 -> 165.04579 | F35: =365/F29 -> 184.90618 | G35: =365/G29 -> 213.88389
B36: Cash Conversion Cycle (in days) | C36: =C33+C35-C34 -> 127.08261 | D36: =D33+D35-D34 -> 124.40713 | E36: =E33+E35-E34 -> 136.295 | F36: =F33+F35-F34 -> 139.27583 | G36: =G33+G35-G34 -> 142.89353
B38: CFO/Sales | C38: ='Consolidated Fs'!T33/'Consolidated Fs'!C6 -> 0.12319133 | D38: ='Consolidated Fs'!U33/'Consolidated Fs'!D6 -> 0.13637634 | E38: ='Consolidated Fs'!V33/'Consolidated Fs'!E6 -> 0.16002304 | F38: ='Consolidated Fs'!W33/'Consolidated Fs'!F6 -> 0.15378604 | G38: ='Consolidated Fs'!X33/'Consolidated Fs'!G6 -> 0.14754908
B39: CFO/Total Assets | C39: ='Consolidated Fs'!T33/'Consolidated Fs'!L33 -> 0.10312568 | D39: ='Consolidated Fs'!U33/((('Consolidated Fs'!L33+'Consolidated Fs'!M33)/2)) -> 0.11906437 | E39: ='Consolidated Fs'!V33/((('Consolidated Fs'!M33+'Consolidated Fs'!N33)/2)) -> 0.13781627 | F39: ='Consolidated Fs'!W33/((('Consolidated Fs'!N33+'Consolidated Fs'!O33)/2)) -> 0.12838746 | G39: ='Consolidated Fs'!X33/((('Consolidated Fs'!O33+'Consolidated Fs'!P33)/2)) -> 0.11487061
B40: CFO/Total Debt

Sheet Relative Valuation Raw Data 
B2: S.No. | C2: Name | D2: CMP Rs. | E2: Net Profit | F2: No. Eq. Shares Cr. | G2: Mar Cap Rs.Cr. | H2: Cash End Rs.Cr. | I2: Debt Rs.Cr. | J2: Sales Rs.Cr. | K2: EV / EBITDA | L2: EBIDT Ann Rs.Cr.
B3: 1 | C3: Aurobindo Pharma | D3: 1452.7 | E3: 3502.97 | F3: 58.08 | G3: 84373.1 | H3: 9870.29 | I3: 8072.84 | J3: 33653.08 | K3: 11.25 | L3: 7339.34
B4: 2 | C4: Laurus Labs | D4: 1363 | E4: 890.14 | F4: 53.99 | G4: 73582.46 | H4: 113.7 | I4: 2518.48 | J4: 6812.9 | K4: 41.46 | L4: 1832.66
B5: 3 | C5: Glenmark Pharma. | D5: 2315 | E5: 1065.01 | F5: 28.22 | G5: 65329.45 | H5: 1705.23 | I5: 1224.17 | J5: 16468.13 | K5: 13.72 | L5: 2465.11
B6: 4 | C6: Alkem Lab | D6: 5400.2 | E6: 2422.44 | F6: 11.96 | G6: 64567.5 | H6: 1563.08 | I6: 2355.6 | J6: 14252.7 | K6: 19.18 | L6: 3001.29
B7: 5 | C7: Anthem Bioscienc | D7: 761.5 | E7: 591.79 | F7: 56.32 | G7: 42887.27 | H7: 274.88 | I7: 53.04 | J7: 2124.33 | K7: 43.11 | L7: 989.59

Sheet Relative Valuation 
B2: Relative Valuation - Alkem Labs
B4: Figures in Crore
B5: Comparable Company Valuation
B7: Company Name | C7: Ticker Name | D7: Market Data | K7: Financials | P7: Valuation
D8: No. of shares | E8: Share Price | F8: Equity value | G8: Debt | H8: cash | I8: Enterprises value | K8: Revenue | L8: EBITDA | M8: Net Profit | N8: EPS | P8: EV/Revenue | Q8: EV/EBITDA | R8: P/E Ratio
B9: Aurobindo Pharma | D9: ='Relative Valuation Raw Data '!F3 -> 58.08 | E9: ='Relative Valuation Raw Data '!D3 -> 1452.7 | F9: =IFERROR(D9*E9,0) -> 84372.816 | G9: ='Relative Valuation Raw Data '!I3 -> 8072.84 | H9: ='Relative Valuation Raw Data '!H3 -> 9870.29 | I9: =IFERROR(F9+G9-H9,0) -> 82575.366 | K9: ='Relative Valuation Raw Data '!J3 -> 33653.08 | L9: ='Relative Valuation Raw Data '!L3 -> 7339.34 | M9: ='Relative Valuation Raw Data '!E3 -> 3502.97 | N9: =IFERROR(M9/D9,0) -> 60.312844 | P9: =IFERROR(I9/K9,0) -> 2.4537239 | Q9: =IFERROR(I9/L9,0) -> 11.251062 | R9: =IFERROR(E9/N9,0) -> 24.08608
B10: Laurus Labs | D10: ='Relative Valuation Raw Data '!F4 -> 53.99 | E10: ='Relative Valuation Raw Data '!D4 -> 1363 | F10: =IFERROR(D10*E10,0) -> 73588.37 | G10: ='Relative Valuation Raw Data '!I4 -> 2518.48 | H10: ='Relative Valuation Raw Data '!H4 -> 113.7 | I10: =IFERROR(F10+G10-H10,0) -> 75993.15 | K10: ='Relative Valuation Raw Data '!J4 -> 6812.9 | L10: ='Relative Valuation Raw Data '!L4 -> 1832.66 | M10: ='Relative Valuation Raw Data '!E4 -> 890.14 | N10: =IFERROR(M10/D10,0) -> 16.487127 | P10: =IFERROR(I10/K10,0) -> 11.154303 | Q10: =IFERROR(I10/L10,0) -> 41.466038 | R10: =IFERROR(E10/N10,0) -> 82.670557
B11: Glenmark Pharma. | D11: ='Relative Valuation Raw Data '!F5 -> 28.22 | E11: ='Relative Valuation Raw Data '!D5 -> 2315 | F11: =IFERROR(D11*E11,0) -> 65329.3 | G11: ='Relative Valuation Raw Data '!I5 -> 1224.17 | H11: ='Relative Valuation Raw Data '!H5 -> 1705.23 | I11: =IFERROR(F11+G11-H11,0) -> 64848.24 | K11: ='Relative Valuation Raw Data '!J5 -> 16468.13 | L11: ='Relative Valuation Raw Data '!L5 -> 2465.11 | M11: ='Relative Valuation Raw Data '!E5 -> 1065.01 | N11: =IFERROR(M11/D11,0) -> 37.739546 | P11: =IFERROR(I11/K11,0) -> 3.9378023 | Q11: =IFERROR(I11/L11,0) -> 26.306429 | R11: =IFERROR(E11/N11,0) -> 61.34149
B12: Alkem Lab | D12: ='Relative Valuation Raw Data '!F6 -> 11.96 | E12: ='Relative Valuation Raw Data '!D6 -> 5400.2 | F12: =IFERROR(D12*E12,0) -> 64586.392 | G12: ='Relative Valuation Raw Data '!I6 -> 2355.6 | H12: ='Relative Valuation Raw Data '!H6 -> 1563.08 | I12: =IFERROR(F12+G12-H12,0) -> 65378.912 | K12: ='Relative Valuation Raw Data '!J6 -> 14252.7 | L12: ='Relative Valuation Raw Data '!L6 -> 3001.29 | M12: ='Relative Valuation Raw Data '!E6 -> 2422.44 | N12: =IFERROR(M12/D12,0) -> 202.54515 | P12: =IFERROR(I12/K12,0) -> 4.5871247 | Q12: =IFERROR(I12/L12,0) -> 21.783604 | R12: =IFERROR(E12/N12,0) -> 26.66171
B13: Anthem Bioscienc | D13: ='Relative Valuation Raw Data '!F7 -> 56.32 | E13: ='Relative Valuation Raw Data '!D7 -> 761.5 | F13: =IFERROR(D13*E13,0) -> 42887.68 | G13: ='Relative Valuation Raw Data '!I7 -> 53.04 | H13: ='Relative Valuation Raw Data '!H7 -> 274.88 | I13: =IFERROR(F13+G13-H13,0) -> 42665.84 | K13: ='Relative Valuation Raw Data '!J7 -> 2124.33 | L13: ='Relative Valuation Raw Data '!L7 -> 989.59 | M13: ='Relative Valuation Raw Data '!E7 -> 591.79 | N13: =IFERROR(M13/D13,0) -> 10.507635 | P13: =IFERROR(I13/K13,0) -> 20.084375 | Q13: =IFERROR(I13/L13,0) -> 43.114664 | R13: =IFERROR(E13/N13,0) -> 72.471113
B15: Max | P15: =IFERROR(MAX(P9:P13),0) -> 20.084375 | Q15: =IFERROR(MAX(Q9:Q13),0) -> 43.114664 | R15: =IFERROR(MAX(R9:R13),0) -> 82.670557
B16: 75th Percentile | P16: =IFERROR(QUARTILE(P9:P13,3),0) -> 11.154303 | Q16: =IFERROR(QUARTILE(Q9:Q13,3),0) -> 41.466038 | R16: =IFERROR(QUARTILE(R9:R13,3),0) -> 72.471113
B17: Average | P17: =IFERROR(AVERAGE(P9:P13),0) -> 8.4434657 | Q17: =IFERROR(AVERAGE(Q9:Q13),0) -> 28.784359 | R17: =IFERROR(AVERAGE(R9:R13),0) -> 53.44619
B18: median | P18: =IFERROR(MEDIAN(P9:P13),0) -> 4.5871247 | Q18: =IFERROR(MEDIAN(Q9:Q13),0) -> 26.306429 | R18: =IFERROR(MEDIAN(R9:R13),0) -> 61.34149
B19: 25th Percentile | P19: =IFERROR(QUARTILE(P9:P13,1),0) -> 3.9378023 | Q19: =IFERROR(QUARTILE(Q9:Q13,1),0) -> 21.783604 | R19: =IFERROR(QUARTILE(R9:R13,1),0) -> 26.66171
B20: Min. | P20: =IFERROR(MIN(P9:P13),0) -> 2.4537239 | Q20: =IFERROR(MIN(Q9:Q13),0) -> 11.251062 | R20: =IFERROR(MIN(R9:R13),0) -> 24.08608
B22: M&M Industry Comparable comps | P22: EV/Revenue | Q22: EV/EBITDA | R22: P/E Ratio
P23: Overvalued | Q23: Overvalued | R23: Overvalued
B24: Implied Enterprise Value | P24: =P18*K12 -> 65378.912 | Q24: =Q18*L12 -> 78953.221 | R24: =SUM(R26+R25) -> 149388.6
B25: Net Debt | P25: =G12-H12 -> 792.52 | Q25: =P25 -> 792.52 | R25: =Q25 -> 792.52
B26: Implied Market Value | P26: =P24-P25 -> 64586.392 | Q26: =Q24-Q25 -> 78160.701 | R26: =R18*M12 -> 148596.08
B27: Share Outstanding | P27: =D12 -> 11.96 | Q27: =P27 -> 11.96 | R27: =Q27 -> 11.96
B29: Implied Value per Share | P29: =P26/P27 -> 5400.2 | Q29: =Q26/Q27 -> 6535.1757 | R29: =R26/R27 -> 12424.421
