Workbook

Sheet About 
F3: Biocon Limited is one of India's largest biopharmaceutical companies, founded in 1978 by Kiran Mazumdar-Shaw and headquartered in Bengaluru. The company operates across biosimilars, generics, APIs, novel biologics and contract research services. Biocon serves patients in more than 120 countries and has a strong presence in diabetes, oncology and autoimmune therapies.
B16: Major Subsidiaries | F16: Key Manufacturing and Research Units
B18: Subsidiary | C18: Business | D18: Location | F18: Unit | G18: Location | H18: PIN Code
B19: Biocon Biologics Limited | C19: Biosimilars and biologics | D19: Bengaluru, Karnataka | F19: Biocon Campus, Electronic City | G19: Electronic City Phase II, Bengaluru, Karnataka | H19: 560100
B20: Syngene International Limited | C20: CRDMO, research and manufacturing services | D20: Bengaluru, Karnataka | F20: Biocon Park SEZ | G20: Bommasandra Jigani Link Road, Bengaluru, Karnataka | H20: 560099
B21: Biocon Research Limited | C21: Novel biologics R&D | D21: Bengaluru, Karnataka | F21: Biocon Biologics Manufacturing Campus | G21: Bommasandra Industrial Area, Bengaluru, Karnataka | H21: 560099
B22: Biocon Pharma Limited | C22: Formulations and pharmaceuticals | D22: Bengaluru, Karnataka | F22: Syngene Biocon SEZ Campus | G22: Bommasandra Industrial Area Phase IV, Bengaluru, Karnataka | H22: 560099
B23: Biocon Pharma Inc. | C23: US commercial operations | D23: New Jersey, USA | F23: Syngene Corporate Office "The Hub" | G23: Electronic City Phase I, Bengaluru, Karnataka | H23: 560100
B24: Biocon SDN. BHD. | C24: Insulin manufacturing and operations | D24: Johor, Malaysia | F24: API Manufacturing Facility | G24: Mangaluru, Karnataka | H24: 575011
B25: Biocon Biologics Healthcare Malaysia Sdn. Bhd. | C25: Biosimilar manufacturing | D25: Johor, Malaysia | F25: Oral Solid Dosage Facility | G25: Cranbury, New Jersey, USA | H25: 8512
B26: Biocon FZ LLC | C26: Regional commercial operations | D26: Dubai, UAE | F26: Integrated Insulin Manufacturing Facility | G26: Johor, Malaysia | H26: 81700
B27: Syngene USA Inc. | C27: Research and manufacturing operations | D27: USA

Sheet Shareholding 
B2: Promoter
B3: Name | C3: No. of Shares | D3: % Held
B4: KIRAN MAZUMDAR SHAW | C4: 48,45,81,970 | D4: 0.299
B5: RAVI RASENDRA MAZUMDAR | C5: 53,01,321 | D5: 0.0033
B6: DEV MAZUMDAR | C6: 9,29,721 | D6: 0.0006
B7: GLENTEC INTERNATIONAL | C7: 23,72,11,164 | D7: 0.1463
B8: Total | C8: 72,80,24,176 | D8: 0.4492
B9: Public Holding
B10: Category & Name of the Shareholders | C10: No. of shareholder | D10: No. of fully paid up equity shares held | E10: Total no. shares held | F10: Shareholding % calculated as per SCRR, 1957 As a % of (A+B+C2)
B13: Institutions | C13: 0 | D13: 0 | E13: - | F13: 0
B14: B2) Institutions (Domestic) | C14: 0 | D14: 0 | E14: - | F14: 0
B15: Mutual Funds/ | C15: 38 | D15: 26,79,52,467 | E15: 26,79,52,467 | F15: 16.53
B16: MIRAE ASSET NIFTY MIDCAP 150 ETF | C16: 1 | D16: 2,02,05,321 | E16: 2,02,05,321 | F16: 1.25
B17: SBI LARGE & MIDCAP FUND | C17: 1 | D17: 13,29,91,385 | E17: 13,29,91,385 | F17: 8.2
B18: NIPPON LIFE INDIA TRUSTEE LTD- A/C NIPPON INDIA VI | C18: 1 | D18: 1,81,65,211 | E18: 1,81,65,211 | F18: 1.12
B19: KOTAK LARGE & MIDCAP FUND | C19: 1 | D19: 1,66,10,890 | E19: 1,66,10,890 | F19: 1.02
B20: ICICI PRUDENTIAL INNOVATION FUND | C20: 1 | D20: 3,88,50,342 | E20: 3,88,50,342 | F20: 2.4
B21: Alternate Investment Funds | C21: 23 | D21: 2,01,56,253 | E21: 2,01,56,253 | F21: 1.24
B22: Banks | C22: 3 | D22: 12,30,914 | E22: 12,30,914 | F22: 0.08
B23: Insurance Companies | C23: 19 | D23: 9,98,87,754 | E23: 9,98,87,754 | F23: 6.16
B24: LICI NEW PENSION PLUS GROWTH FUND | C24: 1 | D24: 6,27,93,704 | E24: 6,27,93,704 | F24: 3.87
B25: Sovereign Wealth Funds | C25: 2 | D25: 8,82,765 | E25: 8,82,765 | F25: 0.05
B26: NBFCs registered with RBI | C26: 4 | D26: 21320 | E26: 21320 | F26: 0
B27: Sub Total B1 | C27: 89 | D27: 39,01,31,473 | E27: 39,01,31,473 | F27: 24.07
B28: B16) Institutions (Foreign) | C28: 0 | D28: 0 | E28: - | F28: 0
B29: Foreign Portfolio Investors Category I | C29: 235 | D29: 11,65,32,695 | E29: 11,65,32,695 | F29: 7.19
B30: Foreign Portfolio Investors Category II | C30: 21 | D30: 53,99,677 | E30: 53,99,677 | F30: 0.33
B31: Sub Total B2 | C31: 256 | D31: 12,19,32,372 | E31: 12,19,32,372 | F31: 7.52
B32: B20) Central Government/ State Government(s)/ President of India | C32: 0 | D32: 0 | E32: - | F32: 0
B33: B21) Non-Institutions | C33: 0 | D33: 0 | E33: - | F33: 0
B34: Directors and their relatives (excluding independent directors and nominee directors) | C34: 3 | D34: 75,89,527 | E34: 75,89,527 | F34: 0.47
B35: Key Managerial Personnel | C35: 1 | D35: 86848 | E35: 86848 | F35: 0.01
B36: Investor Education and Protection Fund (IEPF) | C36: 1 | D36: 1,87,481 | E36: 1,87,481 | F36: 0.01
B37: Resident Individuals holding nominal share capital up to Rs. 2 lakhs | C37: 3,68,665 | D37: 9,35,69,613 | E37: 9,35,69,613 | F37: 5.77
B38: Resident Individuals holding nominal share capital in excess of Rs. 2 lakhs | C38: 270 | D38: 6,86,26,557 | E38: 6,86,26,557 | F38: 4.23
B39: Non Resident Indians (NRIs) | C39: 9459 | D39: 97,63,994 | E39: 97,63,994 | F39: 0.6
B40: Foreign Nationals | C40: 8 | D40: 25,94,624 | E40: 25,94,624 | F40: 0.16
B41: Foreign Companies | C41: 1 | D41: 9,19,67,019 | E41: 9,19,67,019 | F41: 5.67
B42: MYLAN INC. | C42: 1 | D42: 9,19,67,019 | E42: 9,19,67,019 | F42: 5.67
B43: Bodies Corporate | C43: 1642 | D43: 10,00,24,999 | E43: 10,00,24,999 | F43: 6.17
...

Sheet Consolidated Statements  
A1: CONSOLIDATED STATEMENT OF PROFIT & LOSS | J1: Balance Sheet | R1: CashFlow Statement
C3: 2021 | D3: 2022 | E3: 2023 | F3: 2024 | G3: 2025
C4: (₹ Crores) | D4: (₹ Crores) | E4: (₹ Crores) | F4: (₹ Crores) | G4: (₹ Crores) | L4: 2021 | M4: 2022 | N4: 2023 | O4: 2024 | P4: 2025 | T4: 2021 | U4: 2022 | V4: 2023 | W4: 2024 | X4: 2025
L5: (₹ Crores) | M5: (₹ Crores) | N5: (₹ Crores) | O5: (₹ Crores) | P5: (₹ Crores) | T5: (₹ Crores) | U5: (₹ Crores) | V5: (₹ Crores) | W5: (₹ Crores) | X5: (₹ Crores)
A6: REVENUE | J6: NON-CURRENT ASSETS
A7: Total Revenue/Income | C7: 736.03 | D7: 839.67 | E7: 1155.01 | F7: 1562.12 | G7: 1646.99 | J7: Tangible assets | L7: 916.41 | M7: 1067.94 | N7: 1012.26 | O7: 1197.78 | P7: 1341.41 | R7: CASH FLOWS FROM OPERATING ACTIVITIES
J8: Goodwill and intangible assets | L8: 0 | M8: 0 | N8: 2666.21 | O8: 2665.91 | P8: 2705.76 | R8: Profit for the year (before NCI) | T8: 84.62 | U8: 77.16 | V8: 64.3 | W8: 129.78 | X8: 142.94
A9: EXPENSES | J9: Investment in associates and joint venture | L9: 17.95 | M9: 0.8 | N9: 13.78 | O9: 0 | P9: 0 | R9: Adjustments:
A10: Cost of materials consumed | C10: 220.85 | D10: 271.84 | E10: 366.31 | F10: 489.79 | G10: 519.75 | J10: Financial assets | L10: 83.02 | M10: 57.15 | N10: 494.85 | O10: 751.5 | P10: 661.63 | R10: Depreciation and amortisation | T10: 71.51 | U10: 81.42 | V10: 111.31 | W10: 156.88 | X10: 168.7
A11: Employee benefit expense | C11: 156.57 | D11: 170.98 | E11: 200.41 | F11: 213.7 | G11: 294.42 | J11: Deferred tax assets (net) | L11: 30.77 | M11: 29.33 | N11: 0 | O11: 0 | P11: 0 | R11: Unrealised foreign exchange (gain)/loss | T11: 2.88 | U11: 2.62 | V11: 0 | W11: 0 | X11: 0
A12: Finance costs | C12: 5.77 | D12: 6.76 | E12: 41.9 | F12: 97.44 | G12: 89.74 | J12: Tax assets (net) | L12: 26.48 | M12: 31.35 | N12: 0 | O12: 0 | P12: 0 | R12: Share based compensation | T12: 32 | U12: 0 | V12: 0 | W12: 0 | X12: 0
A13: Depreciation and amortisation | C13: 71.51 | D13: 81.42 | E13: 111.31 | F13: 156.88 | G13: 168.7 | J13: Other non-current assets | L13: 17.56 | M13: 16.31 | N13: 88.61 | O13: 114.31 | P13: 122.31 | R13: Provision for doubtful debts | T13: -16 | U13: 0 | V13: 0 | W13: 0 | X13: 0
A14: Research & Development (net) | C14: 55.31 | D14: 59.5 | E14: 111.94 | F14: 115.4 | G14: 85.85 | J14: Current and Deferred tax | L14: 0 | M14: 0 | N14: 65.53 | O14: 73.02 | P14: 62.83 | R14: Interest expense | T14: 5.77 | U14: 6.76 | V14: 41.9 | W14: 97.44 | X14: 89.74
A15: Other expenses | C15: 112.59 | D15: 119.06 | E15: 187.59 | F15: 326.81 | G15: 310.52 | J15: Total Non-Current Assets | L15: 1092.19 | M15: 1202.88 | N15: 5341.24 | O15: 4802.52 | P15: 4893.94 | R15: Interest income | T15: -19 | U15: 0 | V15: 0 | W15: 0 | X15: 0
A16: Total Expenses | C16: 622.6 | D16: 709.56 | E16: 1019.46 | F16: 1400.02 | G16: 1468.98 | R16: Net loss/(gain) on financial assets | T16: 0 | U16: 0 | V16: 0 | W16: 0 | X16: 0
J17: CURRENT ASSETS | R17: Profit on property sold (net) | T17: -75.4 | U17: 0 | V17: 0 | W17: 0 | X17: 0
A18: Share of profit/(loss) - JV & Associate | C18: -6.95 | D18: -20.69 | E18: -16.7 | F18: -8.42 | G18: 0 | J18: Inventories | L18: 186.66 | M18: 229.82 | N18: 424.37 | O18: 494.39 | P18: 493.11 | R18: Dividend income | T18: 0 | U18: 0 | V18: 0 | W18: 0 | X18: 0
J19: Financial assets (current) | L19: 531.78 | M19: 564.63 | N19: 494.85 | O19: 751.5 | P19: 661.63 | R19: Gain on sale of investments | T19: -1 | U19: 0 | V19: 0 | W19: 0 | X19: 0
A20: PROFIT BEFORE TAX & EXCEPTIONAL ITEMS | C20: 106.48 | D20: 109.42 | E20: 118.85 | F20: 153.68 | G20: 179.01 | J20: Cash and bank balances | L20: 0 | M20: 0 | N20: 438.67 | O20: 310.16 | P20: 492.55 | R20: Tax expense | T20: 21.2 | U20: 24.07 | V20: 17.63 | W20: 23.08 | X20: 41.56
A21: Exceptional items (net) | C21: 1.26 | D21: -11.11 | E21: -29.14 | F21: -1.16 | G21: 9.65 | J21: Other current assets | L21: 36.38 | M21: 42.07 | N21: 0 | O21: 0 | P21: 0 | R21: Operating profit before working capital changes | T21: 127.53 | U21: 191.63 | V21: 235.14 | W21: 407.18 | X21: 443.14
A22: PROFIT BEFORE TAX | C22: 107.74 | D22: 98.31 | E22: 89.71 | F22: 152.52 | G22: 188.66 | J22: Assets held for sale | L22: 5.22 | M22: 0 | N22: 0 | O22: 0 | P22: 0
J23: Total Current Assets | L23: 760.04 | M23: 836.52 | N23: 1358.89 | O23: 1556.05 | P23: 1647.29 | R23: Changes in working capital:
A24: TAX EXPENSE | R24: Decrease/(Increase) in inventories | T24: 10.38 | U24: -40.16 | V24: -19.46 | W24: -70 | X24: 1.28
A25: Current tax expense | C25: 21.2 | D25: 24.07 | E25: 17.63 | F25: 23.08 | G25: 41.56 | J25: TOTAL ASSETS | L25: 1852.23 | M25: 2039.4 | N25: 5204.28 | O25: 5607.07 | P25: 5879.6 | R25: Decrease/(Increase) in trade receivables | T25: -2.56 | U25: -57 | V25: 0 | W25: 0 | X25: 0
A26: Tax on exceptional items | C26: 0.95 | D26: -2.92 | E26: -2.93 | F26: -0.34 | G26: 2.17 | R26: Decrease/(Increase) in other assets | T26: 17.07 | U26: -18.2 | V26: 0 | W26: 0 | X26: 0
A27: Tax on new regime (exceptional) | C27: 0 | D27: 0 | E27: 10.71 | F27: 0 | G27: 1.99 | R27: Increase/(Decrease) in payables & provisions | T27: -9.29 | U27: 25.58 | V27: 0 | W27: 0 | X27: 0
A28: PROFIT FOR THE YEAR | C28: 84.62 | D28: 77.16 | E28: 64.3 | F28: 129.78 | G28: 142.94 | J28: EQUITY AND LIABILITIES
R29: CASH GENERATED FROM OPERATIONS | T29: 142.53 | U29: 101.85 | V29: 215.68 | W29: 337.18 | X29: 444.42
A30: Non-controlling interest | C30: 9.89 | D30: 13.16 | E30: 22.44 | F30: 27.61 | G30: 39.28 | J30: EQUITY | R30: Taxes paid | T30: -25.47 | U30: -32.1 | V30: -17.63 | W30: -38.95 | X30: -55.95
A31: Non-controlling on exceptional | C31: 0.68 | D31: -0.84 | E31: -4.41 | F31: -0.08 | G31: 2.33 | J31: Share capital | L31: 60 | M31: 60.03 | N31: 462.19 | O31: 549.11 | P31: 606.85 | R31: NET CASH FROM OPERATING ACTIVITIES | T31: 117.06 | U31: 69.75 | V31: 198.05 | W31: 298.23 | X31: 388.47
A32: PROFIT ATTRIBUTABLE TO SHAREHOLDERS | C32: 74.05 | D32: 64.84 | E32: 46.27 | F32: 102.25 | G32: 101.33 | J32: Other equity | L32: 702.69 | M32: 783.22 | N32: 1786.69 | O32: 1978.37 | P32: 2164.4
J33: Non-controlling interests | L33: 88.07 | M33: 103.75 | N33: 835.16 | O33: 549.11 | P33: 606.85 | R33: CASH FLOWS FROM INVESTING ACTIVITIES
A34: OTHER COMPREHENSIVE INCOME | J34: Total Equity | L34: 850.76 | M34: 947 | N34: 3084.04 | O34: 3076.59 | P34: 3378.1 | R34: Purchase of property, plant & equipment | T34: -85.1 | U34: -96.5 | V34: -120 | W34: -145.6 | X34: -152
A35: OCI attributable to shareholders | C35: 15.82 | D35: 9.67 | E35: 11.38 | F35: 26.88 | G35: 35.63 | R35: Proceeds from sale of assets | T35: 3.2 | U35: 2.1 | V35: 0 | W35: 0 | X35: 0
J36: NON-CURRENT LIABILITIES | R36: Investment in subsidiaries/associates | T36: -10.7 | U36: -5.3 | V36: -15 | W36: -8.4 | X36: -3.5
A37: TOTAL COMPREHENSIVE INCOME | C37: 89.87 | D37: 74.51 | E37: 57.65 | F37: 129.13 | G37: 136.96 | J37: Borrowings (non-current) | L37: 296.16 | M37: 399.85 | N37: 1777.07 | O37: 1572.96 | P37: 1775.55 | R37: Dividend received | T37: 0.5 | U37: 0.3 | V37: 0 | W37: 0 | X37: 0
J38: Financial liabilities (non-current) | L38: 167.92 | M38: 173.84 | N38: 940.19 | O38: 1289.33 | P38: 1098.47 | R38: Interest received | T38: 1.9 | U38: 2.15 | V38: 0 | W38: 0 | X38: 0
J39: Provisions and other liabilities | L39: 116.38 | M39: 135.91 | N39: 174.14 | O39: 170.3 | P39: 233.46 | R39: NET CASH FROM INVESTING ACTIVITIES | T39: -90.2 | U39: -97.25 | V39: -135 | W39: -154 | X39: -155.5
J40: Total Non-Current Liabilities | L40: 580.46 | M40: 709.6 | N40: 2891.4 | O40: 3032.59 | P40: 3107.48
R41: CASH FLOWS FROM FINANCING ACTIVITIES
...

Sheet Quaterly Results 
B2: Particulars | C2: 45352 | D2: 45717 | E2: 46082
B3: Sales | C3: 3168 | D3: 4292 | E3: 6206
B4: Sales Growth % | C4: 0.1423 | D4: 0.3549 | E4: 0.4459
B5: Material Cost % | C5: 0.66 | D5: 0.6 | E5: 0.55
B6: Manufacturing Cost % | C6: 0.02 | D6: 0.02 | E6: 0
B7: Employee Cost % | C7: 0.12 | D7: 0.09 | E7: 0.07
B8: Other Cost % | C8: 0.1 | D8: 0.1 | E8: 0.11
B9: Operating Profit | C9: 332 | D9: 831 | E9: 1684
B10: OPM % | C10: 0.1 | D10: 0.19 | E10: 0.27
B11: Other Income | C11: 22 | D11: 62 | E11: 27
B12: Exceptional Items | C12: 0 | D12: 0 | E12: -64
B13: Other Income Normal | C13: 23 | D13: 63 | E13: 91
... B18: Net Profit | C18: 181 | D18: 608 | E18: 1233

Sheet Ratios 
B2: Ratio Analysis
B3: Years | C3: 46102 | D3: 46103 | E3: 46104 | F3: 46105 | G3: 46106 | H3: Trend
B5: SalesGrowth | D5: =('Consolidated Statements '!D7-'Consolidated Statements '!C7)/'Consolidated Statements '!C7 -> 0.14080948 | E5: =('Consolidated Statements '!E7-'Consolidated Statements '!D7)/'Consolidated Statements '!D7 -> 0.3755523 | F5: =('Consolidated Statements '!F7-'Consolidated Statements '!E7)/'Consolidated Statements '!E7 -> 0.35247314 | G5: =('Consolidated Statements '!G7-'Consolidated Statements '!F7)/'Consolidated Statements '!F7 -> 0.054330013
B6: EBITDA Growth | D6: =(('Consolidated Statements '!D7-'Consolidated Statements '!D16+'Consolidated Statements '!D13)-('Consolidated Statements '!C7-'Consolidated Statements '!C16+'Consolidated Statements '!C13))/('Consolidated Statements '!C7-'Consolidated Statements '!C16+'Consolidated Statements '!C13) -> 0.14377636 | E6: =(('Consolidated Statements '!E7-'Consolidated Statements '!E16+'Consolidated Statements '!E13)-('Consolidated Statements '!D7-'Consolidated Statements '!D16+'Consolidated Statements '!D13))/('Consolidated Statements '!D7-'Consolidated Statements '!D16+'Consolidated Statements '!D13) -> 0.16702123 | F6: =(('Consolidated Statements '!F7-'Consolidated Statements '!F16+'Consolidated Statements '!F13)-('Consolidated Statements '!E7-'Consolidated Statements '!E16+'Consolidated Statements '!E13))/('Consolidated Statements '!E7-'Consolidated Statements '!E16+'Consolidated Statements '!E13) -> 0.2921494 | G6: =(('Consolidated Statements '!G7-'Consolidated Statements '!G16+'Consolidated Statements '!G13)-('Consolidated Statements '!F7-'Consolidated Statements '!F16+'Consolidated Statements '!F13))/('Consolidated Statements '!F7-'Consolidated Statements '!F16+'Consolidated Statements '!F13) -> 0.08693335
B7: EBIT Growth | D7: =(('Consolidated Statements '!D7-'Consolidated Statements '!D16)-('Consolidated Statements '!C7-'Consolidated Statements '!C16))/('Consolidated Statements '!C7-'Consolidated Statements '!C16) -> 0.14705104 | E7: =(('Consolidated Statements '!E7-'Consolidated Statements '!E16)-('Consolidated Statements '!D7-'Consolidated Statements '!D16))/('Consolidated Statements '!D7-'Consolidated Statements '!D16) -> 0.041810775 | F7: =(('Consolidated Statements '!F7-'Consolidated Statements '!F16)-('Consolidated Statements '!E7-'Consolidated Statements '!E16))/('Consolidated Statements '!E7-'Consolidated Statements '!E16) -> 0.19586868 | G7: =(('Consolidated Statements '!G7-'Consolidated Statements '!G16)-('Consolidated Statements '!F7-'Consolidated Statements '!F16))/('Consolidated Statements '!F7-'Consolidated Statements '!F16) -> 0.098149291
B8: Net Profit Growth | D8: =('Consolidated Statements '!D28-'Consolidated Statements '!C28)/'Consolidated Statements '!C28 -> -0.088158828 | E8: =('Consolidated Statements '!E28-'Consolidated Statements '!D28)/'Consolidated Statements '!D28 -> -0.16666667 | F8: =('Consolidated Statements '!F28-'Consolidated Statements '!E28)/'Consolidated Statements '!E28 -> 1.0183515 | G8: =('Consolidated Statements '!G28-'Consolidated Statements '!F28)/'Consolidated Statements '!F28 -> 0.10140237
B9: Dividend Growth | D9: =('Consolidated Statements '!U50-'Consolidated Statements '!T50)/'Consolidated Statements '!T50 -> -15.196498 | E9: =('Consolidated Statements '!V50-'Consolidated Statements '!U50)/'Consolidated Statements '!U50 -> -0.97505824 | F9: =('Consolidated Statements '!W50-'Consolidated Statements '!V50)/'Consolidated Statements '!V50 -> 25.225275 | G9: =('Consolidated Statements '!X50-'Consolidated Statements '!W50)/'Consolidated Statements '!W50 -> -1.0733291
B11: Gross Margin | C11: =('Consolidated Statements '!C7-'Consolidated Statements '!C10)/'Consolidated Statements '!C7 -> 0.6999443 | D11: =('Consolidated Statements '!D7-'Consolidated Statements '!D10)/'Consolidated Statements '!D7 -> 0.67625377 | E11: =('Consolidated Statements '!E7-'Consolidated Statements '!E10)/'Consolidated Statements '!E7 -> 0.68285123 | F11: =('Consolidated Statements '!F7-'Consolidated Statements '!F10)/'Consolidated Statements '!F7 -> 0.68645815 | G11: =('Consolidated Statements '!G7-'Consolidated Statements '!G10)/'Consolidated Statements '!G7 -> 0.68442431
B12: EBITDA Margin | C12: =('Consolidated Statements '!C7-'Consolidated Statements '!C16+'Consolidated Statements '!C13)/'Consolidated Statements '!C7 -> 0.25126693 | D12: =('Consolidated Statements '!D7-'Consolidated Statements '!D16+'Consolidated Statements '!D13)/'Consolidated Statements '!D7 -> 0.2519204 | E12: =('Consolidated Statements '!E7-'Consolidated Statements '!E16+'Consolidated Statements '!E13)/'Consolidated Statements '!E7 -> 0.21372975 | F12: =('Consolidated Statements '!F7-'Consolidated Statements '!F16+'Consolidated Statements '!F13)/'Consolidated Statements '!F7 -> 0.20419686 | G12: =('Consolidated Statements '!G7-'Consolidated Statements '!G16+'Consolidated Statements '!G13)/'Consolidated Statements '!G7 -> 0.2105113
B13: EBIT Margin | C13: ='Assumptions '!E18/'Assumptions '!E6 -> 0.16194992 | D13: ='Assumptions '!F18/'Assumptions '!F6 -> 0.16300451 | E13: ='Assumptions '!G18/'Assumptions '!G6 -> 0.15363503 | F13: ='Assumptions '!H18/'Assumptions '!H6 -> 0.16614601 | G13: ='Assumptions '!I18/'Assumptions '!I6 -> 0.16256929
B14: EBT Margin | C14: ='Consolidated Statements '!C22/'Consolidated Statements '!C7 -> 0.1463799 | D14: ='Consolidated Statements '!D22/'Consolidated Statements '!D7 -> 0.11708171 | E14: ='Consolidated Statements '!E22/'Consolidated Statements '!E7 -> 0.077670323 | F14: ='Consolidated Statements '!F22/'Consolidated Statements '!F7 -> 0.097636545 | G14: ='Consolidated Statements '!G22/'Consolidated Statements '!G7 -> 0.11454836
B15: Net Profit Margin | C15: ='Consolidated Statements '!C28/'Consolidated Statements '!C7 -> 0.11496814 | D15: ='Consolidated Statements '!D28/'Consolidated Statements '!D7 -> 0.091893244 | E15: ='Consolidated Statements '!E28/'Consolidated Statements '!E7 -> 0.055670514 | F15: ='Consolidated Statements '!F28/'Consolidated Statements '!F7 -> 0.083079405 | G15: ='Consolidated Statements '!G28/'Consolidated Statements '!G7 -> 0.086788627
B17: SalesExpenses%Sales | C17: =('Consolidated Statements '!C13+'Consolidated Statements '!C16)/'Consolidated Statements '!C7 -> 0.9430458 | D17: =('Consolidated Statements '!D13+'Consolidated Statements '!D16)/'Consolidated Statements '!D7 -> 0.94201293 | E17: =('Consolidated Statements '!E13+'Consolidated Statements '!E16)/'Consolidated Statements '!E7 -> 0.97901317 | F17: =('Consolidated Statements '!F13+'Consolidated Statements '!F16)/'Consolidated Statements '!F7 -> 0.99665839 | G17: =('Consolidated Statements '!G13+'Consolidated Statements '!G16)/'Consolidated Statements '!G7 -> 0.99434726
B18: Depreciation%Sales | C18: ='Consolidated Statements '!C15/'Consolidated Statements '!C7 -> 0.15296931 | D18: ='Consolidated Statements '!D15/'Consolidated Statements '!D7 -> 0.1417938 | E18: ='Consolidated Statements '!E15/'Consolidated Statements '!E7 -> 0.16241418 | F18: ='Consolidated Statements '!F15/'Consolidated Statements '!F7 -> 0.20920928 | G18: ='Consolidated Statements '!G15/'Consolidated Statements '!G7 -> 0.18853788
B19: OperatingIncome%Sales | C19: ='Assumptions '!E18/'Assumptions '!E6 -> 0.16194992 | D19: ='Assumptions '!F18/'Assumptions '!F6 -> 0.16300451 | E19: ='Assumptions '!G18/'Assumptions '!G6 -> 0.15363503 | F19: ='Assumptions '!H18/'Assumptions '!H6 -> 0.16614601 | G19: ='Assumptions '!I18/'Assumptions '!I6 -> 0.16256929
B21: Return on Capital Employed | C21: =(('Consolidated Statements '!C7-'Consolidated Statements '!C16)*(1-'Consolidated Statements '!C25/'Consolidated Statements '!C22))/('Consolidated Statements '!L34+'Consolidated Statements '!L43+'Consolidated Statements '!L37) -> 0.070813744 | D21: =(('Consolidated Statements '!D7-'Consolidated Statements '!D16)*(1-'Consolidated Statements '!D25/'Consolidated Statements '!D22))/('Consolidated Statements '!M34+('Consolidated Statements '!M43+'Consolidated Statements '!M37)) -> 0.068355475 | E21: =(('Consolidated Statements '!E7-'Consolidated Statements '!E16)*(1-'Consolidated Statements '!E25/'Consolidated Statements '!E22))/('Consolidated Statements '!N34+('Consolidated Statements '!N43+'Consolidated Statements '!N37)) -> 0.022404641 | F21: =(('Consolidated Statements '!F7-'Consolidated Statements '!F16)*(1-'Consolidated Statements '!F25/'Consolidated Statements '!F22))/('Consolidated Statements '!O34+('Consolidated Statements '!O43+'Consolidated Statements '!O37)) -> 0.029587877 | G21: =(('Consolidated Statements '!G7-'Consolidated Statements '!G16)*(1-'Consolidated Statements '!G25/'Consolidated Statements '!G22))/('Consolidated Statements '!P34+('Consolidated Statements '!P43+'Consolidated Statements '!P37)) -> 0.02693161
B22: Retained Earnings% | C22: =('Consolidated Statements '!C28-ABS('Consolidated Statements '!T50))/'Consolidated Statements '!C28 -> 0.93925786 | D22: =('Consolidated Statements '!D28-ABS('Consolidated Statements '!U50))/'Consolidated Statements '!D28 -> 0.054302748 | E22: =('Consolidated Statements '!E28-ABS('Consolidated Statements '!V50))/'Consolidated Statements '!E28 -> 0.97169518 | F22: =('Consolidated Statements '!F28-ABS('Consolidated Statements '!W50))/'Consolidated Statements '!F28 -> 0.63222376 | G22: =('Consolidated Statements '!G28-ABS('Consolidated Statements '!X50))/'Consolidated Statements '!G28 -> 0.9755142
B23: Return on Equity% | C23: ='Consolidated Statements '!C28/'Consolidated Statements '!L34 -> 0.099464009 | D23: ='Consolidated Statements '!D28/(('Consolidated Statements '!L34+'Consolidated Statements '!M34)/2) -> 0.085840157 | E23: ='Consolidated Statements '!E28/(('Consolidated Statements '!M34+'Consolidated Statements '!N34)/2) -> 0.031902437 | F23: ='Consolidated Statements '!F28/(('Consolidated Statements '!N34+'Consolidated Statements '!O34)/2) -> 0.042132055 | G23: ='Consolidated Statements '!G28/(('Consolidated Statements '!O34+'Consolidated Statements '!P34)/2) -> 0.044290276
B24: Self Sustained Growth Rate | C24: =('Consolidated Statements '!C28/'Consolidated Statements '!L40)*('Consolidated Statements '!C28-ABS('Consolidated Statements '!T50))/'Consolidated Statements '!C28 -> 0.13692589 | D24: =('Consolidated Statements '!D28/((('Consolidated Statements '!L40+'Consolidated Statements '!M40)/2)))*('Consolidated Statements '!D28-ABS('Consolidated Statements '!U50))/'Consolidated Statements '!D28 -> 0.0064958219 | E24: =('Consolidated Statements '!E28/((('Consolidated Statements '!M40+'Consolidated Statements '!N40)/2)))*('Consolidated Statements '!E28-ABS('Consolidated Statements '!V50))/'Consolidated Statements '!E28 -> 0.034701472 | F24: =('Consolidated Statements '!F28/((('Consolidated Statements '!N40+'Consolidated Statements '!O40)/2)))*('Consolidated Statements '!F28-ABS('Consolidated Statements '!W50))/'Consolidated Statements '!F28 -> 0.027700925 | G24: =('Consolidated Statements '!G28/((('Consolidated Statements '!O40+'Consolidated Statements '!P40)/2)))*('Consolidated Statements '!G28-ABS('Consolidated Statements '!X50))/'Consolidated Statements '!G28 -> 0.045419678
B25: Interest Coverage Ratio | C25: =('Consolidated Statements '!C7-'Consolidated Statements '!C16)/'Consolidated Statements '!C12 -> 19.658579 | D25: =('Consolidated Statements '!D7-'Consolidated Statements '!D16)/'Consolidated Statements '!D12 -> 19.247041 | E25: =('Consolidated Statements '!E7-'Consolidated Statements '!E16)/'Consolidated Statements '!E12 -> 3.2350835 | F25: =('Consolidated Statements '!F7-'Consolidated Statements '!F16)/'Consolidated Statements '!F12 -> 1.6635878 | G25: =('Consolidated Statements '!G7-'Consolidated Statements '!G16)/'Consolidated Statements '!G12 -> 1.9836193
B27: Debtor Turnover Ratio | C27: ='Consolidated Statements '!C7/'Consolidated Statements '!L25 -> 0.39737506 | D27: ='Consolidated Statements '!D7/((('Consolidated Statements '!L25+'Consolidated Statements '!M25)/2)) -> 0.43152612 | E27: ='Consolidated Statements '!E7/((('Consolidated Statements '!M25+'Consolidated Statements '!N25)/2)) -> 0.31890144 | F27: ='Consolidated Statements '!F7/((('Consolidated Statements '!N25+'Consolidated Statements '!O25)/2)) -> 0.28897779 | G27: ='Consolidated Statements '!G7/((('Consolidated Statements '!O25+'Consolidated Statements '!P25)/2)) -> 0.28676544
B28: Creditor Turnover Ratio | C28: =('Consolidated Statements '!C10+'Consolidated Statements '!C11+'Consolidated Statements '!C12)/'Consolidated Statements '!L49 -> 0.9101684 | D28: =('Consolidated Statements '!D10+'Consolidated Statements '!D11+'Consolidated Statements '!D12)/((('Consolidated Statements '!L49+'Consolidated Statements '!M49)/2)) -> 1.1186226 | E28: =('Consolidated Statements '!E10+'Consolidated Statements '!E11+'Consolidated Statements '!E12)/((('Consolidated Statements '!M49+'Consolidated Statements '!N49)/2)) -> 1.0006494 | F28: =('Consolidated Statements '!F10+'Consolidated Statements '!F11+'Consolidated Statements '!F12)/((('Consolidated Statements '!N49+'Consolidated Statements '!O49)/2)) -> 0.76936673 | G28: =('Consolidated Statements '!G10+'Consolidated Statements '!G11+'Consolidated Statements '!G12)/((('Consolidated Statements '!O49+'Consolidated Statements '!P49)/2)) -> 0.78496776
B29: Inventory Turnover | C29: =('Consolidated Statements '!C10+'Consolidated Statements '!C11+'Consolidated Statements '!C12)/'Consolidated Statements '!L18 -> 2.0528769 | D29: =('Consolidated Statements '!D10+'Consolidated Statements '!D11+'Consolidated Statements '!D12)/((('Consolidated Statements '!L18+'Consolidated Statements '!M18)/2)) -> 2.1589512 | E29: =('Consolidated Statements '!E10+'Consolidated Statements '!E11+'Consolidated Statements '!E12)/((('Consolidated Statements '!M18+'Consolidated Statements '!N18)/2)) -> 1.8606827 | F29: =('Consolidated Statements '!F10+'Consolidated Statements '!F11+'Consolidated Statements '!F12)/((('Consolidated Statements '!N18+'Consolidated Statements '!O18)/2)) -> 1.7435021 | G29: =('Consolidated Statements '!G10+'Consolidated Statements '!G11+'Consolidated Statements '!G12)/((('Consolidated Statements '!O18+'Consolidated Statements '!P18)/2)) -> 1.8307038
B30: Fixed Asset Turnover | C30: ='Consolidated Statements '!C7/'Consolidated Statements '!L15 -> 0.67390289 | D30: ='Consolidated Statements '!D7/((('Consolidated Statements '!L15+'Consolidated Statements '!M15)/2)) -> 0.73171624 | E30: ='Consolidated Statements '!E7/((('Consolidated Statements '!M15+'Consolidated Statements '!N15)/2)) -> 0.35299169 | F30: ='Consolidated Statements '!F7/((('Consolidated Statements '!N15+'Consolidated Statements '!O15)/2)) -> 0.30799625 | G30: ='Consolidated Statements '!G7/((('Consolidated Statements '!O15+'Consolidated Statements '!P15)/2)) -> 0.33970954
B31: Capital Turnover Ratio | C31: ='Consolidated Statements '!C7/('Consolidated Statements '!L40+'Consolidated Statements '!L28) -> 1.2680116 | D31: ='Consolidated Statements '!D7/(((('Consolidated Statements '!L40+'Consolidated Statements '!L28)+('Consolidated Statements '!M40+'Consolidated Statements '!M28))/2)) -> 1.3017534 | E31: ='Consolidated Statements '!E7/(((('Consolidated Statements '!M40+'Consolidated Statements '!M28)+('Consolidated Statements '!N40+'Consolidated Statements '!N28))/2)) -> 0.64149403 | F31: ='Consolidated Statements '!F7/(((('Consolidated Statements '!N40+'Consolidated Statements '!N28)+('Consolidated Statements '!O40+'Consolidated Statements '!O28))/2)) -> 0.52738779 | G31: ='Consolidated Statements '!G7/(((('Consolidated Statements '!O40+'Consolidated Statements '!O28)+('Consolidated Statements '!P40+'Consolidated Statements '!P28))/2)) -> 0.53647271
B33: Debtor Days | C33: =365/C27 -> 918.52771 | D33: =365/D27 -> 845.83524 | E33: =365/E27 -> 1144.5542 | F33: =365/F27 -> 1263.0729 | G33: =365/G27 -> 1272.8172
B34: Payable Days | C34: =365/C28 -> 401.02469 | D34: =365/D28 -> 326.29415 | E34: =365/E28 -> 364.76311 | F34: =365/F28 -> 474.41615 | G34: =365/G28 -> 464.98725
B35: Inventory Days | C35: =365/C29 -> 177.79926 | D35: =365/D29 -> 169.06357 | E35: =365/E29 -> 196.16456 | F35: =365/F29 -> 209.34876 | G35: =365/G29 -> 199.37687
B36: Cash Conversion Cycle (in days) | C36: =C33+C35-C34 -> 695.30229 | D36: =D33+D35-D34 -> 688.60466 | E36: =E33+E35-E34 -> 975.9557 | F36: =F33+F35-F34 -> 998.00547 | G36: =G33+G35-G34 -> 1007.2069

Sheet Stock Analysis
M3: Recommendation
M4: HOLD — Biocon trades at ₹352, valuing the company at ₹57,088 Cr. With FY25 consolidated revenue of ₹15,262 Cr (+3.4% YoY) and PAT of ₹1,429 Cr (+10.1% YoY), the stock offers a mixed risk-reward profile. Current P/E of 69.5x, ROCE of 6.3%, and dividend yield of 0.14% reflect a revaluation amid biosimilar market challenges. Suitable for long-term investors with patience for turnaround execution.
M11: Financial Year | N11: Revenue (₹ Crore) | O11: Profit After Tax (PAT) (₹ Crore) | P11: Revenue Change (%) | Q11: PAT Change (%) | R11: ROCE (%)
M12: FY 2024-25 | N12: 12965 | O12: 2215 | P12: 0.023444901 | Q12: 0.22308117 | R12: 0.204
M13: FY 2023-24 | N13: 12668 | O13: 1811 | P13: 0.092163118 | Q13: 0.79841112 | R13: 0.204
M14: FY 2022-23 | N14: 11599 | O14: 1007 | P14: 0.090746662 | Q14: -0.40059524 | R14: 0.204
M15: FY 2021-22 | N15: 10634 | O15: 1680 | P15: 0.19954879 | Q15: 0.038318912 | R15: 0.204
M16: FY 2020-21 | N16: 8865 | O16: 1618 | P16: - | Q16: - | R16: 0.204
N20: Biocon posts FY25 revenue of ₹15,262 Cr (+3.4% YoY), PAT of ₹1,429 Cr (+10.1% YoY); stock trades at ₹458
H26: FY 2024-25 | I26: 15262 | J26: 1429 | K26: 0.034 | L26: 0.101 | M26: 0.0625
B27: Metric | C27: Value | H27: FY 2023-24 | I27: 14756 | J27: 1298 | K27: 0.318 | L27: -0.107 | M27: 0.0625
B28: Market Cap | C28: ₹ 57,088 Cr. | H28: FY 2022-23 | I28: 11174 | J28: 643 | K28: 0.366 | L28: 0.166 | M28: 0.0625
B29: Current Price | C29: 352 | H29: FY 2021-22 | I29: 8184 | J29: 772 | K29: 0.145 | L29: -0.088 | M29: 0.0625
B30: High / Low | C30: ₹ 425 / 295 | H30: FY 2020-21 | I30: 7143 | J30: 846 | K30: -0.172 | L30: 0.078 | M30: 0.0625
B31: Stock P/E | C31: 69.5
B32: Book Value | C32: 200
B33: Dividend Yield | C33: 0.0014
B34: ROCE | C34: 0.0625
B35: ROE | C35: 0.0476
B36: Face Value | C36: 5

Sheet Assumptions 
C2: [ | D2: Suzlon Energy
D3: Consolidated Profit & Loss account
E4: 44256 | F4: 44621 | G4: 44986 | H4: 45352 | I4: Mar 25
C5: Particulars
C6: Revenue From Operations [Net] | E6: ='Consolidated Statements '!C7 -> 736.03 | F6: ='Consolidated Statements '!D7 -> 839.67 | G6: ='Consolidated Statements '!E7 -> 1155.01 | H6: ='Consolidated Statements '!F7 -> 1562.12 | I6: ='Consolidated Statements '!G7 -> 1646.99
C7: revenue growth | F7: =(F6-E6)/E6 -> 0.14080948 | G7: =(G6-F6)/F6 -> 0.3755523 | H7: =(H6-G6)/G6 -> 0.35247314 | I7: =(I6-H6)/H6 -> 0.054330013
C9: less: Material Consumed | E9: ='Consolidated Statements '!C10 -> 220.85 | F9: ='Consolidated Statements '!D10 -> 271.84 | G9: ='Consolidated Statements '!E10 -> 366.31 | H9: ='Consolidated Statements '!F10 -> 489.79 | I9: ='Consolidated Statements '!G10 -> 519.75
C10: less: Employee Cost | E10: ='Consolidated Statements '!C11 -> 156.57 | F10: ='Consolidated Statements '!D11 -> 170.98 | G10: ='Consolidated Statements '!E11 -> 200.41 | H10: ='Consolidated Statements '!F11 -> 213.7 | I10: ='Consolidated Statements '!G11 -> 294.42
C11: less: Other Expenses | E11: ='Consolidated Statements '!C15+'Consolidated Statements '!C14 -> 167.9 | F11: ='Consolidated Statements '!D15+'Consolidated Statements '!D14 -> 178.56 | G11: ='Consolidated Statements '!E15+'Consolidated Statements '!E14 -> 299.53 | H11: ='Consolidated Statements '!F15+'Consolidated Statements '!F14 -> 442.21 | I11: ='Consolidated Statements '!G15+'Consolidated Statements '!G14 -> 396.37
C12: Total Expenses | E12: =SUM(E9:E11) -> 545.32 | F12: =SUM(F9:F11) -> 621.38 | G12: =SUM(G9:G11) -> 866.25 | H12: =SUM(H9:H11) -> 1145.7 | I12: =SUM(I9:I11) -> 1210.54
C14: EBITDA | E14: =E6-E12 -> 190.71 | F14: =F6-F12 -> 218.29 | G14: =G6-G12 -> 288.76 | H14: =H6-H12 -> 416.42 | I14: =I6-I12 -> 436.45
C16: less: Depreciation & Amortization | E16: ='Consolidated Statements '!C13 -> 71.51 | F16: ='Consolidated Statements '!D13 -> 81.42 | G16: ='Consolidated Statements '!E13 -> 111.31 | H16: ='Consolidated Statements '!F13 -> 156.88 | I16: ='Consolidated Statements '!G13 -> 168.7
C18: EBIT | E18: =E14-E16 -> 119.2 | F18: =F14-F16 -> 136.87 | G18: =G14-G16 -> 177.45 | H18: =H14-H16 -> 259.54 | I18: =I14-I16 -> 267.75
C20: add: Other income | E20: 0 | F20: 0 | G20: 0 | H20: 0 | I20: 0
C21: less: Interest Expense | E21: ='Consolidated Statements '!C12 -> 5.77 | F21: ='Consolidated Statements '!D12 -> 6.76 | G21: ='Consolidated Statements '!E12 -> 41.9 | H21: ='Consolidated Statements '!F12 -> 97.44 | I21: ='Consolidated Statements '!G12 -> 89.74
C23: EBT | E23: =E18+E20-E21 -> 113.43 | F23: =F18+F20-F21 -> 130.11 | G23: =G18+G20-G21 -> 135.55 | H23: =H18+H20-H21 -> 162.1 | I23: =I18+I20-I21 -> 178.01
C25: less: Tax | E25: ='Consolidated Statements '!C25 -> 21.2 | F25: ='Consolidated Statements '!D25 -> 24.07 | G25: ='Consolidated Statements '!E25 -> 17.63 | H25: ='Consolidated Statements '!F25 -> 23.08 | I25: ='Consolidated Statements '!G25 -> 41.56
C26: less: Non Controlling interest | E26: ='Consolidated Statements '!C30+'Consolidated Statements '!C31 -> 10.57 | F26: ='Consolidated Statements '!D30+'Consolidated Statements '!D31 -> 12.32 | G26: ='Consolidated Statements '!E30+'Consolidated Statements '!E31 -> 18.03 | H26: ='Consolidated Statements '!F30+'Consolidated Statements '!F31 -> 27.53 | I26: ='Consolidated Statements '!G30+'Consolidated Statements '!G31 -> 41.61
C28: PAT | E28: =E23-E25-E26 -> 81.66 | F28: =F23-F25-F26 -> 93.72 | G28: =G23-G25-G26 -> 99.89 | H28: =H23-H25-H26 -> 111.49 | I28: =I23-I25-I26 -> 94.84
C30: Historical Growth
C31: Average Growth | E31: =AVERAGE(F7:I7) -> 0.23079123
C32: CAGR | E32: =(I6/E6)^(1/4)-1 -> 0.22306309 | F32: =_xlfn.RRI(4,E6,I6) -> 0.22306309
C34: Margin Analysis
C35: EBITDA Margin | E35: =E14/E6 -> 0.25910629 | F35: =F14/F6 -> 0.25997118 | G35: =G14/G6 -> 0.25000649 | H35: =H14/H6 -> 0.26657363 | I35: =I14/I6 -> 0.26499857
C36: EBIT Margin | E36: =E18/E6 -> 0.16194992 | F36: =F18/F6 -> 0.16300451 | G36: =G18/G6 -> 0.15363503 | H36: =H18/H6 -> 0.16614601 | I36: =I18/I6 -> 0.16256929
C37: EBT Margin | E37: =E23/E6 -> 0.15411057 | F37: =F23/F6 -> 0.15495373 | G37: =G23/G6 -> 0.11735829 | H37: =H23/H6 -> 0.10376924 | I37: =I23/I6 -> 0.10808202
C38: PAT Margin | E38: =E28/E6 -> 0.11094656 | F38: =F28/F6 -> 0.11161528 | G38: =G28/G6 -> 0.0864841 | H38: =H28/H6 -> 0.071370957 | I38: =I28/I6 -> 0.057583835
C40: Tax Rate
C41: Effective Tax Rate | E41: =E25/E23 -> 0.18689941 | F41: =F25/F23 -> 0.18499731 | G41: =G25/G23 -> 0.13006271 | H41: =H25/H23 -> 0.14238125 | I41: =I25/I23 -> 0.23347003
C42: Marginal Tax Rate | E42: =AVERAGE(E41:I41) -> 0.17556214 | F42: =E42 -> 0.17556214 | G42: =F42 -> 0.17556214 | H42: =G42 -> 0.17556214 | I42: =H42 -> 0.17556214
C44: Return on Capital
C45: EBIT(1-t) | E45: =E18*(1-E42) -> 98.272993 | F45: =F18*(1-F42) -> 112.84081 | G45: =G18*(1-G42) -> 146.2965 | H45: =H18*(1-H42) -> 213.9746 | I45: =I18*(1-I42) -> 220.74324
C46: Book Equity | E46: ='Consolidated Statements '!L34 -> 850.76 | F46: ='Consolidated Statements '!M34 -> 947 | G46: ='Consolidated Statements '!N34 -> 3084.04 | H46: ='Consolidated Statements '!O34 -> 3076.59 | I46: ='Consolidated Statements '!P34 -> 3378.1
C47: Book Debt | E47: ='Consolidated Statements '!L37+'Consolidated Statements '!L38+'Consolidated Statements '!L43+'Consolidated Statements '!L44 -> 796.77 | F47: ='Consolidated Statements '!M37+'Consolidated Statements '!M38+'Consolidated Statements '!M43+'Consolidated Statements '!M44 -> 864.76 | G47: ='Consolidated Statements '!N37+'Consolidated Statements '!N38+'Consolidated Statements '!N43+'Consolidated Statements '!N44 -> 2717.26 | H47: ='Consolidated Statements '!O37+'Consolidated Statements '!O38+'Consolidated Statements '!O43+'Consolidated Statements '!O44 -> 2862.29 | I47: ='Consolidated Statements '!P37+'Consolidated Statements '!P38+'Consolidated Statements '!P43+'Consolidated Statements '!P44 -> 2874.02
C48: Cash and Cash Equivalent | E48: ='Consolidated Statements '!L20 -> 0 | F48: ='Consolidated Statements '!M20 -> 0 | G48: ='Consolidated Statements '!N20 -> 438.67 | H48: ='Consolidated Statements '!O20 -> 310.16 | I48: ='Consolidated Statements '!P20 -> 492.55
C49: Capital Employed | E49: =E46+E47-E48 -> 1647.53 | F49: =F46+F47-F48 -> 1811.76 | G49: =G46+G47-G48 -> 5362.63 | H49: =H46+H47-H48 -> 5628.72 | I49: =I46+I47-I48 -> 5759.57
C51: Pre Tax Return on Capital | E51: =E18/E49 -> 0.072350731 | F51: =F18/F49 -> 0.075545326 | G51: =G18/G49 -> 0.033090107 | H51: =H18/H49 -> 0.04610995 | I51: =I18/I49 -> 0.046487845
C52: Post Tax Return on Capital | E52: =E45/E49 -> 0.059648682 | F52: =F45/F49 -> 0.062282427 | G52: =G45/G49 -> 0.027280737 | H52: =H45/H49 -> 0.038014789 | I52: =I45/I49 -> 0.03832634

Sheet BETA
B2: Biocon | F2: NIFTY50
B3: Date | C3: Daily Closing Price | F3: Date | G3: Closing Price | J3: BETA
B4: 01-04-2021 | C4: 410.55 | F4: 44287 | G4: 14867.35 | J4: =SLOPE(D5:D1237,H5:H1237) -> 0.89538966
B5: 05-04-2021 | C5: 406.45 | D5: =(C5-C4)/C4 -> -0.0099866033 | F5: 44291 | G5: 14637.8 | H5: =(G5-G4)/G4 -> -0.015439861
B6: 06-04-2021 | C6: 414.25 | D6: =(C6-C5)/C5 -> 0.019190552 | F6: 44292 | G6: 14683.5 | H6: =(G6-G5)/G5 -> 0.0031220672
B7: 07-04-2021 | C7: 414.2 | D7: =(C7-C6)/C6 -> -0.00012070006 | F7: 44293 | G7: 14819.05 | H7: =(G7-G6)/G6 -> 0.009231437
B8: 08-04-2021 | C8: 413.25 | D8: =(C8-C7)/C7 -> -0.002293578 | F8: 44294 | G8: 14873.8 | H8: =(G8-G7)/G7 -> 0.0036945689
B9: 09-04-2021 | C9: 420.3 | D9: =(C9-C8)/C8 -> 0.017059891 | F9: 44295 | G9: 14834.85 | H9: =(G9-G8)/G8 -> -0.0026187118 | J9: SUMMARY OUTPUT
B10: 12-04-2021 | C10: 404.3 | D10: =(C10-C9)/C9 -> -0.038068047 | F10: 44298 | G10: 14310.8 | H10: =(G10-G9)/G9 -> -0.035325589
B11: 13-04-2021 | C11: 406.95 | D11: =(C11-C10)/C10 -> 0.0065545387 | F11: 44299 | G11: 14504.8 | H11: =(G11-G10)/G10 -> 0.013556196 | J11: Regression Statistics
B12: 15-04-2021 | C12: 404.6 | D12: =(C12-C11)/C11 -> -0.0057746652 | F12: 44301 | G12: 14581.45 | H12: =(G12-G11)/G11 -> 0.0052844846 | J12: Multiple R | K12: 0.39224543
B13: 16-04-2021 | C13: 412.85 | D13: =(C13-C12)/C12 -> 0.020390509 | F13: 44302 | G13: 14617.85 | H13: =(G13-G12)/G12 -> 0.0024962822 | J13: R Square | K13: 0.15385648
B14: 19-04-2021 | C14: 406.35 | D14: =(C14-C13)/C13 -> -0.015744217 | F14: 44305 | G14: 14359.45 | H14: =(G14-G13)/G13 -> -0.017676979 | J14: Adjusted R Square | K14: 0.15316911
B15: 20-04-2021 | C15: 401.15 | D15: =(C15-C14)/C14 -> -0.01279685 | F15: 44306 | G15: 14296.4 | H15: =(G15-G14)/G14 -> -0.004390823 | J15: Standard Error | K15: 0.018217194
B16: 22-04-2021 | C16: 399.35 | D16: =(C16-C15)/C15 -> -0.0044870996 | F16: 44308 | G16: 14406.15 | H16: =(G16-G15)/G15 -> 0.0076767576 | J16: Observations | K16: 1233
B17: 23-04-2021 | C17: 397.6 | D17: =(C17-C16)/C16 -> -0.0043821209 | F17: 44309 | G17: 14341.35 | H17: =(G17-G16)/G16 -> -0.0044981331
B18: 26-04-2021 | C18: 395.5 | D18: =(C18-C17)/C17 -> -0.0052816901 | F18: 44312 | G18: 14485 | H18: =(G18-G17)/G17 -> 0.010016518 | J18: ANOVA
B19: 27-04-2021 | C19: 398.1 | D19: =(C19-C18)/C18 -> 0.006573957 | F19: 44313 | G19: 14653.05 | H19: =(G19-G18)/G18 -> 0.011601643 | K19: df | L19: SS | M19: MS | N19: F | O19: Significance F
B20: 28-04-2021 | C20: 390.85 | D20: =(C20-C19)/C19 -> -0.018211505 | F20: 44314 | G20: 14864.55 | H20: =(G20-G19)/G19 -> 0.014433855 | J20: Regression | K20: 1 | L20: 0.074283568 | M20: 0.074283568 | N20: 223.83593 | O20: 1.2678039e-46
B21: 29-04-2021 | C21: 393.9 | D21: =(C21-C20)/C20 -> 0.0078035052 | F21: 44315 | G21: 14894.9 | H21: =(G21-G20)/G20 -> 0.00204181 | J21: Residual | K21: 1231 | L21: 0.40852723 | M21: 0.00033186615
B22: 30-04-2021 | C22: 379.65 | D22: =(C22-C21)/C21 -> -0.036176695 | F22: 44316 | G22: 14631.1 | H22: =(G22-G21)/G21 -> -0.017710812 | J22: Total | K22: 1232 | L22: 0.48281079
B23: 03-05-2021 | C23: 378.5 | D23: =(C23-C22)/C22 -> -0.0030291058 | F23: 44319 | G23: 14634.15 | H23: =(G23-G22)/G22 -> 0.00020851346
B24: 04-05-2021 | C24: 373.2 | D24: =(C24-C23)/C23 -> -0.014002642 | F24: 44320 | G24: 14496.5 | H24: =(G24-G23)/G23 -> -0.0094061074 | K24: Coefficients | L24: Standard Error | M24: t Stat | N24: P-value | O24: Lower 95% | P24: Upper 95% | Q24: Lower 95.0% | R24: Upper 95.0%
B25: 05-05-2021 | C25: 381.3 | D25: =(C25-C24)/C24 -> 0.02170418 | F25: 44321 | G25: 14617.85 | H25: =(G25-G24)/G24 -> 0.0083709592 | J25: Intercept | K25: -0.00023775343 | L25: 0.00051926642 | M25: -0.45786406 | N25: 0.64713092 | O25: -0.0012564986 | P25: 0.00078099171 | Q25: -0.0012564986 | R25: 0.00078099171
B26: 06-05-2021 | C26: 379.7 | D26: =(C26-C25)/C25 -> -0.004196171 | F26: 44322 | G26: 14724.8 | H26: =(G26-G25)/G25 -> 0.007316411 | J26: X Variable 1 | K26: 0.89538966 | L26: 0.05984766 | M26: 14.961147 | N26: 1.2678039e-46 | O26: 0.77797496 | P26: 1.0128044 | Q26: 0.77797496 | R26: 1.0128044
B27: 07-05-2021 | C27: 381.15 | D27: =(C27-C26)/C26 -> 0.0038188043 | F27: 44323 | G27: 14823.15 | H27: =(G27-G26)/G26 -> 0.0066792477
B28: 10-05-2021 | C28: 384.5 | D28: =(C28-C27)/C27 -> 0.0087891906 | F28: 44326 | G28: 14942.35 | H28: =(G28-G27)/G27 -> 0.0080414227
B29: 11-05-2021 | C29: 387.65 | D29: =(C29-C28)/C28 -> 0.0081924577 | F29: 44327 | G29: 14850.75 | H29: =(G29-G28)/G28 -> -0.0061302012
B30: 12-05-2021 | C30: 385.45 | D30: =(C30-C29)/C29 -> -0.0056752225 | F30: 44328 | G30: 14696.5 | H30: =(G30-G29)/G29 -> -0.010386681
B31: 14-05-2021 | C31: 388.8 | D31: =(C31-C30)/C30 -> 0.0086911402 | F31: 44330 | G31: 14677.8 | H31: =(G31-G30)/G30 -> -0.0012724251
B32: 17-05-2021 | C32: 385.8 | D32: =(C32-C31)/C31 -> -0.0077160494 | F32: 44333 | G32: 14923.15 | H32: =(G32-G31)/G31 -> 0.01671576
B33: 18-05-2021 | C33: 385 | D33: =(C33-C32)/C32 -> -0.0020736133 | F33: 44334 | G33: 15108.1 | H33: =(G33-G32)/G32 -> 0.012393443
B34: 19-05-2021 | C34: 386.65 | D34: =(C34-C33)/C33 -> 0.0042857143 | F34: 44335 | G34: 15030.15 | H34: =(G34-G33)/G33 -> -0.0051594324
B35: 20-05-2021 | C35: 383.55 | D35: =(C35-C34)/C34 -> -0.008017587 | F35: 44336 | G35: 14906.05 | H35: =(G35-G34)/G34 -> -0.0082567761
B36: 21-05-2021 | C36: 382.5 | D36: =(C36-C35)/C35 -> -0.0027375831 | F36: 44337 | G36: 15175.3 | H36: =(G36-G35)/G35 -> 0.018063136
B37: 24-05-2021 | C37: 383.45 | D37: =(C37-C36)/C36 -> 0.0024836601 | F37: 44340 | G37: 15197.7 | H37: =(G37-G36)/G36 -> 0.0014761086
B38: 25-05-2021 | C38: 381.55 | D38: =(C38-C37)/C37 -> -0.0049550137 | F38: 44341 | G38: 15208.45 | H38: =(G38-G37)/G37 -> 0.00070734387
... B1237: 30-03-2026 | C1237: 360.9 | D1237: =(C1237-C1236)/C1236 -> -0.024858146 | F1237: 46111 | G1237: 22331.4 | H1237: =(G1237-G1236)/G1236 -> -0.021393856

Sheet WACC
B1: Weighted Average Cost of Capital
B4: Capital Structure
B5: Total Debt | C5: ='Consolidated Statements '!P37+'Consolidated Statements '!P43 -> 1775.55
B6: Total Equity | C6: ='Consolidated Statements '!P34 -> 3378.1
B7: Total Mix | C7: =SUM(C5:C6) -> 5153.65
B8: % of Debt | C8: =C5/C7 -> 0.34452281
B9: % of Equity | C9: =C6/C7 -> 0.65547719
B10: Debt to Equity | C10: =C5/C6 -> 0.52560611
B14: Cost of Equity | E14: Cost of Debt
B15: Risk free rate(Rf) | C15: 0.066 | E15: Source | F15: Cost
B16: Beta | C16: =BETA!J4 -> 0.89538966 | E16: Cost of debt* | F16: ='Consolidated Statements '!G12/('Consolidated Statements '!P37+'Consolidated Statements '!P43) -> 0.050542086
B17: Market risk premium | C17: 0.07 | E17: Tax rate | F17: =AVERAGE('Assumptions '!E41:I41) -> 0.17556214
B18: Cost of equity | C18: =C15+C16*C17 -> 0.12867728 | E18: Cost of Debt after tax | F18: =F16*(1-F17) -> 0.041668809
B21: WACC
B22: Source | C22: Weight | D22: Cost | E22: Weighted Cost
B23: Debt | C23: =C8 -> 0.34452281 | D23: =F18 -> 0.041668809 | E23: =C23*D23 -> 0.014355855
B24: Equity | C24: =C9 -> 0.65547719 | D24: =C18 -> 0.12867728 | E24: =C24*D24 -> 0.084345019
B25: WACC | E25: =SUM(E23:E24) -> 0.098700874

Sheet Fixed Asset Schedule 
B1: BIOCON "Fixed Asset Schedule "
B2: Particular | C2: 44256 | D2: 44621 | E2: 44986 | F2: 45352 | G2: 45717
B3: Beginning balance | D3: =C7 -> 916.41 | E3: =D7 -> 1067.94 | F3: =E7 -> 1012.26 | G3: =F7 -> 1197.78
B4: Add: Net Purchases | D4: =D5-D3 -> 232.95 | E4: =E5-E3 -> 55.63 | F4: =F5-F3 -> 342.4 | G4: =G5-G3 -> 312.33
B5: Total Fixed Assets | C5: =C6+C7 -> 987.92 | D5: =D6+D7 -> 1149.36 | E5: =E6+E7 -> 1123.57 | F5: =F6+F7 -> 1354.66 | G5: =G6+G7 -> 1510.11
B6: Less: Depreciation | C6: ='Consolidated Statements '!C13 -> 71.51 | D6: ='Consolidated Statements '!D13 -> 81.42 | E6: ='Consolidated Statements '!E13 -> 111.31 | F6: ='Consolidated Statements '!F13 -> 156.88 | G6: ='Consolidated Statements '!G13 -> 168.7
B7: Closing Balance(Fixed Asests ) | C7: ='Consolidated Statements '!L7 -> 916.41 | D7: ='Consolidated Statements '!M7 -> 1067.94 | E7: ='Consolidated Statements '!N7 -> 1012.26 | F7: ='Consolidated Statements '!O7 -> 1197.78 | G7: ='Consolidated Statements '!P7 -> 1341.41
B9: Net Capital expenditure | D9: =D4-D6 -> 151.53 | E9: =E4-E6 -> -55.68 | F9: =F4-F6 -> 185.52 | G9: =G4-G6 -> 143.63
B10: Net Capital expenditure / Sales percentage | D10: =IFERROR(D9/D3,0) -> 0.16535175 | E10: =IFERROR(E9/E3,0) -> -0.052137761 | F10: =IFERROR(F9/F3,0) -> 0.18327307 | G10: =IFERROR(G9/G3,0) -> 0.11991351
B12: Median Capital expenditure /Sales percentage | C12: =MEDIAN(D10:G10) -> 0.14263263
B13: Average Capital expenditure /Sales percentage | C13: =AVERAGE(D10:G10) -> 0.10410014

Sheet Change in WC
B2: "Change in Working Capital "
B3: Particular | C3: 44256 | D3: 44621 | E3: 44986 | F3: 45352 | G3: 45717
B4: Inventory | C4: ='Consolidated Statements '!L18 -> 186.66 | D4: ='Consolidated Statements '!M18 -> 229.82 | E4: ='Consolidated Statements '!N18 -> 424.37 | F4: ='Consolidated Statements '!O18 -> 494.39 | G4: ='Consolidated Statements '!P18 -> 493.11
B5: Trade Receivables | C5: ='Consolidated Statements '!L19 -> 531.78 | D5: ='Consolidated Statements '!M19 -> 564.63 | E5: ='Consolidated Statements '!N19 -> 494.85 | F5: ='Consolidated Statements '!O19 -> 751.5 | G5: ='Consolidated Statements '!P19 -> 661.63
B6: Trade Payable | C6: ='Consolidated Statements '!L38 -> 167.92 | D6: ='Consolidated Statements '!M38 -> 173.84 | E6: ='Consolidated Statements '!N38 -> 940.19 | F6: ='Consolidated Statements '!O38 -> 1289.33 | G6: ='Consolidated Statements '!P38 -> 1098.47
B7: Non Cash working Capital | C7: =C4+C5-C6 -> 550.52 | D7: =D4+D5-D6 -> 620.61 | E7: =E4+E5-E6 -> -20.97 | F7: =F4+F5-F6 -> -43.44 | G7: =G4+G5-G6 -> 56.27
B8: Change in Working Capital | D8: =D7-C7 -> 70.09 | E8: =E7-D7 -> -641.58 | F8: =F7-E7 -> -22.47 | G8: =G7-F7 -> 99.71
B9: changein working Capital /percentage of sales | D9: =D8/'Consolidated Statements '!C7 -> 0.095227097 | E9: =E8/'Consolidated Statements '!D7 -> -0.76408589 | F9: =F8/'Consolidated Statements '!E7 -> -0.019454377 | G9: =G8/'Consolidated Statements '!F7 -> 0.063829923
B11: Median Non Cash working Capital /Sales percentage | C11: =MEDIAN(D9:G9) -> 0.022187773
B12: Average Non Cash working Capital /Sales percentage | C12: =AVERAGE(D9:G9) -> -0.15612081

Sheet FCFF
B2: BIOCON "Free Cash Flow "
B3: Particular | C3: 44256 | D3: 44621 | E3: 44986 | F3: 45352 | G3: 45717
B4: EBIT | C4: ='Assumptions '!E18 -> 119.2 | D4: ='Assumptions '!F18 -> 136.87 | E4: ='Assumptions '!G18 -> 177.45 | F4: ='Assumptions '!H18 -> 259.54 | G4: ='Assumptions '!I18 -> 267.75
B5: Less: Tax on EBIT | C5: ='Assumptions '!E42 -> 0.17556214 | D5: ='Assumptions '!F42 -> 0.17556214 | E5: ='Assumptions '!G42 -> 0.17556214 | F5: ='Assumptions '!H42 -> 0.17556214 | G5: ='Assumptions '!I42 -> 0.17556214
B6: EBIT * (1- Tax) | C6: =C4*(1-C5) -> 98.272993 | D6: =D4*(1-D5) -> 112.84081 | E6: =E4*(1-E5) -> 146.2965 | F6: =F4*(1-F5) -> 213.9746 | G6: =G4*(1-G5) -> 220.74324
B7: Less: Net Capital expenditure | C7: 0 | D7: ='Fixed Asset Schedule '!D9 -> 151.53 | E7: ='Fixed Asset Schedule '!E9 -> -55.68 | F7: ='Fixed Asset Schedule '!F9 -> 185.52 | G7: ='Fixed Asset Schedule '!G9 -> 143.63
B8: Less: Net Change in working Capital | C8: 0 | D8: ='Change in WC'!D8 -> 70.09 | E8: ='Change in WC'!E8 -> -641.58 | F8: ='Change in WC'!F8 -> -22.47 | G8: ='Change in WC'!G8 -> 99.71
B9: Reinvestment | C9: =SUM(C7:C8) -> 0 | D9: =SUM(D7:D8) -> 221.62 | E9: =SUM(E7:E8) -> -697.26 | F9: =SUM(F7:F8) -> 163.05 | G9: =SUM(G7:G8) -> 243.34
B10: Free Cash Flow | C10: =C6-C9 -> 98.272993 | D10: =D6-D9 -> -108.77919 | E10: =E6-E9 -> 843.5565 | F10: =F6-F9 -> 50.924602 | G10: =G6-G9 -> -22.596763
B12: Reinvestment Rate | D12: =D9/D6 -> 1.9640058 | E12: =E9/E6 -> -4.7660744 | F12: =F9/F6 -> 0.76200632 | G12: =G9/G6 -> 1.1023667
B14: Median Reinvestment rate /Sales percentage | C14: =MEDIAN(D12:G12) -> 0.93218653
B15: Average Reinvestment rate /Sales percentage | C15: =AVERAGE(D12:G12) -> -0.23442391

Sheet Growth Scenario
B2: BIOCON "Growth Scenarios"
B4: Scenario 1: High Growth
B5: INR Cr. | C5: LTM | D5: Y1E | E5: Y2E | F5: Y3E | G5: Y4W | H5: Y5E | I5: Y6E | J5: Y7E | K5: Y8E | L5: Y9E | M5: Y10E
B6: Sales | C6: ='Consolidated Statements '!G7 -> 1646.99 | D6: =C6*(1+D7) -> 2053.2058 | E6: =D6*(1+E7) -> 2518.4007 | F6: =E6*(1+F7) -> 3038.4474 | G6: =F6*(1+G7) -> 3604.8977 | H6: =G6*(1+H7) -> 4204.5951 | I6: =H6*(1+I7) -> 4819.6644 | J6: =I6*(1+J7) -> 5427.9724 | K6: =J6*(1+K7) -> 6004.111 | ... M6: =L6*(1+M7) -> 6951.2713 | O6: Risk Free Rate | P6: 0.066
B7: Sales Growth % | D7: =N7 -> 0.24664131 | E7: =D7-$P$9 -> 0.22657005 | F7: =E7-$P$9 -> 0.2064988 | G7: =F7-$P$9 -> 0.18642754 | H7: =G7-$P$9 -> 0.16635628 | I7: =H7-$P$9 -> 0.14628503 | J7: =I7-$P$9 -> 0.12621377 | K7: =J7-$P$9 -> 0.10614251 | L7: =K7-$P$9 -> 0.086071256 | M7: =L7-$P$9 -> 0.066 | N7: =MEDIAN('Assumptions '!F7:I7) -> 0.24664131
B9: Scenario 2: Average Growth | O9: =N7-P6 -> 0.18064131 | P9: =O9/9 -> 0.020071256
B10: INR Cr. | C10: LTM | D10: Y1E | E10: Y2E | F10: Y3E | G10: Y4W | H10: Y5E | I10: Y6E | J10: Y7E | K10: Y8E | L10: Y9E | M10: Y10E
B11: Sales | C11: =C6 -> 1646.99 | D11: =C11*(1+D12) -> 2027.1009 | E11: =D11*(1+E12) -> 2458.1593 | F11: =E11*(1+F12) -> 2936.2818 | G11: =F11*(1+G12) -> 3454.1269 | H11: =G11*(1+H12) -> 4000.6297 | I11: =H11*(1+I12) -> 4561.0135 | J11: =I11*(1+J12) -> 5117.1397 | K11: =J11*(1+K12) -> 5648.232 | ... M11: =L11*(1+M12) -> 6545.8739
B12: Sales Growth % | D12: =AVERAGE('Assumptions '!F7:I7) -> 0.23079123 | E12: =D12-O12 -> 0.21264776 | F12: =E12-O12 -> 0.19450429 | G12: =F12-O12 -> 0.17636082 | H12: =G12-O12 -> 0.15821735 | I12: =H12-O12 -> 0.14007388 | J12: =I12-O12 -> 0.12193041 | K12: =J12-O12 -> 0.10378694 | L12: =K12-O12 -> 0.08564347 | M12: 0.0675 | N12: =D12-M12 -> 0.16329123 | O12: =N12/9 -> 0.01814347
B14: Scenario 3: EBIT Growth
B15: INR Cr. | C15: LTM | D15: Y1E | E15: Y2E | F15: Y3E | G15: Y4W | H15: Y5E | I15: Y6E | J15: Y7E | K15: Y8E | L15: Y9E | M15: Y10E
B16: Sales | C16: =C11 -> 1646.99 | D16: =C16*(1+D17) -> 1705.8325 | E16: =D16*(1+E17) -> 1772.7994 | F16: =E16*(1+F17) -> 1848.6537 | G16: =F16*(1+G17) -> 1934.2801 | H16: =G16*(1+H17) -> 2030.701 | I16: =H16*(1+I17) -> 2139.0974 | J16: =I16*(1+J17) -> 2260.8315 | K16: =J16*(1+K17) -> 2397.4748 | ... M16: =L16*(1+M17) -> 2723.0223
B17: Sales Growth % | D17: =FCFF!C14*'Assumptions '!I52 -> 0.035727298 | E17: =D17-$O$17 -> 0.039257598 | F17: =E17-$O$17 -> 0.042787898 | G17: =F17-$O$17 -> 0.046318198 | H17: =G17-$O$17 -> 0.049848499 | I17: =H17-$O$17 -> 0.053378799 | J17: =I17-$O$17 -> 0.056909099 | K17: =J17-$O$17 -> 0.060439399 | L17: =K17-$O$17 -> 0.0639697 | M17: 0.0675 | N17: =D17-M17 -> -0.031772702 | O17: =N17/9 -> -0.0035303003
B19: Live Scenario | C19: 3
B20: INR Cr. | C20: LTM | D20: Y1E | E20: Y2E | F20: Y3E | G20: Y4W | H20: Y5E | I20: Y6E | J20: Y7E | K20: Y8E | L20: Y9E | M20: Y10E
B21: Sales | C21: =C6 -> 1646.99 | D21: =C21*(1+D22) -> 1705.8325 | E21: =D21*(1+E22) -> 1772.7994 | F21: =E21*(1+F22) -> 1848.6537 | G21: =F21*(1+G22) -> 1934.2801 | H21: =G21*(1+H22) -> 2030.701 | I21: =H21*(1+I22) -> 2139.0974 | J21: =I21*(1+J22) -> 2260.8315 | K21: =J21*(1+K22) -> 2397.4748 | ... M21: =L21*(1+M22) -> 2723.0223
B22: Sales Growth % | D22: =CHOOSE($C$19,D7,D12,D17) -> 0.035727298 | E22: =CHOOSE($C$19,E7,E12,E17) -> 0.039257598 | F22: =CHOOSE($C$19,F7,F12,F17) -> 0.042787898 | G22: =CHOOSE($C$19,G7,G12,G17) -> 0.046318198 | H22: =CHOOSE($C$19,H7,H12,H17) -> 0.049848499 | I22: =CHOOSE($C$19,I7,I12,I17) -> 0.053378799 | J22: =CHOOSE($C$19,J7,J12,J17) -> 0.056909099 | K22: =CHOOSE($C$19,K7,K12,K17) -> 0.060439399 | ... M22: =CHOOSE($C$19,M7,M12,M17) -> 0.0675

Sheet Valuation
B1: Biocon- "VALUATION"
D2: 1 | E2: 2 | F2: 3 | G2: 4 | H2: 5 | I2: 6 | J2: 7 | K2: 8 | L2: 9 | M2: 10
B3: INR Cr | C3: LTM | D3: Y1E | E3: Y2E | F3: Y3E | G3: Y4W | H3: Y5E | I3: Y6E | J3: Y7E | K3: Y8E | L3: Y9E | M3: Y10E | O3: Terminal Year | Q3: Terminal growth rate % | R3: 0.03
B4: Sales | C4: ='Growth Scenario'!C21 -> 1646.99 | D4: ='Growth Scenario'!D21 -> 1705.8325 | E4: ='Growth Scenario'!E21 -> 1772.7994 | F4: ='Growth Scenario'!F21 -> 1848.6537 | G4: ='Growth Scenario'!G21 -> 1934.2801 | H4: ='Growth Scenario'!H21 -> 2030.701 | I4: ='Growth Scenario'!I21 -> 2139.0974 | J4: ='Growth Scenario'!J21 -> 2260.8315 | ... M4: ='Growth Scenario'!M21 -> 2723.0223 | O4: =M4*(1+R3) -> 2804.7129 | Q4: Cost of Capital % | R4: =WACC!E25 -> 0.098700874
B5: Sales Growth | D5: ='Growth Scenario'!D22 -> 0.035727298 | E5: ='Growth Scenario'!E22 -> 0.039257598 | F5: ='Growth Scenario'!F22 -> 0.042787898 | G5: ='Growth Scenario'!G22 -> 0.046318198 | H5: ='Growth Scenario'!H22 -> 0.049848499 | I5: ='Growth Scenario'!I22 -> 0.053378799 | J5: ='Growth Scenario'!J22 -> 0.056909099 | K5: ='Growth Scenario'!K22 -> 0.060439399 | ... M5: ='Growth Scenario'!M22 -> 0.0675 | O5: =R3 -> 0.03 | Q5: Terminal reinvestment rate % | R5: =R4*R3 -> 0.0029610262
B6: EBIT | D6: =D7*D4 -> 393.69119 | E6: =E7*E4 -> 409.14656 | F6: =F7*F4 -> 426.65308 | G6: =G7*G4 -> 446.41488 | H6: =H7*H4 -> 468.66799 | I6: =I7*I4 -> 493.68492 | J6: =J7*J4 -> 521.78009 | K6: =K7*K4 -> 553.31616 | ... M6: =M7*M4 -> 628.44967 | O6: =O7*O4 -> 647.30316
B7: EBIT Margin % | D7: =AVERAGE('Assumptions '!F7:I7) -> 0.23079123 | E7: =D7 -> 0.23079123 | F7: =E7 -> 0.23079123 | G7: =F7 -> 0.23079123 | H7: =G7 -> 0.23079123 | I7: =H7 -> 0.23079123 | J7: =I7 -> 0.23079123 | K7: =J7 -> 0.23079123 | L7: =K7 -> 0.23079123 | M7: =L7 -> 0.23079123 | O7: =M7 -> 0.23079123 | Q7: Enterprise value = Equity Value + Minority interest
B8: Less: Tax on EBIT | D8: =WACC!$F$17*Valuation!D6 -> 69.117267 | E8: =WACC!$F$17*Valuation!E6 -> 71.830645 | F8: =WACC!$F$17*Valuation!F6 -> 74.904127 | G8: =WACC!$F$17*Valuation!G6 -> 78.373552 | H8: =WACC!$F$17*Valuation!H6 -> 82.280356 | I8: =WACC!$F$17*Valuation!I6 -> 86.672382 | J8: =WACC!$F$17*Valuation!J6 -> 91.604829 | K8: =WACC!$F$17*Valuation!K6 -> 97.14137 | ... M8: =WACC!$F$17*Valuation!M6 -> 110.33197
B9: EBIT(1-T) | D9: =D6-D8 -> 324.57392 | E9: =E6-E8 -> 337.31591 | F9: =F6-F8 -> 351.74895 | G9: =G6-G8 -> 368.04133 | H9: =H6-H8 -> 386.38763 | I9: =I6-I8 -> 407.01254 | J9: =J6-J8 -> 430.17526 | K9: =K6-K8 -> 456.17479 | ... M9: =M6-M8 -> 518.1177 | O9: =O6-O8 -> 647.30316
B10: Less: Net Capital Expenditure | D10: =FCFF!$C$14*Valuation!D4 -> 1590.1541 | E10: =FCFF!$C$15*Valuation!E4 -> -415.58656 | F10: =FCFF!$C$15*Valuation!F4 -> -433.36863 | G10: =FCFF!$C$15*Valuation!G4 -> -453.44149 | H10: =FCFF!$C$15*Valuation!H4 -> -476.04487 | I10: =FCFF!$C$15*Valuation!I4 -> -501.45557 | J10: =FCFF!$C$15*Valuation!J4 -> -529.99295 | K10: =FCFF!$C$15*Valuation!K4 -> -562.02541 | L10: =FCFF!$C$15*Valuation!L4 -> -597.97801 | M10: =FCFF!$C$15*Valuation!M4 -> -638.34152
B11: Non Cash Working Capital | C11: ='Change in WC'!G7 -> 56.27 | D11: ='Change in WC'!$C$11*Valuation!D4 -> 37.848625 | E11: ='Change in WC'!$C$11*Valuation!E4 -> 39.334471 | F11: ='Change in WC'!$C$11*Valuation!F4 -> 41.01751 | G11: ='Change in WC'!$C$11*Valuation!G4 -> 42.917367 | H11: ='Change in WC'!$C$11*Valuation!H4 -> 45.056734 | I11: ='Change in WC'!$C$11*Valuation!I4 -> 47.461808 | J11: ='Change in WC'!$C$11*Valuation!J4 -> 50.162817 | K11: ='Change in WC'!$C$11*Valuation!K4 -> 53.194627 | ... M11: ='Change in WC'!$C$11*Valuation!M4 -> 60.417801
B12: Less: Change in Working Capital | D12: =D11-C11 -> -18.421375 | E12: =E11-D11 -> 1.4858461 | F12: =F11-E11 -> 1.6830393 | G12: =G11-F11 -> 1.8998572 | H12: =H11-G11 -> 2.1393663 | I12: =I11-H11 -> 2.4050743 | J12: =J11-I11 -> 2.7010087 | K12: =K11-J11 -> 3.0318105 | ... M12: =M11-L11 -> 3.8203293
B13: Reinvestment | D13: =D10+D12 -> 1571.7327 | E13: =E10+E12 -> -414.10071 | F13: =F10+F12 -> -431.68559 | G13: =G10+G12 -> -451.54163 | H13: =H10+H12 -> -473.9055 | I13: =I10+I12 -> -499.05049 | J13: =J10+J12 -> -527.29194 | K13: =K10+K12 -> -558.9936 | ... M13: =M10+M12 -> -634.52119 | O13: =O9*O15 -> 1.9166816
B14: Free Cash Flow To Firm (FCFF) | D14: =D9-D13 -> -1247.1588 | E14: =E9-E13 -> 751.41662 | F14: =F9-F13 -> 783.43454 | G14: =G9-G13 -> 819.58296 | H14: =H9-H13 -> 860.29313 | I14: =I9-I13 -> 906.06304 | J14: =J9-J13 -> 957.4672 | K14: =K9-K13 -> 1015.1684 | ... M14: =M9-M13 -> 1152.6389 | O14: =O9-O13 -> 645.38648
B15: Implied Reinvestment rate % | D15: =D13/D9 -> 4.8424492 | E15: =E13/E9 -> -1.2276347 | F15: =F13/F9 -> -1.2272548 | G15: =G13/G9 -> -1.2268775 | H15: =H13/H9 -> -1.2265028 | I15: =I13/I9 -> -1.2261305 | J15: =J13/J9 -> -1.2257607 | K15: =K13/K9 -> -1.2253934 | ... M15: =M13/M9 -> -1.2246661 | O15: =R5 -> 0.0029610262
B17: Terminal Value | M17: =M14*(1+R3)/(R4-R3) -> 17280.975
B19: Present Value Interest Factor(PVIF) | D19: =1/(1+$R$4)^D2 -> 0.91016584 | E19: =1/(1+$R$4)^E2 -> 0.82840185 | F19: =1/(1+$R$4)^F2 -> 0.75398306 | G19: =1/(1+$R$4)^G2 -> 0.68624962 | H19: =1/(1+$R$4)^H2 -> 0.62460096 | I19: =1/(1+$R$4)^I2 -> 0.56849046 | J19: =1/(1+$R$4)^J2 -> 0.51742059 | K19: =1/(1+$R$4)^K2 -> 0.47093855 | ... M19: =1/(1+$R$4)^M2 -> 0.39012636
