Workbook

Sheet About 
J5: Hero MotoCorp Limited (NSE: HEROMOTOCO | BSE: 500182 | CIN: L35911DL1984PLC017354) is the world's largest manufacturer of motorcycles and scooters for 24 consecutive years. Incorporated in 1984 as Hero Honda Motors Ltd., it was renamed Hero MotoCorp in July 2011 after Honda's exit from the joint venture. Headquartered in New Delhi, the company has sold over 124 million two-wheelers across 48 countries, backed by 11,000+ customer touchpoints and 9,527 employees. It operates 8 manufacturing facilities — 6 in India (Dharuhera, Gurugram, Haridwar, Neemrana, Halol, Tirupati) and one each in Colombia and Bangladesh — with a combined annual capacity of ~9.4 million units. Key subsidiaries include HMCL Netherlands B.V. (WOS), HMCL Colombia S.A.S. (68%), HMCL Niloy Bangladesh (55%), HMCL Americas Inc. (WOS), and HMC MM Auto (60% JV — fuel injection systems). Associates include Hero FinCorp (41.15%, NBFC), Ather Energy (39.60%, EV two-wheelers, listed May 2025), and Euler Motors (34.10%, electric 3W/4W, acquired April 2025). Vision: Be the Future of Mobility. Mission: Create | Collaborate | Inspire.
C6: =#VALUE! -> #VALUE!
C31: Subsidiaries
C33: Hero FinCorp Limited, New Delhi-110001, India
C34: HMCL Colombia S.A.S., Villa Rica-762570, Colombia
C35: Hero MotoCorp Bangladesh Limited, Jessore-7400, Bangladesh
C36: Hero MotoCorp Global Investments Private Limited, New Delhi-110070, India
C37: Vida Electric Mobility Private Limited, Bengaluru-560001, India
C41: Manufacturing Plants
C43: Dharuhera Plant, Dharuhera-123106, Haryana
C44: Gurugram Plant, Gurugram-122001, Haryana
C45: Haridwar Plant, Haridwar-249403, Uttarakhand
C46: Neemrana Plant, Neemrana-301705, Rajasthan
C47: Halol Plant, Halol-389350, Gujarat
... C61: Freedo Rentals Division, Gurugram-122001, Haryana

Sheet Promoter 
B2: Category of shareholder | C2: Entity Type | D2: Shareholding as a % | E2: Number of equity shares held in dematerialized form
B5: A1) Indian | D5: 0
B6: Individuals/Hindu undivided Family | D6: 14.18 | E6: 2,83,70,707
B7: PAWAN MUNJAL | C7: Promoter | D7: 0.02 | E7: 43364
B8: PAWAN MUNJAL (AS A KARTA OF HUF) | C8: Promoter | D8: 0.02 | E8: 32500
B9: PAWAN MUNJAL, RENU MUNJAL AND SUMAN KANT MUNJAL (ON BEHALF OF BMOP, PARTNERSHIP FIRM) | C9: Promoter | D9: 13.96 | E9: 2,79,27,058
B10: RENU MUNJAL | C10: Promoter | D10: 0.06 | E10: 1,11,482
B11: SUMAN KANT MUNJAL (AS A KARTA OF HUF) | C11: Promoter | D11: 0.01 | E11: 10833
B12: SUMAN KANT MUNJAL | C12: Promoter | D12: 0.05 | E12: 91250
B13: RENUKA MUNJAL | C13: Promoter | D13: 0.02 | E13: 32480
B14: ANIESHA MUNJAL | C14: Promoter Group | D14: 0.02 | E14: 32500
B15: ABHIMANYU MUNJAL | C15: Promoter Group | D15: 0.01 | E15: 10620
B16: UJJWAL MUNJAL | C16: Promoter Group | D16: 0 | E16: 1000
B17: VASUDHA DINODIA | C17: Promoter Group | D17: 0.02 | E17: 32500
B18: SUNIL KANT MUNJAL | C18: Promoter Group | D18: 0.02 | E18: 32500
B19: AKSHAY MUNJAL | C19: Promoter Group | D19: 0 | E19: 1000
B20: RAHUL MUNJAL | C20: Promoter Group | D20: 0.01 | E20: 10620
B21: VIDUR MUNJAL | C21: Promoter Group | D21: 0 | E21: 1000
B22: Any Other (specify) | D22: 20.55 | E22: 4,11,17,474
B23: BAHADUR CHAND INVESTMENTS PVT LTD | C23: Promoter | D23: 20.01 | E23: 4,00,33,238
B24: HERO INVESTCORP PRIVATE LIMITED | C24: Promoter | D24: 0.44 | E24: 8,73,766
B25: HERO FINCORP LIMITED | C25: Promoter Group | D25: 0 | E25: 1370
B26: PAWAN MUNJAL FAMILY TRUST (PAWAN MUNJAL & ANIESHA MUNJAL) | C26: Promoter | D26: 0.1 | E26: 2,01,100
B27: RK MUNJAL & SONS TRUST (RENU MUNJAL) | C27: Promoter | D27: 0 | E27: 8000
B28: Sub Total A1 | D28: 34.73 | E28: 6,94,88,181
B29: A2) Foreign | D29: 0
B30: A=A1+A2 | D30: 34.73 | E30: 6,94,88,181

Sheet Public Holdings
A1: Category & Name of the Shareholders | B1: No. of shareholder | C1: Total no. shares held | D1: Shareholding %
A7: Institutions | B7: 0 | D7: 0
A8: B1) Institutions (Domestic) | B8: 0 | D8: 0
A9: Mutual Funds/ | B9: 41 | C9: 2,88,32,723 | D9: 14.41
A10: KOTAK ESG EXCLUSIONARY STRATEGY FUND | B10: 1 | C10: 80,03,516 | D10: 4
A11: ICICI PRUDENTIAL VALUE FUND | B11: 1 | C11: 53,10,129 | D11: 2.65
A12: MIRAE ASSET LARGE & MIDCAP FUND | B12: 1 | C12: 27,73,745 | D12: 1.39
A13: UTI NIFTY 200 MOMENTUM 30 INDEX FUND | B13: 1 | C13: 20,57,581 | D13: 1.03
A14: Venture Capital Funds | B14: 0 | D14: 0
A15: Alternate Investment Funds | B15: 26 | C15: 4,31,217 | D15: 0.22
A16: Banks | B16: 11 | C16: 92069 | D16: 0.05
A17: Insurance Companies | B17: 12 | C17: 41,25,070 | D17: 2.06
A18: Sovereign Wealth Funds | B18: 2 | C18: 1,59,783 | D18: 0.08
A19: NBFCs registered with RBI | B19: 5 | C19: 968 | D19: 0
A20: Other Financial Institutions | B20: 3 | C20: 24930 | D20: 0.01
A21: Any Other(Institutions (Domestic)) | B21: 21 | C21: 1,90,75,843 | D21: 9.53
A22: LIFE INSURANCE CORPORATION OF INDIA | B22: 1 | C22: 1,14,65,756 | D22: 5.73
A23: NPS TRUST- A/C HDFC PENSION FUND MANAGEMENT LIMITED | B23: 1 | C23: 49,67,101 | D23: 2.48
A24: Sub Total B1 | B24: 121 | C24: 5,27,42,603 | D24: 26.36
A25: B2) Institutions (Foreign) | B25: 0 | D25: 0
A26: Foreign Portfolio Investors Category I | B26: 955 | C26: 5,20,64,791 | D26: 26.02
A27: GOVERNMENT PENSION FUND GLOBAL | B27: 1 | C27: 50,56,554 | D27: 2.53
A28: Foreign Portfolio Investors Category II | B28: 53 | C28: 68,07,416 | D28: 3.4
A29: WGI EMERGING MARKETS FUND, LLC | B29: 1 | C29: 40,01,139 | D29: 2
A30: Overseas Depositories (holding DRs) (balancing figure) | B30: 0 | D30: 0
A31: Any Other(Institutions (Foreign)) | B31: 2 | C31: 22085 | D31: 0.01
A32: BANKS | B32: 2 | C32: 22085 | D32: 0.01
A33: Sub Total B2 | B33: 1010 | C33: 5,88,94,292 | D33: 29.44
A34: B3) Central Government/ State Government(s)/ President of India | B34: 0 | D34: 0
A35: B4) Non-Institutions | B35: 0 | D35: 0
A36: Directors and their relatives (excluding independent directors and nominee directors) | B36: 5 | C36: 43557 | D36: 0.02
A37: Investor Education and Protection Fund (IEPF) | B37: 1 | C37: 9,52,633 | D37: 0.48
A38: Resident Individuals holding nominal share capital up to Rs. 2 lakhs | B38: 811234 | C38: 1,48,24,898 | D38: 7.41
A39: Resident Individuals holding nominal share capital in excess of Rs. 2 lakhs | B39: 1 | C39: 1,52,000 | D39: 0.08
A40: Non Resident Indians (NRIs) | B40: 13025 | C40: 8,82,767 | D40: 0.44
A41: Foreign Nationals | B41: 2 | C41: 72 | D41: 0
A42: Bodies Corporate | B42: 2146 | C42: 6,47,034 | D42: 0.32
A43: Any Other (specify) | B43: 44934 | C43: 14,53,575 | D43: 0.73
A44: Clearing Members | B44: 7 | C44: 7643 | D44: 0
A45: HUF | B45: 44888 | C45: 4,12,139 | D45: 0.21
...

Sheet Consolidated Balance sheet 
B2: HERO MOTOCORP LIMITED
B3: Consolidated Balance Sheet | (₹ in Crores)
B4: Particulars | C4: Mar 31, 2024 | D4: Mar 31, 2025
B5: ASSETS
B6: Non-Current Assets
B7: Property, plant & equipment | C7: 5212.58 | D7: 5219.13 | F7: =(D7-C7)/C7 -> 0.0012565754
B8: Capital work-in-progress | C8: 127.16 | D8: 105.37 | F8: =(D8-C8)/C8 -> -0.17135892
B9: Right-of-use assets | C9: 475.97 | D9: 483.39 | F9: =(D9-C9)/C9 -> 0.015589218
B10: Other intangible assets | C10: 543.65 | D10: 580.46 | F10: =(D10-C10)/C10 -> 0.067709004
B11: Intangible assets under development | C11: 356.9 | D11: 381.81 | F11: =(D11-C11)/C11 -> 0.069795461
B12: Equity accounted investments in associates | C12: 3083.59 | D12: 2980.94 | F12: =(D12-C12)/C12 -> -0.033289121
B13: Investments (non-current) | C13: 5362.57 | D13: 4767.33 | F13: =(D13-C13)/C13 -> -0.11099902
B14: Loans (non-current) | C14: 21.15 | D14: 24.87 | F14: =(D14-C14)/C14 -> 0.17588652
B15: Other financial assets (non-current) | C15: 189.44 | D15: 47.09 | F15: =(D15-C15)/C15 -> -0.75142525
B16: Income tax assets (net) | C16: 335.68 | D16: 254.49 | F16: =(D16-C16)/C16 -> -0.24186725
B17: Other non-current assets | C17: 128.65 | D17: 111.55 | F17: =(D17-C17)/C17 -> -0.13291877
B18: Total Non-Current Assets | C18: 15837.34 | D18: 14956.43 | F18: =(D18-C18)/C18 -> -0.055622346
B19: Current Assets
B20: Inventories | C20: 1755.9 | D20: 2013.34 | F20: =(D20-C20)/C20 -> 0.14661427
B21: Investments (current) | C21: 4305.08 | D21: 6635.99 | F21: =(D21-C21)/C21 -> 0.54143245
B22: Trade receivables | C22: 2630.22 | D22: 3381.29 | F22: =(D22-C22)/C22 -> 0.28555406
B23: Cash & cash equivalents | C23: 604.91 | D23: 383.55 | F23: =(D23-C23)/C23 -> -0.36593873
B24: Bank balances (other) | C24: 91.56 | D24: 190.53 | F24: =(D24-C24)/C24 -> 1.0809305
B25: Loans (current) | C25: 24.56 | D25: 27.07 | F25: =(D25-C25)/C25 -> 0.1021987
B26: Other financial assets (current) | C26: 423.53 | D26: 141.59 | F26: =(D26-C26)/C26 -> -0.66569074
B27: Income tax assets (current) | C27: 479.69 | D27: 198.12 | F27: =(D27-C27)/C27 -> -0.58698326
B28: Other current assets | D28: 462.41
B29: Total Current Assets | C29: 10315.45 | D29: 13433.89 | F29: =(D29-C29)/C29 -> 0.3023077
B30: TOTAL ASSETS | C30: 26152.79 | D30: 28390.32 | F30: =(D30-C30)/C30 -> 0.085556073
B31: EQUITY & LIABILITIES
B32: Equity
B33: Equity share capital | C33: 39.98 | D33: 40 | F33: =(D33-C33)/C33 -> 0.00050025013
B34: Other equity (attributable to owners) | C34: 17658.94 | D34: 19232.04 | F34: =(D34-C34)/C34 -> 0.089082357
B35: Equity attributable to owners | C35: 17698.92 | D35: 19272.04 | F35: =(D35-C35)/C35 -> 0.088882259
B36: Non-controlling interests | C36: 135.65 | D36: 132.05 | F36: =(D36-C36)/C36 -> -0.026538887
B37: Total Equity | C37: 17834.57 | D37: 19404.09 | F37: =(D37-C37)/C37 -> 0.088004365
B38: Non-Current Liabilities
B39: Lease liabilities (non-current) | C39: 199.13 | D39: 196.21 | F39: =(D39-C39)/C39 -> -0.014663787
B40: Other financial liabilities | C40: 178.13 | D40: 143.83 | F40: =(D40-C40)/C40 -> -0.192556
B41: Provisions | C41: 322.46 | D41: 495.29 | F41: =(D41-C41)/C41 -> 0.53597345
...

Sheet Consolidated PL
B2: HERO MOTOCORP LIMITED
B3: Consolidated Statement of Profit & Loss | (₹ in Crores)
B4: Particulars | C4: FY 2023-24 | D4: FY 2024-25
B5: INCOME
B6: Revenue from operations | C6: 37788.62 | D6: 40923.42 | F6: =(D6-C6)/C6 -> 0.082956192
B7: Other income | C7: 854.54 | D7: 1044.08 | F7: =(D7-C7)/C7 -> 0.22180354
B8: Total Income | C8: 38643.16 | D8: 41967.5 | F8: =(D8-C8)/C8 -> 0.086026609
B9: EXPENSES
B10: Cost of materials consumed | C10: 24836.89 | D10: 26607.07 | F10: =(D10-C10)/C10 -> 0.071272208
B11: Purchases of stock-in-trade | C11: 484.2 | D11: 547.91 | F11: =(D11-C11)/C11 -> 0.13157786
B12: Change in inventories | C12: 188.35 | D12: -244.34 | F12: =(D12-C12)/C12 -> -2.2972657
B13: Employee benefits expense | C13: 2471.55 | D13: 2680.07 | F13: =(D13-C13)/C13 -> 0.084368109
B14: Finance costs | C14: 76.37 | D14: 70.65 | F14: =(D14-C14)/C14 -> -0.07489852
B15: Depreciation & amortisation | C15: 757.36 | D15: 824.59 | F15: =(D15-C15)/C15 -> 0.088768881
B16: Other expenses | C16: 4458 | D16: 5386.87 | F16: =(D16-C16)/C16 -> 0.20836025
B17: Total Expenses | C17: 33272.72 | D17: 35872.82 | F17: =(D17-C17)/C17 -> 0.078145099
B18: Profit before share of associates & exceptional items | C18: 5370.44 | D18: 6094.68 | F18: =(D18-C18)/C18 -> 0.13485673
B19: Share in profit/(loss) of associates (net of tax) | C19: -120.25 | D19: -161.12 | F19: =(D19-C19)/C19 -> 0.33987526
B20: Profit before tax & exceptional items | C20: 5250.19 | D20: 5933.56 | F20: =(D20-C20)/C20 -> 0.130161
B21: Exceptional item — VRS expenses | C21: 159.99 | F21: =(D21-C21)/C21 -> -1
B22: Profit Before Tax | C22: 5090.2 | D22: 5933.56 | F22: =(D22-C22)/C22 -> 0.16568308
B23: TAX EXPENSE
B24: Current tax | C24: 1264.18 | D24: 1448.02 | F24: =(D24-C24)/C24 -> 0.14542233
B25: Deferred tax charge/(credit) | C25: 83.86 | D25: 109.73 | F25: =(D25-C25)/C25 -> 0.30849034
B26: Total Tax Expense | C26: 1348.04 | D26: 1557.75 | F26: =(D26-C26)/C26 -> 0.1555666
B27: Net Profit After Tax | C27: 3742.16 | D27: 4375.81 | F27: =(D27-C27)/C27 -> 0.16932734
B28: OTHER COMPREHENSIVE INCOME
B29: Re-measurement gains/(losses) on defined benefit plans | C29: -30 | D29: -16.07 | F29: =(D29-C29)/C29 -> -0.46433333
B30: Income tax effect | C30: 7.51 | D30: 4.05 | F30: =(D30-C30)/C30 -> -0.46071904
B31: Share of OCI of associates (not reclassified) | C31: -1.55 | D31: 0.09 | F31: =(D31-C31)/C31 -> -1.0580645
B32: Exchange differences on foreign operations | C32: 1.92 | D32: -18.83 | F32: =(D32-C32)/C32 -> -10.807292
B33: Income tax effect on exchange differences | C33: -0.48 | D33: 4.74 | F33: =(D33-C33)/C33 -> -10.875
B34: Share of OCI of associates (reclassified) | C34: -10.26 | D34: -13.02 | F34: =(D34-C34)/C34 -> 0.26900585
B35: Total OCI for the year | C35: -32.86 | D35: -39.04 | F35: =(D35-C35)/C35 -> 0.1880706
B36: Total Comprehensive Income | C36: 3709.3 | D36: 4336.77 | F36: =(D36-C36)/C36 -> 0.1691613
B37: ATTRIBUTION
B38: Net Profit — Owners of Company | C38: 3744.83 | D38: 4378.48 | F38: =(D38-C38)/C38 -> 0.16920661
B39: Net Profit — Non-controlling interests | C39: -2.67 | D39: -2.67 | F39: =(D39-C39)/C39 -> 0
B40: OCI — Owners of Company | C40: -32.76 | D40: -32.1 | F40: =(D40-C40)/C40 -> -0.02014652
B41: OCI — Non-controlling interests | C41: -0.1 | D41: -6.94 | F41: =(D41-C41)/C41 -> 68.4
...

Sheet Consolidated CF
B2: HERO MOTOCORP LIMITED
B3: Consolidated Statement of Cash Flows | (₹ in Crores)
B4: Particulars | C4: FY 2023-24 | D4: FY 2024-25
B5: A. CASH FLOW FROM OPERATING ACTIVITIES
B6: Profit after tax & share in profit/(loss) of associates | C6: 3742.16 | D6: 4375.81 | F6: =(D6-C6)/C6 -> 0.16932734
B7: Add: Depreciation & amortisation | C7: 757.36 | D7: 824.59 | F7: =(D7-C7)/C7 -> 0.088768881
B8: Add: Tax expense | C8: 1348.04 | D8: 1557.75 | F8: =(D8-C8)/C8 -> 0.1555666
B9: Loss on PPE sold/discarded | C9: 5.57 | D9: 4.15 | F9: =(D9-C9)/C9 -> -0.25493716
B10: Finance cost | C10: 76.37 | D10: 70.65 | F10: =(D10-C10)/C10 -> -0.07489852
B11: Employee stock compensation | C11: 23.74 | D11: 15.66 | F11: =(D11-C11)/C11 -> -0.34035383
B12: Loss allowances on financial assets | C12: 19.66 | D12: 158.41 | F12: =(D12-C12)/C12 -> 7.0574771
B13: Less: Interest income | C13: -301.31 | D13: -445.74 | F13: =(D13-C13)/C13 -> 0.47934021
B14: Less: Dividend income | C14: -18.59 | D14: -22.88 | F14: =(D14-C14)/C14 -> 0.23076923
B15: Less: Profit on sale of investments | C15: -120.82 | D15: -158.57 | F15: =(D15-C15)/C15 -> 0.31244827
B16: Less: Fair value gains on investments | C16: -403.01 | D16: -414.64 | F16: =(D16-C16)/C16 -> 0.028857845
B17: Less: Share of profit/(loss) in associates | C17: 120.25 | D17: 161.12 | F17: =(D17-C17)/C17 -> 0.33987526
... B24: Net Cash from Operating Activities (A) | C24: 4297.39 | D24: 4923.07 | F24: =(D24-C24)/C24 -> 0.14559535
B25: B. CASH FLOW FROM INVESTING ACTIVITIES
B26: Capital expenditure (PPE & intangibles) | C26: -787.89 | D26: -856.63 | F26: =(D26-C26)/C26 -> 0.087245682
B27: Proceeds from sale of PPE | C27: 10.7 | D27: 22.44 | F27: =(D27-C27)/C27 -> 1.0971963
B28: Deposits (made)/withdrawn | C28: 45306.67 | D28: 49335.75 | F28: =(D28-C28)/C28 -> 0.088929069
B29: Purchase of investments | C29: -46178.27 | D29: -50498.2 | F29: =(D29-C29)/C29 -> 0.093548979
B30: Investment in associates | C30: -639.41 | D30: -123.83 | F30: =(D30-C30)/C30 -> -0.80633709
B31: Dividend from associates | C31: 42.47 | D31: 52.43 | F31: =(D31-C31)/C31 -> 0.23451848
B32: Dividend from others | C32: 18.59 | D32: 22.88 | F32: =(D32-C32)/C32 -> 0.23076923
B33: Interest income received | C33: 301.31 | D33: 445.74 | F33: =(D33-C33)/C33 -> 0.47934021
B34: Net Cash used in Investing Activities (B) | C34: -1827.87 | D34: -1703.36 | F34: =(D34-C34)/C34 -> -0.068117536
B35: C. CASH FLOW FROM FINANCING ACTIVITIES
B36: Interest paid | C36: -76.37 | D36: -70.65 | F36: =(D36-C36)/C36 -> -0.07489852
B37: Repayment of lease liabilities | C37: -11.32 | D37: -55.16 | F37: =(D37-C37)/C37 -> 3.8727915
B38: Dividends paid | C38: -2702.09 | D38: -2799.83 | F38: =(D38-C38)/C38 -> 0.036172
B39: Additions to minority interest | C39: 12.58 | D39: 10 | F39: =(D39-C39)/C39 -> -0.20508744
B40: Proceeds from issue of equity shares | C40: 10.41 | D40: 6.92 | F40: =(D40-C40)/C40 -> -0.33525456
B41: (Repayment)/proceeds of non-current borrowings | C41: -20.09 | D41: 93.33 | F41: =(D41-C41)/C41 -> -5.6455948
B42: (Repayment)/proceeds from current borrowings | C42: 70.29 | F42: =(D42-C42)/C42 -> -1
B43: Net Cash used in Financing Activities (C) | C43: -2716.59 | D43: -2815.39 | F43: =(D43-C43)/C43 -> 0.036369125
B44: NET INCREASE/(DECREASE) IN CASH (A+B+C) | C44: 378.61 | D44: -221.36 | F44: =(D44-C44)/C44 -> -1.584665
B45: Cash & equivalents at beginning of year | C45: 226.3 | D45: 604.91 | F45: =(D45-C45)/C45 -> 1.6730446
B46: Cash & equivalents at end of year | C46: 604.91 | D46: 383.56 | F46: =(D46-C46)/C46 -> -0.3659222

Sheet ConsolidatedQuaterly 
B2: HERO MOTOCORP LIMITED — Consolidated Quarterly P&L | (₹ in Crores)
B3: Particulars | C3: Jun 2025 | D3: Sep 2025 | E3: Dec 2025 | G3: Change%
B4: INCOME
B5: Revenue from operations | C5: 9970 | D5: 9728 | E5: 12218 | G5: =(D5-C5)/C5 -> -0.024272818 | H5: =(E5-D5)/D5 -> 0.25596217
B6: Other income | C6: 939 | D6: 240 | E6: 179 | G6: =(D6-C6)/C6 -> -0.74440895 | H6: =(E6-D6)/D6 -> -0.25416667
B7: Total Income | C7: 10667 | D7: 12458 | E7: 12666 | G7: =(D7-C7)/C7 -> 0.167901 | H7: =(E7-D7)/D7 -> 0.016696099
B8: EXPENSES
B9: Cost of materials consumed | C9: 6420 | D9: 8064 | E9: 8366 | G9: =(D9-C9)/C9 -> 0.25607477 | H9: =(E9-D9)/D9 -> 0.037450397
B10: Purchases of stock-in-trade
B11: Change in inventories
B12: Employee benefits expense | C12: 681 | D12: 733 | E12: 749 | G12: =(D12-C12)/C12 -> 0.076358297 | H12: =(E12-D12)/D12 -> 0.021828104
B13: Finance costs | C13: 21 | D13: 19 | E13: 20 | G13: =(D13-C13)/C13 -> -0.095238095 | H13: =(E13-D13)/D13 -> 0.052631579
B14: Depreciation & amortisation | C14: 206 | D14: 210 | E14: 219 | G14: =(D14-C14)/C14 -> 0.019417476 | H14: =(E14-D14)/D14 -> 0.042857143
B15: Other expenses
B16: Total Expenses | C16: 8315 | D16: 10452 | E16: 10735 | G16: =(D16-C16)/C16 -> 0.25700541 | H16: =(E16-D16)/D16 -> 0.027076158
B17: Profit before share of associates & exceptional items | C17: 1413 | D17: 1766 | E17: 1752 | G17: =(D17-C17)/C17 -> 0.24982307 | H17: =(E17-D17)/D17 -> -0.0079275198
B18: Share in profit/(loss) of associates (net of tax)
B19: Profit before tax & exceptional items | C19: 1413 | D19: 1766 | E19: 1752 | G19: =(D19-C19)/C19 -> 0.24982307 | H19: =(E19-D19)/D19 -> -0.0079275198
B20: Exceptional item — VRS expenses | C20: 0 | D20: 0 | E20: 0
B21: Profit Before Tax | C21: 2126 | D21: 1777 | E21: 1692 | G21: =(D21-C21)/C21 -> -0.16415804 | H21: =(E21-D21)/D21 -> -0.047833427
B22: TAX EXPENSE
B23: Current tax
B24: Deferred tax charge/(credit)
B25: Total Tax Expense | C25: 425 | D25: 462 | E25: 423 | G25: =(D25-C25)/C25 -> 0.087058824 | H25: =(E25-D25)/D25 -> -0.084415584
B26: Net Profit After Tax | C26: 1706 | D26: 1321 | E26: 1275 | G26: =(D26-C26)/C26 -> -0.22567409 | H26: =(E26-D26)/D26 -> -0.034822104
B27: Net Profit — Owners of Company | C27: 1706 | D27: 1333 | E27: 1283 | G27: =(D27-C27)/C27 -> -0.21864009 | H27: =(E27-D27)/D27 -> -0.037509377
B28: Net Profit — Non-controlling interests | C28: 0 | D28: -12 | E28: -8 | G28: - | H28: =(E28-D28)/D28 -> -0.33333333
B29: EARNINGS PER SHARE (₹)
B30: Basic EPS (₹) | C30: 85.26 | D30: 65.42 | E30: 63.35 | G30: =(D30-C30)/C30 -> -0.23269998 | H30: =(E30-D30)/D30 -> -0.0316417
B31: Diluted EPS (₹) | C31: 85.26 | D31: 65.42 | E31: 63.35 | G31: =(D31-C31)/C31 -> -0.23269998 | H31: =(E31-D31)/D31 -> -0.0316417

Sheet Peers
C4: HEROMOTOCO | D4: Hero MotoCorp Limited is the world's largest manufacturer of motorcycles and scooters. It manufactures a wide range of two-wheelers including entry-level, deluxe, premium motorcycles and scooters. Key brands include Splendor, HF Deluxe, Passion, Xtreme, Xpulse, Karizma and VIDA electric scooters.
C9: BAJAJ-AUTO | D9: Bajaj Auto Limited is the flagship company of the Bajaj Group and India's largest exporter of two and three-wheelers, exporting to 79 countries. It is the 2nd-largest player in domestic motorcycles and the world's largest three-wheeler producer. Key brands include Pulsar, Dominar, CT, Platina, Chetak EV and KTM (48% stake).
C12: TVSMOTOR | D12: TVS Motor Company Limited is one of the leading two-wheeler manufacturers globally, with presence in motorcycles, scooters, and mopeds. It also manufactures three-wheelers and has a strategic investment in Norton Motorcycles (UK). Key brands include Apache, Jupiter, NTorq, Raider, Ronin, iQube EV and TVS King three-wheelers.
C16: EICHER MOTOR | D16: Eicher Motors Limited is the listed company of the Eicher Group and the global leader in middleweight motorcycles through its Royal Enfield brand. It also has a joint venture with AB Volvo VE Commercial Vehicles (VECV) — for trucks and buses. Royal Enfield crossed 1 million annual motorcycle sales for the first time in FY25.
C20: Attribute | D20: LTP (₹) | E20: Change (%) | F20: Sales (₹ crore) | G20: PAT (₹ crore) | H20: Equity (₹ crore) | I20: Operating Profit Margin (OPM%) | J20: Net Profit Margin (NPM%) | K20: Earnings Per Share (EPS) | L20: Cash Earnings Per Share (CEPS)
B21: 1 | C21: HEROMOTOCO | D21: 5247 | E21: -4.02 | F21: 40923 | G21: 4376 | H21: 40 | I21: 14.14 | J21: 10.69 | K21: 218.91 | L21: 259.92
B22: 2 | C22: BAJAJ-AUTO | D22: 9758 | E22: -0.16 | F22: 50995 | G22: 7325 | H22: 279 | I22: 18.74 | J22: 14.37 | K22: 262.29 | L22: 277.38
B23: 3 | C23: TVSMOTOR | D23: 3736 | E23: -0.11 | F23: 44089 | G23: 2380 | H23: 47.5 | I23: 14.91 | J23: 5.4 | K23: 47.05 | L23: 72.21
B24: 4 | C24: EICHERMOT | D24: 7168.5 | E24: -0.29 | F24: 18870 | G24: 4733 | H24: 27.4 | I24: 25.03 | J24: 25.08 | K24: 172.73 | L24: 199.34
C28: HEROMOTOCO | H28: BAJAJ-AUTO
C29: Metric | D29: 44986 | E29: 45352 | F29: 45717 | H29: Metric | I29: 44986 | J29: 45352 | K29: 45717
C30: Debtor Days | D30: 28 | E30: 25 | F30: 30 | H30: Debtor Days | I30: 6 | J30: 6 | K30: 5
C31: Inventory Days | D31: 19 | E31: 17 | F31: 18 | H31: Inventory Days | I31: 23 | J31: 24 | K31: 20
C32: Days Payable | D32: 82 | E32: 75 | F32: 78 | H32: Days Payable | I32: 36 | J32: 37 | K32: 42
C33: Cash Conversion Cycle | D33: -35 | E33: -33 | F33: -30 | H33: Cash Conversion Cycle | I33: -7 | J33: -7 | K33: -17
C34: Working Capital Days | D34: -26 | E34: -24 | F34: -22 | H34: Working Capital Days | I34: -8 | J34: -7 | K34: -16
C35: ROCE % | D35: 0.19 | E35: 0.25 | F35: 0.3 | H35: ROCE % | I35: 0.34 | J35: 0.34 | K35: 0.28
C37: TVSMOTOR | H37: EICHERMOT
C38: Metric | D38: 44986 | E38: 45352 | F38: 45717 | H38: Metric | I38: 44986 | J38: 45352 | K38: 45717
C39: Debtor Days | D39: 9 | E39: 10 | F39: 14 | H39: Debtor Days | I39: 10 | J39: 11 | K39: 14
C40: Inventory Days | D40: 24 | E40: 24 | F40: 25 | H40: Inventory Days | I40: 25 | J40: 30 | K40: 30
C41: Days Payable | D41: 54 | E41: 46 | F41: 45 | H41: Days Payable | I41: 28 | J41: 27 | K41: 28
C42: Cash Conversion Cycle | D42: -21 | E42: -12 | F42: -6 | H42: Cash Conversion Cycle | I42: 7 | J42: 14 | K42: 16
C43: Working Capital Days | D43: -15 | E43: -9 | F43: -5 | H43: Working Capital Days | I43: 8 | J43: 14 | K43: 15
C44: ROCE % | D44: 0.22 | E44: 0.22 | F44: 0.15 | H44: ROCE % | I44: 0.38 | J44: 0.38 | K44: 0.3

Sheet Stock Analysis
P3: Recommendation
P4: BUY — Hero MotoCorp's stock offers an attractive entry point at current levels, trading at ~19x P/E, a steep 50% discount to peers' median of ~38x. With record FY25 consolidated revenue of ₹40,923 Cr (+8.3% YoY) and PAT of ₹4,376 Cr (+16.9% YoY), strong ROCE of 30.3%, a debt-free balance sheet, and a generous dividend yield of 3.14%, the risk-reward is favourable for long-term investors.
P7: Hero MotoCorp remains the world's largest two-wheeler manufacturer by volume, holding ~29% domestic market share in FY25. The company's stock has corrected ~18% over the last year despite delivering its best-ever revenue and profit, creating a valuation gap vs peers. Key near-term triggers include: (1) rural demand revival driven by a healthy monsoon forecast and income tax relief in the Union Budget 2025; (2) strong scooter momentum — scooter sales grew 53% YoY in March 2026; (3) export acceleration with 34% YoY growth in Feb 2026; (4) VIDA EV scaling up with 12,500+ monthly registrations. Risks to monitor: (1) market share erosion to Honda HMSI, which is within 2 percentage points of Hero's domestic share; (2) EV transition pace — VIDA volumes remain small relative to overall portfolio; (3) rising input costs from commodity price volatility. Motilal Oswal maintains a BUY with a target price of ₹6,205, implying ~18% upside from current levels. The company has guided for 7% volume CAGR and 11% revenue/EBITDA/PAT CAGR over FY25-28.
Q16: Financial Year | R16: Revenue (₹ Crore) | S16: Profit After Tax (PAT) (₹ Crore) | T16: Revenue Change (%) | U16: PAT Change (%) | V16: Nifty 50 Change (%)
Q17: FY 2024-25 | R17: 40923 | S17: 4376 | T17: 0.083 | U17: 0.169 | V17: 0.053
Q18: FY 2023-24 | R18: 37789 | S18: 3742 | T18: 0.106 | U18: 0.336 | V18: 0.286
Q19: FY 2022-23 | R19: 34158 | S19: 2800 | T19: 0.156 | U19: 0.202 | V19: -0.006
Q20: FY 2021-22 | R20: 29551 | S20: 2329 | T20: -0.045 | U20: -0.207 | V20: 0.189
B21: Metric | C21: Value | Q21: FY 2020-21 | R21: 30959 | S21: 2936 | T21: - | U21: - | V21: 0.709
B22: Market Cap | C22: ₹ 1,04,987 Cr.
B23: Current Price | C23: 5247
B24: High / Low | C24: ₹ 6,390 / ₹ 3,664
B25: Stock P/E | C25: 19
B26: Book Value | C26: 1050
B27: Dividend Yield | C27: 0.0314
B28: ROCE | C28: 0.303
B29: ROE | C29: 0.231
B30: Face Value | C30: 2
B34: Hero MotoCorp records best-ever annual revenue of ₹40,923 Cr in FY25, PAT up 17% YoY
B42: MOSL maintains BUY on Hero MotoCorp with TP ₹6,205 — Groww | April 2026

Sheet BETA 
B2: NIFTY | G2: HERO
B3: Date | C3: Close | G3: Date | H3: Close | L3: BETA
B4: 43922 | C4: 8253.7998 | G4: 43922 | H4: 1341.0676
B5: 43924 | C5: 8083.7998 | D5: =(C5-C4)/C4 -> -0.020596574 | G5: 43924 | H5: 1293.9569 | I5: =(H5-H4)/H4 -> -0.035129263 | L5: =SLOPE(I5:I1485,D5:D1485) -> 0.90659833
B6: 43928 | C6: 8792.2002 | D6: =(C6-C5)/C5 -> 0.087632105 | G6: 43928 | H6: 1447.0266 | I6: =(H6-H5)/H5 -> 0.11829583
B7: 43929 | C7: 8748.75 | D7: =(C7-C6)/C6 -> -0.0049419024 | G7: 43929 | H7: 1489.9254 | I7: =(H7-H6)/H6 -> 0.029646175
B8: 43930 | C8: 9111.9004 | D8: =(C8-C7)/C7 -> 0.041508832 | G8: 43930 | H8: 1628.3547 | I8: =(H8-H7)/H7 -> 0.092910236 | L8: =_xlfn.COVARIANCE.S(I5:I1485,D5:D1485)/_xlfn.VAR.S(D5:D1485) -> 0.90659833
B9: 43934 | C9: 8993.8496 | D9: =(C9-C8)/C8 -> -0.012955671 | G9: 43934 | H9: 1569.5887 | I9: =(H9-H8)/H8 -> -0.036089182
B10: 43936 | C10: 8925.2998 | D10: =(C10-C9)/C9 -> -0.0076218536 | G10: 43936 | H10: 1491.9293 | I10: =(H10-H9)/H9 -> -0.049477562 | L10: SUMMARY OUTPUT
B11: 43937 | C11: 8992.7998 | D11: =(C11-C10)/C10 -> 0.0075627712 | G11: 43937 | H11: 1458.0272 | I11: =(H11-H10)/H10 -> -0.022723663
B12: 43938 | C12: 9266.75 | D12: =(C12-C11)/C11 -> 0.030463282 | G12: 43938 | H12: 1501.5804 | I12: =(H12-H11)/H11 -> 0.029871337 | L12: Regression Statistics
B13: 43941 | C13: 9261.8496 | D13: =(C13-C12)/C12 -> -0.00052881438 | G13: 43941 | H13: 1477.0023 | I13: =(H13-H12)/H12 -> -0.016368171 | L13: Multiple R | M13: 0.50490537
B14: 43942 | C14: 8981.4502 | D14: =(C14-C13)/C13 -> -0.030274667 | G14: 43942 | H14: 1494.7511 | I14: =(H14-H13)/H13 -> 0.012016758 | L14: R Square | M14: 0.25492944
B15: 43943 | C15: 9187.2998 | D15: =(C15-C14)/C14 -> 0.022919418 | G15: 43943 | H15: 1543.9069 | I15: =(H15-H14)/H14 -> 0.032885583 | L15: Adjusted R Square | M15: 0.25442567
B16: 43944 | C16: 9313.9004 | D16: =(C16-C15)/C15 -> 0.013779956 | G16: 43944 | H16: 1525.3812 | I16: =(H16-H15)/H15 -> -0.011999192 | L16: Standard Error | M16: 0.015190429
B17: 43945 | C17: 9154.4004 | D17: =(C17-C16)/C16 -> -0.017124942 | G17: 43945 | H17: 1549.7546 | I17: =(H17-H16)/H16 -> 0.015978572 | L17: Observations | M17: 1481
B18: 43948 | C18: 9282.2998 | D18: =(C18-C17)/C17 -> 0.013971359 | G18: 43948 | H18: 1582.7979 | I18: =(H18-H17)/H17 -> 0.021321577
B19: 43949 | C19: 9380.9004 | D19: =(C19-C18)/C18 -> 0.010622431 | G19: 43949 | H19: 1589.2594 | I19: =(H19-H18)/H18 -> 0.0040823582 | L19: ANOVA
B20: 43950 | C20: 9553.3496 | D20: =(C20-C19)/C19 -> 0.018383014 | G20: 43950 | H20: 1611.4652 | I20: =(H20-H19)/H19 -> 0.013972427 | M20: df | N20: SS | O20: MS | P20: F | Q20: Significance F
B21: 43951 | C21: 9859.9004 | D21: =(C21-C20)/C20 -> 0.032088303 | G21: 43951 | H21: 1772.1416 | I21: =(H21-H20)/H20 -> 0.09970826 | L21: Regression | M21: 1 | N21: 0.11676989 | O21: 0.11676989 | P21: 506.04689 | Q21: 1.2670704e-96
B22: 43955 | C22: 9293.5 | D22: =(C22-C21)/C21 -> -0.057444839 | G22: 43955 | H22: 1636.3701 | I22: =(H22-H21)/H21 -> -0.076614354 | L22: Residual | M22: 1479 | N22: 0.34127798 | O22: 0.00023074914
B23: 43956 | C23: 9205.5996 | D23: =(C23-C22)/C22 -> -0.0094582655 | G23: 43956 | H23: 1607.4575 | I23: =(H23-H22)/H22 -> -0.01766874 | L23: Total | M23: 1480 | N23: 0.45804787
B24: 43957 | C24: 9270.9004 | D24: =(C24-C23)/C23 -> 0.0070935935 | G24: 43957 | H24: 1657.6764 | I24: =(H24-H23)/H23 -> 0.031241181
B25: 43958 | C25: 9199.0498 | D25: =(C25-C24)/C24 -> -0.0077501195 | G25: 43958 | H25: 1636.0431 | I25: =(H25-H24)/H24 -> -0.013050376 | M25: Coefficients | N25: Standard Error | O25: t Stat | P25: P-value | Q25: Lower 95% | R25: Upper 95% | S25: Lower 95.0% | T25: Upper 95.0%
B26: 43959 | C26: 9251.5 | D26: =(C26-C25)/C25 -> 0.0057016971 | G26: 43959 | H26: 1605.2081 | I26: =(H26-H25)/H25 -> -0.018847279 | L26: Intercept | M26: 0.00039828845 | N26: 0.00039578886 | O26: 1.0063155 | P26: 0.31442844 | Q26: -0.00037807879 | R26: 0.0011746557 | S26: -0.00037807879 | T26: 0.0011746557
B27: 43962 | C27: 9239.2002 | D27: =(C27-C26)/C26 -> -0.001329493 | G27: 43962 | H27: 1708.3043 | I27: =(H27-H26)/H26 -> 0.064226059 | L27: X Variable 1 | M27: 0.90659833 | N27: 0.040301345 | O27: 22.495486 | P27: 1.2670704e-96 | Q27: 0.82754445 | R27: 0.98565221 | S27: 0.82754445 | T27: 0.98565221
B28: 43963 | C28: 9196.5498 | D28: =(C28-C27)/C27 -> -0.0046162427 | G28: 43963 | H28: 1729.2837 | I28: =(H28-H27)/H27 -> 0.012280815
B29: 43964 | C29: 9383.5498 | D29: =(C29-C28)/C28 -> 0.020333713 | G29: 43964 | H29: 1789.2357 | I29: =(H29-H28)/H28 -> 0.034668705
B30: 43965 | C30: 9142.75 | D30: =(C30-C29)/C29 -> -0.025661909 | G30: 43965 | H30: 1833.1975 | I30: =(H30-H29)/H29 -> 0.024570151
B31: 43966 | C31: 9136.8496 | D31: =(C31-C30)/C30 -> -0.00064536279 | G31: 43966 | H31: 1794.1021 | I31: =(H31-H30)/H30 -> -0.021326376
B32: 43969 | C32: 8823.25 | D32: =(C32-C31)/C31 -> -0.03432251 | G32: 43969 | H32: 1693.5005 | I32: =(H32-H31)/H31 -> -0.056073489
B33: 43970 | C33: 8879.0996 | D33: =(C33-C32)/C32 -> 0.0063298228 | G33: 43970 | H33: 1695.9133 | I33: =(H33-H32)/H32 -> 0.0014247659
B34: 43971 | C34: 9066.5498 | D34: =(C34-C33)/C33 -> 0.021111397 | G34: 43971 | H34: 1655.1002 | I34: =(H34-H33)/H33 -> -0.024065564
B35: 43972 | C35: 9106.25 | D35: =(C35-C34)/C34 -> 0.0043787545 | G35: 43972 | H35: 1733.5365 | I35: =(H35-H34)/H34 -> 0.047390652
B36: 43973 | C36: 9039.25 | D36: =(C36-C35)/C35 -> -0.0073575841 | G36: 43973 | H36: 1758.9731 | I36: =(H36-H35)/H35 -> 0.014673268
B37: 43977 | C37: 9029.0498 | D37: =(C37-C36)/C36 -> -0.0011284338 | G37: 43977 | H37: 1728.752 | I37: =(H37-H36)/H36 -> -0.017181156
B38: 43978 | C38: 9314.9502 | D38: =(C38-C37)/C37 -> 0.031664505 | G38: 43978 | H38: 1779.4617 | I38: =(H38-H37)/H37 -> 0.029333136
B39: 43979 | C39: 9490.0996 | D39: =(C39-C38)/C38 -> 0.018803044 | G39: 43979 | H39: 1879.6138 | I39: =(H39-H38)/H38 -> 0.056282246
... B1485: 46111 | C1485: 22331.4 | D1485: =(C1485-C1484)/C1484 -> -0.021393856 | G1485: 46111 | H1485: 5063 | I1485: =(H1485-H1484)/H1484 -> -0.015555123

Sheet Consolidated PL 5y
B2: Hero Motocorp
B3: Consolidated Profit & Loss account
C4: 44256 | D4: 44621 | E4: 44986 | F4: 45352 | G4: Mar 25
B5: INCOME
B6: Revenue From Operations [Gross] | C6: 30451.59 | D6: 28977.64 | E6: 33737.72 | F6: 37599.03 | G6: 40712.49 | I6: =(D6-C6)/C6 -> -0.048403055 | J6: =(E6-D6)/D6 -> 0.16426735 | K6: =(F6-E6)/E6 -> 0.11445083 | L6: =(G6-F6)/F6 -> 0.082806923
B7: Revenue From Operations [Net] | C7: 30451.59 | D7: 28977.64 | E7: 33737.72 | F7: 37599.03 | G7: 40712.49
B8: Other Operating Revenues | C8: 507.6 | D8: 573.64 | E8: 420.66 | F8: 189.59 | G8: 210.93
B9: Total Operating Revenues | C9: 30959.19 | D9: 29551.28 | E9: 34158.38 | F9: 37788.62 | G9: 40923.42
B10: Other Income | C10: 557.9 | D10: 555.01 | E10: 569.01 | F10: 854.54 | G10: 1044.08
B11: Total Revenue | C11: 31517.09 | D11: 30106.29 | E11: 34727.39 | F11: 38643.16 | G11: 41967.5
B12: EXPENSES
B13: Cost Of Materials Consumed | C13: 21968.04 | D13: 20845.74 | E13: 24060.29 | F13: 24836.89 | G13: 26607.07
B14: Purchase Of Stock-In Trade | C14: 31.14 | D14: 45.95 | E14: 47.43 | F14: 484.2 | G14: 547.91
B15: Changes In Inventories Of FG,WIP And Stock-In Trade | C15: -255.57 | D15: 28.67 | E15: -163.69 | F15: 188.35 | G15: -244.34
B16: Employee Benefit Expenses | C16: 1951.02 | D16: 1995.78 | E16: 2250.05 | F16: 2471.55 | G16: 2680.07
B17: Finance Costs | C17: 46.41 | D17: 53.1 | E17: 104.88 | F17: 76.37 | G17: 70.65
B18: Depreciation And Amortisation Expenses | C18: 715.12 | D18: 689.52 | E18: 697.39 | F18: 757.36 | G18: 824.59
B19: Other Expenses | C19: 3165.05 | D19: 3190.37 | E19: 3870.53 | F19: 4458 | G19: 5386.87
B20: Total Expenses | C20: 27621.21 | D20: 26849.13 | E20: 30866.88 | F20: 33272.72 | G20: 35872.82
B21: Profit/Loss Before Exceptional, ExtraOrdinary Items And Tax | C21: 3895.88 | D21: 3257.16 | E21: 3860.51 | F21: 5370.44 | G21: 6094.68
B22: Exceptional Items | C22: 0 | D22: 0 | E22: 0 | F22: -159.99 | G22: 0
B23: Profit/Loss Before Tax | C23: 3895.88 | D23: 3257.16 | E23: 3860.51 | F23: 5210.45 | G23: 6094.68
B24: Tax Expenses-Continued Operations
B25: Current Tax | C25: 931.38 | D25: 805.44 | E25: 947.69 | F25: 1264.18 | G25: 1448.02
B26: Deferred Tax | C26: -18.11 | D26: -76.38 | E26: 116.03 | F26: 83.86 | G26: 109.73
B27: Total Tax Expenses | C27: 913.27 | D27: 729.06 | E27: 1063.72 | F27: 1348.04 | G27: 1557.75
B28: Profit/Loss After Tax And Before ExtraOrdinary Items | C28: 2982.61 | D28: 2528.1 | E28: 2796.79 | F28: 3862.41 | G28: 4536.93
B29: Profit/Loss From Continuing Operations | C29: 2982.61 | D29: 2528.1 | E29: 2796.79 | F29: 3862.41 | G29: 4536.93
B30: Profit/Loss For The Period | C30: 2982.61 | D30: 2528.1 | E30: 2796.79 | F30: 3862.41 | G30: 4536.93
B31: Minority Interest | C31: -18.3 | D31: -12.17 | E31: 10.06 | F31: 2.67 | G31: 2.67
B32: Share Of Profit/Loss Of Associates | C32: -46.56 | D32: -199.05 | E32: 3.11 | F32: -120.25 | G32: -161.12
B33: Consolidated Profit/Loss After MI And Associates | C33: 2917.75 | D33: 2316.88 | E33: 2809.96 | F33: 3744.83 | G33: 4378.48
B34: OTHER ADDITIONAL INFORMATION
B35: EARNINGS PER SHARE
B36: Basic EPS (Rs.) | C36: 146 | D36: 116 | E36: 141 | F36: 187 | G36: 219
B37: Diluted EPS (Rs.) | C37: 146 | D37: 116 | E37: 141 | F37: 187 | G37: 219
B38: DIVIDEND AND DIVIDEND PERCENTAGE
B39: Equity Share Dividend | C39: 1897.81 | D39: 1898.13 | E39: 1998.33 | F39: 2698.67 | G39: 2799.83
B40: Tax On Dividend | C40: 2.49 | D40: 1.12 | E40: 0 | F40: 0 | G40: 0

Sheet Consolidated BS 5y
B2: Hero Motocorp
B3: Consolidated Balance Sheet
C5: 44256 | D5: 44621 | E5: 44986 | F5: 45352 | G5: Mar 25
B6: EQUITIES AND LIABILITIES
B7: SHAREHOLDER'S FUNDS
B8: Equity Share Capital | C8: 39.96 | D8: 39.96 | E8: 39.97 | F8: 39.98 | G8: 40
B9: Total Share Capital | C9: 39.96 | D9: 39.96 | E9: 39.97 | F9: 39.98 | G9: 40
B10: Reserves and Surplus | C10: 15357.42 | D10: 15782.24 | E10: 16579.97 | F10: 17613.31 | G10: 19232.04
B11: Total Reserves and Surplus | C11: 15357.42 | D11: 15782.24 | E11: 16579.97 | F11: 17613.31 | G11: 19232.04
B12: Employees Stock Options | C12: 19.04 | D12: 24.45 | E12: 35.63 | F12: 45.63 | G12: 0
B13: Total Shareholders Funds | C13: 15416.42 | D13: 15846.65 | E13: 16655.57 | F13: 17698.92 | G13: 19272.04
B14: Minority Interest | C14: 143.19 | D14: 148.05 | E14: 125.06 | F14: 135.65 | G14: 132.05
B15: NON-CURRENT LIABILITIES
B16: Long Term Borrowings | C16: 45.18 | D16: 36.17 | E16: 20.09 | F16: 0 | G16: 0
B17: Deferred Tax Liabilities [Net] | C17: 452.74 | D17: 378.21 | E17: 485.79 | F17: 570.13 | G17: 674.92
B18: Other Long Term Liabilities | C18: 358.46 | D18: 370.55 | E18: 415.96 | F18: 377.26 | G18: 340.04
B19: Long Term Provisions | C19: 175.57 | D19: 181.13 | E19: 201.94 | F19: 322.46 | G19: 495.29
B20: Total Non-Current Liabilities | C20: 1031.95 | D20: 966.06 | E20: 1123.78 | F20: 1269.85 | G20: 1510.25
B21: CURRENT LIABILITIES
B22: Short Term Borrowings | C22: 285.16 | D22: 317.31 | E22: 293.15 | F22: 363.43 | G22: 456.76
B23: Trade Payables | C23: 5264.18 | D23: 4343.09 | E23: 4760.14 | F23: 5622.9 | G23: 5699.66
B24: Other Current Liabilities | C24: 779.37 | D24: 678.08 | E24: 766.65 | F24: 902.6 | G24: 1098.07
B25: Short Term Provisions | C25: 175.82 | D25: 179.15 | E25: 192.68 | F25: 159.44 | G25: 221.49
B26: Total Current Liabilities | C26: 6504.53 | D26: 5517.63 | E26: 6012.62 | F26: 7048.37 | G26: 7475.98
B27: Total Capital And Liabilities | C27: 23096.09 | D27: 22478.39 | E27: 23917.03 | F27: 26152.79 | G27: 28390.32
B28: ASSETS
B29: NON-CURRENT ASSETS
B30: Tangible Assets | C30: 6061.91 | D30: 5872.24 | E30: 5640.7 | F30: 5688.55 | G30: 5702.52
B31: Intangible Assets | C31: 318.48 | D31: 321.3 | E31: 518.5 | F31: 543.65 | G31: 580.46
B32: Capital Work-In-Progress | C32: 236.4 | D32: 149.13 | E32: 122.09 | F32: 127.16 | G32: 105.37
B33: Intangible Assets Under Development | C33: 258.73 | D33: 368.09 | E33: 331.62 | F33: 356.9 | G33: 381.81
B34: Fixed Assets | C34: 6875.52 | D34: 6710.76 | E34: 6612.91 | F34: 6716.26 | G34: 6770.16
B35: Non-Current Investments | C35: 4356.28 | D35: 4657.56 | E35: 7219.08 | F35: 8446.16 | G35: 7748.27
B36: Long Term Loans And Advances | C36: 52.64 | D36: 59.44 | E36: 19.87 | F36: 21.15 | G36: 24.87
B37: Other Non-Current Assets | C37: 441.17 | D37: 478.41 | E37: 629.84 | F37: 653.77 | G37: 413.13
B38: Total Non-Current Assets | C38: 11725.61 | D38: 11906.17 | E38: 14481.7 | F38: 15837.34 | G38: 14956.43
B39: CURRENT ASSETS
B40: Current Investments | C40: 6225.34 | D40: 5870.31 | E40: 3671.85 | F40: 4305.08 | G40: 6635.99
B41: Inventories | C41: 1789.27 | D41: 1472.41 | E41: 1756.39 | F41: 1755.9 | G41: 2013.34
B42: Trade Receivables | C42: 2274.68 | D42: 2158.49 | E42: 2719.47 | F42: 2630.22 | G42: 3381.29
...

Sheet Assumptions
C2: [ | D2: Hero Motocorp
D3: Consolidated Profit & Loss account
E4: 44256 | F4: 44621 | G4: 44986 | H4: 45352 | I4: Mar 25
C5: Particulars
C6: ='Consolidated PL 5y'!B7 -> Revenue From Operations [Net] | E6: ='Consolidated PL 5y'!C7 -> 30451.59 | F6: ='Consolidated PL 5y'!D7 -> 28977.64 | G6: ='Consolidated PL 5y'!E7 -> 33737.72 | H6: ='Consolidated PL 5y'!F7 -> 37599.03 | I6: ='Consolidated PL 5y'!G7 -> 40712.49
C7: revenue growth | F7: ='Consolidated PL 5y'!I6 -> -0.048403055 | G7: ='Consolidated PL 5y'!J6 -> 0.16426735 | H7: ='Consolidated PL 5y'!K6 -> 0.11445083 | I7: ='Consolidated PL 5y'!L6 -> 0.082806923 | K7: =AVERAGE(F7:I7) -> 0.07828051 | L7: =MEDIAN(F7:G7) -> 0.057932145 | M7: =MEDIAN(F7:I7) -> 0.098628876
C9: less: Material Consumed | E9: =SUM('Consolidated PL 5y'!C13:C15) -> 21743.61 | F9: =SUM('Consolidated PL 5y'!D13:D15) -> 20920.36 | G9: =SUM('Consolidated PL 5y'!E13:E15) -> 23944.03 | H9: =SUM('Consolidated PL 5y'!F13:F15) -> 25509.44 | I9: =SUM('Consolidated PL 5y'!G13:G15) -> 26910.64
C10: less: Employee Cost | E10: ='Consolidated PL 5y'!C16 -> 1951.02 | F10: ='Consolidated PL 5y'!D16 -> 1995.78 | G10: ='Consolidated PL 5y'!E16 -> 2250.05 | H10: ='Consolidated PL 5y'!F16 -> 2471.55 | I10: ='Consolidated PL 5y'!G16 -> 2680.07
C11: less: Other Expenses | E11: ='Consolidated PL 5y'!C19 -> 3165.05 | F11: ='Consolidated PL 5y'!D19 -> 3190.37 | G11: ='Consolidated PL 5y'!E19 -> 3870.53 | H11: ='Consolidated PL 5y'!F19 -> 4458 | I11: ='Consolidated PL 5y'!G19 -> 5386.87
C12: Total Expenses | E12: =SUM(Assumptions!E9:E11) -> 26859.68 | F12: =SUM(Assumptions!F9:F11) -> 26106.51 | G12: =SUM(Assumptions!G9:G11) -> 30064.61 | H12: =SUM(Assumptions!H9:H11) -> 32438.99 | I12: =SUM(Assumptions!I9:I11) -> 34977.58
C14: EBITDA | E14: =E6-E12 -> 3591.91 | F14: =F6-F12 -> 2871.13 | G14: =G6-G12 -> 3673.11 | H14: =H6-H12 -> 5160.04 | I14: =I6-I12 -> 5734.91
C16: less: Depreciation & Amortization | E16: ='Consolidated PL 5y'!C18 -> 715.12 | F16: ='Consolidated PL 5y'!D18 -> 689.52 | G16: ='Consolidated PL 5y'!E18 -> 697.39 | H16: ='Consolidated PL 5y'!F18 -> 757.36 | I16: ='Consolidated PL 5y'!G18 -> 824.59
C18: EBIT | E18: =E14-E16 -> 2876.79 | F18: =F14-F16 -> 2181.61 | G18: =G14-G16 -> 2975.72 | H18: =H14-H16 -> 4402.68 | I18: =I14-I16 -> 4910.32
C20: add: Other income | E20: ='Consolidated PL 5y'!C10+'Consolidated PL 5y'!C22 -> 557.9 | F20: ='Consolidated PL 5y'!D10+'Consolidated PL 5y'!D22 -> 555.01 | G20: ='Consolidated PL 5y'!E10+'Consolidated PL 5y'!E22 -> 569.01 | H20: ='Consolidated PL 5y'!F10+'Consolidated PL 5y'!F22 -> 694.55 | I20: ='Consolidated PL 5y'!G10+'Consolidated PL 5y'!G22 -> 1044.08
C21: less: Interest Expense | E21: ='Consolidated PL 5y'!C17 -> 46.41 | F21: ='Consolidated PL 5y'!D17 -> 53.1 | G21: ='Consolidated PL 5y'!E17 -> 104.88 | H21: ='Consolidated PL 5y'!F17 -> 76.37 | I21: ='Consolidated PL 5y'!G17 -> 70.65
C23: EBT | E23: =E18+E20-E21 -> 3388.28 | F23: =F18+F20-F21 -> 2683.52 | G23: =G18+G20-G21 -> 3439.85 | H23: =H18+H20-H21 -> 5020.86 | I23: =I18+I20-I21 -> 5883.75
C25: less: Tax | E25: ='Consolidated PL 5y'!C27 -> 913.27 | F25: ='Consolidated PL 5y'!D27 -> 729.06 | G25: ='Consolidated PL 5y'!E27 -> 1063.72 | H25: ='Consolidated PL 5y'!F27 -> 1348.04 | I25: ='Consolidated PL 5y'!G27 -> 1557.75
C26: less: Non Controlling interest | E26: ='Consolidated PL 5y'!C31 -> -18.3 | F26: ='Consolidated PL 5y'!D31 -> -12.17 | G26: ='Consolidated PL 5y'!E31 -> 10.06 | H26: ='Consolidated PL 5y'!F31 -> 2.67 | I26: ='Consolidated PL 5y'!G31 -> 2.67
C28: PAT | E28: =E23-E25-E26 -> 2493.31 | F28: =F23-F25-F26 -> 1966.63 | G28: =G23-G25-G26 -> 2366.07 | H28: =H23-H25-H26 -> 3670.15 | I28: =I23-I25-I26 -> 4323.33
C30: Historical Growth
C31: Average Growth | E31: =AVERAGE(F7:I7) -> 0.07828051
C32: CAGR | E32: =(I6/E6)^(1/4)-1 -> 0.075299448 | F32: =_xlfn.RRI(4,E6,I6) -> 0.075299448
C34: Margin Analysis
C35: EBITDA Margin | E35: =E14/E6 -> 0.11795476 | F35: =F14/F6 -> 0.099080878 | G35: =G14/G6 -> 0.1088725 | H35: =H14/H6 -> 0.13723865 | I35: =I14/I6 -> 0.14086365
C36: EBIT Margin | E36: =E18/E6 -> 0.094470929 | F36: =F18/F6 -> 0.075285979 | G36: =G18/G6 -> 0.088201574 | H36: =H18/H6 -> 0.11709557 | I36: =I18/I6 -> 0.12060967
C37: EBT Margin | E37: =E23/E6 -> 0.11126775 | F37: =F23/F6 -> 0.092606575 | G37: =G23/G6 -> 0.10195858 | H37: =H23/H6 -> 0.13353696 | I37: =I23/I6 -> 0.14451953
C38: PAT Margin | E38: =E28/E6 -> 0.081877826 | F38: =F28/F6 -> 0.067867156 | G38: =G28/G6 -> 0.070131295 | H38: =H28/H6 -> 0.097612891 | I38: =I28/I6 -> 0.10619174
C40: Tax Rate
C41: Effective Tax Rate | D41: =E25/E23 -> 0.26953794 | E41: =F25/F23 -> 0.27168048 | F41: =G25/G23 -> 0.30923441 | G41: =H25/H23 -> 0.26848787 | H41: =I25/I23 -> 0.26475462
C42: Marginal Tax Rate | D42: 0.25 | E42: 0.25 | F42: 0.25 | G42: 0.25 | H42: 0.25
C44: Return on Capital
C45: EBIT(1-t) | D45: =E18*(1-D42) -> 2157.5925 | E45: =F18*(1-E42) -> 1636.2075 | F45: =G18*(1-F42) -> 2231.79 | G45: =H18*(1-G42) -> 3302.01 | H45: =I18*(1-H42) -> 3682.74
C46: Book Equity | D46: ='Consolidated BS 5y'!C13 -> 15416.42 | E46: ='Consolidated BS 5y'!D13 -> 15846.65 | F46: ='Consolidated BS 5y'!E13 -> 16655.57 | G46: ='Consolidated BS 5y'!F13 -> 17698.92 | H46: ='Consolidated BS 5y'!G13 -> 19272.04
C47: Book Debt | D47: ='Consolidated BS 5y'!C22+'Consolidated BS 5y'!C16 -> 330.34 | E47: ='Consolidated BS 5y'!D22+'Consolidated BS 5y'!D16 -> 353.48 | F47: ='Consolidated BS 5y'!E22+'Consolidated BS 5y'!E16 -> 313.24 | G47: ='Consolidated BS 5y'!F22+'Consolidated BS 5y'!F16 -> 363.43 | H47: ='Consolidated BS 5y'!G22+'Consolidated BS 5y'!G16 -> 456.76
C48: Cash and Cash Equivalent | D48: ='Consolidated BS 5y'!C43 -> 396.24 | E48: ='Consolidated BS 5y'!D43 -> 299.74 | F48: ='Consolidated BS 5y'!E43 -> 422.8 | G48: ='Consolidated BS 5y'!F43 -> 696.47 | H48: ='Consolidated BS 5y'!G43 -> 574.08
C49: Capital Employed | D49: =D46+D47-D48 -> 15350.52 | E49: =E46+E47-E48 -> 15900.39 | F49: =F46+F47-F48 -> 16546.01 | G49: =G46+G47-G48 -> 17365.88 | H49: =H46+H47-H48 -> 19154.72
C51: Pre Tax Return on Capital | D51: =E18/D49 -> 0.18740668 | E51: =F18/E49 -> 0.13720481 | F51: =G18/F49 -> 0.17984517 | G51: =H18/G49 -> 0.25352473 | H51: =I18/H49 -> 0.25635039
C52: Post Tax Return on Capital | D52: =D45/D49 -> 0.14055501 | E52: =E45/E49 -> 0.10290361 | F52: =F45/F49 -> 0.13488388 | G52: =G45/G49 -> 0.19014355 | H52: =H45/H49 -> 0.19226279
B54: Growth in EBIT | D54: =FCFF!C13*Assumptions!H52 -> -0.012400204

Sheet Ratios
B2: Ratio Analysis
B3: Years | C3: 46102 | D3: 46103 | E3: 46104 | F3: 46105 | G3: 46106 | H3: Trend | I3: Mean | J3: Median
B5: SalesGrowth | D5: =('Consolidated PL 5y'!D9-'Consolidated PL 5y'!C9)/'Consolidated PL 5y'!C9 -> -0.045476319 | E5: =('Consolidated PL 5y'!E9-'Consolidated PL 5y'!D9)/'Consolidated PL 5y'!D9 -> 0.15590188 | F5: =('Consolidated PL 5y'!F9-'Consolidated PL 5y'!E9)/'Consolidated PL 5y'!E9 -> 0.1062767 | G5: =('Consolidated PL 5y'!G9-'Consolidated PL 5y'!F9)/'Consolidated PL 5y'!F9 -> 0.082956192
B6: EBITDA Growth | D6: =(Assumptions!F14-Assumptions!E14)/Assumptions!E14 -> -0.20066761 | E6: =(Assumptions!G14-Assumptions!F14)/Assumptions!F14 -> 0.27932556 | F6: =(Assumptions!H14-Assumptions!G14)/Assumptions!G14 -> 0.40481499 | G6: =(Assumptions!I14-Assumptions!H14)/Assumptions!H14 -> 0.11140805
B7: EBIT Growth | D7: =(Assumptions!F18-Assumptions!E18)/Assumptions!E18 -> -0.24165128 | E7: =(Assumptions!G18-Assumptions!F18)/Assumptions!F18 -> 0.36400182 | F7: =(Assumptions!H18-Assumptions!G18)/Assumptions!G18 -> 0.47953436 | G7: =(Assumptions!I18-Assumptions!H18)/Assumptions!H18 -> 0.1153025
B8: Net Profit Growth | D8: =(Assumptions!F28-Assumptions!E28)/Assumptions!E28 -> -0.21123727 | E8: =(Assumptions!G28-Assumptions!F28)/Assumptions!F28 -> 0.20310887 | F8: =(Assumptions!H28-Assumptions!G28)/Assumptions!G28 -> 0.55115867 | G8: =(Assumptions!I28-Assumptions!H28)/Assumptions!H28 -> 0.17797093
B9: Dividend Growth | D9: =('Consolidated PL 5y'!D39-'Consolidated PL 5y'!C39)/'Consolidated PL 5y'!C39 -> 0.0001686154 | E9: =('Consolidated PL 5y'!E39-'Consolidated PL 5y'!D39)/'Consolidated PL 5y'!D39 -> 0.052788797 | F9: =('Consolidated PL 5y'!F39-'Consolidated PL 5y'!E39)/'Consolidated PL 5y'!E39 -> 0.35046264 | G9: =('Consolidated PL 5y'!G39-'Consolidated PL 5y'!F39)/'Consolidated PL 5y'!F39 -> 0.037485132
B11: Gross Margin | C11: =(Assumptions!E6-Assumptions!E9)/Assumptions!E6 -> 0.28596142 | D11: =(Assumptions!F6-Assumptions!F9)/Assumptions!F6 -> 0.27805163 | E11: =(Assumptions!G6-Assumptions!G9)/Assumptions!G6 -> 0.29028903 | F11: =(Assumptions!H6-Assumptions!H9)/Assumptions!H6 -> 0.32153994 | G11: =(Assumptions!I6-Assumptions!I9)/Assumptions!I6 -> 0.33900776
B12: EBITDA Margin | C12: =Assumptions!E14/Assumptions!E6 -> 0.11795476 | D12: =Assumptions!F14/Assumptions!F6 -> 0.099080878 | E12: =Assumptions!G14/Assumptions!G6 -> 0.1088725 | F12: =Assumptions!H14/Assumptions!H6 -> 0.13723865 | G12: =Assumptions!I14/Assumptions!I6 -> 0.14086365
B13: EBIT Margin | C13: =Assumptions!E18/Assumptions!E6 -> 0.094470929 | D13: =Assumptions!F18/Assumptions!F6 -> 0.075285979 | E13: =Assumptions!G18/Assumptions!G6 -> 0.088201574 | F13: =Assumptions!H18/Assumptions!H6 -> 0.11709557 | G13: =Assumptions!I18/Assumptions!I6 -> 0.12060967
B14: EBT Margin | C14: =Assumptions!E23/Assumptions!E6 -> 0.11126775 | D14: =Assumptions!F23/Assumptions!F6 -> 0.092606575 | E14: =Assumptions!G23/Assumptions!G6 -> 0.10195858 | F14: =Assumptions!H23/Assumptions!H6 -> 0.13353696 | G14: =Assumptions!I23/Assumptions!I6 -> 0.14451953
B15: Net Profit Margin | C15: =Assumptions!E28/Assumptions!E6 -> 0.081877826 | D15: =Assumptions!F28/Assumptions!F6 -> 0.067867156 | E15: =Assumptions!G28/Assumptions!G6 -> 0.070131295 | F15: =Assumptions!H28/Assumptions!H6 -> 0.097612891 | G15: =Assumptions!I28/Assumptions!I6 -> 0.10619174
B17: SalesExpenses%Sales | C17: =('Consolidated PL 5y'!C18+'Consolidated PL 5y'!C20)/'Consolidated PL 5y'!C9 -> 0.91528008 | D17: =('Consolidated PL 5y'!D18+'Consolidated PL 5y'!D20)/'Consolidated PL 5y'!D9 -> 0.93189364 | E17: =('Consolidated PL 5y'!E18+'Consolidated PL 5y'!E20)/'Consolidated PL 5y'!E9 -> 0.92405641 | F17: =('Consolidated PL 5y'!F18+'Consolidated PL 5y'!F20)/'Consolidated PL 5y'!F9 -> 0.90053778 | G17: =('Consolidated PL 5y'!G18+'Consolidated PL 5y'!G20)/'Consolidated PL 5y'!G9 -> 0.8967337
B18: Depreciation%Sales | C18: ='Consolidated PL 5y'!C19/'Consolidated PL 5y'!C9 -> 0.10223297 | D18: ='Consolidated PL 5y'!D19/'Consolidated PL 5y'!D9 -> 0.10796047 | E18: ='Consolidated PL 5y'!E19/'Consolidated PL 5y'!E9 -> 0.11331129 | F18: ='Consolidated PL 5y'!F19/'Consolidated PL 5y'!F9 -> 0.11797202 | G18: ='Consolidated PL 5y'!G19/'Consolidated PL 5y'!G9 -> 0.13163294
B19: OperatingIncome%Sales | C19: =Assumptions!E18/Assumptions!E6 -> 0.094470929 | D19: =Assumptions!F18/Assumptions!F6 -> 0.075285979 | E19: =Assumptions!G18/Assumptions!G6 -> 0.088201574 | F19: =Assumptions!H18/Assumptions!H6 -> 0.11709557 | G19: =Assumptions!I18/Assumptions!I6 -> 0.12060967
B21: Return on Capital Employed | C21: =(Assumptions!E18*(1-'Consolidated PL 5y'!C27/'Consolidated PL 5y'!C23))/('Consolidated BS 5y'!C13+'Consolidated BS 5y'!C16+'Consolidated BS 5y'!C22) -> 0.13986461 | D21: =(Assumptions!F18*(1-'Consolidated PL 5y'!D27/'Consolidated PL 5y'!D23))/('Consolidated BS 5y'!D13+'Consolidated BS 5y'!D16+'Consolidated BS 5y'!D22) -> 0.10452346 | E21: =(Assumptions!G18*(1-'Consolidated PL 5y'!E27/'Consolidated PL 5y'!E23))/('Consolidated BS 5y'!E13+'Consolidated BS 5y'!E16+'Consolidated BS 5y'!E22) -> 0.1270445 | F21: =(Assumptions!H18*(1-'Consolidated PL 5y'!F27/'Consolidated PL 5y'!F23))/('Consolidated BS 5y'!F13+'Consolidated BS 5y'!F16+'Consolidated BS 5y'!F22) -> 0.18068663 | G21: =(Assumptions!I18*(1-'Consolidated PL 5y'!G27/'Consolidated PL 5y'!G23))/('Consolidated BS 5y'!G13+'Consolidated BS 5y'!G16+'Consolidated BS 5y'!G22) -> 0.18527648
B22: Retained Earnings% | C22: =(Assumptions!E28-ABS('Consolidated PL 5y'!C39))/Assumptions!E28 -> 0.23883913 | D22: =(Assumptions!F28-ABS('Consolidated PL 5y'!D39))/Assumptions!F28 -> 0.034831158 | E22: =(Assumptions!G28-ABS('Consolidated PL 5y'!E39))/Assumptions!G28 -> 0.15542228 | F22: =(Assumptions!H28-ABS('Consolidated PL 5y'!F39))/Assumptions!H28 -> 0.26469763 | G22: =(Assumptions!I28-ABS('Consolidated PL 5y'!G39))/Assumptions!I28 -> 0.3523904
B23: Return on Equity% | C23: =Assumptions!E28/'Consolidated BS 5y'!C13 -> 0.1617308 | D23: =Assumptions!F28/(('Consolidated BS 5y'!C13+'Consolidated BS 5y'!D13)/2) -> 0.1258117 | E23: =Assumptions!G28/(('Consolidated BS 5y'!D13+'Consolidated BS 5y'!E13)/2) -> 0.14559436 | F23: =Assumptions!H28/(('Consolidated BS 5y'!E13+'Consolidated BS 5y'!F13)/2) -> 0.21366348 | G23: =Assumptions!I28/(('Consolidated BS 5y'!F13+'Consolidated BS 5y'!G13)/2) -> 0.23387708
B24: Self Sustained Growth Rate | C24: =(Assumptions!E28/'Consolidated BS 5y'!C20)*((Assumptions!E28-ABS('Consolidated PL 5y'!C39))/Assumptions!E28) -> 0.57706284 | D24: =(Assumptions!F28/(('Consolidated BS 5y'!C20+'Consolidated BS 5y'!D20)/2))*((Assumptions!F28-ABS('Consolidated PL 5y'!D39))/Assumptions!F28) -> 0.068568225 | E24: =(Assumptions!G28/(('Consolidated BS 5y'!D20+'Consolidated BS 5y'!E20)/2))*((Assumptions!G28-ABS('Consolidated PL 5y'!E39))/Assumptions!G28) -> 0.35193125 | F24: =(Assumptions!H28/(('Consolidated BS 5y'!E20+'Consolidated BS 5y'!F20)/2))*((Assumptions!H28-ABS('Consolidated PL 5y'!F39))/Assumptions!H28) -> 0.81172111 | G24: =(Assumptions!I28/(('Consolidated BS 5y'!F20+'Consolidated BS 5y'!G20)/2))*((Assumptions!I28-ABS('Consolidated PL 5y'!G39))/Assumptions!I28) -> 1.0960037
B25: Interest Coverage Ratio | C25: ='Consolidated PL 5y'!C21/'Consolidated PL 5y'!C17 -> 83.944839 | D25: ='Consolidated PL 5y'!D21/'Consolidated PL 5y'!D17 -> 61.340113 | E25: ='Consolidated PL 5y'!E21/'Consolidated PL 5y'!E17 -> 36.808829 | F25: ='Consolidated PL 5y'!F21/'Consolidated PL 5y'!F17 -> 70.32133 | G25: ='Consolidated PL 5y'!G21/'Consolidated PL 5y'!G17 -> 86.265817
B27: Debtor Turnover Ratio | C27: ='Consolidated PL 5y'!C11/'Consolidated BS 5y'!C47 -> 1.3646072 | D27: ='Consolidated PL 5y'!D11/(('Consolidated BS 5y'!C47+'Consolidated BS 5y'!D47)/2) -> 1.3211907 | E27: ='Consolidated PL 5y'!E11/(('Consolidated BS 5y'!D47+'Consolidated BS 5y'!E47)/2) -> 1.497018 | F27: ='Consolidated PL 5y'!F11/(('Consolidated BS 5y'!E47+'Consolidated BS 5y'!F47)/2) -> 1.543571 | G27: ='Consolidated PL 5y'!G11/(('Consolidated BS 5y'!F47+'Consolidated BS 5y'!G47)/2) -> 1.5388745
B28: Creditor Turnover Ratio | C28: =(Assumptions!E9+'Consolidated PL 5y'!C16+'Consolidated PL 5y'!C17)/'Consolidated BS 5y'!C26 -> 3.649924 | D28: =(Assumptions!F9+'Consolidated PL 5y'!D16+'Consolidated PL 5y'!D17)/(('Consolidated BS 5y'!C26+'Consolidated BS 5y'!D26)/2) -> 3.8211503 | E28: =(Assumptions!G9+'Consolidated PL 5y'!E16+'Consolidated PL 5y'!E17)/(('Consolidated BS 5y'!D26+'Consolidated BS 5y'!E26)/2) -> 4.5617328 | F28: =(Assumptions!H9+'Consolidated PL 5y'!F16+'Consolidated PL 5y'!F17)/(('Consolidated BS 5y'!E26+'Consolidated BS 5y'!F26)/2) -> 4.2963604 | G28: =(Assumptions!I9+'Consolidated PL 5y'!G16+'Consolidated PL 5y'!G17)/(('Consolidated BS 5y'!F26+'Consolidated BS 5y'!G26)/2) -> 4.0843632
B29: Inventory Turnover | C29: =(Assumptions!E9+'Consolidated PL 5y'!C16+'Consolidated PL 5y'!C17)/'Consolidated BS 5y'!C41 -> 13.268562 | D29: =(Assumptions!F9+'Consolidated PL 5y'!D16+'Consolidated PL 5y'!D17)/(('Consolidated BS 5y'!C41+'Consolidated BS 5y'!D41)/2) -> 14.0843 | E29: =(Assumptions!G9+'Consolidated PL 5y'!E16+'Consolidated PL 5y'!E17)/(('Consolidated BS 5y'!D41+'Consolidated BS 5y'!E41)/2) -> 16.290238 | F29: =(Assumptions!H9+'Consolidated PL 5y'!F16+'Consolidated PL 5y'!F17)/(('Consolidated BS 5y'!E41+'Consolidated BS 5y'!F41)/2) -> 15.976676 | G29: =(Assumptions!I9+'Consolidated PL 5y'!G16+'Consolidated PL 5y'!G17)/(('Consolidated BS 5y'!F41+'Consolidated BS 5y'!G41)/2) -> 15.738642
B30: Fixed Asset Turnover | C30: ='Consolidated PL 5y'!C11/'Consolidated BS 5y'!C38 -> 2.6878849 | D30: ='Consolidated PL 5y'!D11/(('Consolidated BS 5y'!C38+'Consolidated BS 5y'!D38)/2) -> 2.5479494 | E30: ='Consolidated PL 5y'!E11/(('Consolidated BS 5y'!D38+'Consolidated BS 5y'!E38)/2) -> 2.6320722 | F30: ='Consolidated PL 5y'!F11/(('Consolidated BS 5y'!E38+'Consolidated BS 5y'!F38)/2) -> 2.5491018 | G30: ='Consolidated PL 5y'!G11/(('Consolidated BS 5y'!F38+'Consolidated BS 5y'!G38)/2) -> 2.7257137
B31: Capital Turnover Ratio | C31: ='Consolidated PL 5y'!C11/'Consolidated BS 5y'!C20 -> 30.541296 | D31: ='Consolidated PL 5y'!D11/(('Consolidated BS 5y'!C20+'Consolidated BS 5y'!D20)/2) -> 30.136276 | E31: ='Consolidated PL 5y'!E11/(('Consolidated BS 5y'!D20+'Consolidated BS 5y'!E20)/2) -> 33.234496 | F31: ='Consolidated PL 5y'!F11/(('Consolidated BS 5y'!E20+'Consolidated BS 5y'!F20)/2) -> 32.288332 | G31: ='Consolidated PL 5y'!G11/(('Consolidated BS 5y'!F20+'Consolidated BS 5y'!G20)/2) -> 30.19136
B33: Debtor Days | C33: =365/C27 -> 267.47624 | D33: =365/D27 -> 276.26594 | E33: =365/E27 -> 243.81804 | F33: =365/F27 -> 236.46467 | G33: =365/G27 -> 237.18634
B34: Payable Days | C34: =365/C28 -> 100.00208 | D34: =365/D28 -> 95.520975 | E34: =365/E28 -> 80.013454 | F34: =365/F28 -> 84.955629 | G34: =365/G28 -> 89.365217
B35: Inventory Days | C35: =365/C29 -> 27.508633 | D35: =365/D29 -> 25.915381 | E35: =365/E29 -> 22.406057 | F35: =365/F29 -> 22.845803 | G35: =365/G29 -> 23.191327
B36: Cash Conversion Cycle (in days) | C36: =C33+C35-C34 -> 194.98279 | D36: =D33+D35-D34 -> 206.66035 | E36: =E33+E35-E34 -> 186.21064 | F36: =F33+F35-F34 -> 174.35485 | G36: =G33+G35-G34 -> 171.01245
B38: CFO/Sales
B39: CFO/Total Assets
B40: CFO/Total Debt

Sheet Fixed Asset Schedule 
B1: Hero Motocorp "Fixed Asset Schedule "
B2: Particular | C2: 44256 | D2: 44621 | E2: 44986 | F2: 45352 | G2: 45717
B3: Beginning balance | D3: =C7 -> 6875.52 | E3: =D7 -> 6710.76 | F3: =E7 -> 6612.91 | G3: =F7 -> 6716.26
B4: Add: Net Purchases | D4: =D5-D3 -> 524.76 | E4: =E5-E3 -> 599.54 | F4: =F5-F3 -> 860.71 | G4: =G5-G3 -> 878.49
B5: Total Fixed Assets | C5: =C6+C7 -> 7590.64 | D5: =D6+D7 -> 7400.28 | E5: =E6+E7 -> 7310.3 | F5: =F6+F7 -> 7473.62 | G5: =G6+G7 -> 7594.75
B6: Less: Depreciation | C6: ='Consolidated PL 5y'!C18 -> 715.12 | D6: ='Consolidated PL 5y'!D18 -> 689.52 | E6: ='Consolidated PL 5y'!E18 -> 697.39 | F6: ='Consolidated PL 5y'!F18 -> 757.36 | G6: ='Consolidated PL 5y'!G18 -> 824.59
B7: Closing Balance(Fixed Asests ) | C7: ='Consolidated BS 5y'!C34 -> 6875.52 | D7: ='Consolidated BS 5y'!D34 -> 6710.76 | E7: ='Consolidated BS 5y'!E34 -> 6612.91 | F7: ='Consolidated BS 5y'!F34 -> 6716.26 | G7: ='Consolidated BS 5y'!G34 -> 6770.16
B9: Net Capital expenditure | D9: =D4-D6 -> -164.76 | E9: =E4-E6 -> -97.85 | F9: =F4-F6 -> 103.35 | G9: =G4-G6 -> 53.9
B10: Net Capital expenditure / Sales percentage | D10: =IFERROR(D9/D3,0) -> -0.023963278 | E10: =IFERROR(E9/E3,0) -> -0.014581061 | F10: =IFERROR(F9/F3,0) -> 0.015628521 | G10: =IFERROR(G9/G3,0) -> 0.0080252998
B12: Median Capital expenditure /Sales percentage | C12: =MEDIAN(D10:G10) -> -0.0032778805
B13: Average Capital expenditure /Sales percentage | C13: =AVERAGE(D10:G10) -> -0.0037226297

Sheet Change in Working Cap
B2: Change in Working Capital
B3: Particular | C3: 44256 | D3: 44621 | E3: 44986 | F3: 45352 | G3: 45717
B4: Inventory | C4: ='Consolidated BS 5y'!C41 -> 1789.27 | D4: ='Consolidated BS 5y'!D41 -> 1472.41 | E4: ='Consolidated BS 5y'!E41 -> 1756.39 | F4: ='Consolidated BS 5y'!F41 -> 1755.9 | G4: ='Consolidated BS 5y'!G41 -> 2013.34
B5: Trade Receivables | C5: ='Consolidated BS 5y'!C42 -> 2274.68 | D5: ='Consolidated BS 5y'!D42 -> 2158.49 | E5: ='Consolidated BS 5y'!E42 -> 2719.47 | F5: ='Consolidated BS 5y'!F42 -> 2630.22 | G5: ='Consolidated BS 5y'!G42 -> 3381.29
B6: Trade Payable | C6: ='Consolidated BS 5y'!C23 -> 5264.18 | D6: ='Consolidated BS 5y'!D23 -> 4343.09 | E6: ='Consolidated BS 5y'!E23 -> 4760.14 | F6: ='Consolidated BS 5y'!F23 -> 5622.9 | G6: ='Consolidated BS 5y'!G23 -> 5699.66
B7: Non Cash working Capital | C7: =C4+C5-C6 -> -1200.23 | D7: =D4+D5-D6 -> -712.19 | E7: =E4+E5-E6 -> -284.28 | F7: =F4+F5-F6 -> -1236.78 | G7: =G4+G5-G6 -> -305.03
B8: Change in Working Capital | D8: =D7-C7 -> 488.04 | E8: =E7-D7 -> 427.91 | F8: =F7-E7 -> -952.5 | G8: =G7-F7 -> 931.75
B9: changein working Capital /percentage of sales | D9: =D7/'Consolidated PL 5y'!D7 -> -0.024577226 | E9: =E7/'Consolidated PL 5y'!E7 -> -0.008426177 | F9: =F7/'Consolidated PL 5y'!F7 -> -0.032893934 | G9: =G7/'Consolidated PL 5y'!G7 -> -0.0074922954
B11: Median Non Cash working Capital /Sales percentage | C11: =MEDIAN(D9:G9) -> -0.016501701
B12: Average Non Cash working Capital /Sales percentage | C12: =AVERAGE(D9:G9) -> -0.018347408

Sheet FCFF
B1: Hero MotoCorp "Free Cash Flow "
B2: Particular | C2: 44256 | D2: 44621 | E2: 44986 | F2: 45352 | G2: 45717
B3: EBIT | C3: =Assumptions!E18 -> 2876.79 | D3: =Assumptions!F18 -> 2181.61 | E3: =Assumptions!G18 -> 2975.72 | F3: =Assumptions!H18 -> 4402.68 | G3: =Assumptions!I18 -> 4910.32
B4: Less: Tax on EBIT | C4: =25%*C3 -> 719.1975 | D4: =25%*D3 -> 545.4025 | E4: =25%*E3 -> 743.93 | F4: =25%*F3 -> 1100.67 | G4: =25%*G3 -> 1227.58
B5: EBIT * (1- Tax) | C5: =C3-C4 -> 2157.5925 | D5: =D3-D4 -> 1636.2075 | E5: =E3-E4 -> 2231.79 | F5: =F3-F4 -> 3302.01 | G5: =G3-G4 -> 3682.74
