Workbook

Sheet About
I19: ABOUT
D20: ICICI Prudential Asset Management Company Limited is one of India's leading asset management companies and a joint venture between ICICI Bank Limited and Prudential Corporation Holdings Limited. Established in 1993, the company manages a diverse range of investment products including equity, debt, hybrid, exchange traded funds, portfolio management services, and alternative investment solutions. With a strong distribution network, extensive investor base, and a well diversified product portfolio, ICICI Prudential AMC has established itself as a prominent player in the Indian mutual fund industry. The company focuses on delivering long term wealth creation through disciplined investment management, innovation, and customer-centric financial solutions.

Sheet Shareholding 
B4: (A) Promoter & Promoter Group | C4: 43,29,29,855 | D4: 87.59
B5: (B) Public | C5: 6,13,28,665 | D5: 12.41
B6: (C1) Shares underlying DRs | C6: - | D6: --
B7: (C2) Shares held by Employee Trust | C7: - | D7: --
B8: (C) Non Promoter-Non Public | C8: - | D8: --
B9: Grand Total | C9: 49,42,58,520 | D9: 100

Sheet Data Sheet
B1: ICICI AMC LIMITED – Consolidated Profit & Loss Account (Rs. Cr.)
B2: Particulars | C2: Mar '22 | D2: Mar '23 | E2: Mar '24 | F2: Mar '25 | G2: Mar '26
B3: ── INCOME ──
B4: Revenue From Operations [Net] | C4: 2634.07 | D4: 2837.35 | E4: 3758.23 | F4: 4977.33 | G4: 5764.63
B5: Other Operating Revenues | C5: 2634.07 | D5: 2837.35 | E5: 3758.23 | F5: 4977.33 | G5: 5764.63
B6: Total Operating Revenues | C6: 2634.07 | D6: 2837.35 | E6: 3758.23 | F6: 4977.33 | G6: 5764.63
B7: Other Income | C7: 1.22 | D7: 0.83 | E7: 2.98 | F7: 2.34 | G7: 236.29
B8: Total Revenue | C8: 2635.29 | D8: 2838.18 | E8: 3761.21 | F8: 4979.67 | G8: 6000.92
B9: ── EXPENSES ──
B10: Operating & DiICICI AMC t Expenses | C10: 0 | D10: 95.75 | E10: 152.97 | F10: 319.42 | G10: 0
B11: Employee Benefit Expenses | C11: 331.84 | D11: 411.71 | E11: 521.56 | F11: 614.21 | G11: 637.64
B12: Finance Costs | C12: 13.87 | D12: 14.91 | E12: 16.19 | F12: 18.55 | G12: 17.77
B13: Provisions & Contingencies | C13: 0 | D13: 0 | E13: 0 | F13: 0 | G13: 0
B14: Depreciation & Amortisation | C14: 50.9 | D14: 50.5 | E14: 65.71 | F14: 85.39 | G14: 105.51
B15: Other Expenses | C15: 309.65 | D15: 258.14 | E15: 306.67 | F15: 409.05 | G15: 833.16
B16: Total Expenses | C16: 706.26 | D16: 831.01 | E16: 1063.1 | F16: 1446.62 | G16: 1594.08
B17: ── PROFIT ──
B18: Profit Before Exceptional Items & Tax | C18: 1929.03 | D18: 2007.17 | E18: 2698.11 | F18: 3533.05 | G18: 4406.84
B19: Exceptional Items | C19: 0 | D19: 0 | E19: 0 | F19: 0 | G19: 0
B20: Profit Before Tax | C20: 1929.03 | D20: 2007.17 | E20: 2698.11 | F20: 3533.05 | G20: 4406.84
B21: Current Tax | C21: 476.65 | D21: 509.5 | E21: 612.14 | F21: 870.49 | G21: 1108.58
B22: Deferred Tax | C22: -1.71 | D22: -18.11 | E22: 36.24 | F22: 11.9 | G22: 0
B23: Total Tax Expenses | C23: 474.94 | D23: 491.39 | E23: 648.38 | F23: 882.39 | G23: 1108.58
B24: Profit After Tax | C24: 1454.09 | D24: 1515.78 | E24: 2049.73 | F24: 2650.66 | G24: 3298.26
B25: Consolidated PAT (After MI & Associates) | C25: =C24 -> 1454.09 | D25: =D24 -> 1515.78 | E25: =E24 -> 2049.73 | F25: =F24 -> 2650.66 | G25: =G24 -> 3298.26
B26: ── EPS ──
B27: Basic EPS (Rs.) | C27: 66.73 | D27: 53.6 | E27: 41.5 | F27: 30.7 | G27: 29.37
B28: Diluted EPS (Rs.) | C28: 66.73 | D28: 53.6 | E28: 41.5 | F28: 30.7 | G28: 29.37
B29: ── DIVIDEND ──
B30: Equity Share Dividend | C30: 1203.87 | D30: 1219.76 | E30: 1477.48 | F30: 2012.34 | G30: 0
B31: Equity Dividend Rate (%) | C31: 0 | D31: 84 | E31: 76 | F31: 81 | G31: 2725
B33: ICICI AMC LIMITED – Consolidated Balance Sheet (Rs. Cr.)
B34: Particulars | C34: Mar '22 | D34: Mar '23 | E34: Mar '24 | F34: Mar '25 | G34: Mar '26
B35: ── EQUITIES & LIABILITIES ──
B36: ── SHAREHOLDER'S FUNDS ──
B37: Equity Share Capital | C37: 17.65 | D37: 17.65 | E37: 17.65 | F37: 17.65 | G37: 49.43
B38: Total Share Capital | C38: 17.65 | D38: 17.65 | E38: 17.65 | F38: 17.65 | G38: 49.43
B39: Reserves and Surplus | C39: 1999.76 | D39: 2295.41 | E39: 2865.19 | F39: 3499.29 | G39: 4121.74
B40: Total Reserves and Surplus | C40: 1999.76 | D40: 2295.41 | E40: 2865.19 | F40: 3499.29 | G40: 4121.74
B41: Total Shareholders Funds | C41: 2017.41 | D41: 2313.06 | E41: 2882.84 | F41: 3516.94 | G41: 4171.17
...

Sheet Historical FS
B2: Historical Financial Statement - ICICI AMC LIMITED
B3: Years | C3: ='Data Sheet'!C2 -> Mar '22 | D3: ='Data Sheet'!D2 -> Mar '23 | E3: ='Data Sheet'!E2 -> Mar '24 | F3: ='Data Sheet'!F2 -> Mar '25 | G3: ='Data Sheet'!G2 -> Mar '26 | H3: LTM
A5: # | B5: Income statement
B6: Interest Income (Revenue) | C6: =IFERROR('Data Sheet'!C6,0) -> 2634.07 | D6: =IFERROR('Data Sheet'!D6,0) -> 2837.35 | E6: =IFERROR('Data Sheet'!E6,0) -> 3758.23 | F6: =IFERROR('Data Sheet'!F6,0) -> 4977.33 | G6: =IFERROR('Data Sheet'!G6,0) -> 5764.63 | H6: =IFERROR('Data Sheet'!G6,0) -> 5764.63
B7: Sales Growth | C7: - | D7: =D6/C6-1 -> 0.077173348 | E7: =E6/D6-1 -> 0.32455636 | F7: =F6/E6-1 -> 0.32438142 | G7: =G6/F6-1 -> 0.15817718 | H7: =H6/G6-1 -> 0 | K7: =AVERAGE(D7:G7) -> 0.22107208
B9: Finance Costs (Cost of Funds) | C9: =IFERROR('Data Sheet'!C12,0) -> 13.87 | D9: =IFERROR('Data Sheet'!D12,0) -> 14.91 | E9: =IFERROR('Data Sheet'!E12,0) -> 16.19 | F9: =IFERROR('Data Sheet'!F12,0) -> 18.55 | G9: =IFERROR('Data Sheet'!G12,0) -> 17.77 | H9: =IFERROR('Data Sheet'!G12,0) -> 17.77
B10: Cost of Funds % Revenue | C10: =C9/C6 -> 0.0052656156 | D10: =D9/D6 -> 0.0052549033 | E10: =E9/E6 -> 0.004307879 | F10: =F9/F6 -> 0.0037268978 | G10: =G9/G6 -> 0.0030825916 | H10: =H9/H6 -> 0.0030825916
B12: Net Interest Income (NII) | C12: =C6-C9 -> 2620.2 | D12: =D6-D9 -> 2822.44 | E12: =E6-E9 -> 3742.04 | F12: =F6-F9 -> 4958.78 | G12: =G6-G9 -> 5746.86 | H12: =H6-H9 -> 5746.86
B13: NIM (Net Interest Margin) | C13: =C12/C6 -> 0.99473438 | D13: =D12/D6 -> 0.9947451 | E13: =E12/E6 -> 0.99569212 | F13: =F12/F6 -> 0.9962731 | G13: =G12/G6 -> 0.99691741 | H13: =H12/H6 -> 0.99691741
B15: Operating Expenses (OpEx) | C15: =IFERROR(SUM('Data Sheet'!C10,'Data Sheet'!C11,'Data Sheet'!C15),0) -> 641.49 | D15: =IFERROR(SUM('Data Sheet'!D10,'Data Sheet'!D11,'Data Sheet'!D15),0) -> 765.6 | E15: =IFERROR(SUM('Data Sheet'!E10,'Data Sheet'!E11,'Data Sheet'!E15),0) -> 981.2 | F15: =IFERROR(SUM('Data Sheet'!F10,'Data Sheet'!F11,'Data Sheet'!F15),0) -> 1342.68 | G15: =IFERROR(SUM('Data Sheet'!G10,'Data Sheet'!G11,'Data Sheet'!G15),0) -> 1470.8 | H15: =IFERROR(SUM('Data Sheet'!G10,'Data Sheet'!G11,'Data Sheet'!G15),0) -> 1470.8
B16: OpEx % Revenue | C16: =C15/C6 -> 0.24353567 | D16: =D15/D6 -> 0.26982924 | E16: =E15/E6 -> 0.26108035 | F16: =F15/F6 -> 0.26975909 | G16: =G15/G6 -> 0.25514213 | H16: =H15/H6 -> 0.25514213
B18: EBITDA | C18: =C12-C15 -> 1978.71 | D18: =D12-D15 -> 2056.84 | E18: =E12-E15 -> 2760.84 | F18: =F12-F15 -> 3616.1 | G18: =G12-G15 -> 4276.06 | H18: =H12-H15 -> 4276.06
B19: EBITDA Margins | C19: =C18/C6 -> 0.75119872 | D19: =D18/D6 -> 0.72491585 | E19: =E18/E6 -> 0.73461177 | F19: =F18/F6 -> 0.72651401 | G19: =G18/G6 -> 0.74177527 | H19: =H18/H6 -> 0.74177527
B21: Depriciation | C21: =IFERROR(SUM('Data Sheet'!C14),0) -> 50.9 | D21: =IFERROR(SUM('Data Sheet'!D14),0) -> 50.5 | E21: =IFERROR(SUM('Data Sheet'!E14),0) -> 65.71 | F21: =IFERROR(SUM('Data Sheet'!F14),0) -> 85.39 | G21: =IFERROR(SUM('Data Sheet'!G14),0) -> 105.51 | H21: =IFERROR(SUM('Data Sheet'!G14),0) -> 105.51
B22: Depriciation % of Sales | C22: =C21/C6 -> 0.019323708 | D22: =D21/D6 -> 0.017798298 | E22: =E21/E6 -> 0.017484294 | F22: =F21/F6 -> 0.017155784 | G22: =G21/G6 -> 0.018302996 | H22: =H21/H6 -> 0.018302996
B24: EBIT | C24: =IFERROR(C18-C21,0) -> 1927.81 | D24: =IFERROR(D18-D21,0) -> 2006.34 | E24: =IFERROR(E18-E21,0) -> 2695.13 | F24: =IFERROR(F18-F21,0) -> 3530.71 | G24: =IFERROR(G18-G21,0) -> 4170.55 | H24: =IFERROR(H18-H21,0) -> 4170.55
B25: EBIT Margin | C25: =C24/C6 -> 0.73187501 | D25: =D24/D6 -> 0.70711756 | E25: =E24/E6 -> 0.71712748 | F25: =F24/F6 -> 0.70935823 | G25: =G24/G6 -> 0.72347228 | H25: =H24/H6 -> 0.72347228
B27: Provisions & Contingencies | C27: =IFERROR('Data Sheet'!C13,0) -> 0 | D27: =IFERROR('Data Sheet'!D13,0) -> 0 | E27: =IFERROR('Data Sheet'!E13,0) -> 0 | F27: =IFERROR('Data Sheet'!F13,0) -> 0 | G27: =IFERROR('Data Sheet'!G13,0) -> 0 | H27: =IFERROR('Data Sheet'!G13,0) -> 0
B28: Provisions % Revenue | C28: =C27/C6 -> 0 | D28: =D27/D6 -> 0 | E28: =E27/E6 -> 0 | F28: =F27/F6 -> 0 | G28: =G27/G6 -> 0 | H28: =H27/H6 -> 0
B30: Other Income | C30: =IFERROR('Data Sheet'!C7,0) -> 1.22 | D30: =IFERROR('Data Sheet'!D7,0) -> 0.83 | E30: =IFERROR('Data Sheet'!E7,0) -> 2.98 | F30: =IFERROR('Data Sheet'!F7,0) -> 2.34 | G30: =IFERROR('Data Sheet'!G7,0) -> 236.29 | H30: =IFERROR('Data Sheet'!G7,0) -> 236.29
B32: Profit Before Tax (PBT) | C32: =IFERROR(C24-C27+C30+IFERROR('Data Sheet'!C19,0),0) -> 1929.03 | D32: =IFERROR(D24-D27+D30+IFERROR('Data Sheet'!D19,0),0) -> 2007.17 | E32: =IFERROR(E24-E27+E30+IFERROR('Data Sheet'!E19,0),0) -> 2698.11 | F32: =IFERROR(F24-F27+F30+IFERROR('Data Sheet'!F19,0),0) -> 3533.05 | G32: =IFERROR(G24-G27+G30+IFERROR('Data Sheet'!G19,0),0) -> 4406.84 | H32: =IFERROR(H24-H27+H30+IFERROR('Data Sheet'!G19,0),0) -> 4406.84
B33: EBT % Sales | C33: =C32/C6 -> 0.73233817 | D33: =D32/D6 -> 0.70741008 | E33: =E32/E6 -> 0.7179204 | F33: =F32/F6 -> 0.70982836 | G33: =G32/G6 -> 0.7644619 | H33: =H32/H6 -> 0.7644619
B35: Tax | C35: =IFERROR('Data Sheet'!C23,0) -> 474.94 | D35: =IFERROR('Data Sheet'!D23,0) -> 491.39 | E35: =IFERROR('Data Sheet'!E23,0) -> 648.38 | F35: =IFERROR('Data Sheet'!F23,0) -> 882.39 | G35: =IFERROR('Data Sheet'!G23,0) -> 1108.58 | H35: =IFERROR('Data Sheet'!G23,0) -> 1108.58
B36: Effective Tax Rate | C36: =C35/C32 -> 0.24620664 | D36: =D35/D32 -> 0.24481733 | E36: =E35/E32 -> 0.24030896 | F36: =F35/F32 -> 0.24975305 | G36: =G35/G32 -> 0.25155894 | H36: =H35/H32 -> 0.25155894
B38: Net Profit | C38: =IFERROR(C32-C35,0) -> 1454.09 | D38: =IFERROR(D32-D35,0) -> 1515.78 | E38: =IFERROR(E32-E35,0) -> 2049.73 | F38: =IFERROR(F32-F35,0) -> 2650.66 | G38: =IFERROR(G32-G35,0) -> 3298.26 | H38: =IFERROR(H32-H35,0) -> 3298.26
B39: Net Margins | C39: =C38/C6 -> 0.55203165 | D39: =D38/D6 -> 0.53422384 | E39: =E38/E6 -> 0.5453977 | F39: =F38/F6 -> 0.53254657 | G39: =G38/G6 -> 0.57215467 | H39: =H38/H6 -> 0.57215467
B41: No. of Equity Shares | C41: =IFERROR('Data Sheet'!C37/'Data Sheet'!C89,0) -> 1.765 | D41: =IFERROR('Data Sheet'!D37/'Data Sheet'!D89,0) -> 1.765 | E41: =IFERROR('Data Sheet'!E37/'Data Sheet'!E89,0) -> 1.765 | F41: =IFERROR('Data Sheet'!F37/'Data Sheet'!F89,0) -> 1.765 | G41: 49.43 | H41: 49.43
B43: Earnings Per Share (Basic EPS) | C43: =IFERROR('Data Sheet'!C27,0) -> 66.73 | D43: =IFERROR('Data Sheet'!D27,0) -> 53.6 | E43: =IFERROR('Data Sheet'!E27,0) -> 41.5 | F43: =IFERROR('Data Sheet'!F27,0) -> 30.7 | G43: =IFERROR('Data Sheet'!G27,0) -> 29.37 | H43: =IFERROR('Data Sheet'!G27,0) -> 29.37
B44: EPS Growth % | D44: =IFERROR(D43/C43-1,0) -> -0.19676308 | E44: =IFERROR(E43/D43-1,0) -> -0.22574627 | F44: =IFERROR(F43/E43-1,0) -> -0.26024096 | G44: =IFERROR(G43/F43-1,0) -> -0.043322476 | H44: =IFERROR(H43/G43-1,0) -> 0
B46: Dividend per Share | C46: =IFERROR('Data Sheet'!C30/'Historical FS'!C41,0) -> 682.07932 | D46: =IFERROR('Data Sheet'!D30/'Historical FS'!D41,0) -> 691.08215 | E46: =IFERROR('Data Sheet'!E30/'Historical FS'!E41,0) -> 837.09915 | F46: =IFERROR('Data Sheet'!F30/'Historical FS'!F41,0) -> 1140.136 | G46: =IFERROR('Data Sheet'!G30/'Historical FS'!G41,0) -> 0 | H46: =IFERROR('Data Sheet'!G30/'Historical FS'!H41,0) -> 0
B47: Divident Payout Ratio | C47: =IFERROR(C46/C43,0) -> 10.221479 | D47: =IFERROR(D46/D43,0) -> 12.893324 | E47: =IFERROR(E46/E43,0) -> 20.171064 | F47: =IFERROR(F46/F43,0) -> 37.13798 | G47: =IFERROR(G46/G43,0) -> 0 | H47: =IFERROR(H46/H43,0) -> 0
B49: Retained Earnings | C49: =IFERROR(IF(C43>C46,1-C47,0),0) -> 0 | D49: =IFERROR(IF(D43>D46,1-D47,0),0) -> 0 | E49: =IFERROR(IF(E43>E46,1-E47,0),0) -> 0 | F49: =IFERROR(IF(F43>F46,1-F47,0),0) -> 0 | G49: =IFERROR(IF(G43>G46,1-G47,0),0) -> 1 | H49: =IFERROR(IF(H43>H46,1-H47,0),0) -> 1
A51: # | B51: Balance statement | C51: =C3 -> Mar '22 | D51: =D3 -> Mar '23 | E51: =E3 -> Mar '24 | F51: =F3 -> Mar '25 | G51: =G3 -> Mar '26 | H51: =H3 -> LTM
B52: Equity Share Capital | C52: =IFERROR('Data Sheet'!C37,0) -> 17.65 | D52: =IFERROR('Data Sheet'!D37,0) -> 17.65 | E52: =IFERROR('Data Sheet'!E37,0) -> 17.65 | F52: =IFERROR('Data Sheet'!F37,0) -> 17.65 | G52: =IFERROR('Data Sheet'!G37,0) -> 49.43 | H52: =IFERROR('Data Sheet'!G37,0) -> 49.43
B53: Reserves | C53: =IFERROR('Data Sheet'!C39,0) -> 1999.76 | D53: =IFERROR('Data Sheet'!D39,0) -> 2295.41 | E53: =IFERROR('Data Sheet'!E39,0) -> 2865.19 | F53: =IFERROR('Data Sheet'!F39,0) -> 3499.29 | G53: =IFERROR('Data Sheet'!G39,0) -> 4121.74 | H53: =IFERROR('Data Sheet'!G39,0) -> 4121.74
B54: Borrowings | C54: =IFERROR(SUM('Data Sheet'!C44,'Data Sheet'!C49,'Data Sheet'!C42),0) -> 35.36 | D54: =IFERROR(SUM('Data Sheet'!D44,'Data Sheet'!D49,'Data Sheet'!D42),0) -> 20.29 | E54: =IFERROR(SUM('Data Sheet'!E44,'Data Sheet'!E49,'Data Sheet'!E42),0) -> 58.26 | F54: =IFERROR(SUM('Data Sheet'!F44,'Data Sheet'!F49,'Data Sheet'!F42),0) -> 84.98 | G54: =IFERROR(SUM('Data Sheet'!G44,'Data Sheet'!G49,'Data Sheet'!G42),0) -> 98.5 | H54: =IFERROR(SUM('Data Sheet'!G44,'Data Sheet'!G49,'Data Sheet'!G42),0) -> 98.5
B55: Other Liabilities | C55: =IFERROR(SUM('Data Sheet'!C45,'Data Sheet'!C46,'Data Sheet'!C50,'Data Sheet'!C51),0) -> 427.56 | D55: =IFERROR(SUM('Data Sheet'!D45,'Data Sheet'!D46,'Data Sheet'!D50,'Data Sheet'!D51),0) -> 471.41 | E55: =IFERROR(SUM('Data Sheet'!E45,'Data Sheet'!E46,'Data Sheet'!E50,'Data Sheet'!E51),0) -> 612.99 | F55: =IFERROR(SUM('Data Sheet'!F45,'Data Sheet'!F46,'Data Sheet'!F50,'Data Sheet'!F51),0) -> 781.76 | G55: =IFERROR(SUM('Data Sheet'!G45,'Data Sheet'!G46,'Data Sheet'!G50,'Data Sheet'!G51),0) -> 780.72 | H55: =IFERROR(SUM('Data Sheet'!G45,'Data Sheet'!G46,'Data Sheet'!G50,'Data Sheet'!G51),0) -> 780.72
B56: Total Liabilities | C56: =IFERROR('Data Sheet'!C53,0) -> 2480.32 | D56: =IFERROR('Data Sheet'!D53,0) -> 2804.76 | E56: =IFERROR('Data Sheet'!E53,0) -> 3554.09 | F56: =IFERROR('Data Sheet'!F53,0) -> 4383.68 | G56: =IFERROR('Data Sheet'!G53,0) -> 5050.38 | H56: =IFERROR('Data Sheet'!G53,0) -> 5050.38
B58: Fixed Assets Net Block | C58: =IFERROR(SUM('Data Sheet'!C56,'Data Sheet'!C57),0) -> 47.38 | D58: =IFERROR(SUM('Data Sheet'!D56,'Data Sheet'!D57),0) -> 151.72 | E58: =IFERROR(SUM('Data Sheet'!E56,'Data Sheet'!E57),0) -> 202.69 | F58: =IFERROR(SUM('Data Sheet'!F56,'Data Sheet'!F57),0) -> 313.79 | G58: =IFERROR(SUM('Data Sheet'!G56,'Data Sheet'!G57),0) -> 634.94 | H58: =IFERROR(SUM('Data Sheet'!G56,'Data Sheet'!G57),0) -> 634.94
B59: Capital Work in Progress | C59: =IFERROR('Data Sheet'!C58,0) -> 1.92 | D59: =IFERROR('Data Sheet'!D58,0) -> 4.87 | E59: =IFERROR('Data Sheet'!E58,0) -> 3.17 | F59: =IFERROR('Data Sheet'!F58,0) -> 284.14 | G59: =IFERROR('Data Sheet'!G58,0) -> 6.39 | H59: =IFERROR('Data Sheet'!G58,0) -> 6.39
...

Sheet Assumptions
B2: Assumptions: ICICI AMC Ltd.
B3: Margins | C3: 44651 | D3: 45016 | E3: 45382 | F3: 45747 | G3: 46112
B4: EBITDA | C4: =IFERROR('Historical FS'!C19,0) -> 0.75119872 | D4: =IFERROR('Historical FS'!D19,0) -> 0.72491585 | E4: =IFERROR('Historical FS'!E19,0) -> 0.73461177 | F4: =IFERROR('Historical FS'!F19,0) -> 0.72651401 | G4: =IFERROR('Historical FS'!G19,0) -> 0.74177527
B5: EBIT | C5: =IFERROR('Historical FS'!C25,0) -> 0.73187501 | D5: =IFERROR('Historical FS'!D25,0) -> 0.70711756 | E5: =IFERROR('Historical FS'!E25,0) -> 0.71712748 | F5: =IFERROR('Historical FS'!F25,0) -> 0.70935823 | G5: =IFERROR('Historical FS'!G25,0) -> 0.72347228
B6: EBT | C6: =IFERROR('Historical FS'!C33,0) -> 0.73233817 | D6: =IFERROR('Historical FS'!D33,0) -> 0.70741008 | E6: =IFERROR('Historical FS'!E33,0) -> 0.7179204 | F6: =IFERROR('Historical FS'!F33,0) -> 0.70982836 | G6: =IFERROR('Historical FS'!G33,0) -> 0.7644619
B7: Net Profit | C7: =IFERROR('Historical FS'!C39,0) -> 0.55203165 | D7: =IFERROR('Historical FS'!D39,0) -> 0.53422384 | E7: =IFERROR('Historical FS'!E39,0) -> 0.5453977 | F7: =IFERROR('Historical FS'!F39,0) -> 0.53254657 | G7: =IFERROR('Historical FS'!G39,0) -> 0.57215467
B9: Historical Growth | C9: 44651 | D9: 45016 | E9: 45382 | F9: 45747 | G9: 46112
B10: Average Growth | C10: =IFERROR(AVERAGE('Historical FS'!D7:G7),0) -> 0.22107208
B11: CAGR % | C11: =IFERROR(('Historical FS'!G6/'Historical FS'!C6)^(1/4)-1,0) -> 0.21628691 | D11: =IFERROR(('Historical FS'!G6/'Historical FS'!C6)^(1/4)-1,0) -> 0.21628691 | E11: (RRI Formula)
B13: Tax Rate | C13: 44651 | D13: 45016 | E13: 45382 | F13: 45747 | G13: 46112
B14: Effective Tax Rate | C14: =IFERROR('Historical FS'!C36,0) -> 0.24620664 | D14: =IFERROR('Historical FS'!D36,0) -> 0.24481733 | E14: =IFERROR('Historical FS'!E36,0) -> 0.24030896 | F14: =IFERROR('Historical FS'!F36,0) -> 0.24975305 | G14: =IFERROR('Historical FS'!G36,0) -> 0.25155894
B15: Marginal Tax Rate | C15: =AVERAGE(C14:G14) -> 0.24652898 | D15: =C15 -> 0.24652898 | E15: =D15 -> 0.24652898 | F15: =E15 -> 0.24652898 | G15: =F15 -> 0.24652898
B17: Return On Capital Employed | C17: 44651 | D17: 45016 | E17: 45382 | F17: 45747 | G17: 46112
B18: EBIT*(1-T) | C18: =IFERROR('Historical FS'!C24*(1-Assumptions!$C$15),0) -> 1452.549 | D18: =IFERROR('Historical FS'!D24*(1-Assumptions!$C$15),0) -> 1511.719 | E18: =IFERROR('Historical FS'!E24*(1-Assumptions!$C$15),0) -> 2030.7023 | F18: =IFERROR('Historical FS'!F24*(1-Assumptions!$C$15),0) -> 2660.2877 | G18: =IFERROR('Historical FS'!G24*(1-Assumptions!$C$15),0) -> 3142.3885
B19: Book Equity | C19: =IFERROR('Historical FS'!C52+'Historical FS'!C53,0) -> 2017.41 | D19: =IFERROR('Historical FS'!D52+'Historical FS'!D53,0) -> 2313.06 | E19: =IFERROR('Historical FS'!E52+'Historical FS'!E53,0) -> 2882.84 | F19: =IFERROR('Historical FS'!F52+'Historical FS'!F53,0) -> 3516.94 | G19: =IFERROR('Historical FS'!G52+'Historical FS'!G53,0) -> 4171.17
B20: Book Debt | C20: =IFERROR('Historical FS'!C54,0) -> 35.36 | D20: =IFERROR('Historical FS'!D54,0) -> 20.29 | E20: =IFERROR('Historical FS'!E54,0) -> 58.26 | F20: =IFERROR('Historical FS'!F54,0) -> 84.98 | G20: =IFERROR('Historical FS'!G54,0) -> 98.5
B21: Cash and Equivalents | C21: =IFERROR('Historical FS'!C66,0) -> 25.19 | D21: =IFERROR('Historical FS'!D66,0) -> 31.45 | E21: =IFERROR('Historical FS'!E66,0) -> 33.81 | F21: =IFERROR('Historical FS'!F66,0) -> 28.01 | G21: =IFERROR('Historical FS'!G66,0) -> 147.49
B22: Capital Employed | C22: =C19+C20-C21 -> 2027.58 | D22: =D19+D20-D21 -> 2301.9 | E22: =E19+E20-E21 -> 2907.29 | F22: =F19+F20-F21 -> 3573.91 | G22: =G19+G20-G21 -> 4122.18
B24: Pre/Post Tax Return on Capital Employed | C24: 44651 | D24: 45016 | E24: 45382 | F24: 45747 | G24: 46112
B25: Pre Tax Return on Capital | C25: =IFERROR('Historical FS'!C24/Assumptions!C22,0) -> 0.95079356 | D25: =IFERROR('Historical FS'!D24/Assumptions!D22,0) -> 0.87160172 | E25: =IFERROR('Historical FS'!E24/Assumptions!E22,0) -> 0.92702482 | F25: =IFERROR('Historical FS'!F24/Assumptions!F22,0) -> 0.9879124 | G25: =IFERROR('Historical FS'!G24/Assumptions!G22,0) -> 1.0117341
B26: Post Tax Return on Capital | C26: =IFERROR(C18/C22,0) -> 0.71639539 | D26: =IFERROR(D18/D22,0) -> 0.65672663 | E26: =IFERROR(E18/E22,0) -> 0.69848634 | F26: =IFERROR(F18/F22,0) -> 0.74436336 | G26: =IFERROR(G18/G22,0) -> 0.76231231
B28: Growth in EBIT | C28: =IFERROR(('Historical FS'!G24/'Historical FS'!C24)^(1/4)-1,0) -> 0.2127807

Sheet Ratio Analysis
B2: Ratio Analysis - ICICI AMC LTD
B3: Years | D3: 44621 | E3: 44986 | F3: 45352 | G3: 45717 | H3: 46082 | I3: Trends | J3: Mean
B5: Sales Growth | D5: =IFERROR('Historical FS'!D7,0) -> 0.077173348 | E5: =IFERROR('Historical FS'!E7,0) -> 0.32455636 | F5: =IFERROR('Historical FS'!F7,0) -> 0.32438142 | G5: =IFERROR('Historical FS'!G7,0) -> 0.15817718 | H5: =IFERROR('Historical FS'!H7,0) -> 0 | J5: =IFERROR(AVERAGE(D5:H5),0) -> 0.17685766 | K5: =IFERROR(MEDIAN(D5:H5),0) -> 0.15817718
B6: EBITDA Growth | D6: =IFERROR('Historical FS'!D18/'Historical FS'!C18-1,0) -> 0.039485321 | E6: =IFERROR('Historical FS'!E18/'Historical FS'!D18-1,0) -> 0.34227261 | F6: =IFERROR('Historical FS'!F18/'Historical FS'!E18-1,0) -> 0.30978253 | G6: =IFERROR('Historical FS'!G18/'Historical FS'!F18-1,0) -> 0.18250601 | H6: =IFERROR('Historical FS'!H18/'Historical FS'!G18-1,0) -> 0 | J6: =IFERROR(AVERAGE(D6:H6),0) -> 0.1748093 | K6: =IFERROR(MEDIAN(D6:H6),0) -> 0.18250601
B7: EBIT Growth | D7: =IFERROR('Historical FS'!D24/'Historical FS'!C24-1,0) -> 0.040735342 | E7: =IFERROR('Historical FS'!E24/'Historical FS'!D24-1,0) -> 0.34330672 | F7: =IFERROR('Historical FS'!F24/'Historical FS'!E24-1,0) -> 0.31003328 | G7: =IFERROR('Historical FS'!G24/'Historical FS'!F24-1,0) -> 0.18122134 | H7: =IFERROR('Historical FS'!H24/'Historical FS'!G24-1,0) -> 0 | J7: =IFERROR(AVERAGE(D7:H7),0) -> 0.17505934 | K7: =IFERROR(MEDIAN(D7:H7),0) -> 0.18122134
B8: Net Profit Growth | D8: =IFERROR('Historical FS'!D38/'Historical FS'!C38-1,0) -> 0.042425159 | E8: =IFERROR('Historical FS'!E38/'Historical FS'!D38-1,0) -> 0.35226088 | F8: =IFERROR('Historical FS'!F38/'Historical FS'!E38-1,0) -> 0.2931752 | G8: =IFERROR('Historical FS'!G38/'Historical FS'!F38-1,0) -> 0.24431651 | H8: =IFERROR('Historical FS'!H38/'Historical FS'!G38-1,0) -> 0 | J8: =IFERROR(AVERAGE(D8:H8),0) -> 0.18643555 | K8: =IFERROR(MEDIAN(D8:H8),0) -> 0.24431651
B9: Dividend Growth | D9: =IFERROR('Historical FS'!D46/'Historical FS'!C46-1,0) -> 0.0131991 | E9: =IFERROR('Historical FS'!E46/'Historical FS'!D46-1,0) -> 0.21128747 | F9: =IFERROR('Historical FS'!F46/'Historical FS'!E46-1,0) -> 0.36200828 | G9: =IFERROR('Historical FS'!G46/'Historical FS'!F46-1,0) -> -1 | H9: =IFERROR('Historical FS'!H46/'Historical FS'!G46-1,0) -> 0 | J9: =IFERROR(AVERAGE(D9:H9),0) -> -0.08270103 | K9: =IFERROR(MEDIAN(D9:H9),0) -> 0.0131991
B11: Gross Margin | C11: =IFERROR('Historical FS'!C13,0) -> 0.99473438 | D11: =IFERROR('Historical FS'!D13,0) -> 0.9947451 | E11: =IFERROR('Historical FS'!E13,0) -> 0.99569212 | F11: =IFERROR('Historical FS'!F13,0) -> 0.9962731 | G11: =IFERROR('Historical FS'!G13,0) -> 0.99691741 | H11: =IFERROR('Historical FS'!H13,0) -> 0.99691741 | J11: =IFERROR(AVERAGE(C11:H11),0) -> 0.99587992 | K11: =IFERROR(MEDIAN(C11:H11),0) -> 0.99598261
B12: EBITDA Margin | C12: =IFERROR('Historical FS'!C19,0) -> 0.75119872 | D12: =IFERROR('Historical FS'!D19,0) -> 0.72491585 | E12: =IFERROR('Historical FS'!E19,0) -> 0.73461177 | F12: =IFERROR('Historical FS'!F19,0) -> 0.72651401 | G12: =IFERROR('Historical FS'!G19,0) -> 0.74177527 | H12: =IFERROR('Historical FS'!H19,0) -> 0.74177527 | J12: =IFERROR(AVERAGE(C12:H12),0) -> 0.73679848 | K12: =IFERROR(MEDIAN(C12:H12),0) -> 0.73819352
B13: EBIT Margin | C13: =IFERROR('Historical FS'!C25,0) -> 0.73187501 | D13: =IFERROR('Historical FS'!D25,0) -> 0.70711756 | E13: =IFERROR('Historical FS'!E25,0) -> 0.71712748 | F13: =IFERROR('Historical FS'!F25,0) -> 0.70935823 | G13: =IFERROR('Historical FS'!G25,0) -> 0.72347228 | H13: =IFERROR('Historical FS'!H25,0) -> 0.72347228 | J13: =IFERROR(AVERAGE(C13:H13),0) -> 0.71873714 | K13: =IFERROR(MEDIAN(C13:H13),0) -> 0.72029988
B14: EBT Margin | C14: =IFERROR('Historical FS'!C33,0) -> 0.73233817 | D14: =IFERROR('Historical FS'!D33,0) -> 0.70741008 | E14: =IFERROR('Historical FS'!E33,0) -> 0.7179204 | F14: =IFERROR('Historical FS'!F33,0) -> 0.70982836 | G14: =IFERROR('Historical FS'!G33,0) -> 0.7644619 | H14: =IFERROR('Historical FS'!H33,0) -> 0.7644619 | J14: =IFERROR(AVERAGE(C14:H14),0) -> 0.7327368 | K14: =IFERROR(MEDIAN(C14:H14),0) -> 0.72512929
B15: Net Profit Margin | C15: =IFERROR('Historical FS'!C39,0) -> 0.55203165 | D15: =IFERROR('Historical FS'!D39,0) -> 0.53422384 | E15: =IFERROR('Historical FS'!E39,0) -> 0.5453977 | F15: =IFERROR('Historical FS'!F39,0) -> 0.53254657 | G15: =IFERROR('Historical FS'!G39,0) -> 0.57215467 | H15: =IFERROR('Historical FS'!H39,0) -> 0.57215467 | J15: =IFERROR(AVERAGE(C15:H15),0) -> 0.55141818 | K15: =IFERROR(MEDIAN(C15:H15),0) -> 0.54871467
B17: Sales Expenses%Sales | C17: =IFERROR('Historical FS'!C16,0) -> 0.24353567 | D17: =IFERROR('Historical FS'!D16,0) -> 0.26982924 | E17: =IFERROR('Historical FS'!E16,0) -> 0.26108035 | F17: =IFERROR('Historical FS'!F16,0) -> 0.26975909 | G17: =IFERROR('Historical FS'!G16,0) -> 0.25514213 | H17: =IFERROR('Historical FS'!H16,0) -> 0.25514213 | J17: =IFERROR(AVERAGE(C17:H17),0) -> 0.25908144 | K17: =IFERROR(MEDIAN(C17:H17),0) -> 0.25811124
B18: Depriciation%Sales | C18: =IFERROR('Historical FS'!C22,0) -> 0.019323708 | D18: =IFERROR('Historical FS'!D22,0) -> 0.017798298 | E18: =IFERROR('Historical FS'!E22,0) -> 0.017484294 | F18: =IFERROR('Historical FS'!F22,0) -> 0.017155784 | G18: =IFERROR('Historical FS'!G22,0) -> 0.018302996 | H18: =IFERROR('Historical FS'!H22,0) -> 0.018302996 | J18: =IFERROR(AVERAGE(C18:H18),0) -> 0.018061346 | K18: =IFERROR(MEDIAN(C18:H18),0) -> 0.018050647
B19: Operating Income%Sales | C19: =C13 -> 0.73187501 | D19: =D13 -> 0.70711756 | E19: =E13 -> 0.71712748 | F19: =F13 -> 0.70935823 | G19: =G13 -> 0.72347228 | H19: =H13 -> 0.72347228 | J19: =IFERROR(AVERAGE(C19:H19),0) -> 0.71873714 | K19: =IFERROR(MEDIAN(C19:H19),0) -> 0.72029988
B21: Return on Capital Employed | C21: =IFERROR(Assumptions!C26,0) -> 0.71639539 | D21: =IFERROR(Assumptions!D26,0) -> 0.65672663 | E21: =IFERROR(Assumptions!E26,0) -> 0.69848634 | F21: =IFERROR(Assumptions!F26,0) -> 0.74436336 | G21: =IFERROR(Assumptions!G26,0) -> 0.76231231 | H21: =IFERROR(Assumptions!G26,0) -> 0.76231231 | J21: =IFERROR(AVERAGE(C21:H21),0) -> 0.72343272 | K21: =IFERROR(MEDIAN(C21:H21),0) -> 0.73037937
B22: Retained Earning % | C22: =IFERROR('Historical FS'!C49,0) -> 0 | D22: =IFERROR('Historical FS'!D49,0) -> 0 | E22: =IFERROR('Historical FS'!E49,0) -> 0 | F22: =IFERROR('Historical FS'!F49,0) -> 0 | G22: =IFERROR('Historical FS'!G49,0) -> 1 | H22: =IFERROR('Historical FS'!H49,0) -> 1 | J22: =IFERROR(AVERAGE(C22:H22),0) -> 0.33333333 | K22: =IFERROR(MEDIAN(C22:H22),0) -> 0
B23: Return on Equity % | C23: =IFERROR('Historical FS'!C38/('Historical FS'!C52+'Historical FS'!C53),0) -> 0.72077069 | D23: =IFERROR('Historical FS'!D38/(('Historical FS'!D52+'Historical FS'!D53+'Historical FS'!C52+'Historical FS'!C53)/2),0) -> 0.70005334 | E23: =IFERROR('Historical FS'!E38/(('Historical FS'!E52+'Historical FS'!E53+'Historical FS'!D52+'Historical FS'!D53)/2),0) -> 0.78897977 | F23: =IFERROR('Historical FS'!F38/(('Historical FS'!F52+'Historical FS'!F53+'Historical FS'!E52+'Historical FS'!E53)/2),0) -> 0.82835972 | G23: =IFERROR('Historical FS'!G38/(('Historical FS'!G52+'Historical FS'!G53+'Historical FS'!F52+'Historical FS'!F53)/2),0) -> 0.85801582 | H23: =IFERROR('Historical FS'!H38/(('Historical FS'!H52+'Historical FS'!H53+'Historical FS'!G52+'Historical FS'!G53)/2),0) -> 0.79072778 | J23: =IFERROR(AVERAGE(C23:H23),0) -> 0.78115119 | K23: =IFERROR(MEDIAN(C23:H23),0) -> 0.78985378
B24: Self Sustained Growth Rate | C24: =IFERROR(C22*C23,0) -> 0 | D24: =IFERROR(D22*D23,0) -> 0 | E24: =IFERROR(E22*E23,0) -> 0 | F24: =IFERROR(F22*F23,0) -> 0 | G24: =IFERROR(G22*G23,0) -> 0.85801582 | H24: =IFERROR(H22*H23,0) -> 0.79072778 | J24: =IFERROR(AVERAGE(C24:H24),0) -> 0.2747906 | K24: =IFERROR(MEDIAN(C24:H24),0) -> 0
B25: Interest Coverage Ratio | C25: 0 | D25: 0 | E25: 0 | F25: 0 | G25: 0 | H25: 0 | J25: =IFERROR(AVERAGE(C25:H25),0) -> 0 | K25: =IFERROR(MEDIAN(C25:H25),0) -> 0

Sheet Fixed Assets Schedule
B2: Fixed Asset Schedule
B3: Particulars | C3: 44621 | D3: 44986 | E3: 45352 | F3: 45717 | G3: 46082
B4: Beginning Balance | D4: =IFERROR(C8,0) -> 47.38 | E4: =IFERROR(D8,0) -> 151.72 | F4: =IFERROR(E8,0) -> 202.69 | G4: =IFERROR(F8,0) -> 313.79
B5: Add: Net Purchases | D5: =IFERROR(D6-D4,0) -> 154.84 | E5: =IFERROR(E6-E4,0) -> 116.68 | F5: =IFERROR(F6-F4,0) -> 196.49 | G5: =IFERROR(G6-G4,0) -> 426.66
B6: Total Fixed Assets | C6: =IFERROR(SUM(C7+C8),0) -> 98.28 | D6: =IFERROR(SUM(D7+D8),0) -> 202.22 | E6: =IFERROR(SUM(E7+E8),0) -> 268.4 | F6: =IFERROR(SUM(F7+F8),0) -> 399.18 | G6: =IFERROR(SUM(G7+G8),0) -> 740.45
B7: Less: Depriciation | C7: =IFERROR('Historical FS'!C21,0) -> 50.9 | D7: =IFERROR('Historical FS'!D21,0) -> 50.5 | E7: =IFERROR('Historical FS'!E21,0) -> 65.71 | F7: =IFERROR('Historical FS'!F21,0) -> 85.39 | G7: =IFERROR('Historical FS'!G21,0) -> 105.51
B8: Closing Balance (Fixed Assets) | C8: =IFERROR('Historical FS'!C58,0) -> 47.38 | D8: =IFERROR('Historical FS'!D58,0) -> 151.72 | E8: =IFERROR('Historical FS'!E58,0) -> 202.69 | F8: =IFERROR('Historical FS'!F58,0) -> 313.79 | G8: =IFERROR('Historical FS'!G58,0) -> 634.94
B10: Net Capital Expenditure | D10: =IFERROR(D5-D7,0) -> 104.34 | E10: =IFERROR(E5-E7,0) -> 50.97 | F10: =IFERROR(F5-F7,0) -> 111.1 | G10: =IFERROR(G5-G7,0) -> 321.15
B11: Net Capital Expenditure / Sales % | D11: =IFERROR(D10/'Historical FS'!D6,0) -> 0.03677375 | E11: =IFERROR(E10/'Historical FS'!E6,0) -> 0.013562235 | F11: =IFERROR(F10/'Historical FS'!F6,0) -> 0.022321204 | G11: =IFERROR(G10/'Historical FS'!G6,0) -> 0.055710427
B13: Median Capex / sales % | D13: =IFERROR(MEDIAN(D11:G11),0) -> 0.029547477
B14: Average capital expenditure / sales % | D14: =IFERROR(AVERAGE(D11:G11),0) -> 0.032091904

Sheet Changes In Working Capital
B2: Change in Working Capital
B3: Particulars | C3: 44621 | D3: 44986 | E3: 45352 | F3: 45717 | G3: 46082
B4: Inventories | C4: 0 | D4: 0 | E4: 0 | F4: 0 | G4: 0
B5: ICICI AMC eivables | C5: =IFERROR('Historical FS'!C64,0) -> 100.36 | D5: =IFERROR('Historical FS'!D64,0) -> 112.43 | E5: =IFERROR('Historical FS'!E64,0) -> 195.97 | F5: =IFERROR('Historical FS'!F64,0) -> 237.49 | G5: =IFERROR('Historical FS'!G64,0) -> 186.82
B6: Payables | C6: =IFERROR('Data Sheet'!C50,0) -> 75.41 | D6: =IFERROR('Data Sheet'!D50,0) -> 84.62 | E6: =IFERROR('Data Sheet'!E50,0) -> 121.57 | F6: =IFERROR('Data Sheet'!F50,0) -> 175.35 | G6: =IFERROR('Data Sheet'!G50,0) -> 198.2
B7: Non Cash WC | C7: =IFERROR(C4+C5-C6,0) -> 24.95 | D7: =IFERROR(D4+D5-D6,0) -> 27.81 | E7: =IFERROR(E4+E5-E6,0) -> 74.4 | F7: =IFERROR(F4+F5-F6,0) -> 62.14 | G7: =IFERROR(G4+G5-G6,0) -> -11.38
B9: Change in working capital | D9: =IFERROR(D7-C7,0) -> 2.86 | E9: =IFERROR(E7-D7,0) -> 46.59 | F9: =IFERROR(F7-E7,0) -> -12.26 | G9: =IFERROR(G7-F7,0) -> -73.52
B10: Change in Working Capital / % of sales | D10: =IFERROR(D9/'Historical FS'!D6,0) -> 0.0010079828 | E10: =IFERROR(E9/'Historical FS'!E6,0) -> 0.012396793 | F10: =IFERROR(F9/'Historical FS'!F6,0) -> -0.002463168 | G10: =IFERROR(G9/'Historical FS'!G6,0) -> -0.012753637
B12: Median Change in working capital / % of sales | D12: =IFERROR(MEDIAN(D10:G10),0) -> -0.0007275926
B13: Average Change in working capital / % of sales | D13: =IFERROR(AVERAGE(D10:G10),0) -> -0.00045300732

Sheet FCFF
B2: FCFF
B3: Particulars | C3: 44621 | D3: 44986 | E3: 45352 | F3: 45717 | G3: 46082
B4: EBIT | C4: =IFERROR('Historical FS'!C24,0) -> 1927.81 | D4: =IFERROR('Historical FS'!D24,0) -> 2006.34 | E4: =IFERROR('Historical FS'!E24,0) -> 2695.13 | F4: =IFERROR('Historical FS'!F24,0) -> 3530.71 | G4: =IFERROR('Historical FS'!G24,0) -> 4170.55
B5: Less: Tax on EBIT | C5: =IFERROR(25%*C4,0) -> 481.9525 | D5: =IFERROR(25%*D4,0) -> 501.585 | E5: =IFERROR(25%*E4,0) -> 673.7825 | F5: =IFERROR(25%*F4,0) -> 882.6775 | G5: =IFERROR(25%*G4,0) -> 1042.6375
B6: EBIT*(1-tax) | C6: =IFERROR(C4-C5,0) -> 1445.8575 | D6: =IFERROR(D4-D5,0) -> 1504.755 | E6: =IFERROR(E4-E5,0) -> 2021.3475 | F6: =IFERROR(F4-F5,0) -> 2648.0325 | G6: =IFERROR(G4-G5,0) -> 3127.9125
B7: Less: Net capital expenditure | D7: =IFERROR('Fixed Assets Schedule'!D10,0) -> 104.34 | E7: =IFERROR('Fixed Assets Schedule'!E10,0) -> 50.97 | F7: =IFERROR('Fixed Assets Schedule'!F10,0) -> 111.1 | G7: =IFERROR('Fixed Assets Schedule'!G10,0) -> 321.15
B8: Less: Change in WC | D8: =IFERROR('Changes In Working Capital'!D9,0) -> 2.86 | E8: =IFERROR('Changes In Working Capital'!E9,0) -> 46.59 | F8: =IFERROR('Changes In Working Capital'!F9,0) -> -12.26 | G8: =IFERROR('Changes In Working Capital'!G9,0) -> -73.52
B9: Reinvestment | D9: =IFERROR(SUM(D7+D8),0) -> 107.2 | E9: =IFERROR(SUM(E7+E8),0) -> 97.56 | F9: =IFERROR(SUM(F7+F8),0) -> 98.84 | G9: =IFERROR(SUM(G7+G8),0) -> 247.63
B10: Free Cah Flow to Firm | D10: =IFERROR(D6-D9,0) -> 1397.555 | E10: =IFERROR(E6-E9,0) -> 1923.7875 | F10: =IFERROR(F6-F9,0) -> 2549.1925 | G10: =IFERROR(G6-G9,0) -> 2880.2825
B12: Reinvestment Rate % | D12: =IFERROR(D9/D6,0) -> 0.071240833 | E12: =IFERROR(E9/E6,0) -> 0.048264833 | F12: =IFERROR(F9/F6,0) -> 0.037325826 | G12: =IFERROR(G9/G6,0) -> 0.079167816
B13: Medium Reinvestment Rate | D13: =IFERROR(MEDIAN(D12:G12),0) -> 0.059752833
B14: Average Reinvestment Rate | D14: =IFERROR(AVERAGE(D12:G12),0) -> 0.058999827

Sheet Beta Calculation
D2: Beta Calculation for ICICI AMC Limited
B4: ICICI AMC LTD | G4: Nifty 50 | K4: BETA-
B5: Date | C5: Close | D5: Return | G5: Date | H5: Close | I5: Return
B6: 46010 | C6: 2586.7 | G6: 46010 | H6: 25966.4 | L6: =IFERROR(SLOPE(D7:D72,I7:I72),0) -> 1.5052514
B7: 46013 | C7: 2610.1001 | D7: =C7/C6-1 -> 0.009046332 | G7: 46013 | H7: 26172.4 | I7: =H7/H6-1 -> 0.0079333291 | L7: =IFERROR(COVAR(D7:D72,I7:I72)/VAR(I7:I72),0) -> 1.4824446
B8: 46014 | C8: 2609.3 | D8: =C8/C7-1 -> -0.00030652036 | G8: 46014 | H8: 26177.15 | I8: =H8/H7-1 -> 0.00018148889 | L8: =IFERROR(L6,0) -> 1.5052514
B9: 46015 | C9: 2639.3501 | D9: =C9/C8-1 -> 0.011516517 | G9: 46015 | H9: 26142.1 | I9: =H9/H8-1 -> -0.0013389838
B10: 46017 | C10: 2629.8999 | D10: =C10/C9-1 -> -0.0035805009 | G10: 46017 | H10: 26042.301 | I10: =H10/H9-1 -> -0.0038175521
B11: 46020 | C11: 2658.5 | D11: =C11/C10-1 -> 0.010874976 | G11: 46020 | H11: 25942.1 | I11: =H11/H10-1 -> -0.0038476313
B12: 46021 | C12: 2640.7 | D12: =C12/C11-1 -> -0.0066955234 | G12: 46021 | H12: 25938.85 | I12: =H12/H11-1 -> -0.00012527899
B13: 46022 | C13: 2660.8999 | D13: =C13/C12-1 -> 0.0076494685 | G13: 46022 | H13: 26129.6 | I13: =H13/H12-1 -> 0.0073538342
B14: 46023 | C14: 2625.45 | D14: =C14/C13-1 -> -0.013322542 | G14: 46023 | H14: 26146.551 | I14: =H14/H13-1 -> 0.00064873447
B15: 46024 | C15: 2665.55 | D15: =C15/C14-1 -> 0.01527361 | G15: 46024 | H15: 26328.551 | I15: =H15/H14-1 -> 0.0069607652
B16: 46027 | C16: 2677.95 | D16: =C16/C15-1 -> 0.0046519113 | G16: 46027 | H16: 26250.301 | I16: =H16/H15-1 -> -0.0029720588
B17: 46028 | C17: 2694.5 | D17: =C17/C16-1 -> 0.0061801188 | G17: 46028 | H17: 26178.699 | I17: =H17/H16-1 -> -0.0027276473
B18: 46029 | C18: 2695.3 | D18: =C18/C17-1 -> 0.00029691922 | G18: 46029 | H18: 26140.75 | I18: =H18/H17-1 -> -0.001449622
B19: 46030 | C19: 2717.55 | D19: =C19/C18-1 -> 0.0082551106 | G19: 46030 | H19: 25876.85 | I19: =H19/H18-1 -> -0.010095364
B20: 46031 | C20: 2664.6001 | D20: =C20/C19-1 -> -0.019484444 | G20: 46031 | H20: 25683.301 | I20: =H20/H19-1 -> -0.0074796133
... B72: 46111 | C72: 2803.3999 | D72: =C72/C71-1 -> -0.022848098 | G72: 46111 | H72: 22331.4 | I72: =H72/H71-1 -> -0.021393856

Sheet WACC
Q1: (Check Alpha Spread)
B2: ICICI AMC Ltd.
B4: Cost of capital
B5: As On Date: Jun 2025
B7: Cost of equity using CAPM:
B8: Risk-free rate | C8: 0.066
B9: India default spread | C9: 0.0145
B10: Beta | C10: =IFERROR('Beta Calculation'!L6,1.3) -> 1.5052514
B11: Market Return | C11: 0.12
B12: Equity risk premium | C12: =C11-C8 -> 0.054
B13: Cost of equity | C13: =C8+(C10*C12) -> 0.14728358 | E13: =(C8+C9)+C10*C12 -> 0.16178358
B16: Cost of debt:
B17: Risk-free rate | C17: =C8 -> 0.066
B18: Company credit rating
B19: Rating default spread | C19: 0.005
B20: Pre-tax cost of debt | C20: =C17+C19 -> 0.071
B22: Marginal tax rate % | C22: 0.25
B23: Post-tax cost of debt | C23: =IFERROR(C20*(1-C22),0) -> 0.05325
B26: Market value weights:
B27: Book value of Debt | C27: =IFERROR('Historical FS'!H54,0) -> 98.5
B28: Share price (as on above date) | C28: 3285
B29: No. of shares outstanding | C29: 49.42
B30: Market value of Equity | C30: =IFERROR(WACC!C28*WACC!C29,0) -> 162344.7
B33: D/E Ratio | C33: =IFERROR(C27/C30,0) -> 0.0006067337
B34: weight of debt, wa | C34: =IFERROR(C27/(C27+C30),0) -> 0.00060636579
B35: Weightof equity, we | C35: =IFERROR(C30/(C27+C30),0) -> 0.99939363
B37: Cost of Capital | C37: =IFERROR((C13*C35)+(C23*C34),0) -> 0.14722656 | E37: =(E13*C35)+(C23*C34) -> 0.16171777

Sheet Growth Scenarios
B2: ICICI AMC LTD. "Growth Scenarios"
Q3: take 23%
B4: Scenario 1: High Growth
B5: INR Cr. | C5: LTM | D5: Y1E | E5: Y2E | F5: Y3E | G5: Y4W | H5: Y5E | I5: Y6E | J5: Y7E | K5: Y8E | L5: Y9E | M5: Y10E
B6: Sales | C6: =IFERROR('Historical FS'!H6,0) -> 5764.63 | D6: =C6*(1+D7) -> 7635.5774 | E6: =D6*(1+E7) -> 9895.6666 | F6: =E6*(1+F7) -> 12542.092 | G6: =F6*(1+G7) -> 15538.033 | H6: =G6*(1+H7) -> 18805.822 | I6: =H6*(1+I7) -> 22223.729 | J6: =I6*(1+J7) -> 25628.081 | K6: =J6*(1+K7) -> 28821.946 | ... M6: =L6*(1+M7) -> 33723.002
B7: Sales Growth % | D7: =N7 -> 0.32455636 | E7: =D7-$P$9 -> 0.29599455 | F7: =E7-$P$9 -> 0.26743273 | G7: =F7-$P$9 -> 0.23887091 | H7: =G7-$P$9 -> 0.21030909 | I7: =H7-$P$9 -> 0.18174727 | J7: =I7-$P$9 -> 0.15318545 | K7: =J7-$P$9 -> 0.12462364 | L7: =K7-$P$9 -> 0.096061818 | M7: 0.0675 | N7: =MAX('Historical FS'!C7:H7) -> 0.32455636
B9: Scenario 2: Average Growth | N9: 0.0675 | O9: =N7-N9 -> 0.25705636 | P9: =O9/9 -> 0.028561818
B10: INR Cr. | C10: LTM | D10: Y1E | E10: Y2E | F10: Y3E | G10: Y4W | H10: Y5E | I10: Y6E | J10: Y7E | K10: Y8E | L10: Y9E | M10: Y10E
B11: Sales | C11: =C6 -> 5764.63 | D11: =C11*(1+D12) -> 7039.0287 | E11: =D11*(1+E12) -> 8475.0505 | F11: =E11*(1+F12) -> 10059.418 | G11: =F11*(1+G12) -> 11768.326 | H11: =G11*(1+H12) -> 13566.736 | I11: =H11*(1+I12) -> 15408.479 | J11: =I11*(1+J12) -> 17237.322 | K11: =J11*(1+K12) -> 18989.101 | ... M11: =L11*(1+M12) -> 21985.042
B12: Sales Growth % | D12: =Assumptions!C10 -> 0.22107208 | E12: =D12-O12 -> 0.20400851 | F12: =E12-O12 -> 0.18694495 | G12: =F12-O12 -> 0.16988139 | H12: =G12-O12 -> 0.15281782 | I12: =H12-O12 -> 0.13575426 | J12: =I12-O12 -> 0.11869069 | K12: =J12-O12 -> 0.10162713 | L12: =K12-O12 -> 0.084563564 | M12: 0.0675 | N12: =D12-M12 -> 0.15357208 | O12: =N12/9 -> 0.017063564
B14: Scenario 3: EBIT Growth
B15: INR Cr. | C15: LTM | D15: Y1E | E15: Y2E | F15: Y3E | G15: Y4W | H15: Y5E | I15: Y6E | J15: Y7E | K15: Y8E | L15: Y9E | M15: Y10E
B16: Sales | C16: =C11 -> 5764.63 | D16: =C16*(1+D17) -> 6991.232 | E16: =D16*(1+E17) -> 8365.9766 | F16: =E16*(1+F17) -> 9876.0028 | G16: =F16*(1+G17) -> 11499.161 | H16: =G16*(1+H17) -> 13203.469 | I16: =H16*(1+I17) -> 14947.241 | J16: =I16*(1+J17) -> 16680.028 | K16: =J16*(1+K17) -> 18344.438 | ... M16: =L16*(1+M17) -> 21220.629
B17: Sales Growth % | D17: =Assumptions!C28 -> 0.2127807 | E17: =D17-$O$17 -> 0.1966384 | F17: =E17-$O$17 -> 0.1804961 | G17: =F17-$O$17 -> 0.1643538 | H17: =G17-$O$17 -> 0.1482115 | I17: =H17-$O$17 -> 0.1320692 | J17: =I17-$O$17 -> 0.1159269 | K17: =J17-$O$17 -> 0.099784599 | L17: =K17-$O$17 -> 0.0836423 | M17: 0.0675 | N17: =D17-M17 -> 0.1452807 | O17: =N17/9 -> 0.0161423
B19: Live Scenario | C19: 3
B20: INR Cr. | C20: LTM | D20: Y1E | E20: Y2E | F20: Y3E | G20: Y4W | H20: Y5E | I20: Y6E | J20: Y7E | K20: Y8E | L20: Y9E | M20: Y10E
B21: Sales | C21: =C6 -> 5764.63 | D21: =C21*(1+D22) -> 6991.232 | E21: =D21*(1+E22) -> 8365.9766 | F21: =E21*(1+F22) -> 9876.0028 | G21: =F21*(1+G22) -> 11499.161 | H21: =G21*(1+H22) -> 13203.469 | I21: =H21*(1+I22) -> 14947.241 | J21: =I21*(1+J22) -> 16680.028 | K21: =J21*(1+K22) -> 18344.438 | ... M21: =L21*(1+M22) -> 21220.629
B22: Sales Growth % | D22: =CHOOSE($C$19,D7,D12,D17) -> 0.2127807 | E22: =CHOOSE($C$19,E7,E12,E17) -> 0.1966384 | F22: =CHOOSE($C$19,F7,F12,F17) -> 0.1804961 | G22: =CHOOSE($C$19,G7,G12,G17) -> 0.1643538 | H22: =CHOOSE($C$19,H7,H12,H17) -> 0.1482115 | I22: =CHOOSE($C$19,I7,I12,I17) -> 0.1320692 | J22: =CHOOSE($C$19,J7,J12,J17) -> 0.1159269 | K22: =CHOOSE($C$19,K7,K12,K17) -> 0.099784599 | ... M22: =CHOOSE($C$19,M7,M12,M17) -> 0.0675
B25: ── NBFC GROWTH FRAMEWORK (ROE × Retention) ──
B26: Sustainable Growth Rate = ROE × Retention Ratio
B28: Metric | C28: FY22 | D28: FY23 | E28: FY24 | F28: FY25 | G28: Average
B29: ROE (%) | C29: ='Ratio Analysis'!C23 -> 0.72077069 | D29: ='Ratio Analysis'!D23 -> 0.70005334 | E29: ='Ratio Analysis'!E23 -> 0.78897977 | F29: ='Ratio Analysis'!F23 -> 0.82835972 | G29: =AVERAGE('Ratio Analysis'!C23:F23) -> 0.75954088
B30: Retention Ratio (b = 1 - Payout) | C30: ='Ratio Analysis'!C22 -> 0 | D30: ='Ratio Analysis'!D22 -> 0 | E30: ='Ratio Analysis'!E22 -> 0 | F30: ='Ratio Analysis'!F22 -> 0 | G30: =AVERAGE('Ratio Analysis'!C22:F22) -> 0
B31: Sustainable Growth (ROE × b) | C31: =C29*C30 -> 0 | D31: =D29*D30 -> 0 | E31: =E29*E30 -> 0 | F31: =F29*F30 -> 0 | G31: =G29*G30 -> 0
B33: Loan Book / AUM Growth (primary driver for NBFC)
B34: Loan Book (Cr) | C34: ='Historical FS'!C56 -> 2480.32 | D34: ='Historical FS'!D56 -> 2804.76 | E34: ='Historical FS'!E56 -> 3554.09 | F34: ='Historical FS'!F56 -> 4383.68 | G34: =F34/C34 -> 1.7673849
B35: YoY Loan Book Growth | D35: =IFERROR(D34/C34-1,0) -> 0.1308057 | E35: =IFERROR(E34/D34-1,0) -> 0.26716368 | F35: =IFERROR(F34/E34-1,0) -> 0.2334184 | G35: =IFERROR(AVERAGE(D35:F35),0) -> 0.21046259

Sheet Valuation
B2: ICICI AMC LTD. – NBFC VALUATION MODEL
B5: SECTION A – KEY INPUTS & ASSUMPTIONS
B6: Item | C6: Source | D6: Value
B7: Cost of Equity (Ke) | C7: =WACC!C13 -> 0.14728358 | D7: % – CAPM
B8: Risk-Free Rate (Rf) | C8: =WACC!C8 -> 0.066 | D8: % – 10Y GOI bond
B9: Beta (5Y Monthly) | C9: ='Beta Calculation'!L6 -> 1.5052514 | D9: ICICI AMC vs Nifty 50
B10: Equity Risk Premium | C10: =WACC!C12 -> 0.054 | D10: Market Rtn - Rf
B11: Shares Outstanding (Cr) | C11: 49.43 | D11: Cr shares
B12: Book Value Per Share (BVPS) | C12: =IFERROR(('Historical FS'!G52+'Historical FS'!G53)/'Historical FS'!G41,0) -> 84.385393 | D12: Rs per share
B13: Latest EPS (FY25) | C13: =IFERROR('Historical FS'!G43,0) -> 29.37 | D13: Rs
B14: ROE (FY25) | C14: =IFERROR('Ratio Analysis'!G23,0) -> 0.85801582 | D14: %
B15: Retention Ratio (b) | C15: =IF(AND(C14>0,C13>0),1-('Historical FS'!F47/C13),'Historical FS'!G51/C13) -> -0.26448688 | D15: 1 - Payout
B16: Sustainable Growth (g=ROE×b) | C16: =IFERROR(C14*C15,0) -> -0.22693393 | D16: %
B17: Terminal Growth Rate | C17: 0.065 | D17: % – Long-run nominal GDP
B18: Current Share Price | C18: =WACC!C28 -> 3285 | D18: Rs – Market reference
B20: SECTION B – P/BOOK VALUATION
B21: Justified P/B = ROE / Cost of Equity
B22: ROE (LTM avg) | F22: =IFERROR(AVERAGE('Ratio Analysis'!D23:G23),0) -> 0.79385216
B23: Cost of Equity (Ke) | F23: =WACC!C13 -> 0.14728358
B24: Justified P/B Multiple | F24: =IFERROR(F22/F23,0) -> 5.3899571
B25: Book Value Per Share (Rs) | F25: =C12 -> 84.385393
B26: Intrinsic Value (P/B) – Rs/share | F26: =IFERROR(F24*F25,0) -> 454.83365
B27: Current Price (Rs) | F27: =C18 -> 3285
B28: Upside / (Downside) | F28: =IFERROR((F26-F27)/F27,0) -> -0.86154227
B30: SECTION C – RESIDUAL INCOME MODEL
B31: Intrinsic Value = BVPS + PV(Residual Income) where RI = EPS - (Ke × BVPS_prev)
B33: Item | D33: FY26E | E33: FY27E | F33: FY28E | G33: FY29E | H33: FY30E | I33: Terminal
B34: EPS Growth Assumption (g) | D34: =C16 -> -0.22693393
B35: EPS (Rs) | D35: ='Historical FS'!G39 -> 0.57215467 | E35: =D35*(1+$D$34) -> 0.44231337 | F35: =E35*(1+$D$34) -> 0.34193746 | G35: =F35*(1+$D$34) -> 0.26434025 | H35: =G35*(1+$D$34) -> 0.20435248 | I35: =H35*(1+$C$17) -> 0.21763539
B36: BVPS start of year (Rs) | D36: =C12 -> 84.385393 | E36: =D36+D35*D37 -> 84.385393 | F36: =E36+E35*E37 -> 84.385393 | G36: =F36+F35*F37 -> 84.385393 | H36: =G36+G35*G37 -> 84.385393
B37: Retention Ratio | D37: =IFERROR(AVERAGE('Ratio Analysis'!D22:F22),0) -> 0 | E37: =$D$37 -> 0 | F37: =$D$37 -> 0 | G37: =$D$37 -> 0 | H37: =$D$37 -> 0
B38: Equity Charge (Ke × BVPS) | D38: =WACC!$C$13*D36 -> 12.428583 | E38: =WACC!$C$13*E36 -> 12.428583 | F38: =WACC!$C$13*F36 -> 12.428583 | G38: =WACC!$C$13*G36 -> 12.428583 | H38: =WACC!$C$13*H36 -> 12.428583 | I38: =WACC!$C$13*I36 -> 0
B39: Residual Income (RI) | D39: =D35-D38 -> -11.856428 | E39: =E35-E38 -> -11.986269 | F39: =F35-F38 -> -12.086645 | G39: =G35-G38 -> -12.164242 | H39: =H35-H38 -> -12.22423
B40: PV Factor | D40: =1/(1+WACC!$C$13)^1 -> 0.87162409 | E40: =1/(1+WACC!$C$13)^2 -> 0.75972855 | F40: =1/(1+WACC!$C$13)^3 -> 0.6621977 | G40: =1/(1+WACC!$C$13)^4 -> 0.57718747 | H40: =1/(1+WACC!$C$13)^5 -> 0.5030905
B41: PV of RI | D41: =D39*D40 -> -10.334348 | E41: =E39*E40 -> -9.1063109 | F41: =F39*F40 -> -8.0037486 | G41: =G39*G40 -> -7.0210482 | H41: =H39*H40 -> -6.149894
B42: Terminal RI Value (PV) | I42: =IFERROR((I39/(WACC!C13-C17))*H40,0) -> 0
B44: Sum of PV(RI) Years 1-5 | F44: =SUM(D41:H41) -> -40.61535
B45: PV of Terminal RI | F45: =I42 -> 0
B46: Current BVPS | F46: =C12 -> 84.385393
B47: Intrinsic Value (RI Model) – Rs/share | F47: =F44+F45+F46 -> 43.770043
...

Sheet Relative Valuation
B2: Relative Valuation
B4: Figures in Crore
B5: Comparable Company Valuation
B7: Company Name | C7: Market Data | J7: Financials | O7: Valuation
C8: No. of shares | D8: Share Price | E8: Equity value | F8: Debt | G8: cash | H8: Enterprises value | J8: Revenue | K8: EBITDA | L8: Net Profit | M8: EPS | O8: EV/Revenue | P8: EV/EBITDA | Q8: P/E Ratio
B9: UTI | C9: 12.85 | D9: 940.9 | E9: =IFERROR(C9*D9,0) -> 12090.565 | F9: 140.93 | G9: 444.03 | H9: =IFERROR(E9+F9-G9,0) -> 11787.465 | J9: 1698.05 | K9: 773.71 | L9: 472.43 | M9: =IFERROR(L9/C9,0) -> 36.764981 | O9: =IFERROR(H9/J9,0) -> 6.9417656 | P9: =IFERROR(H9/K9,0) -> 15.234991 | Q9: =IFERROR(D9/M9,0) -> 25.592289
B10: Aditya AMC | C10: 28.92 | D10: 1099.3 | E10: =IFERROR(C10*D10,0) -> 31791.756 | F10: 63.73 | G10: 139.02 | H10: =IFERROR(E10+F10-G10,0) -> 31716.466 | J10: 1845.03 | K10: 1273.39 | L10: 975.07 | M10: =IFERROR(L10/C10,0) -> 33.716113 | O10: =IFERROR(H10/J10,0) -> 17.190217 | P10: =IFERROR(H10/K10,0) -> 24.907111 | Q10: =IFERROR(D10/M10,0) -> 32.604588
B11: Nippon | C11: 63.88 | D11: 1148.9 | E11: =IFERROR(C11*D11,0) -> 73391.732 | F11: 75.34 | G11: 302.12 | H11: =IFERROR(E11+F11-G11,0) -> 73164.952 | J11: 2708.74 | K11: 1978.96 | L11: 1529.38 | M11: =IFERROR(L11/C11,0) -> 23.941453 | O11: =IFERROR(H11/J11,0) -> 27.010696 | P11: =IFERROR(H11/K11,0) -> 36.971415 | Q11: =IFERROR(D11/M11,0) -> 47.987898
B12: ICICI | C12: 49.43 | D12: 3269.7 | E12: =IFERROR(C12*D12,0) -> 161621.27 | F12: 0 | G12: 147.49 | H12: =IFERROR(E12+F12-G12,0) -> 161473.78 | J12: 5999.14 | K12: 4424.61 | L12: 3298.26 | M12: =IFERROR(L12/C12,0) -> 66.725875 | O12: =IFERROR(H12/J12,0) -> 26.916155 | P12: =IFERROR(H12/K12,0) -> 36.494466 | Q12: =IFERROR(D12/M12,0) -> 49.00198
B13: HDFC | C13: 42.84 | D13: 2694.5 | E13: =IFERROR(C13*D13,0) -> 115432.38 | F13: 0 | G13: 24.17 | H13: =IFERROR(E13+F13-G13,0) -> 115408.21 | J13: 4611.41 | K13: 3723.12 | L13: 2859.36 | M13: =IFERROR(L13/C13,0) -> 66.745098 | O13: =IFERROR(H13/J13,0) -> 25.026664 | P13: =IFERROR(H13/K13,0) -> 30.997714 | Q13: =IFERROR(D13/M13,0) -> 40.370006
B15: Max | O15: =IFERROR(MAX(O9:O13),0) -> 27.010696 | P15: =IFERROR(MAX(P9:P13),0) -> 36.971415 | Q15: =IFERROR(MAX(Q9:Q13),0) -> 49.00198
B16: 75th Percentile | O16: =IFERROR(QUARTILE(O9:O13,3),0) -> 26.916155 | P16: =IFERROR(QUARTILE(P9:P13,3),0) -> 36.494466 | Q16: =IFERROR(QUARTILE(Q9:Q13,3),0) -> 47.987898
B17: Average | O17: =IFERROR(AVERAGE(O9:O13),0) -> 20.617099 | P17: =IFERROR(AVERAGE(P9:P13),0) -> 28.92114 | Q17: =IFERROR(AVERAGE(Q9:Q13),0) -> 39.111352
B18: median | O18: =IFERROR(MEDIAN(O9:O13),0) -> 25.026664 | P18: =IFERROR(MEDIAN(P9:P13),0) -> 30.997714 | Q18: =IFERROR(MEDIAN(Q9:Q13),0) -> 40.370006
B19: 25th Percentile | O19: =IFERROR(QUARTILE(O9:O13,1),0) -> 17.190217 | P19: =IFERROR(QUARTILE(P9:P13,1),0) -> 24.907111 | Q19: =IFERROR(QUARTILE(Q9:Q13,1),0) -> 32.604588
B20: Min. | O20: =IFERROR(MIN(O9:O13),0) -> 6.9417656 | P20: =IFERROR(MIN(P9:P13),0) -> 15.234991 | Q20: =IFERROR(MIN(Q9:Q13),0) -> 25.592289
B22: M&M Industry Comparable comps | O22: EV/Revenue | P22: EV/EBITDA | Q22: P/E Ratio
B23: Implied Enterprise Value | O23: =O18*J12 -> 150138.46 | P23: =P18*K12 -> 137152.8 | Q23: =SUM(Q25+Q24) -> 133003.29
B24: Net Debt | O24: =F12-G12 -> -147.49 | P24: =O24 -> -147.49 | Q24: =P24 -> -147.49
B25: Implied Market Value | O25: =O23-O24 -> 150285.95 | P25: =P23-P24 -> 137300.29 | Q25: =Q18*L12 -> 133150.78
B26: Share Outstanding | O26: =C12 -> 49.43 | P26: =O26 -> 49.43 | Q26: =P26 -> 49.43
B28: Implied Value per Share | O28: =O25/O26 -> 3040.3794 | P28: =P25/P26 -> 2777.6712 | Q28: =Q25/Q26 -> 2693.724
