Workbook

Sheet About 
J3: ABOUT
J4: Infosys Limited is one of India's largest information technology services and consulting companies. Founded in 1981 and headquartered in Bengaluru, the company provides a wide range of services including digital transformation, cloud computing, artificial intelligence, cybersecurity, software development, and business process management. Infosys serves clients across industries such as banking, financial services, healthcare, retail, manufacturing, and telecommunications in more than 50 countries. Known for its strong global delivery model, skilled workforce, and focus on innovation, Infosys is among the leading IT exporters from India and is a constituent of major stock market indices including the Nifty 50 and BSE Sensex.
B14: Subsidaries
B16: Bengaluru, Karnataka, 560100
B17: Singapore, 018989
B18: Atlanta, Georgia, USA, 30328
B19: Richardson, Texas, USA, 75082

Sheet Shareholders 
B3: Promoters - | C3: 0.1438
B4: Sudha Gopalakrishnan | C4: 2.54
B5: Rohan Murty | C5: 1.62
B6: Nandan M Nilekani | C6: 1.09
B7: Akshata Murty | C7: 1.04
B8: Asha Dinesh | C8: 1.03
B9: S Gopalakrishnan | C9: 0.85
B10: Sudha N Murty | C10: 0.92
B11: Rohini Nilekani | C11: 0.92
B12: Dinesh Krishnaswamy | C12: 0.87
B13: Shreyas Shibulal | C13: 0.48
B14: Narayana Murthy | C14: 0.4
... B23: Nikita Shibulal Manchanda | C23: 0.16
B24: Bhairavi Madhusudhan
B25: Bhairavi Madhusudhan Shibulal | C25: 0.13
B26: Shruti Shibulal | C26: 0.23
B27: S D Shibulal | C27: 0.14
B28: Meghana
B29: Tanush Nilekani Chandra | C29: 0.09
B30: Ekagrah Rohan Murty | C30: 0.04
B31: Shray Chandra | C31: 0.02
B32: FIIs - | C32: 0.2845
B33: Oppenheimer Developing Markets Fund
B34: Government Of Singapore
B35: Abu Dhabi Investment Authority
B36: Vanguard Emerging Markets Stock Index Fund, A Seri...
B37: Vanguard Total International Stock Index Fund | C37: 1.34
B38: Government Pension Fund Global
B39: Vanguard Emerging Markets Stock Index Fund | C39: 1.27
B40: DIIs - | C40: 0.4319
B41: Life Insurance Corporation Of India - Ulif00220091 | C41: 11.54
B42: Life Insurance Corporation of India
B43: Lic Of India
B44: Sbi Mutual Fund | C44: 4.66
B45: Hdfc Trustee Company Limited
B46: - Hdfc Prudance Fund
B47: Icici Prudential Mutual Fund | C47: 4.74
B48: National Pension System Trust | C48: 2.99
B49: Hdfc Mutual Fund | C49: 2.04
B50: Nippon Life India Trustee | C50: 2.24
...

Sheet Quaterly Results 
B2: Particulars | C2: 45901 | D2: 45992 | E2: 46082
B3: Sales | C3: 44490 | D3: 45479 | E3: 46402
B4: YOY Sales Growth % | C4: 0.0855 | D4: 0.089 | E4: 0.1338
B5: Expenses | C5: 33955 | D5: 34845 | E5: 35235
B6: Employee Cost % | C6: 0.53 | D6: 0.53 | E6: 0.53
B7: Operating Profit | C7: 10535 | D7: 10634 | E7: 11167
B8: OPM % | C8: 0.24 | D8: 0.23 | E8: 0.24
B9: Other Income | C9: 982 | D9: -150 | E9: 1159
B10: Exceptional Items | C10: 0 | D10: -1289 | E10: 0
B11: Other Income Normal | C11: 982 | D11: 1139 | E11: 1159
B12: Interest | C12: 106 | D12: 100 | E12: 105
B13: Depreciation | C13: 1182 | D13: 1155 | E13: 1424
... B23: EPS in Rs | C23: 17.73 | D23: 16.41 | E23: 20.96

Sheet Consolidated FS
B2: INFOSYS LIMITED
B3: Consolidated Statement of Profit and Loss | M3: Consolidated Balance Sheet
B4: (In ₹ crore) | M4: (In ₹ crore)
B6: Particulars | C6: Year ended March 31, 2022 (₹ crore) | D6: Year ended March 31, 2023 (₹ crore) | E6: Year ended March 31, 2024 (₹ crore) | F6: Year ended March 31, 2025 (₹ crore) | G6: Year ended March 31, 2026 (₹ crore) | M6: Particulars | N6: As at March 31, 2022 (₹ crore) | O6: As at March 31, 2023 (₹ crore) | P6: As at March 31, 2024 (₹ crore) | Q6: As at March 31, 2025 (₹ crore) | R6: As at March 31, 2026 (₹ crore)
B7: Revenue from operations | C7: 121641 | D7: 152671 | E7: 162026 | F7: 162990 | G7: 178650 | M7: Non-current assets
B8: Other income, net | C8: 2295 | D8: 2917 | E8: 2957 | F8: 3600 | G8: 4322 | M8: Property, plant and equipment | N8: 13075 | O8: 13346 | P8: 12370 | Q8: 11778 | R8: 12651
B9: Total income | C9: 123936 | D9: 155588 | E9: 164983 | F9: 166590 | G9: 182972 | M9: Right-of-use assets | N9: 4823 | O9: 6882 | P9: 6552 | Q9: 6311 | R9: 6177
B10: Employee benefit expenses | C10: 63986 | D10: 77449 | E10: 81768 | F10: 85950 | G10: 95094 | M10: Capital work-in-progress | N10: 416 | O10: 288 | P10: 293 | Q10: 814 | R10: 526
B11: Cost of technical sub-contractors | C11: 12606 | D11: 11487 | E11: 13019 | F11: 12937 | G11: 15421 | M11: Goodwill | N11: 6195 | O11: 7248 | P11: 7303 | Q11: 10106 | R11: 12117
B12: Travel expenses | C12: 827 | D12: 1139 | E12: 1506 | F12: 1894 | G12: 2097 | M12: Other intangible assets | N12: 1707 | O12: 1749 | P12: 1397 | Q12: 2766 | R12: 2825
B13: Cost of software packages and others | C13: 6811 | D13: 8433 | E13: 8987 | F13: 15911 | G13: 15722 | M13: Investments | N13: 13651 | O13: 12569 | P13: 11708 | Q13: 11059 | R13: 8930
B14: Communication expenses | C14: 611 | D14: 629 | E14: 647 | F14: 620 | G14: 603 | M14: Loans | N14: 34 | O14: 39 | P14: 34 | Q14: 16 | R14: 6
B15: Consultancy and professional charges | C15: 1885 | D15: 1724 | E15: 1729 | F15: 1655 | G15: 2090 | M15: Other financial assets | N15: 1460 | O15: 2798 | P15: 3105 | Q15: 3511 | R15: 2776
B16: Depreciation and amortization | C16: 3476 | D16: 4018 | E16: 4516 | F16: 4812 | G16: 4902 | M16: Deferred tax assets | N16: 1030 | O16: 1400 | P16: 1200 | Q16: 1108 | R16: 2264
B17: Finance cost | C17: 200 | D17: 341 | E17: 369 | F17: 416 | G17: 416 | M17: Income tax assets | N17: 1543 | O17: 1627 | P17: 1700 | Q17: 1622 | R17: 666
B18: Other expenses | C18: 3424 | D18: 3768 | E18: 4262 | F18: 4787 | G18: 5343 | M18: Other non-current assets | N18: 1827 | O18: 1755 | P18: 2188 | Q18: 2713 | R18: 3540
B19: Total expenses | C19: 93826 | D19: 108988 | E19: 116803 | F19: 128982 | G19: 141688 | M19: Total non-current assets | N19: 45761 | O19: 49701 | P19: 47852 | Q19: 51804 | R19: 52478
B20: Profit before tax | C20: 30110 | D20: 46600 | E20: 48180 | F20: 37608 | G20: 39995 | M20: Current assets
B21: Current tax | C21: 7811 | D21: 11984 | E21: 12412 | F21: 12130 | G21: 11767 | M21: Investments | N21: 8000 | O21: 10000 | P21: 10500 | Q21: 12482 | R21: 12950
B22: Deferred tax | C22: 153 | D22: -1012 | E22: -951 | F22: -1272 | G22: -1246 | M22: Trade receivables | N22: 25000 | O22: 28000 | P22: 30000 | Q22: 31158 | R22: 35234
B23: Profit for the period | C23: 22146 | D23: 35628 | E23: 36719 | F23: 26750 | G23: 29474 | M23: Cash and cash equivalents | N23: 10000 | O23: 12000 | P23: 12500 | Q23: 24455 | R23: 22201
M24: Loans | N24: 240 | O24: 300 | P24: 250 | Q24: 249 | R24: 234
M25: Other financial assets | N25: 9500 | O25: 10000 | P25: 11000 | Q25: 13840 | R25: 15890
M26: Income tax assets | N26: 2500 | O26: 2500 | P26: 2200 | Q26: 2975 | R26: 1835
M27: Other current assets | N27: 11000 | O27: 12000 | P27: 13000 | Q27: 11940 | R27: 15145
M28: Total current assets | N28: 66240 | O28: 74800 | P28: 79450 | Q28: 97099 | R28: 103489
M29: Total assets | N29: 112001 | O29: 124501 | P29: 127302 | Q29: 148903 | R29: 155967
M30: Equity
M31: Equity share capital | N31: 2089 | O31: 2083 | P31: 2076 | Q31: 2073 | R31: 2024
M32: Other equity | N32: 76000 | O32: 84000 | P32: 89000 | Q32: 93745 | R32: 90828
M33: Total equity attributable to equity holders | N33: 78089 | O33: 86083 | P33: 91076 | Q33: 95818 | R33: 92852
M34: Non-controlling interests | N34: 350 | O34: 380 | P34: 400 | Q34: 385 | R34: 445
M35: Total equity | N35: 78439 | O35: 86463 | P35: 91476 | Q35: 96203 | R35: 93297
M36: Non-current liabilities
M37: Lease liabilities | N37: 4500 | O37: 6000 | P37: 5500 | Q37: 5772 | R37: 6016
M38: Other financial liabilities | N38: 1800 | O38: 1700 | P38: 1800 | Q38: 2141 | R38: 2092
M39: Deferred tax liabilities | N39: 1500 | O39: 1500 | P39: 1200 | Q39: 1722 | R39: 1679
M40: Other non-current liabilities | N40: 400 | O40: 500 | P40: 600 | Q40: 0 | R40: 561
M41: Total non-current liabilities | N41: 8200 | O41: 9700 | P41: 9100 | Q41: 9635 | R41: 10348
M42: Current liabilities
...

Sheet Stock Analysis 
M3: Recommendation
M4: HOLD — Infosys trades at ₹1,211, valuing the company at ₹4,90,974 Cr. With FY26 consolidated revenue of ₹1,78,650 Cr (+9.6% YoY) and PAT of ₹29,474 Cr (+10.1% YoY), the stock shows recovery momentum. Current P/E of 16.2x is ATTRACTIVE (below historical average), ROCE of 40.3% is exceptional, and dividend yield of 3.56% is attractive. Strong fundamentals with FY26 dividend approved at ₹25 per share (₹18 interim + ₹7 final). Suitable for value and dividend investors.
M11: Financial Year | N11: Revenue (₹ Crore) | O11: Profit After Tax (PAT) (₹ Crore) | P11: Revenue Change (%) | Q11: PAT Change (%) | R11: ROCE (%)
M12: FY 2025-26 | N12: 178650 | O12: 29474 | P12: 72.59 | Q12: 0.096 | R12: 0.1014
M13: FY 2024-25 | N13: 162990 | O13: 26750 | P13: 64.32 | Q13: 0.0059 | R13: -0.2716
M14: FY 2023-24 | N14: 162026 | O14: 36719 | P14: 88.4 | Q14: 0.0611 | R14: 0.0297
M15: FY 2022-23 | N15: 152671 | O15: 35628 | P15: 85.8 | Q15: 0.2565 | R15: 0.6087
M16: FY 2021-22 | N16: 121641 | O16: 22146 | P16: 53.3 | Q16: - | R16: -
B27: Metric | C27: Value
B28: Market Cap | C28: ₹ 4,90,974 Cr.
B29: Current Price | C29: ₹ 1,211
B30: High / Low | C30: ₹ 1,728 / ₹ 1,202
B31: Stock P/E | C31: 16.2
B32: Book Value | C32: ₹ 229
B33: Dividend Yield | C33: 0.0356
B34: ROCE | C34: 0.403
B35: ROE | C35: 0.322
B36: Face Value | C36: ₹ 5.00

Sheet Assumptions 
C2: [ | D2: INFOSYS
D3: Consolidated Profit & Loss account
E4: 2022 | F4: =E4+1 -> 2023 | G4: =F4+1 -> 2024 | H4: =G4+1 -> 2025 | I4: =H4+1 -> 2026
C5: Particulars
C6: Revenue From Operations [Net] | E6: ='Consolidated FS'!C7 -> 121641 | F6: ='Consolidated FS'!D7 -> 152671 | G6: ='Consolidated FS'!E7 -> 162026 | H6: ='Consolidated FS'!F7 -> 162990 | I6: ='Consolidated FS'!G7 -> 178650
C7: revenue growth | F7: =(F6-E6)/E6 -> 0.25509491 | G7: =(G6-F6)/F6 -> 0.061275553 | H7: =(H6-G6)/G6 -> 0.0059496624 | I7: =(I6-H6)/H6 -> 0.096079514
C9: less: Cost of technical sub-contractors | E9: ='Consolidated FS'!C11 -> 12606 | F9: ='Consolidated FS'!D11 -> 11487 | G9: ='Consolidated FS'!E11 -> 13019 | H9: ='Consolidated FS'!F11 -> 12937 | I9: ='Consolidated FS'!G11 -> 15421
C10: less: Employee Cost | E10: ='Consolidated FS'!C10 -> 63986 | F10: ='Consolidated FS'!D10 -> 77449 | G10: ='Consolidated FS'!E10 -> 81768 | H10: ='Consolidated FS'!F10 -> 85950 | I10: ='Consolidated FS'!G10 -> 95094
C11: less: Other Expenses | E11: ='Consolidated FS'!C12+'Consolidated FS'!C13+'Consolidated FS'!C14+'Consolidated FS'!C15 -> 10134 | F11: ='Consolidated FS'!D12+'Consolidated FS'!D13+'Consolidated FS'!D14+'Consolidated FS'!D15 -> 11925 | G11: ='Consolidated FS'!E12+'Consolidated FS'!E13+'Consolidated FS'!E14+'Consolidated FS'!E15 -> 12869 | H11: ='Consolidated FS'!F12+'Consolidated FS'!F13+'Consolidated FS'!F14+'Consolidated FS'!F15 -> 20080 | I11: ='Consolidated FS'!G12+'Consolidated FS'!G13+'Consolidated FS'!G14+'Consolidated FS'!G15 -> 20512
C12: Total Expenses | E12: =SUM(E9:E11) -> 86726 | F12: =SUM(F9:F11) -> 100861 | G12: =SUM(G9:G11) -> 107656 | H12: =SUM(H9:H11) -> 118967 | I12: =SUM(I9:I11) -> 131027
C14: EBITDA | E14: =E6-E12 -> 34915 | F14: =F6-F12 -> 51810 | G14: =G6-G12 -> 54370 | H14: =H6-H12 -> 44023 | I14: =I6-I12 -> 47623
C16: less: Depreciation & Amortization | E16: ='Consolidated FS'!C16 -> 3476 | F16: ='Consolidated FS'!D16 -> 4018 | G16: ='Consolidated FS'!E16 -> 4516 | H16: ='Consolidated FS'!F16 -> 4812 | I16: ='Consolidated FS'!G16 -> 4902
C18: EBIT | E18: =E14-E16 -> 31439 | F18: =F14-F16 -> 47792 | G18: =G14-G16 -> 49854 | H18: =H14-H16 -> 39211 | I18: =I14-I16 -> 42721
C20: add: Other income | E20: ='Consolidated FS'!C8 -> 2295 | F20: ='Consolidated FS'!D8 -> 2917 | G20: ='Consolidated FS'!E8 -> 2957 | H20: ='Consolidated FS'!F8 -> 3600 | I20: ='Consolidated FS'!G8 -> 4322
C21: less: Interest Expense | E21: ='Consolidated FS'!C17 -> 200 | F21: ='Consolidated FS'!D17 -> 341 | G21: ='Consolidated FS'!E17 -> 369 | H21: ='Consolidated FS'!F17 -> 416 | I21: ='Consolidated FS'!G17 -> 416
C23: EBT | E23: =E18+E20-E21 -> 33534 | F23: =F18+F20-F21 -> 50368 | G23: =G18+G20-G21 -> 52442 | H23: =H18+H20-H21 -> 42395 | I23: =I18+I20-I21 -> 46627
C25: less: Tax | E25: ='Consolidated FS'!C21+'Consolidated FS'!C22 -> 7964 | F25: ='Consolidated FS'!D21+'Consolidated FS'!D22 -> 10972 | G25: ='Consolidated FS'!E21+'Consolidated FS'!E22 -> 11461 | H25: ='Consolidated FS'!F21+'Consolidated FS'!F22 -> 10858 | I25: ='Consolidated FS'!G21+'Consolidated FS'!G22 -> 10521
C26: less: Non Controlling interest | E26: ='Consolidated FS'!N34 -> 350 | F26: ='Consolidated FS'!O34 -> 380 | G26: ='Consolidated FS'!P34 -> 400 | H26: ='Consolidated FS'!Q34 -> 385 | I26: ='Consolidated FS'!R34 -> 445
C28: PAT | E28: =E23-E25-E26 -> 25220 | F28: =F23-F25-F26 -> 39016 | G28: =G23-G25-G26 -> 40581 | H28: =H23-H25-H26 -> 31152 | I28: =I23-I25-I26 -> 35661
C30: Historical Growth
C31: Average Growth | E31: =AVERAGE(F7:I7) -> 0.10459991
C32: CAGR | E32: =(I6/E6)^(1/4)-1 -> 0.10085662 | F32: =_xlfn.RRI(4,E6,I6) -> 0.10085662
C34: Margin Analysis
C35: EBITDA Margin | E35: =E14/E6 -> 0.28703315 | F35: =F14/F6 -> 0.33935718 | G35: =G14/G6 -> 0.33556343 | H35: =H14/H6 -> 0.27009632 | I35: =I14/I6 -> 0.26657151
C36: EBIT Margin | E36: =E18/E6 -> 0.25845726 | F36: =F18/F6 -> 0.31303915 | G36: =G18/G6 -> 0.30769136 | H36: =H18/H6 -> 0.24057304 | I36: =I18/I6 -> 0.23913238
C37: EBT Margin | E37: =E23/E6 -> 0.27568007 | F37: =F23/F6 -> 0.32991203 | G37: =G23/G6 -> 0.3236641 | H37: =H23/H6 -> 0.26010798 | I37: =I23/I6 -> 0.26099636
C38: PAT Margin | E38: =E28/E6 -> 0.20733141 | F38: =F28/F6 -> 0.25555607 | G38: =G28/G6 -> 0.2504598 | H38: =H28/H6 -> 0.19112829 | I38: =I28/I6 -> 0.19961377
C40: Tax Rate
C41: Effective Tax Rate | E41: =E25/E23 -> 0.23749031 | F41: =F25/F23 -> 0.21783672 | G41: =G25/G23 -> 0.2185462 | H41: =H25/H23 -> 0.25611511 | I41: =I25/I23 -> 0.2256418
C42: Marginal Tax Rate | E42: =MEDIAN(E41:I41) -> 0.2256418 | F42: =E42 -> 0.2256418 | G42: =F42 -> 0.2256418 | H42: =G42 -> 0.2256418 | I42: =H42 -> 0.2256418
C44: Return on Capital
C45: EBIT(1-t) | E45: =E18*(1-E42) -> 24345.048 | F45: =F18*(1-F42) -> 37008.127 | G45: =G18*(1-G42) -> 38604.854 | H45: =H18*(1-H42) -> 30363.36 | I45: =I18*(1-I42) -> 33081.357
C46: Book Equity | E46: ='Consolidated FS'!N35 -> 78439 | F46: ='Consolidated FS'!O35 -> 86463 | G46: ='Consolidated FS'!P35 -> 91476 | H46: ='Consolidated FS'!Q35 -> 96203 | I46: ='Consolidated FS'!R35 -> 93297
C47: Book Debt | E47: ='Consolidated FS'!N41+'Consolidated FS'!N44 -> 20200 | F47: ='Consolidated FS'!O41+'Consolidated FS'!O44 -> 21700 | G47: ='Consolidated FS'!P41+'Consolidated FS'!P44 -> 21100 | H47: ='Consolidated FS'!Q41+'Consolidated FS'!Q44 -> 24664 | I47: ='Consolidated FS'!R41+'Consolidated FS'!R44 -> 26010
C48: Cash and Cash Equivalent | E48: 0 | F48: 0 | G48: 438.67 | H48: 310.16 | I48: 492.55
C49: Capital Employed | E49: =E46+E47-E48 -> 98639 | F49: =F46+F47-F48 -> 108163 | G49: =G46+G47-G48 -> 112137.33 | H49: =H46+H47-H48 -> 120556.84 | I49: =I46+I47-I48 -> 118814.45
C51: Pre Tax Return on Capital | E51: =E18/E49 -> 0.31872789 | F51: =F18/F49 -> 0.44185165 | G51: =G18/G49 -> 0.44457987 | H51: =H18/H49 -> 0.32524907 | I51: =I18/I49 -> 0.35956064
C52: Post Tax Return on Capital | E52: =E45/E49 -> 0.24680955 | F52: =F45/F49 -> 0.34215145 | G52: =G45/G49 -> 0.34426407 | H52: =H45/H49 -> 0.25185929 | I52: =I45/I49 -> 0.27842873

Sheet BETA
B2: INFOSYS | F2: NIFTY
B3: Date | C3: Close | F3: Date | G3: Closing Price | K3: BETA
B4: 44652 | C4: 1903.55 | F4: 44652 | G4: 17670.449
B5: 44655 | C5: 1882.95 | D5: =(C5-C4)/C4 -> -0.010821936 | F5: 44655 | G5: 18053.4 | H5: =(G5-G4)/G4 -> 0.021671841 | K5: =SLOPE(D5:D989,H5:H989) -> 1.011478
B6: 44656 | C6: 1861.1 | D6: =(C6-C5)/C5 -> -0.011604119 | F6: 44656 | G6: 17957.4 | H6: =(G6-G5)/G5 -> -0.0053175578
B7: 44657 | C7: 1828.85 | D7: =(C7-C6)/C6 -> -0.017328462 | F7: 44657 | G7: 17807.65 | H7: =(G7-G6)/G6 -> -0.0083391803 | K7: SUMMARY OUTPUT
B8: 44658 | C8: 1811 | D8: =(C8-C7)/C7 -> -0.0097602186 | F8: 44658 | G8: 17639.551 | H8: =(G8-G7)/G7 -> -0.0094397411
B9: 44659 | C9: 1814.6 | D9: =(C9-C8)/C8 -> 0.0019878385 | F9: 44659 | G9: 17784.35 | H9: =(G9-G8)/G8 -> 0.0082087594 | K9: Regression Statistics
B10: 44662 | C10: 1766.55 | D10: =(C10-C9)/C9 -> -0.026479625 | F10: 44662 | G10: 17674.949 | H10: =(G10-G9)/G9 -> -0.006151498 | K10: Multiple R | L10: 0.53152526
B11: 44663 | C11: 1742.45 | D11: =(C11-C10)/C10 -> -0.013642465 | F11: 44663 | G11: 17530.301 | H11: =(G11-G10)/G10 -> -0.0081838106 | K11: R Square | L11: 0.2825191
B12: 44664 | C12: 1748.55 | D12: =(C12-C11)/C11 -> 0.003500874 | F12: 44664 | G12: 17475.65 | H12: =(G12-G11)/G11 -> -0.0031174816 | K12: Adjusted R Square | L12: 0.28178921
B13: 44669 | C13: 1621.4 | D13: =(C13-C12)/C12 -> -0.072717406 | F13: 44669 | G13: 17173.65 | H13: =(G13-G12)/G12 -> -0.017281188 | K13: Standard Error | L13: 0.013413065
B14: 44670 | C14: 1562 | D14: =(C14-C13)/C13 -> -0.036635021 | F14: 44670 | G14: 16958.65 | H14: =(G14-G13)/G13 -> -0.012519179 | K14: Observations | L14: 985
B15: 44671 | C15: 1587.7 | D15: =(C15-C14)/C14 -> 0.016453234 | F15: 44671 | G15: 17136.551 | H15: =(G15-G14)/G14 -> 0.010490245
B16: 44672 | C16: 1618.8 | D16: =(C16-C15)/C15 -> 0.019588146 | F16: 44672 | G16: 17392.6 | H16: =(G16-G15)/G15 -> 0.014941678 | K16: ANOVA
B17: 44673 | C17: 1585.45 | D17: =(C17-C16)/C16 -> -0.02060174 | F17: 44673 | G17: 17171.949 | H17: =(G17-G16)/G16 -> -0.012686453 | L17: df | M17: SS | N17: MS | O17: F | P17: Significance F
B18: 44676 | C18: 1561.1 | D18: =(C18-C17)/C17 -> -0.015358401 | F18: 44676 | G18: 16953.949 | H18: =(G18-G17)/G17 -> -0.012695123 | K18: Regression | L18: 1 | M18: 0.069638118 | N18: 0.069638118 | O18: 387.07131 | P18: 6.4520965e-73
B19: 44677 | C19: 1581 | D19: =(C19-C18)/C18 -> 0.012747438 | F19: 44677 | G19: 17200.801 | H19: =(G19-G18)/G18 -> 0.014560122 | K19: Residual | L19: 983 | M19: 0.17685183 | N19: 0.00017991031
B20: 44678 | C20: 1552.8 | D20: =(C20-C19)/C19 -> -0.017836781 | F20: 44678 | G20: 17038.4 | H20: =(G20-G19)/G19 -> -0.0094414436 | K20: Total | L20: 984 | M20: 0.24648995
B21: 44679 | C21: 1582.6 | D21: =(C21-C20)/C20 -> 0.019191091 | F21: 44679 | G21: 17245.051 | H21: =(G21-G20)/G20 -> 0.012128509
B22: 44680 | C22: 1567.55 | D22: =(C22-C21)/C21 -> -0.0095096215 | F22: 44680 | G22: 17102.551 | H22: =(G22-G21)/G21 -> -0.0082632404 | L22: Coefficients | M22: Standard Error | N22: t Stat | O22: P-value | P22: Lower 95% | Q22: Upper 95% | R22: Lower 95.0% | S22: Upper 95.0%
B23: 44683 | C23: 1541 | D23: =(C23-C22)/C22 -> -0.016937289 | F23: 44683 | G23: 17069.1 | H23: =(G23-G22)/G22 -> -0.0019559171 | K23: Intercept | L23: -0.00057624704 | M23: 0.00042760503 | N23: -1.3476152 | O23: 0.17809268 | P23: -0.0014153707 | Q23: 0.0002628766 | R23: -0.0014153707 | S23: 0.0002628766
B24: 44685 | C24: 1535.55 | D24: =(C24-C23)/C23 -> -0.0035366328 | F24: 44685 | G24: 16677.6 | H24: =(G24-G23)/G23 -> -0.022936183 | K24: X Variable 1 | L24: 1.011478 | M24: 0.05141158 | N24: 19.674128 | O24: 6.4520965e-73 | P24: 0.91058894 | Q24: 1.1123671 | R24: 0.91058894 | S24: 1.1123671
B25: 44686 | C25: 1585.15 | D25: =(C25-C24)/C24 -> 0.032301113 | F25: 44686 | G25: 16682.65 | H25: =(G25-G24)/G24 -> 0.00030284821
B26: 44687 | C26: 1542.85 | D26: =(C26-C25)/C25 -> -0.026685202 | F26: 44687 | G26: 16411.25 | H26: =(G26-G25)/G25 -> -0.016268422
B27: 44690 | C27: 1570.35 | D27: =(C27-C26)/C26 -> 0.017824157 | F27: 44690 | G27: 16301.85 | H27: =(G27-G26)/G26 -> -0.0066661827
B28: 44691 | C28: 1553 | D28: =(C28-C27)/C27 -> -0.011048477 | F28: 44691 | G28: 16240.05 | H28: =(G28-G27)/G27 -> -0.0037909689
B29: 44692 | C29: 1526.75 | D29: =(C29-C28)/C28 -> -0.016902769 | F29: 44692 | G29: 16167.1 | H29: =(G29-G28)/G28 -> -0.0044919933
B30: 44693 | C30: 1508.8 | D30: =(C30-C29)/C29 -> -0.011756968 | F30: 44693 | G30: 15808 | H30: =(G30-G29)/G29 -> -0.022211752
B31: 44694 | C31: 1504.4 | D31: =(C31-C30)/C30 -> -0.0029162409 | F31: 44694 | G31: 15782.15 | H31: =(G31-G30)/G30 -> -0.0016352233
B32: 44697 | C32: 1489.1 | D32: =(C32-C31)/C31 -> -0.0101702 | F32: 44697 | G32: 15842.3 | H32: =(G32-G31)/G31 -> 0.0038112306
B33: 44698 | C33: 1518.45 | D33: =(C33-C32)/C32 -> 0.019709876 | F33: 44698 | G33: 16259.3 | H33: =(G33-G32)/G32 -> 0.026321936
B34: 44699 | C34: 1509.2 | D34: =(C34-C33)/C33 -> -0.0060917385 | F34: 44699 | G34: 16240.3 | H34: =(G34-G33)/G33 -> -0.001168562
B35: 44700 | C35: 1427.15 | D35: =(C35-C34)/C34 -> -0.054366505 | F35: 44700 | G35: 15809.4 | H35: =(G35-G34)/G34 -> -0.026532725
B36: 44701 | C36: 1455.15 | D36: =(C36-C35)/C35 -> 0.019619521 | F36: 44701 | G36: 16266.15 | H36: =(G36-G35)/G35 -> 0.028891039
... B989: 46111 | C989: 1250.6 | D989: =(C989-C988)/C988 -> -0.015042905 | F989: 46111 | G989: 22331.4 | H989: =(G989-G988)/G988 -> -0.021393856

Sheet WACC
B2: Weighted Average Cost of Capital
B5: Capital Structure
B6: Total Debt | C6: ='Consolidated FS'!R37+'Consolidated FS'!R38+'Consolidated FS'!R44+'Consolidated FS'!R45-'Consolidated FS'!R23 -> 2477
B7: Total Equity | C7: ='Consolidated FS'!R33 -> 92852
B8: Total Mix | C8: =SUM(C6:C7) -> 95329
B9: % of Debt | C9: =C6/C8 -> 0.025983699
B10: % of Equity | C10: =C7/C8 -> 0.9740163
B11: Debt to Equity | C11: =C6/C7 -> 0.026676862
B15: Cost of Equity | E15: Cost of Debt
B16: Risk free rate(Rf) | C16: 0.066 | E16: Source | F16: Cost
B17: Beta | C17: =BETA!K5 -> 1.011478 | E17: Cost of debt* | F17: ='Consolidated FS'!G17/C6 -> 0.16794509
B18: Market risk premium | C18: 0.07 | E18: Tax rate | F18: ='Assumptions '!I42 -> 0.2256418
B19: Cost of equity | C19: =C16+C17*C18 -> 0.13680346 | E19: Cost of Debt after tax | F19: =F17*(1-F18) -> 0.13004966
B22: WACC
B23: Source | C23: Weight | D23: Cost | E23: Weighted Cost
B24: Debt | C24: =C9 -> 0.025983699 | D24: =F19 -> 0.13004966 | E24: =C24*D24 -> 0.0033791712
B25: Equity | C25: =C10 -> 0.9740163 | D25: =C19 -> 0.13680346 | E25: =C25*D25 -> 0.1332488
B26: WACC | E26: =SUM(E24:E25) -> 0.13662797

Sheet Fixed Asset Schedule 
B2: INFOSYS "Fixed Asset Schedule "
B3: Particular | C3: 2022 | D3: =C3+1 -> 2023 | E3: =D3+1 -> 2024 | F3: =E3+1 -> 2025 | G3: =F3+1 -> 2026
B4: Beginning balance | D4: =C8 -> 13075 | E4: =D8 -> 13346 | F4: =E8 -> 12370 | G4: =F8 -> 11778
B5: Add: Net Purchases | D5: =D6-D4 -> 4289 | E5: =E6-E4 -> 3540 | F5: =F6-F4 -> 4220 | G5: =G6-G4 -> 5775
B6: Total Fixed Assets | C6: =C7+C8 -> 16551 | D6: =D7+D8 -> 17364 | E6: =E7+E8 -> 16886 | F6: =F7+F8 -> 16590 | G6: =G7+G8 -> 17553
B7: Less: Depreciation | C7: ='Consolidated FS'!C16 -> 3476 | D7: ='Consolidated FS'!D16 -> 4018 | E7: ='Consolidated FS'!E16 -> 4516 | F7: ='Consolidated FS'!F16 -> 4812 | G7: ='Consolidated FS'!G16 -> 4902
B8: Closing Balance(Fixed Asests ) | C8: ='Consolidated FS'!N8 -> 13075 | D8: ='Consolidated FS'!O8 -> 13346 | E8: ='Consolidated FS'!P8 -> 12370 | F8: ='Consolidated FS'!Q8 -> 11778 | G8: ='Consolidated FS'!R8 -> 12651
B10: Net Capital expenditure | D10: =D5-D7 -> 271 | E10: =E5-E7 -> -976 | F10: =F5-F7 -> -592 | G10: =G5-G7 -> 873
B11: Net Capital expenditure / Sales percentage | D11: =IFERROR(D10/D4,0) -> 0.020726577 | E11: =IFERROR(E10/E4,0) -> -0.073130526 | F11: =IFERROR(F10/F4,0) -> -0.04785772 | G11: =IFERROR(G10/G4,0) -> 0.074121243
B13: Median Capital expenditure /Sales percentage | C13: =MEDIAN(D11:G11) -> -0.013565571
B14: Average Capital expenditure /Sales percentage | C14: =AVERAGE(D11:G11) -> -0.0065351065

Sheet Change in Working Cap 
B2: "Change in Working Capital "
B3: Particular | C3: 2022 | D3: =C3+1 -> 2023 | E3: =D3+1 -> 2024 | F3: =E3+1 -> 2025 | G3: =F3+1 -> 2026
B4: Days Sales Outstanding | C4: =('Consolidated FS'!N22/'Consolidated FS'!C9)*365 -> 73.626711 | D4: =('Consolidated FS'!O22/'Consolidated FS'!D9)*365 -> 65.6863 | E4: =('Consolidated FS'!P22/'Consolidated FS'!E9)*365 -> 66.370475 | F4: =('Consolidated FS'!Q22/'Consolidated FS'!F9)*365 -> 68.267423 | G4: =('Consolidated FS'!R22/'Consolidated FS'!G9)*365 -> 70.286219
B5: Trade Receivables | C5: ='Consolidated FS'!N22 -> 25000 | D5: ='Consolidated FS'!O22 -> 28000 | E5: ='Consolidated FS'!P22 -> 30000 | F5: ='Consolidated FS'!Q22 -> 31158 | G5: ='Consolidated FS'!R22 -> 35234
B6: Trade Payable | C6: ='Consolidated FS'!N43 -> 2800 | D6: ='Consolidated FS'!O43 -> 2800 | E6: ='Consolidated FS'!P43 -> 2800 | F6: ='Consolidated FS'!Q43 -> 3072 | G6: ='Consolidated FS'!R43 -> 3046
B7: Non Cash working Capital | C7: =C4+C5-C6 -> 22273.627 | D7: =D4+D5-D6 -> 25265.686 | E7: =E4+E5-E6 -> 27266.37 | F7: =F4+F5-F6 -> 28154.267 | G7: =G4+G5-G6 -> 32258.286
B8: Change in Working Capital | D8: =D7-C7 -> 2992.0596 | E8: =E7-D7 -> 2000.6842 | F8: =F7-E7 -> 887.89695 | G8: =G7-F7 -> 4104.0188
B9: changein working Capital /percentage of sales | D9: =D8/'Consolidated FS'!D7 -> 0.019598087 | E9: =E8/'Consolidated FS'!E7 -> 0.012347921 | F9: =F8/'Consolidated FS'!F7 -> 0.0054475547 | G9: =G8/'Consolidated FS'!G7 -> 0.022972397
B11: Median Non Cash working Capital /Sales percentage | C11: =MEDIAN(D9:G9) -> 0.015973004
B12: Average Non Cash working Capital /Sales percentage | C12: =AVERAGE(D9:G9) -> 0.01509149

Sheet FCFF
B2: INFOSYS "Free Cash Flow "
B3: Particular | C3: 2022 | D3: =C3+1 -> 2023 | E3: =D3+1 -> 2024 | F3: =E3+1 -> 2025 | G3: =F3+1 -> 2026
B4: EBIT | C4: ='Assumptions '!E18 -> 31439 | D4: ='Assumptions '!F18 -> 47792 | E4: ='Assumptions '!G18 -> 49854 | F4: ='Assumptions '!H18 -> 39211 | G4: ='Assumptions '!I18 -> 42721
B5: Less: Tax on EBIT | C5: ='Assumptions '!E41 -> 0.23749031 | D5: ='Assumptions '!F41 -> 0.21783672 | E5: ='Assumptions '!G41 -> 0.2185462 | F5: ='Assumptions '!H41 -> 0.25611511 | G5: ='Assumptions '!I41 -> 0.2256418
B6: EBIT * (1- Tax) | C6: =C4*(1-C5) -> 23972.542 | D6: =D4*(1-D5) -> 37381.147 | E6: =E4*(1-E5) -> 38958.598 | F6: =F4*(1-F5) -> 29168.471 | G6: =G4*(1-G5) -> 33081.357
B7: Less: Net Capital expenditure | C7: 0 | D7: ='Fixed Asset Schedule '!D10 -> 271 | E7: ='Fixed Asset Schedule '!E10 -> -976 | F7: ='Fixed Asset Schedule '!F10 -> -592 | G7: ='Fixed Asset Schedule '!G10 -> 873
B8: Less: Net Change in working Capital | C8: 0 | D8: ='Change in Working Cap '!D8 -> 2992.0596 | E8: ='Change in Working Cap '!E8 -> 2000.6842 | F8: ='Change in Working Cap '!F8 -> 887.89695 | G8: ='Change in Working Cap '!G8 -> 4104.0188
B9: Reinvestment | C9: =SUM(C7:C8) -> 0 | D9: =SUM(D7:D8) -> 3263.0596 | E9: =SUM(E7:E8) -> 1024.6842 | F9: =SUM(F7:F8) -> 295.89695 | G9: =SUM(G7:G8) -> 4977.0188
B10: Free Cash Flow | C10: =C6-C9 -> 23972.542 | D10: =D6-D9 -> 34118.088 | E10: =E6-E9 -> 37933.913 | F10: =F6-F9 -> 28872.574 | G10: =G6-G9 -> 28104.338
B12: Reinvestment Rate | D12: =D9/D6 -> 0.087291585 | E12: =E9/E6 -> 0.026301875 | F12: =F9/F6 -> 0.010144411 | G12: =G9/G6 -> 0.15044784
B14: Median Reinvestment rate /Sales percentage | C14: =MEDIAN(D12:G12) -> 0.05679673
B15: Average Reinvestment rate /Sales percentage | C15: =AVERAGE(D12:G12) -> 0.068546429

Sheet Growth Scenario 
B2: INFOSYS "Growth Scenarios"
B4: Scenario 1: High Growth
B5: INR Cr. | C5: LTM | D5: Y1E | E5: Y2E | F5: Y3E | G5: Y4W | H5: Y5E | I5: Y6E | J5: Y7E | K5: Y8E | L5: Y9E | M5: Y10E
B6: Sales | C6: ='Consolidated FS'!G9 -> 182972 | D6: =C6*(1+D7) -> 197367.79 | E6: =D6*(1+E7) -> 212618.18 | F6: =E6*(1+F7) -> 228747.46 | G6: =F6*(1+G7) -> 245778.1 | H6: =G6*(1+H7) -> 263730.48 | I6: =H6*(1+I7) -> 282622.67 | J6: =I6*(1+J7) -> 302470.09 | K6: =J6*(1+K7) -> 323285.24 | ... M6: =L6*(1+M7) -> 367852.57 | O6: Risk Free Rate | P6: 0.066
B7: Sales Growth % | D7: =N7 -> 0.078677534 | E7: =D7-$P$9 -> 0.077268919 | F7: =E7-$P$9 -> 0.075860304 | G7: =F7-$P$9 -> 0.074451689 | H7: =G7-$P$9 -> 0.073043074 | I7: =H7-$P$9 -> 0.071634459 | J7: =I7-$P$9 -> 0.070225845 | K7: =J7-$P$9 -> 0.06881723 | L7: =K7-$P$9 -> 0.067408615 | M7: =L7-$P$9 -> 0.066 | N7: =MEDIAN('Assumptions '!F7:I7) -> 0.078677534
B9: Scenario 2: Average Growth | O9: =N7-P6 -> 0.012677534 | P9: =O9/9 -> 0.0014086149
B10: INR Cr. | C10: LTM | D10: Y1E | E10: Y2E | F10: Y3E | G10: Y4W | H10: Y5E | I10: Y6E | J10: Y7E | K10: Y8E | L10: Y9E | M10: Y10E
B11: Sales | C11: =C6 -> 182972 | D11: =C11*(1+D12) -> 202110.85 | E11: =D11*(1+E12) -> 222418.49 | F11: =E11*(1+F12) -> 243849.73 | G11: =F11*(1+G12) -> 266340.79 | H11: =G11*(1+H12) -> 289808.36 | I11: =H11*(1+I12) -> 314149.03 | J11: =I11*(1+J12) -> 339239.05 | K11: =J11*(1+K12) -> 364934.52 | ... M11: =L11*(1+M12) -> 417469.3
B12: Sales Growth % | D12: =AVERAGE('Assumptions '!F7:I7) -> 0.10459991 | E12: =D12-O12 -> 0.1004777 | F12: =E12-O12 -> 0.096355486 | G12: =F12-O12 -> 0.092233273 | H12: =G12-O12 -> 0.088111061 | I12: =H12-O12 -> 0.083988849 | J12: =I12-O12 -> 0.079866637 | K12: =J12-O12 -> 0.075744424 | L12: =K12-O12 -> 0.071622212 | M12: 0.0675 | N12: =D12-M12 -> 0.03709991 | O12: =N12/9 -> 0.0041222122
B14: Scenario 3: EBIT Growth
B15: INR Cr. | C15: LTM | D15: Y1E | E15: Y2E | F15: Y3E | G15: Y4W | H15: Y5E | I15: Y6E | J15: Y7E | K15: Y8E | L15: Y9E | M15: Y10E
B16: Sales | C16: =C11 -> 182972 | D16: =C16*(1+D17) -> 185865.49 | E16: =D16*(1+E17) -> 189872.15 | F16: =E16*(1+F17) -> 195055.59 | G16: =F16*(1+G17) -> 201500.73 | H16: =G16*(1+H17) -> 209316.03 | I16: =H16*(1+I17) -> 218636.53 | J16: =I16*(1+J17) -> 229627.67 | K16: =J16*(1+K17) -> 242490.07 | ... M16: =L16*(1+M17) -> 274844.48
B17: Sales Growth % | D17: =FCFF!C14*'Assumptions '!I52 -> 0.015813842 | E17: =D17-$O$17 -> 0.021556748 | F17: =E17-$O$17 -> 0.027299655 | G17: =F17-$O$17 -> 0.033042561 | H17: =G17-$O$17 -> 0.038785468 | I17: =H17-$O$17 -> 0.044528374 | J17: =I17-$O$17 -> 0.050271281 | K17: =J17-$O$17 -> 0.056014187 | L17: =K17-$O$17 -> 0.061757094 | M17: 0.0675 | N17: =D17-M17 -> -0.051686158 | O17: =N17/9 -> -0.0057429065
B19: Live Scenario | C19: 3
B20: INR Cr. | C20: LTM | D20: Y1E | E20: Y2E | F20: Y3E | G20: Y4W | H20: Y5E | I20: Y6E | J20: Y7E | K20: Y8E | L20: Y9E | M20: Y10E
B21: Sales | C21: =C6 -> 182972 | D21: =C21*(1+D22) -> 185865.49 | E21: =D21*(1+E22) -> 189872.15 | F21: =E21*(1+F22) -> 195055.59 | G21: =F21*(1+G22) -> 201500.73 | H21: =G21*(1+H22) -> 209316.03 | I21: =H21*(1+I22) -> 218636.53 | J21: =I21*(1+J22) -> 229627.67 | K21: =J21*(1+K22) -> 242490.07 | ... M21: =L21*(1+M22) -> 274844.48
B22: Sales Growth % | D22: =CHOOSE($C$19,D7,D12,D17) -> 0.015813842 | E22: =CHOOSE($C$19,E7,E12,E17) -> 0.021556748 | F22: =CHOOSE($C$19,F7,F12,F17) -> 0.027299655 | G22: =CHOOSE($C$19,G7,G12,G17) -> 0.033042561 | H22: =CHOOSE($C$19,H7,H12,H17) -> 0.038785468 | I22: =CHOOSE($C$19,I7,I12,I17) -> 0.044528374 | J22: =CHOOSE($C$19,J7,J12,J17) -> 0.050271281 | K22: =CHOOSE($C$19,K7,K12,K17) -> 0.056014187 | ... M22: =CHOOSE($C$19,M7,M12,M17) -> 0.0675

Sheet Valuation 
B2: INFOSYS - "VALUATION"
D3: 1 | E3: 2 | F3: 3 | G3: 4 | H3: 5 | I3: 6 | J3: 7 | K3: 8 | L3: 9 | M3: 10
B4: INR Cr | C4: LTM | D4: Y1E | E4: Y2E | F4: Y3E | G4: Y4W | H4: Y5E | I4: Y6E | J4: Y7E | K4: Y8E | L4: Y9E | M4: Y10E | O4: Terminal Year | Q4: Terminal growth rate % | R4: 0.03
B5: Sales | C5: ='Growth Scenario '!C21 -> 182972 | D5: ='Growth Scenario '!D21 -> 185865.49 | E5: ='Growth Scenario '!E21 -> 189872.15 | F5: ='Growth Scenario '!F21 -> 195055.59 | G5: ='Growth Scenario '!G21 -> 201500.73 | H5: ='Growth Scenario '!H21 -> 209316.03 | I5: ='Growth Scenario '!I21 -> 218636.53 | J5: ='Growth Scenario '!J21 -> 229627.67 | ... M5: ='Growth Scenario '!M21 -> 274844.48 | O5: =M5*(1+R4) -> 283089.82 | Q5: Cost of Capital % | R5: =WACC!E26 -> 0.13662797
B6: Sales Growth | D6: ='Growth Scenario '!D7 -> 0.078677534 | E6: ='Growth Scenario '!E7 -> 0.077268919 | F6: ='Growth Scenario '!F7 -> 0.075860304 | G6: ='Growth Scenario '!G7 -> 0.074451689 | H6: ='Growth Scenario '!H7 -> 0.073043074 | I6: ='Growth Scenario '!I7 -> 0.071634459 | J6: ='Growth Scenario '!J7 -> 0.070225845 | K6: ='Growth Scenario '!K7 -> 0.06881723 | ... M6: ='Growth Scenario '!M7 -> 0.066 | O6: =R4 -> 0.03 | Q6: Terminal reinvestment rate % | R6: =R5*R4 -> 0.0040988392
B7: EBIT | D7: =D8*D5 -> 19441.514 | E7: =E8*E5 -> 19860.609 | F7: =F8*F5 -> 20402.797 | G7: =G8*G5 -> 21076.958 | H7: =H8*H5 -> 21894.437 | I7: =I8*I5 -> 22869.361 | J7: =J8*J5 -> 24019.033 | K7: =K8*K5 -> 25364.44 | ... M7: =M8*M5 -> 28748.708 | O7: =O8*O5 -> 29611.169
B8: EBIT Margin % | D8: =AVERAGE('Assumptions '!F7:I7) -> 0.10459991 | E8: =D8 -> 0.10459991 | F8: =E8 -> 0.10459991 | G8: =F8 -> 0.10459991 | H8: =G8 -> 0.10459991 | I8: =H8 -> 0.10459991 | J8: =I8 -> 0.10459991 | K8: =J8 -> 0.10459991 | L8: =K8 -> 0.10459991 | M8: =L8 -> 0.10459991 | O8: =M8 -> 0.10459991 | Q8: Enterprise value = Equity Value + Minority interest
B9: Less: Tax on EBIT | D9: =WACC!$F$18*'Valuation '!D7 -> 4386.818 | E9: =WACC!$F$18*'Valuation '!E7 -> 4481.3836 | F9: =WACC!$F$18*'Valuation '!F7 -> 4603.7238 | G9: =WACC!$F$18*'Valuation '!G7 -> 4755.8426 | H9: =WACC!$F$18*'Valuation '!H7 -> 4940.3002 | I9: =WACC!$F$18*'Valuation '!I7 -> 5160.2837 | J9: =WACC!$F$18*'Valuation '!J7 -> 5419.6978 | K9: =WACC!$F$18*'Valuation '!K7 -> 5723.2778 | ... M9: =WACC!$F$18*'Valuation '!M7 -> 6486.9101
B10: EBIT(1-T) | D10: =D7-D9 -> 15054.696 | E10: =E7-E9 -> 15379.226 | F10: =F7-F9 -> 15799.073 | G10: =G7-G9 -> 16321.115 | H10: =H7-H9 -> 16954.137 | I10: =I7-I9 -> 17709.077 | J10: =J7-J9 -> 18599.335 | K10: =K7-K9 -> 19641.162 | ... M10: =M7-M9 -> 22261.798 | O10: =O7-O9 -> 29611.169
B11: Less: Net Capital Expenditure | D11: =FCFF!$C$14*'Valuation '!D5 -> 10556.552 | E11: =FCFF!$C$14*'Valuation '!E5 -> 10784.117 | F11: =FCFF!$C$14*'Valuation '!F5 -> 11078.52 | G11: =FCFF!$C$14*'Valuation '!G5 -> 11444.582 | H11: =FCFF!$C$14*'Valuation '!H5 -> 11888.466 | I11: =FCFF!$C$14*'Valuation '!I5 -> 12417.84 | J11: =FCFF!$C$14*'Valuation '!J5 -> 13042.101 | K11: =FCFF!$C$14*'Valuation '!K5 -> 13772.643 | ... M11: =FCFF!$C$14*'Valuation '!M5 -> 15610.268
B12: Non Cash Working Capital | C12: ='Change in Working Cap '!G8 -> 4104.0188 | D12: ='Change in Working Cap '!$C$11*'Valuation '!D5 -> 2968.8302 | E12: ='Change in Working Cap '!$C$11*'Valuation '!E5 -> 3032.8285 | F12: ='Change in Working Cap '!$C$11*'Valuation '!F5 -> 3115.6237 | G12: ='Change in Working Cap '!$C$11*'Valuation '!G5 -> 3218.5719 | H12: ='Change in Working Cap '!$C$11*'Valuation '!H5 -> 3343.4057 | I12: ='Change in Working Cap '!$C$11*'Valuation '!I5 -> 3492.2821 | J12: ='Change in Working Cap '!$C$11*'Valuation '!J5 -> 3667.8436 | K12: ='Change in Working Cap '!$C$11*'Valuation '!K5 -> 3873.2949 | ... M12: ='Change in Working Cap '!$C$11*'Valuation '!M5 -> 4390.092
B13: Less: Change in Working Capital | D13: =D12-C12 -> -1135.1886 | E13: =E12-D12 -> 63.998325 | F13: =F12-E12 -> 82.795171 | G13: =G12-F12 -> 102.94819 | H13: =H12-G12 -> 124.83382 | I13: =I12-H12 -> 148.87642 | J13: =J12-I12 -> 175.56149 | K13: =K12-J12 -> 205.45128 | ... M13: =M12-L12 -> 277.59364
B14: Reinvestment | D14: =D11+D13 -> 9421.3635 | E14: =E11+E13 -> 10848.115 | F14: =F11+F13 -> 11161.315 | G14: =G11+G13 -> 11547.531 | H14: =H11+H13 -> 12013.3 | I14: =I11+I13 -> 12566.716 | J14: =J11+J13 -> 13217.662 | K14: =K11+K13 -> 13978.094 | ... M14: =M11+M13 -> 15887.861 | O14: =O10*O16 -> 121.37142
B15: Free Cash Flow To Firm (FCFF) | D15: =D10-D14 -> 5633.3321 | E15: =E10-E14 -> 4531.1105 | F15: =F10-F14 -> 4637.7585 | G15: =G10-G14 -> 4773.5847 | H15: =H10-H14 -> 4940.8377 | I15: =I10-I14 -> 5142.3612 | J15: =J10-J14 -> 5381.6734 | K15: =K10-K14 -> 5663.0676 | ... M15: =M10-M14 -> 6373.9365 | O15: =O10-O14 -> 29489.798
B16: Implied Reinvestment rate % | D16: =D14/D10 -> 0.62580897 | E16: =E14/E10 -> 0.7053746 | F16: =F14/F10 -> 0.70645376 | G16: =G14/G10 -> 0.70752092 | H16: =H14/H10 -> 0.70857628 | I16: =I14/I10 -> 0.70962004 | J16: =J14/J10 -> 0.71065238 | K16: =K14/K10 -> 0.7116735 | ... M16: =M14/M10 -> 0.71368276 | O16: =R6 -> 0.0040988392
B18: Terminal Value | M18: =M15*(1+R4)/(R5-R4) -> 61570.66
B20: Present Value Interest Factor(PVIF) | D20: =1/(1+$R$5)^D3 -> 0.87979535 | E20: =1/(1+$R$5)^E3 -> 0.77403985 | F20: =1/(1+$R$5)^F3 -> 0.68099666 | G20: =1/(1+$R$5)^G3 -> 0.59913769 | H20: =1/(1+$R$5)^H3 -> 0.52711855 | I20: =1/(1+$R$5)^I3 -> 0.46375645 | J20: =1/(1+$R$5)^J3 -> 0.40801077 | K20: =1/(1+$R$5)^K3 -> 0.35896597 | ... M20: =1/(1+$R$5)^M3 -> 0.27785397
B22: Present value of FCFF | D22: =SUMPRODUCT(D15:M15,D20:M20) -> 27362.926
B23: Present value of Terminal value | D23: =M18*M20 -> 17107.652
I24: Calculation of Sensitivity Analysis
B25: Value of operating assets | D25: =D22+D23 -> 44470.578 | I25: =D32 -> 1572.1228 | J25: =K25-1% -> 0.12662797 | K25: =R5 -> 0.13662797 | L25: =K25+1% -> 0.14662797 | M25: =L25+1% -> 0.15662797
B26: Add: Cash | D26: ='Consolidated FS'!R23 -> 22201 | I26: =I27-1% -> 0.047 | J26: 647.64581 | K26: 647.64581 | L26: 525.46011 | M26: 380.7948
B27: Less: Debt | D27: =WACC!C6 -> 2477 | I27: =I28-1% -> 0.057 | J27: 488.12563 | K27: 488.12563 | L27: 411.63691 | M27: 313.33096
B28: Less: Minority Interest | D28: ='Consolidated FS'!R34 -> 445 | I28: 0.067 | J28: 384.07289 | K28: 384.07289 | L28: 332.97385 | M28: 263.15813
B29: Equity Value | D29: =D25+D26-D27-D28 -> 63749.578 | I29: =I28+1% -> 0.077 | J29: 311.961 | K29: 311.961 | L29: 276.13091 | M29: 224.78524
I30: =I29+1% -> 0.087 | J30: 259.70008 | K30: 259.70008 | L30: 233.60488 | M30: 194.74248
B31: No. of Shares outstanding (Cr) | D31: 40.55
B32: Intrinsic value per share | D32: =D29/D31 -> 1572.1228 | F32: Intrinsic Value | G32: 1 508.98

Sheet Relative Valuation 
B2: Relative Valuation - INFOSYS
B4: Figures in Crore
B5: Comparable Company Valuation
B7: Company Name | C7: Market Data | J7: Financials | O7: Valuation
C8: No. of shares | D8: Share Price | E8: Equity value | F8: Debt | G8: cash | H8: Enterprises value | J8: Revenue | K8: EBITDA | L8: Net Profit | M8: EPS | O8: EV/Revenue | P8: EV/EBITDA | Q8: P/E Ratio
B9: TCS | C9: 361.81 | D9: 2162 | E9: =IFERROR(C9*D9,0) -> 782233.22 | F9: 11283 | G9: 12908 | H9: =IFERROR(E9+F9-G9,0) -> 780608.22 | J9: 267021 | K9: 76450 | L9: 49454 | M9: =IFERROR(L9/C9,0) -> 136.685 | O9: =IFERROR(H9/J9,0) -> 2.9233964 | P9: =IFERROR(H9/K9,0) -> 10.210703 | Q9: =IFERROR(D9/M9,0) -> 15.81739
B10: Infosys | C10: 405.73 | D10: 1134 | E10: =IFERROR(C10*D10,0) -> 460097.82 | F10: 9176 | G10: 22201 | H10: =IFERROR(E10+F10-G10,0) -> 447072.82 | J10: 178650 | K10: 46226 | L10: 29474 | M10: =IFERROR(L10/C10,0) -> 72.644369 | O10: =IFERROR(H10/J10,0) -> 2.5025067 | P10: =IFERROR(H10/K10,0) -> 9.6714581 | Q10: =IFERROR(D10/M10,0) -> 15.610294
B11: HCL | C11: 271.37 | D11: 1119.3 | E11: =IFERROR(C11*D11,0) -> 303744.44 | F11: 303850.07 | G11: 5215 | H11: =IFERROR(E11+F11-G11,0) -> 602379.51 | J11: 130144 | K11: 28282 | L11: 16652 | M11: =IFERROR(L11/C11,0) -> 61.362715 | O11: =IFERROR(H11/J11,0) -> 4.6285615 | P11: =IFERROR(H11/K11,0) -> 21.299042 | Q11: =IFERROR(D11/M11,0) -> 18.240718
B12: WIPRO | C12: 1050.3 | D12: 181.38 | E12: =IFERROR(C12*D12,0) -> 190503.41 | F12: 190545.94 | G12: 20291 | H12: =IFERROR(E12+F12-G12,0) -> 360758.35 | J12: 92624 | K12: 21710 | L12: 13265 | M12: =IFERROR(L12/C12,0) -> 12.629725 | O12: =IFERROR(H12/J12,0) -> 3.8948691 | P12: =IFERROR(H12/K12,0) -> 16.617151 | Q12: =IFERROR(D12/M12,0) -> 14.361358
B13: Tech Mahindra | C13: 98.01 | D13: 1425.6 | E13: =IFERROR(C13*D13,0) -> 139723.06 | F13: 139697.51 | G13: 2186.2 | H13: =IFERROR(E13+F13-G13,0) -> 277234.37 | J13: 9064.5 | K13: 4805.5 | L13: 4805.5 | M13: =IFERROR(L13/C13,0) -> 49.030711 | O13: =IFERROR(H13/J13,0) -> 30.584629 | P13: =IFERROR(H13/K13,0) -> 57.691055 | Q13: =IFERROR(D13/M13,0) -> 29.075654
B15: Max | O15: =IFERROR(MAX(O9:O13),0) -> 30.584629 | P15: =IFERROR(MAX(P9:P13),0) -> 57.691055 | Q15: =IFERROR(MAX(Q9:Q13),0) -> 29.075654
B16: 75th Percentile | O16: =IFERROR(QUARTILE(O9:O13,3),0) -> 4.6285615 | P16: =IFERROR(QUARTILE(P9:P13,3),0) -> 21.299042 | Q16: =IFERROR(QUARTILE(Q9:Q13,3),0) -> 18.240718
B17: Average | O17: =IFERROR(AVERAGE(O9:O13),0) -> 8.9067925 | P17: =IFERROR(AVERAGE(P9:P13),0) -> 23.097882 | Q17: =IFERROR(AVERAGE(Q9:Q13),0) -> 18.621083
B18: median | O18: =IFERROR(MEDIAN(O9:O13),0) -> 3.8948691 | P18: =IFERROR(MEDIAN(P9:P13),0) -> 16.617151 | Q18: =IFERROR(MEDIAN(Q9:Q13),0) -> 15.81739
B19: 25th Percentile | O19: =IFERROR(QUARTILE(O9:O13,1),0) -> 2.9233964 | P19: =IFERROR(QUARTILE(P9:P13,1),0) -> 10.210703 | Q19: =IFERROR(QUARTILE(Q9:Q13,1),0) -> 15.610294
B20: Min. | O20: =IFERROR(MIN(O9:O13),0) -> 2.5025067 | P20: =IFERROR(MIN(P9:P13),0) -> 9.6714581 | Q20: =IFERROR(MIN(Q9:Q13),0) -> 14.361358
B22: M&M Industry Comparable comps | O22: EV/Revenue | P22: EV/EBITDA | Q22: P/E Ratio
B23: Implied Enterprise Value | O23: =O10*J12 -> 231792.18 | P23: =P10*K12 -> 209967.35 | Q23: =SUM(Q25+Q24) -> 196792.68
B24: Net Debt | O24: =F10-G10 -> -13025 | P24: =O24 -> -13025 | Q24: =P24 -> -13025
B25: Implied Market Value | O25: =O23-O24 -> 244817.18 | P25: =P23-P24 -> 222992.35 | Q25: =Q18*L12 -> 209817.68
B26: Share Outstanding | O26: =C10 -> 405.73 | P26: =O26 -> 405.73 | Q26: =P26 -> 405.73
B28: Implied Value per Share | O28: =O25/O26 -> 603.39925 | P28: =P25/P26 -> 549.60775 | Q28: =Q25/Q26 -> 517.13623

Sheet Ratios
A1: Ratio Analysis
A3: Particular | B3: FY 2022 | C3: FY 2023 | D3: FY 2024 | E3: FY 2025 | F3: FY 2026
A4: SECTION 1: GROWTH RATIOS
A5: Sales Growth % | C5: =('Consolidated FS'!D7-'Consolidated FS'!C7)/'Consolidated FS'!C7 -> 0.25509491 | D5: =('Consolidated FS'!E7-'Consolidated FS'!D7)/'Consolidated FS'!D7 -> 0.061275553 | E5: =('Consolidated FS'!F7-'Consolidated FS'!E7)/'Consolidated FS'!E7 -> 0.0059496624 | F5: =('Consolidated FS'!G7-'Consolidated FS'!F7)/'Consolidated FS'!F7 -> 0.096079514
A6: EBITDA Growth % | C6: =(('Consolidated FS'!D7-('Consolidated FS'!D10+'Consolidated FS'!D11+'Consolidated FS'!D12+'Consolidated FS'!D13+'Consolidated FS'!D14+'Consolidated FS'!D15+'Consolidated FS'!D18))-('Consolidated FS'!C7-('Consolidated FS'!C10+'Consolidated FS'!C11+'Consolidated FS'!C12+'Consolidated FS'!C13+'Consolidated FS'!C14+'Consolidated FS'!C15+'Consolidated FS'!C18)))/('Consolidated FS'!C7-('Consolidated FS'!C10+'Consolidated FS'!C11+'Consolidated FS'!C12+'Consolidated FS'!C13+'Consolidated FS'!C14+'Consolidated FS'!C15+'Consolidated FS'!C18)) -> 0.52557874 | D6: =(('Consolidated FS'!E7-('Consolidated FS'!E10+'Consolidated FS'!E11+'Consolidated FS'!E12+'Consolidated FS'!E13+'Consolidated FS'!E14+'Consolidated FS'!E15+'Consolidated FS'!E18))-('Consolidated FS'!D7-('Consolidated FS'!D10+'Consolidated FS'!D11+'Consolidated FS'!D12+'Consolidated FS'!D13+'Consolidated FS'!D14+'Consolidated FS'!D15+'Consolidated FS'!D18)))/('Consolidated FS'!D7-('Consolidated FS'!D10+'Consolidated FS'!D11+'Consolidated FS'!D12+'Consolidated FS'!D13+'Consolidated FS'!D14+'Consolidated FS'!D15+'Consolidated FS'!D18)) -> 0.043004038 | E6: =(('Consolidated FS'!F7-('Consolidated FS'!F10+'Consolidated FS'!F11+'Consolidated FS'!F12+'Consolidated FS'!F13+'Consolidated FS'!F14+'Consolidated FS'!F15+'Consolidated FS'!F18))-('Consolidated FS'!E7-('Consolidated FS'!E10+'Consolidated FS'!E11+'Consolidated FS'!E12+'Consolidated FS'!E13+'Consolidated FS'!E14+'Consolidated FS'!E15+'Consolidated FS'!E18)))/('Consolidated FS'!E7-('Consolidated FS'!E10+'Consolidated FS'!E11+'Consolidated FS'!E12+'Consolidated FS'!E13+'Consolidated FS'!E14+'Consolidated FS'!E15+'Consolidated FS'!E18)) -> -0.21697134 | F6: =(('Consolidated FS'!G7-('Consolidated FS'!G10+'Consolidated FS'!G11+'Consolidated FS'!G12+'Consolidated FS'!G13+'Consolidated FS'!G14+'Consolidated FS'!G15+'Consolidated FS'!G18))-('Consolidated FS'!F7-('Consolidated FS'!F10+'Consolidated FS'!F11+'Consolidated FS'!F12+'Consolidated FS'!F13+'Consolidated FS'!F14+'Consolidated FS'!F15+'Consolidated FS'!F18)))/('Consolidated FS'!F7-('Consolidated FS'!F10+'Consolidated FS'!F11+'Consolidated FS'!F12+'Consolidated FS'!F13+'Consolidated FS'!F14+'Consolidated FS'!F15+'Consolidated FS'!F18)) -> 0.077581813
A7: EBIT Growth % | C7: =(('Consolidated FS'!D7-'Consolidated FS'!D19)-('Consolidated FS'!C7-'Consolidated FS'!C19))/('Consolidated FS'!C7-'Consolidated FS'!C19) -> 0.57048355 | D7: =(('Consolidated FS'!E7-'Consolidated FS'!E19)-('Consolidated FS'!D7-'Consolidated FS'!D19))/('Consolidated FS'!D7-'Consolidated FS'!D19) -> 0.035253989 | E7: =(('Consolidated FS'!F7-'Consolidated FS'!F19)-('Consolidated FS'!E7-'Consolidated FS'!E19))/('Consolidated FS'!E7-'Consolidated FS'!E19) -> -0.24799328 | F7: =(('Consolidated FS'!G7-'Consolidated FS'!G19)-('Consolidated FS'!F7-'Consolidated FS'!F19))/('Consolidated FS'!F7-'Consolidated FS'!F19) -> 0.086861915
A8: Net Profit Growth % | C8: =('Consolidated FS'!D23-'Consolidated FS'!C23)/'Consolidated FS'!C23 -> 0.60877811 | D8: =('Consolidated FS'!E23-'Consolidated FS'!D23)/'Consolidated FS'!D23 -> 0.030621983 | E8: =('Consolidated FS'!F23-'Consolidated FS'!E23)/'Consolidated FS'!E23 -> -0.27149432 | F8: =('Consolidated FS'!G23-'Consolidated FS'!F23)/'Consolidated FS'!F23 -> 0.10183178
A9: SECTION 2: MARGIN RATIOS
A10: EBITDA Margin % | B10: =('Consolidated FS'!C7-('Consolidated FS'!C10+'Consolidated FS'!C11+'Consolidated FS'!C12+'Consolidated FS'!C13+'Consolidated FS'!C14+'Consolidated FS'!C15+'Consolidated FS'!C18))/'Consolidated FS'!C7 -> 0.25888475 | C10: =('Consolidated FS'!D7-('Consolidated FS'!D10+'Consolidated FS'!D11+'Consolidated FS'!D12+'Consolidated FS'!D13+'Consolidated FS'!D14+'Consolidated FS'!D15+'Consolidated FS'!D18))/'Consolidated FS'!D7 -> 0.31467666 | D10: =('Consolidated FS'!E7-('Consolidated FS'!E10+'Consolidated FS'!E11+'Consolidated FS'!E12+'Consolidated FS'!E13+'Consolidated FS'!E14+'Consolidated FS'!E15+'Consolidated FS'!E18))/'Consolidated FS'!E7 -> 0.30925901 | E10: =('Consolidated FS'!F7-('Consolidated FS'!F10+'Consolidated FS'!F11+'Consolidated FS'!F12+'Consolidated FS'!F13+'Consolidated FS'!F14+'Consolidated FS'!F15+'Consolidated FS'!F18))/'Consolidated FS'!F7 -> 0.24072642 | F10: =('Consolidated FS'!G7-('Consolidated FS'!G10+'Consolidated FS'!G11+'Consolidated FS'!G12+'Consolidated FS'!G13+'Consolidated FS'!G14+'Consolidated FS'!G15+'Consolidated FS'!G18))/'Consolidated FS'!G7 -> 0.23666387
A11: EBIT Margin % | B11: =('Consolidated FS'!C7-'Consolidated FS'!C19)/'Consolidated FS'!C7 -> 0.22866468 | C11: =('Consolidated FS'!D7-'Consolidated FS'!D19)/'Consolidated FS'!D7 -> 0.28612507 | D11: =('Consolidated FS'!E7-'Consolidated FS'!E19)/'Consolidated FS'!E7 -> 0.27910953 | E11: =('Consolidated FS'!F7-'Consolidated FS'!F19)/'Consolidated FS'!F7 -> 0.20865084 | F11: =('Consolidated FS'!G7-'Consolidated FS'!G19)/'Consolidated FS'!G7 -> 0.20689617
A12: EBT Margin % | B12: ='Consolidated FS'!C20/'Consolidated FS'!C7 -> 0.24753167 | C12: ='Consolidated FS'!D20/'Consolidated FS'!D7 -> 0.30523151 | D12: ='Consolidated FS'!E20/'Consolidated FS'!E7 -> 0.29735968 | E12: ='Consolidated FS'!F20/'Consolidated FS'!F7 -> 0.23073808 | F12: ='Consolidated FS'!G20/'Consolidated FS'!G7 -> 0.2238735
A13: Net Profit Margin % | B13: ='Consolidated FS'!C23/'Consolidated FS'!C7 -> 0.18206033 | C13: ='Consolidated FS'!D23/'Consolidated FS'!D7 -> 0.23336456 | D13: ='Consolidated FS'!E23/'Consolidated FS'!E7 -> 0.22662412 | E13: ='Consolidated FS'!F23/'Consolidated FS'!F7 -> 0.1641205 | F13: ='Consolidated FS'!G23/'Consolidated FS'!G7 -> 0.16498181
A14: SECTION 3: WORKING CAPITAL & EFFICIENCY RATIOS
A15: Debtor Turnover Ratio | B15: ='Consolidated FS'!C7/'Consolidated FS'!N23 -> 12.1641 | C15: ='Consolidated FS'!D7/(('Consolidated FS'!O23+'Consolidated FS'!N23)/2) -> 13.879182 | D15: ='Consolidated FS'!E7/(('Consolidated FS'!P23+'Consolidated FS'!O23)/2) -> 13.226612 | E15: ='Consolidated FS'!F7/(('Consolidated FS'!Q23+'Consolidated FS'!P23)/2) -> 8.8209985 | F15: ='Consolidated FS'!G7/(('Consolidated FS'!R23+'Consolidated FS'!Q23)/2) -> 7.658179
A16: Debtor Days (DSO) | B16: =365/B17 -> 11.336661 | C16: =365/C17 -> 9.7678464 | D16: =365/D17 -> 9.1316857 | E16: =365/E17 -> 8.6594373 | F16: =365/F17 -> 8.1875412
A17: Creditor Turnover Ratio | B17: =('Consolidated FS'!C10+'Consolidated FS'!C11+'Consolidated FS'!C12+'Consolidated FS'!C13+'Consolidated FS'!C14+'Consolidated FS'!C15+'Consolidated FS'!C18)/'Consolidated FS'!N43 -> 32.196429 | C17: =('Consolidated FS'!D10+'Consolidated FS'!D11+'Consolidated FS'!D12+'Consolidated FS'!D13+'Consolidated FS'!D14+'Consolidated FS'!D15+'Consolidated FS'!D18)/(('Consolidated FS'!O43+'Consolidated FS'!N43)/2) -> 37.3675 | D17: =('Consolidated FS'!E10+'Consolidated FS'!E11+'Consolidated FS'!E12+'Consolidated FS'!E13+'Consolidated FS'!E14+'Consolidated FS'!E15+'Consolidated FS'!E18)/(('Consolidated FS'!P43+'Consolidated FS'!O43)/2) -> 39.970714 | E17: =('Consolidated FS'!F10+'Consolidated FS'!F11+'Consolidated FS'!F12+'Consolidated FS'!F13+'Consolidated FS'!F14+'Consolidated FS'!F15+'Consolidated FS'!F18)/(('Consolidated FS'!Q43+'Consolidated FS'!P43)/2) -> 42.150545 | F17: =('Consolidated FS'!G10+'Consolidated FS'!G11+'Consolidated FS'!G12+'Consolidated FS'!G13+'Consolidated FS'!G14+'Consolidated FS'!G15+'Consolidated FS'!G18)/(('Consolidated FS'!R43+'Consolidated FS'!Q43)/2) -> 44.579928
A18: Payable Days (DPO) | B18: =365/B17 -> 11.336661 | C18: =365/C17 -> 9.7678464 | D18: =365/D17 -> 9.1316857 | E18: =365/E17 -> 8.6594373 | F18: =365/F17 -> 8.1875412
A19: Cash Conversion Cycle | B19: =B18-B21 -> 11.054327 | C19: =C18-C21 -> 9.3357352 | D19: =D18-D21 -> 8.7189712 | E19: =E18-E21 -> 8.3743761 | F19: =F18-F21 -> 7.87647
A20: SECTION 4: RETURN RATIOS
A21: Return on Equity (ROE) % | B21: ='Consolidated FS'!C23/'Consolidated FS'!N35 -> 0.28233404 | C21: ='Consolidated FS'!D23/(('Consolidated FS'!O35+'Consolidated FS'!N35)/2) -> 0.43211119 | D21: ='Consolidated FS'!E23/(('Consolidated FS'!P35+'Consolidated FS'!O35)/2) -> 0.41271447 | E21: ='Consolidated FS'!F23/(('Consolidated FS'!Q35+'Consolidated FS'!P35)/2) -> 0.28506119 | F21: ='Consolidated FS'!G23/(('Consolidated FS'!R35+'Consolidated FS'!Q35)/2) -> 0.31107124
A22: Return on Capital Employed (ROCE) % | B22: =('Consolidated FS'!C7-'Consolidated FS'!C19)*(1-(('Consolidated FS'!C21+'Consolidated FS'!C22)/'Consolidated FS'!C20))/(('Consolidated FS'!N35+('Consolidated FS'!N37+'Consolidated FS'!N38))-'Consolidated FS'!N23) -> 0.27372617 | C22: =('Consolidated FS'!D7-'Consolidated FS'!D19)*(1-(('Consolidated FS'!D21+'Consolidated FS'!D22)/'Consolidated FS'!D20))/(('Consolidated FS'!O35+('Consolidated FS'!O37+'Consolidated FS'!O38))-'Consolidated FS'!O23) -> 0.40648235 | D22: =('Consolidated FS'!E7-'Consolidated FS'!E19)*(1-(('Consolidated FS'!E21+'Consolidated FS'!E22)/'Consolidated FS'!E20))/(('Consolidated FS'!P35+('Consolidated FS'!P37+'Consolidated FS'!P38))-'Consolidated FS'!P23) -> 0.39947851 | E22: =('Consolidated FS'!F7-'Consolidated FS'!F19)*(1-(('Consolidated FS'!F21+'Consolidated FS'!F22)/'Consolidated FS'!F20))/(('Consolidated FS'!Q35+('Consolidated FS'!Q37+'Consolidated FS'!Q38))-'Consolidated FS'!Q23) -> 0.30365392 | F22: =('Consolidated FS'!G7-'Consolidated FS'!G19)*(1-(('Consolidated FS'!G21+'Consolidated FS'!G22)/'Consolidated FS'!G20))/(('Consolidated FS'!R35+('Consolidated FS'!R37+'Consolidated FS'!R38))-'Consolidated FS'!R23) -> 0.34390756
A23: SECTION 5: LEVERAGE & SOLVENCY RATIOS
A24: Interest Coverage Ratio | B24: =('Consolidated FS'!C7-'Consolidated FS'!C19)/'Consolidated FS'!C17 -> 139.075 | C24: =('Consolidated FS'!D7-'Consolidated FS'!D19)/'Consolidated FS'!D17 -> 128.10264 | D24: =('Consolidated FS'!E7-'Consolidated FS'!E19)/'Consolidated FS'!E17 -> 122.55556 | E24: =('Consolidated FS'!F7-'Consolidated FS'!F19)/'Consolidated FS'!F17 -> 81.75 | F24: =('Consolidated FS'!G7-'Consolidated FS'!G19)/'Consolidated FS'!G17 -> 88.850962
A25: Debt to Equity Ratio | B25: =(('Consolidated FS'!N37+'Consolidated FS'!N38+'Consolidated FS'!N45+'Consolidated FS'!N44))/('Consolidated FS'!N35) -> 0.24095157 | C25: =(('Consolidated FS'!O37+'Consolidated FS'!O38+'Consolidated FS'!O45+'Consolidated FS'!O44))/('Consolidated FS'!O35) -> 0.23593907 | D25: =(('Consolidated FS'!P37+'Consolidated FS'!P38+'Consolidated FS'!P45+'Consolidated FS'!P44))/('Consolidated FS'!P35) -> 0.21863658 | E25: =(('Consolidated FS'!Q37+'Consolidated FS'!Q38+'Consolidated FS'!Q45+'Consolidated FS'!Q44))/('Consolidated FS'!Q35) -> 0.24637485 | F25: =(('Consolidated FS'!R37+'Consolidated FS'!R38+'Consolidated FS'!R45+'Consolidated FS'!R44))/('Consolidated FS'!R35) -> 0.26451011
A26: Net Debt to EBITDA | B26: =(('Consolidated FS'!N37+'Consolidated FS'!N38+'Consolidated FS'!N45+'Consolidated FS'!N44)-'Consolidated FS'!N23)/('Consolidated FS'!C7-('Consolidated FS'!C10+'Consolidated FS'!C11+'Consolidated FS'!C12+'Consolidated FS'!C13+'Consolidated FS'!C14+'Consolidated FS'!C15+'Consolidated FS'!C18)) -> 0.28262043 | C26: =(('Consolidated FS'!O37+'Consolidated FS'!O38+'Consolidated FS'!O45+'Consolidated FS'!O44)-'Consolidated FS'!O23)/('Consolidated FS'!D7-('Consolidated FS'!D10+'Consolidated FS'!D11+'Consolidated FS'!D12+'Consolidated FS'!D13+'Consolidated FS'!D14+'Consolidated FS'!D15+'Consolidated FS'!D18)) -> 0.17484701 | D26: =(('Consolidated FS'!P37+'Consolidated FS'!P38+'Consolidated FS'!P45+'Consolidated FS'!P44)-'Consolidated FS'!P23)/('Consolidated FS'!E7-('Consolidated FS'!E10+'Consolidated FS'!E11+'Consolidated FS'!E12+'Consolidated FS'!E13+'Consolidated FS'!E14+'Consolidated FS'!E15+'Consolidated FS'!E18)) -> 0.1496767 | E26: =(('Consolidated FS'!Q37+'Consolidated FS'!Q38+'Consolidated FS'!Q45+'Consolidated FS'!Q44)-'Consolidated FS'!Q23)/('Consolidated FS'!F7-('Consolidated FS'!F10+'Consolidated FS'!F11+'Consolidated FS'!F12+'Consolidated FS'!F13+'Consolidated FS'!F14+'Consolidated FS'!F15+'Consolidated FS'!F18)) -> -0.019191559 | F26: =(('Consolidated FS'!R37+'Consolidated FS'!R38+'Consolidated FS'!R45+'Consolidated FS'!R44)-'Consolidated FS'!R23)/('Consolidated FS'!G7-('Consolidated FS'!G10+'Consolidated FS'!G11+'Consolidated FS'!G12+'Consolidated FS'!G13+'Consolidated FS'!G14+'Consolidated FS'!G15+'Consolidated FS'!G18)) -> 0.05858562
A27: SECTION 6: EFFICIENCY RATIOS
A28: Asset Turnover Ratio | B28: ='Consolidated FS'!C7/'Consolidated FS'!N29 -> 1.0860707 | C28: ='Consolidated FS'!D7/(('Consolidated FS'!O29+'Consolidated FS'!N29)/2) -> 1.2910758 | D28: ='Consolidated FS'!E7/(('Consolidated FS'!P29+'Consolidated FS'!O29)/2) -> 1.2869267 | E28: ='Consolidated FS'!F7/(('Consolidated FS'!Q29+'Consolidated FS'!P29)/2) -> 1.1802104 | F28: ='Consolidated FS'!G7/(('Consolidated FS'!R29+'Consolidated FS'!Q29)/2) -> 1.1719749
A29: Capital Turnover Ratio | B29: ='Consolidated FS'!C7/('Consolidated FS'!N35+(('Consolidated FS'!N37+'Consolidated FS'!N38+'Consolidated FS'!N45+'Consolidated FS'!N44)-'Consolidated FS'!N23)) -> 1.3927455 | C29: ='Consolidated FS'!D7/(('Consolidated FS'!O35+(('Consolidated FS'!O37+'Consolidated FS'!O38+'Consolidated FS'!O45+'Consolidated FS'!O44)-'Consolidated FS'!O23)+'Consolidated FS'!N35+(('Consolidated FS'!N37+'Consolidated FS'!N38+'Consolidated FS'!N45+'Consolidated FS'!N44)-'Consolidated FS'!N23))/2) -> 1.6758433 | D29: ='Consolidated FS'!E7/(('Consolidated FS'!P35+(('Consolidated FS'!P37+'Consolidated FS'!P38+'Consolidated FS'!P45+'Consolidated FS'!P44)-'Consolidated FS'!P23)+'Consolidated FS'!O35+(('Consolidated FS'!O37+'Consolidated FS'!O38+'Consolidated FS'!O45+'Consolidated FS'!O44)-'Consolidated FS'!O23))/2) -> 1.6717585 | E29: ='Consolidated FS'!F7/(('Consolidated FS'!Q35+(('Consolidated FS'!Q37+'Consolidated FS'!Q38+'Consolidated FS'!Q45+'Consolidated FS'!Q44)-'Consolidated FS'!Q23)+'Consolidated FS'!P35+(('Consolidated FS'!P37+'Consolidated FS'!P38+'Consolidated FS'!P45+'Consolidated FS'!P44)-'Consolidated FS'!P23))/2) -> 1.6766276 | F29: ='Consolidated FS'!G7/(('Consolidated FS'!R35+(('Consolidated FS'!R37+'Consolidated FS'!R38+'Consolidated FS'!R45+'Consolidated FS'!R44)-'Consolidated FS'!R23)+'Consolidated FS'!Q35+(('Consolidated FS'!Q37+'Consolidated FS'!Q38+'Consolidated FS'!Q45+'Consolidated FS'!Q44)-'Consolidated FS'!Q23))/2) -> 1.8684893
A30: Fixed Asset Turnover Ratio | B30: ='Consolidated FS'!C7/('Consolidated FS'!N8+'Consolidated FS'!N9) -> 6.796346 | C30: ='Consolidated FS'!D7/((('Consolidated FS'!O8+'Consolidated FS'!O9)+('Consolidated FS'!N8+'Consolidated FS'!N9))/2) -> 8.0087604 | D30: ='Consolidated FS'!E7/((('Consolidated FS'!P8+'Consolidated FS'!P9)+('Consolidated FS'!O8+'Consolidated FS'!O9))/2) -> 8.2771903 | E30: ='Consolidated FS'!F7/((('Consolidated FS'!Q8+'Consolidated FS'!Q9)+('Consolidated FS'!P8+'Consolidated FS'!P9))/2) -> 8.8076518 | F30: ='Consolidated FS'!G7/((('Consolidated FS'!R8+'Consolidated FS'!R9)+('Consolidated FS'!Q8+'Consolidated FS'!Q9))/2) -> 9.6784679
