Workbook

Sheet About 
J19: About
H21: Kotak Mahindra Bank is one of India’s leading private sector banks, serving over 50 million customers across a network of 2,200+ branches. Headquartered in Mumbai, it made history in 2003 as the first non-banking financial company (NBFC) in India to be converted into a fully commercial bank. The bank operates an integrated financial services model spanning consumer, commercial, and corporate banking, alongside major subsidiaries in stock broking, mutual funds, investment banking, and insurance. It is highly regarded in the industry for its strong digital platform (Kotak 811), high financial stability, and excellent asset quality.

Sheet Shareholding 
B2: Promoter
B3: Category of shareholder | C3: Entity Type | D3: Nos. of shareholders | E3: No. of fully paid up equity shares held | F3: Total nos. shares held
B6: A9) Indian | D6: - | E6: - | F6: -
B7: Individuals/Hindu undivided Family | D7: 6 | E7: 2,57,17,43,405 | F7: 2,57,17,43,405
B8: Uday Suresh Kotak | C8: Promoter | D8: 1 | E8: 2,55,51,35,500 | F8: 2,55,51,35,500
B9: Pallavi Kotak | C9: Promoter Group | D9: 1 | E9: 55,57,900 | F9: 55,57,900
B10: Suresh Amritlal Kotak | C10: Promoter Group | D10: 1 | E10: 5,00,000 | F10: 5,00,000
B11: Suresh A Kotak (HUF) | C11: Promoter Group | D11: 1 | E11: 5,50,000 | F11: 5,50,000
B12: Indira Suresh Kotak | C12: Promoter Group | D12: 1 | E12: 1,00,00,000 | F12: 1,00,00,000
B13: Janak Dinkarrai Desai | C13: Promoter Group | D13: 1 | E13: 5 | F13: 5
B14: Jay Kotak | C14: Promoter Group | D14: - | E14: - | F14: -
B15: Uday S Kotak (HUF) | C15: Promoter Group | D15: - | E15: - | F15: -
B16: Any Other (specify) | D16: 2 | E16: 11,71,780 | F16: 11,71,780
B17: Kotak Trustee Company Private Limited | C17: Promoter Group | D17: 1 | E17: 2,20,000 | F17: 2,20,000
B18: Kotak Trustee Company Private Limited | C18: Promoter Group | D18: 1 | E18: 9,51,780 | F18: 9,51,780
B19: Infina Finance Private Limited | C19: Promoter Group | D19: - | E19: - | F19: -
B20: Laburnum Adarsh Trust | C20: Promoter Group | D20: - | E20: - | F20: -
B21: Kotak Trustee Company Private Limited | C21: Promoter Group | D21: - | E21: - | F21: -
B22: Amrit Lila Enterprises Private Limited | C22: Promoter Group | D22: - | E22: - | F22: -
B23: Business Standard Private Limited | C23: Promoter Group | D23: - | E23: - | F23: -
B24: Insurekot Sports Private Limited | C24: Promoter Group | D24: - | E24: - | F24: -
B25: Kotak Commodity Services Private Limited | C25: Promoter Group | D25: - | E25: - | F25: -
B26: Helena Realty Private Limited | C26: Promoter Group | D26: - | E26: - | F26: -
B27: Puma Properties Private Limited | C27: Promoter Group | D27: - | E27: - | F27: -
B28: Palko Properties Private Limited | C28: Promoter Group | D28: - | E28: - | F28: -
B29: Harisiddha Trading & Finance Private Limited | C29: Promoter Group | D29: - | E29: - | F29: -
B30: Aero Agencies Private Limited | C30: Promoter Group | D30: - | E30: - | F30: -
... B42: Freeland Foods, Inc. | C42: Promoter Group | D42: - | E42: - | F42: -
B43: Sub Total A1 | D43: 8 | E43: 2,57,29,15,185 | F43: 2,57,29,15,185
B44: A10) Foreign | D44: - | E44: - | F44: -
B45: Individuals (NonResident Individuals/ Foreign Individuals) | D45: 1 | E45: 2,86,800 | F45: 2,86,800
B46: Aarti Neal Chandaria | C46: Promoter Group | D46: 1 | E46: 2,86,800 | F46: 2,86,800
B47: Dhawal Kotak | C47: Promoter Group | D47: - | E47: - | F47: -
B48: Sub Total A2 | D48: 1 | E48: 2,86,800 | F48: 2,86,800
B49: A=A1+A2 | D49: 9 | E49: 2,57,32,01,985 | F49: 2,57,32,01,985
B50: Public
B51: Category & Name of the Shareholders | C51: No. of shareholder | D51: No. of fully paid up equity shares held | E51: Total no. shares held | F51: Shareholding % calculated as per SCRR, 1957 As a % of (A+B+C2)
B54: Institutions | C54: 0 | D54: 0 | E54: - | F54: 0
B55: B2) Institutions (Domestic) | C55: 0 | D55: 0 | E55: - | F55: 0
B56: Mutual Funds/ | C56: 47 | D56: 2,34,39,06,602 | E56: 2,34,39,06,602 | F56: 23.57
...

Sheet Consolidated FS
B2: Audited Consolidated Profit and Loss Account (For the year ended) | K2: Audited Consolidated Balance Sheet (As of March 31st) | S2: Audited Consolidated Cash Flow Statement
B3: Particulars (₹ in crore) | C3: 2021 | D3: 2022 | E3: 2023 | F3: 2024 | G3: 2025 | K3: Capital and Liabilities (₹ in crore) | L3: 2021 | M3: 2022 | N3: 2023 | O3: 2024 | P3: 2025 | S3: Particulars (₹ in crore) | T3: 2021 | U3: 2022 | V3: 2023 | W3: 2024 | X3: 2025
B4: I. INCOME | K4: Capital | L4: 1490.92 | M4: 1492.33 | N4: 1493.28 | O4: 993.96 | P4: 994.11 | S4: Net Profit Before Taxes | T4: 1316.83 | U4: 1594.83 | V4: 19646.18 | W4: 23863.38 | X4: 28989.03
B5: Interest Earned | C5: 53947 | D5: 62452 | E5: 42151.06 | F5: 56236.63 | G5: 65668.83 | K5: Employees' Stock Options Outstanding | L5: 2.16 | M5: 31.31 | N5: 60.31 | O5: 79.2938 | P5: 94.27 | S5: Adjustments for:
B6: Other Income | C6: 19606 | D6: 24565 | E6: 30163 | F6: 36685 | G6: 43703 | K6: Reserves and Surplus | L6: 83345.53 | M6: 95641.7 | N6: 110760.81 | O6: 128898.44 | P6: 156400.97 | S6: Depreciation | T6: 461.05 | U6: 480.35 | V6: 599.26 | W6: 791.75 | X6: 940.91
B7: Total Income | C7: 73553 | D7: 87017 | E7: 68142.03 | F7: 94273.91 | G7: 106902.24 | K7: Deposits | L7: 278871.41 | M7: 310086.89 | N7: 361272.62 | O7: 445268.76 | P7: 494707.48 | S7: (Profit) / Loss on sale of Investments | T7: -1767.77 | U7: -1547.75 | V7: -906.86 | W7: -2773.55 | X7: -4730.27
B8: II. EXPENDITURE | K8: Borrowings | L8: 47738.9 | M8: 55148.27 | N8: 57033.92 | O8: 75105.61 | P8: 97622.03 | S8: Provision for NPAs & Others | T8: 288.04 | U8: 427.51 | V8: 457.85 | W8: 1898.24 | X8: 3765.59
B9: Interest Expended | C9: 26891 | D9: 31254 | E9: 14411.13 | F9: 22567.24 | G9: 28274.55 | K9: Policyholders' Funds | L9: 42071.52 | M9: 50666.79 | N9: 57979.47 | O9: 73375.6 | P9: 85121.06 | S9: Operating Profit before WC Changes | T9: 1189.98 | U9: 1568.5 | V9: 21798.52 | W9: 19519.48 | X9: 25454.35
B10: Operating Expenses | C10: 20341 | D10: 24487 | E10: 29822 | F10: 36057 | G10: 42334 | K10: Other Liabilities and Provisions | L10: 25352.26 | M10: 33430.62 | N10: 31829.32 | O10: 43945.3 | P10: 44834.42 | S10: Changes in Working Capital:
B11: Provisions & Contingencies | C11: 3221 | D11: 4567 | E11: 5305.42 | F11: 7859.02 | G11: 10902.53 | K11: Total Liabilities | L11: 478872.69 | M11: 546497.91 | N11: 620429.73 | O11: 767666.96 | P11: 879774.34 | S11: (Increase) / Decrease in Investments | T11: -3027.21 | U11: -3839.24 | V11: -22134.83 | W11: -36326.75 | X11: -685.57
B12: Total Expenditure | C12: =SUM(C9:C11) -> 50453 | D12: =SUM(D9:D11) -> 60308 | E12: =SUM(E9:E11) -> 49538.55 | F12: =SUM(F9:F11) -> 66483.26 | G12: =SUM(G9:G11) -> 81511.08 | S12: (Increase) / Decrease in Advances | T12: -437.16 | U12: -5228.54 | V12: -55142.32 | W12: -70818.64 | X12: -59396.48
B13: III. PROFIT / LOSS | K13: Assets | S13: Increase / (Decrease) in Deposits | T13: -394.45 | U13: 3121.55 | V13: 51185.73 | W13: 83996.14 | X13: 49438.71
B14: Profit before Tax | C14: =C7-C12 -> 23100 | D14: =D7-D12 -> 26709 | E14: =E7-E12 -> 18603.48 | F14: =F7-F12 -> 27790.65 | G14: =G7-G12 -> 25391.16 | K14: Cash and Balances with RBI | L14: 12528 | M14: 19985.2 | N14: 19985.2 | O14: 36286.74 | P14: 41748.35 | S14: Net Cash from Operating Activities | T14: 488.11 | U14: 1568.5 | V14: -1242.43 | W14: 15685 | X14: 16915.73
B15: Less: Provision for Taxes | C15: 5878 | D15: 7546 | E15: 4865.74 | F15: 5886.56 | G15: 7043.29 | K15: Balances with Banks & Money at Call | L15: 35188.62 | M15: 22940.14 | N15: 22940.14 | O15: 28919.65 | P15: 37313.4 | S15: Net Cash from Investing Activities | T15: -1111.61 | U15: -909.69 | V15: -10550.18 | W15: -9096.93 | X15: -25272.08
B16: NET PROFIT AFTER TAX | C16: 9990 | D16: 12089 | E16: 14925.01 | F16: 18213.21 | G16: 22125.99 | K16: Investments | L16: 156945.55 | M16: 195337.97 | N16: 195337.97 | O16: 246445.72 | P16: 284255 | S16: Net Cash from Financing Activities | T16: -1007.21 | U16: 754.89 | V16: 1883 | W16: 15515.11 | X16: 22165.2
K17: Advances | L17: 252188.22 | M17: 304473.6 | N17: 359107.46 | O17: 430351.58 | P17: 486165.52 | S17: Net Change in Cash & Equivalents | T17: -1636.32 | U17: -89.45 | V17: -9740.14 | W17: 22281.04 | X17: 13878.61
K18: Fixed Assets | L18: 1740.16 | M18: 1909.63 | N18: 2261.2 | O18: 2562.51 | P18: 2810.8 | S18: Opening Cash & Equivalents | T18: 6407.99 | U18: 4771.66 | V18: 52665.48 | W18: 42925.35 | X18: 65206.39
K19: Other Assets | L19: 19468.38 | M19: 4009.94 | N19: 19984 | O19: 22153 | P19: 26533.51 | S19: Closing Cash & Equivalents | T19: 4771.66 | U19: 5266.55 | V19: 42925.35 | W19: 65206.39 | X19: 79061.75
K20: Goodwill on Consolidation | L20: 813.75 | M20: 813.75 | N20: 813.75 | O20: 947.76 | P20: 947.76
K21: Total Assets | L21: 478872.69 | M21: 546497.91 | N21: 620429.73 | O21: 767666.96 | P21: 879774.34
K23: Contingent Liabilities | L23: 202290.05 | M23: 202290.05 | N23: 467640.38 | O23: 734057.38 | P23: 1127159.3
K24: Bills for Collection | L24: 41272.8 | M24: 41272.8 | N24: 44655.24 | O24: 47467.71 | P24: 52690.82

Sheet Assumptions 
C2: Actual | H2: Average | I2: Estimated
C3: 2021 | D3: =C3+1 -> 2022 | E3: =D3+1 -> 2023 | F3: =G3-1 -> 2024 | G3: 2025 | I3: =G3+1 -> 2026 | J3: =I3+1 -> 2027 | K3: =J3+1 -> 2028 | L3: =K3+1 -> 2029 | M3: =L3+1 -> 2030
B4: Assumptions
B5: Loan Growth % | D5: =('Consolidated FS'!M17-'Consolidated FS'!L17)/'Consolidated FS'!L17 -> 0.20732681 | E5: =('Consolidated FS'!N17-'Consolidated FS'!M17)/'Consolidated FS'!M17 -> 0.1794371 | F5: =('Consolidated FS'!O17-'Consolidated FS'!N17)/'Consolidated FS'!N17 -> 0.1983922 | G5: =('Consolidated FS'!P17-'Consolidated FS'!O17)/'Consolidated FS'!O17 -> 0.12969382 | H5: =MEDIAN(D5:G5) -> 0.18891465 | I5: =H5+V5 -> 0.17113172 | J5: =I5+$V$5 -> 0.15334879 | K5: =J5+$V$5 -> 0.13556586 | L5: =K5+$V$5 -> 0.11778293 | M5: =L5+$V$5 -> 0.1 | P5: Terminal Growth | R5: 0.1 | T5: Annual Step Down | V5: =-(H5-R5)/5 -> -0.01778293
B6: Deposit Growth % | D6: =('Consolidated FS'!M7-'Consolidated FS'!L7)/'Consolidated FS'!L7 -> 0.11193503 | E6: =('Consolidated FS'!N7-'Consolidated FS'!M7)/'Consolidated FS'!M7 -> 0.16506899 | F6: =('Consolidated FS'!O7-'Consolidated FS'!N7)/'Consolidated FS'!N7 -> 0.23250071 | G6: =('Consolidated FS'!P7-'Consolidated FS'!O7)/'Consolidated FS'!O7 -> 0.11103119 | H6: =MEDIAN(D6:G6) -> 0.13850201 | I6: =I5-$R$6 -> 0.16113172 | J6: =J5-$R$6 -> 0.14334879 | K6: =K5-$R$6 -> 0.12556586 | L6: =L5-$R$6 -> 0.10778293 | M6: =M5-$R$6 -> 0.09 | P6: Spread to Loan Growth | R6: 0.01
B7: NIM % | D7: =('Consolidated FS'!D5-'Consolidated FS'!D9)/AVERAGE('Consolidated FS'!M17+'Consolidated FS'!M16+'Consolidated FS'!M15,'Consolidated FS'!L17+'Consolidated FS'!L16+'Consolidated FS'!L15) -> 0.064520392 | E7: =('Consolidated FS'!E5-'Consolidated FS'!E9)/AVERAGE('Consolidated FS'!N17+'Consolidated FS'!N16+'Consolidated FS'!N15,'Consolidated FS'!M17+'Consolidated FS'!M16+'Consolidated FS'!M15) -> 0.050429943 | F7: =('Consolidated FS'!F5-'Consolidated FS'!F9)/AVERAGE('Consolidated FS'!O17+'Consolidated FS'!O16+'Consolidated FS'!O15,'Consolidated FS'!N17+'Consolidated FS'!N16+'Consolidated FS'!N15) -> 0.052481216 | G7: =('Consolidated FS'!G5-'Consolidated FS'!G9)/AVERAGE('Consolidated FS'!P17+'Consolidated FS'!P16+'Consolidated FS'!P15,'Consolidated FS'!O17+'Consolidated FS'!O16+'Consolidated FS'!O15) -> 0.049415915 | H7: =AVERAGE(D7:G7) -> 0.054211866 | I7: =G7 -> 0.049415915 | J7: =I7+$V$7 -> 0.048665915 | K7: =J7+$V$7 -> 0.047915915 | L7: =K7+$V$7 -> 0.047165915 | M7: =L7+$V$7 -> 0.046415915 | P7: Terminal NIM | R7: =G7-0.003 -> 0.046415915 | T7: Annual Step Down | V7: =-(G7-R7)/4 -> -0.00075
B8: Cost to Income % | C8: ='Consolidated FS'!C10/'Consolidated FS'!C7 -> 0.27654888 | D8: ='Consolidated FS'!D10/'Consolidated FS'!D7 -> 0.28140478 | E8: ='Consolidated FS'!E10/'Consolidated FS'!E7 -> 0.43764473 | F8: ='Consolidated FS'!F10/'Consolidated FS'!F7 -> 0.38247061 | G8: ='Consolidated FS'!G10/'Consolidated FS'!G7 -> 0.39600667 | H8: =MEDIAN(D8:G8) -> 0.38923864 | I8: =H8+V8 -> 0.35939091 | J8: =I8+$V$8 -> 0.32954318 | K8: =J8+$V$8 -> 0.29969546 | L8: =K8+$V$8 -> 0.26984773 | M8: =L8+$V$8 -> 0.24 | P8: Terminal CTI | R8: 0.24 | T8: Annual Step Down | V8: =-(H8-R8)/5 -> -0.029847728
B9: Credit Cost % | D9: ='Consolidated FS'!D11/AVERAGE('Consolidated FS'!M17,'Consolidated FS'!L17) -> 0.016408526 | E9: ='Consolidated FS'!E11/AVERAGE('Consolidated FS'!N17,'Consolidated FS'!M17) -> 0.01599027 | F9: ='Consolidated FS'!F11/AVERAGE('Consolidated FS'!O17,'Consolidated FS'!N17) -> 0.019909887 | G9: ='Consolidated FS'!G11/AVERAGE('Consolidated FS'!P17,'Consolidated FS'!O17) -> 0.02379122 | H9: =AVERAGE(D9:G9) -> 0.019024976 | I9: =H9+V9 -> 0.01801998 | J9: =I9+$V$9 -> 0.017014985 | K9: =J9+$V$9 -> 0.01600999 | L9: =K9+$V$9 -> 0.015004995 | M9: =L9+$V$9 -> 0.014 | P9: Terminal Cost | R9: 0.014 | T9: Annual Step Down | V9: =-(H9-R9)/5 -> -0.0010049951
B10: Tax Rate % | C10: ='Consolidated FS'!C15/'Consolidated FS'!C14 -> 0.25445887 | D10: ='Consolidated FS'!D15/'Consolidated FS'!D14 -> 0.28252649 | E10: ='Consolidated FS'!E15/'Consolidated FS'!E14 -> 0.26154999 | F10: ='Consolidated FS'!F15/'Consolidated FS'!F14 -> 0.211818 | G10: ='Consolidated FS'!G15/'Consolidated FS'!G14 -> 0.27739142 | H10: =AVERAGE(C10:G10) -> 0.25754896 | I10: =$H$10 -> 0.25754896 | J10: =$H$10 -> 0.25754896 | K10: =$H$10 -> 0.25754896 | L10: =$H$10 -> 0.25754896 | M10: =$H$10 -> 0.25754896
B11: Dividend Payout % | C11: =1988.22/'Consolidated FS'!C16 -> 0.19902102 | D11: =1988.22/'Consolidated FS'!D16 -> 0.16446522 | E11: =1988.22/'Consolidated FS'!E16 -> 0.13321398 | F11: =1988.22/'Consolidated FS'!F16 -> 0.10916362 | G11: =1988.22/'Consolidated FS'!G16 -> 0.08985903 | H11: =MEDIAN(C11:G11) -> 0.13321398 | I11: =(1988/I29)+$V$11 -> 0.055262129 | J11: =1988.22/J29 -> 0.042329017 | K11: =1988.22/K29 -> 0.035441984 | L11: =1988.22/L29 -> 0.030469038 | M11: =1988.22/M29 -> 0.026892401 | P11: Terminal Payout | R11: 0.15 | T11: Annual Step Down | V11: =(R11-H11)/5 -> 0.0033572038
B12: Yield on Earning Assets % | D12: ='Consolidated FS'!D5 / AVERAGE('Consolidated FS'!M17+'Consolidated FS'!M16, 'Consolidated FS'!L17+'Consolidated FS'!L16) -> 0.1374164 | E12: ='Consolidated FS'!E5 / AVERAGE('Consolidated FS'!N17+'Consolidated FS'!N16, 'Consolidated FS'!M17+'Consolidated FS'!M16) -> 0.079963538 | F12: ='Consolidated FS'!F5 / AVERAGE('Consolidated FS'!O17+'Consolidated FS'!O16, 'Consolidated FS'!N17+'Consolidated FS'!N16) -> 0.09134938 | G12: ='Consolidated FS'!G5 / AVERAGE('Consolidated FS'!P17+'Consolidated FS'!P16, 'Consolidated FS'!O17+'Consolidated FS'!O16) -> 0.090751826
B14: Advances (Loans) | C14: ='Consolidated FS'!L17 -> 252188.22 | D14: ='Consolidated FS'!M17 -> 304473.6 | E14: ='Consolidated FS'!N17 -> 359107.46 | F14: ='Consolidated FS'!O17 -> 430351.58 | G14: ='Consolidated FS'!P17 -> 486165.52 | I14: =G14*(1+I5) -> 569363.86 | J14: =I14*(1+J5) -> 656675.12 | K14: =J14*(1+K5) -> 745697.85 | L14: =K14*(1+L5) -> 833528.33 | M14: =L14*(M5+1) -> 916881.16
B15: Deposits | C15: ='Consolidated FS'!L7 -> 278871.41 | D15: ='Consolidated FS'!M7 -> 310086.89 | E15: ='Consolidated FS'!N7 -> 361272.62 | F15: ='Consolidated FS'!O7 -> 445268.76 | G15: ='Consolidated FS'!P7 -> 494707.48 | I15: =G15*(I6+1) -> 574420.55 | J15: =I15*(1+J6) -> 656763.04 | K15: =J15*(1+K6) -> 739230.06 | L15: =K15*(1+L6) -> 818906.44 | M15: =L15*(1+M6) -> 892608.02
B16: Borrowings | C16: ='Consolidated FS'!L8 -> 47738.9 | D16: ='Consolidated FS'!M8 -> 55148.27 | E16: ='Consolidated FS'!N8 -> 57033.92 | F16: ='Consolidated FS'!O8 -> 75105.61 | G16: ='Consolidated FS'!P8 -> 97622.03 | I16: =I14*0.18 -> 102485.5 | J16: =J14*0.18 -> 118201.52 | K16: =K14*0.18 -> 134225.61 | L16: =L14*0.18 -> 150035.1 | M16: =M14*0.18 -> 165038.61
B18: Interest Income | C18: ='Consolidated FS'!C5 -> 53947 | D18: ='Consolidated FS'!D5 -> 62452 | E18: ='Consolidated FS'!E5 -> 42151.06 | F18: ='Consolidated FS'!F5 -> 56236.63 | G18: ='Consolidated FS'!G5 -> 65668.83 | I18: =((I14+G14)/2)*(('Consolidated FS'!P15+'Consolidated FS'!P16+'Consolidated FS'!P17)/'Consolidated FS'!P17)*I7+I19 -> 75582.389 | J18: =((J14+I14)/2)*(('Consolidated FS'!P15+'Consolidated FS'!P16+'Consolidated FS'!P17)/'Consolidated FS'!P17)*J7+J19 -> 86458.943 | K18: =((K14+J14)/2)*(('Consolidated FS'!P15+'Consolidated FS'!P16+'Consolidated FS'!P17)/'Consolidated FS'!P17)*K7+K19 -> 97708.445 | L18: =((L14+K14)/2)*(('Consolidated FS'!P15+'Consolidated FS'!P16+'Consolidated FS'!P17)/'Consolidated FS'!P17)*L7+L19 -> 108693.19 | M18: =((M14+L14)/2)*(('Consolidated FS'!P15+'Consolidated FS'!P16+'Consolidated FS'!P17)/'Consolidated FS'!P17)*M7+M19 -> 118990.27
B19: Interest Expense | C19: ='Consolidated FS'!C9 -> 26891 | D19: ='Consolidated FS'!D9 -> 31254 | E19: ='Consolidated FS'!E9 -> 14411.13 | F19: ='Consolidated FS'!F9 -> 22567.24 | G19: ='Consolidated FS'!G9 -> 28274.55 | I19: =((I15 + I16 + G15 + G16) / 2) * WACC!$F$16 -> 32252.125 | J19: =((J15 + J16 + I15 + I16) / 2) * WACC!$F$16 -> 36893.003 | K19: =((K15 + K16 + J15 + J16) / 2) * WACC!$F$16 -> 41887.461 | L19: =((L15 + L16 + K15 + K16) / 2) * WACC!$F$16 -> 46816.546 | M19: =((M15 + M16 + L15 + L16) / 2) * WACC!$F$16 -> 51496.961
B20: NII | C20: =C18-C19 -> 27056 | D20: =D18-D19 -> 31198 | E20: =E18-E19 -> 27739.93 | F20: =F18-F19 -> 33669.39 | G20: =G18-G19 -> 37394.28 | I20: =I18-I19 -> 43330.265 | J20: =J18-J19 -> 49565.94 | K20: =K18-K19 -> 55820.985 | L20: =L18-L19 -> 61876.647 | M20: =M18-M19 -> 67493.313
B21: Other Income | C21: ='Consolidated FS'!C6 -> 19606 | D21: ='Consolidated FS'!D6 -> 24565 | E21: ='Consolidated FS'!E6 -> 30163 | F21: ='Consolidated FS'!F6 -> 36685 | G21: ='Consolidated FS'!G6 -> 43703 | I21: =G21*(1+R21+V21) -> 52043.462 | J21: =I21*(1+R21+2*V21) -> 60351.322 | K21: =J21*(1+R21+3*V21) -> 68101.764 | L21: =K21*(1+R21+4*V21) -> 74722.007 | M21: =L21*(1+R21+5*V21) -> 79653.659 | P21: Other Income growth | R21: =MEDIAN((D21-C21)/C21,(E21-D21)/D21,(F21-E21)/E21,(G21-F21)/F21) -> 0.22205519 | T21: Annual Step Down | V21: =-(R21-WACC!$C$15)/5 -> -0.031211038
B22: Total Income | C22: ='Consolidated FS'!C7 -> 73553 | D22: ='Consolidated FS'!D7 -> 87017 | E22: ='Consolidated FS'!E7 -> 68142.03 | F22: ='Consolidated FS'!F7 -> 94273.91 | G22: ='Consolidated FS'!G7 -> 106902.24 | I22: =I21+I20 -> 95373.727 | J22: =J21+J20 -> 109917.26 | K22: =K21+K20 -> 123922.75 | L22: =L21+L20 -> 136598.65 | M22: =M21+M20 -> 147146.97
B24: Operating Expense | C24: ='Consolidated FS'!C10 -> 20341 | D24: ='Consolidated FS'!D10 -> 24487 | E24: ='Consolidated FS'!E10 -> 29822 | F24: ='Consolidated FS'!F10 -> 36057 | G24: ='Consolidated FS'!G10 -> 42334 | I24: =I22*I8 -> 34276.451 | J24: =J22*J8 -> 36222.484 | K24: =K22*K8 -> 37139.085 | L24: =L22*L8 -> 36860.836 | M24: =M22*M8 -> 35315.273
B25: Provisions | C25: ='Consolidated FS'!C11 -> 3221 | D25: ='Consolidated FS'!D11 -> 4567 | E25: ='Consolidated FS'!E11 -> 5305.42 | F25: ='Consolidated FS'!F11 -> 7859.02 | G25: ='Consolidated FS'!G11 -> 10902.53 | I25: =((I14+G14)/2)*I9 -> 9510.3094 | J25: =((J14+I14)/2)*J9 -> 10430.518 | K25: =((K14+J14)/2)*K9 -> 11225.989 | L25: =((L14+K14)/2)*L9 -> 11848.141 | M25: =((M14+L14)/2)*M9 -> 12252.866
B26: PBT | C26: ='Consolidated FS'!C14 -> 23100 | D26: ='Consolidated FS'!D14 -> 26709 | E26: ='Consolidated FS'!E14 -> 18603.48 | F26: ='Consolidated FS'!F14 -> 27790.65 | G26: ='Consolidated FS'!G14 -> 25391.16 | I26: =I22-I24-I25 -> 51586.967 | J26: =J22-J24-J25 -> 63264.26 | K26: =K22-K24-K25 -> 75557.675 | L26: =L22-L24-L25 -> 87889.677 | M26: =M22-M24-M25 -> 99578.833
B27: Tax | C27: ='Consolidated FS'!C15 -> 5878 | D27: ='Consolidated FS'!D15 -> 7546 | E27: ='Consolidated FS'!E15 -> 4865.74 | F27: ='Consolidated FS'!F15 -> 5886.56 | G27: ='Consolidated FS'!G15 -> 7043.29 | I27: =I26*I10 -> 13286.169 | J27: =J26*J10 -> 16293.644 | K27: =K26*K10 -> 19459.8 | L27: =L26*L10 -> 22635.895 | M27: =M26*M10 -> 25646.424
B29: PAT | C29: ='Consolidated FS'!C16 -> 9990 | D29: ='Consolidated FS'!D16 -> 12089 | E29: ='Consolidated FS'!E16 -> 14925.01 | F29: ='Consolidated FS'!F16 -> 18213.21 | G29: ='Consolidated FS'!G16 -> 22125.99 | I29: =I26-I27 -> 38300.797 | J29: =J26-J27 -> 46970.616 | K29: =K26-K27 -> 56097.875 | L29: =L26-L27 -> 65253.783 | M29: =M26-M27 -> 73932.408

Sheet Equity Schedule 
C2: 2021 | D2: =C2+1 -> 2022 | E2: =D2+1 -> 2023 | F2: =E2+1 -> 2024 | G2: =F2+1 -> 2025 | H2: =G2+1 -> 2026 | I2: =H2+1 -> 2027 | J2: =I2+1 -> 2028 | K2: =J2+1 -> 2029 | L2: =K2+1 -> 2030
B3: Opening Equity | C3: ='Consolidated FS'!L4+'Consolidated FS'!L6 -> 84836.45 | D3: =C7 -> 92838.23 | E3: =D7 -> 102939.01 | F3: =E7 -> 115875.8 | G3: =F7 -> 132100.79 | H3: =G7 -> 152238.56 | I3: =H7 -> 188422.77 | J3: =I7 -> 233405.17 | K3: =J7 -> 287514.82 | L3: =K7 -> 350780.39
B4: PAT | C4: ='Assumptions '!C29 -> 9990 | D4: ='Assumptions '!D29 -> 12089 | E4: ='Assumptions '!E29 -> 14925.01 | F4: ='Assumptions '!F29 -> 18213.21 | G4: ='Assumptions '!G29 -> 22125.99 | H4: ='Assumptions '!I29 -> 38300.797 | I4: ='Assumptions '!J29 -> 46970.616 | J4: ='Assumptions '!K29 -> 56097.875 | K4: ='Assumptions '!L29 -> 65253.783 | L4: ='Assumptions '!M29 -> 73932.408
B5: Dividend Paid | C5: ='Assumptions '!C29*'Assumptions '!C11 -> 1988.22 | D5: ='Assumptions '!D29*'Assumptions '!D11 -> 1988.22 | E5: ='Assumptions '!E29*'Assumptions '!E11 -> 1988.22 | F5: ='Assumptions '!F29*'Assumptions '!F11 -> 1988.22 | G5: ='Assumptions '!G29*'Assumptions '!G11 -> 1988.22 | H5: ='Assumptions '!I29*'Assumptions '!I11 -> 2116.5836 | I5: ='Assumptions '!J29*'Assumptions '!J11 -> 1988.22 | J5: ='Assumptions '!K29*'Assumptions '!K11 -> 1988.22 | K5: ='Assumptions '!L29*'Assumptions '!L11 -> 1988.22 | L5: ='Assumptions '!M29*'Assumptions '!M11 -> 1988.22
B6: Retained Earnings | C6: =C4-C5 -> 8001.78 | D6: =D4-D5 -> 10100.78 | E6: =E4-E5 -> 12936.79 | F6: =F4-F5 -> 16224.99 | G6: =G4-G5 -> 20137.77 | H6: =H4-H5 -> 36184.214 | I6: =I4-I5 -> 44982.396 | J6: =J4-J5 -> 54109.655 | ... L6: =L4-L5 -> 71944.188
B7: Closing Equity | C7: =C3+C6 -> 92838.23 | D7: =D3+D6 -> 102939.01 | E7: =E3+E6 -> 115875.8 | F7: =F3+F6 -> 132100.79 | G7: =G3+G6 -> 152238.56 | H7: =H3+H6 -> 188422.77 | I7: =I3+I6 -> 233405.17 | J7: =J3+J6 -> 287514.82 | ... L7: =L3+L6 -> 422724.57
B8: Average Equity | C8: =(C3+C7)/2 -> 88837.34 | D8: =(D3+D7)/2 -> 97888.62 | E8: =(E3+E7)/2 -> 109407.4 | F8: =(F3+F7)/2 -> 123988.29 | G8: =(G3+G7)/2 -> 142169.67 | H8: =(H3+H7)/2 -> 170330.67 | I8: =(I3+I7)/2 -> 210913.97 | J8: =(J3+J7)/2 -> 260460 | ... L8: =(L3+L7)/2 -> 386752.48
B9: RoE | C9: =C4/C8 -> 0.11245271 | D9: =D4/D8 -> 0.1234975 | E9: =E4/E8 -> 0.13641682 | F9: =F4/F8 -> 0.14689459 | G9: =G4/G8 -> 0.15563087 | H9: =H4/H8 -> 0.22486143 | I9: =I4/I8 -> 0.22270035 | J9: =J4/J8 -> 0.21538 | ... L9: =L4/L8 -> 0.19116208
B10: Ke | C10: =WACC!$C$18 -> 0.13429084 | D10: =WACC!$C$18 -> 0.13429084 | E10: =WACC!$C$18 -> 0.13429084 | F10: =WACC!$C$18 -> 0.13429084 | G10: =WACC!$C$18 -> 0.13429084 | H10: =WACC!$C$18 -> 0.13429084 | I10: =WACC!$C$18 -> 0.13429084 | J10: =WACC!$C$18 -> 0.13429084 | ... L10: =WACC!$C$18 -> 0.13429084
B11: Excess Returns | C11: =C9-C10 -> -0.021838121 | D11: =D9-D10 -> -0.010793334 | E11: =E9-E10 -> 0.002125982 | F11: =F9-F10 -> 0.012603756 | G11: =G9-G10 -> 0.021340033 | H11: =H9-H10 -> 0.090570594 | I11: =I9-I10 -> 0.088409516 | J11: =J9-J10 -> 0.081089167 | ... L11: =L9-L10 -> 0.056871244

Sheet Residual Income Schedule 
B2: B | C2: C | D2: D | E2: E | F2: F | G2: G | J2: KOTAKBANK.NS
B3: Item | C3: 2026 | D3: 2027 | E3: 2028 | F3: 2029 | G3: 2030 | J3: exchangeName | K3: NSI
B4: Opening Equity | C4: ='Equity Schedule '!H3 -> 152238.56 | D4: ='Equity Schedule '!I3 -> 188422.77 | E4: ='Equity Schedule '!J3 -> 233405.17 | F4: ='Equity Schedule '!K3 -> 287514.82 | G4: ='Equity Schedule '!L3 -> 350780.39 | J4: fullExchangeName | K4: NSE
B5: PAT | C5: ='Equity Schedule '!H4 -> 38300.797 | D5: ='Equity Schedule '!I4 -> 46970.616 | E5: ='Equity Schedule '!J4 -> 56097.875 | F5: ='Equity Schedule '!K4 -> 65253.783 | G5: ='Equity Schedule '!L4 -> 73932.408 | J5: instrumentType | K5: EQUITY
B6: Capital Charge | C6: ='Equity Schedule '!H3*WACC!$C$18 -> 20444.243 | D6: ='Equity Schedule '!I3*WACC!$C$18 -> 25303.452 | E6: ='Equity Schedule '!J3*WACC!$C$18 -> 31344.175 | F6: ='Equity Schedule '!K3*WACC!$C$18 -> 38610.606 | G6: ='Equity Schedule '!L3*WACC!$C$18 -> 47106.591 | J6: firstTradeDate | K6: 994045500
B7: Residual Income | C7: =C5-C6 -> 17856.554 | D7: =D5-D6 -> 21667.164 | E7: =E5-E6 -> 24753.7 | F7: =F5-F6 -> 26643.177 | G7: =G5-G6 -> 26825.817 | J7: regularMarketTime | K7: 1780908425
B8: Discount Factor | C8: =1/(1+WACC!$C$18)^1 -> 0.88160811 | D8: =1/(1+WACC!$C$18)^2 -> 0.77723286 | E8: =1/(1+WACC!$C$18)^3 -> 0.68521479 | F8: =1/(1+WACC!$C$18)^4 -> 0.60409092 | G8: =1/(1+WACC!$C$18)^5 -> 0.53257145 | J8: hasPrePostMarketData | K8: FALSE
B9: PV of RI | C9: =C7*C8 -> 15742.483 | D9: =D7*D8 -> 16840.432 | E9: =E7*E8 -> 16961.601 | F9: =F7*F8 -> 16094.901 | G9: =G7*G8 -> 14286.665 | J9: gmtoffset | K9: 19800
J10: timezone | K10: IST
B11: Terminal Growth | C11: =WACC!$C$15 -> 0.066 | J11: exchangeTimezoneName | K11: Asia/Kolkata
B12: Terminal RI | G12: =G7*(1+$C$11)/(WACC!$C$18-$C$11) -> 418743.17 | J12: regularMarketPrice | K12: 376.4
B13: PV Terminal RI | C13: =G12*G8 -> 223010.66 | J13: fiftyTwoWeekHigh | K13: 453.2
J14: fiftyTwoWeekLow | K14: 345.5
B15: Current Book Value | C15: ='Consolidated FS'!P4+'Consolidated FS'!P6 -> 157395.08 | J15: shortName | K15: KOTAK MAHINDRA BANK LTD
B16: Equity Value | C16: =C15+SUM(C9:G9)+C13 -> 460331.82
B17: Shares Outstanding | C17: 995
B18: Value Per Share | C18: =C16/C17 -> 462.64505 | E18: Current Value | F18: =K12 -> 376.4
B20: Upside/Downside | D20: =(C18-F18)/F18 -> 0.22913137

Sheet BETA 
B2: KOTAK BANK | G2: NIFTY50
C3: Open | D3: Close | G3: Date | H3: Closing Price | L3: BETA
B4: 44287 | C4: 352.53 | D4: 359.41 | G4: 44287 | H4: 14867.35
B5: 44291 | C5: 355.73 | D5: 350.38 | E5: =(D5-D4)/D4 -> -0.02512451 | G5: 44291 | H5: 14637.8 | I5: =(H5-H4)/H4 -> -0.015439861 | L5: =SLOPE(E5:E1237,I5:I1237) -> 0.97558336
B6: 44292 | C6: 353.72 | D6: 352.19 | E6: =(D6-D5)/D5 -> 0.00516582 | G6: 44292 | H6: 14683.5 | I6: =(H6-H5)/H5 -> 0.0031220672
B7: 44293 | C7: 351.74 | D7: 356.91 | E7: =(D7-D6)/D6 -> 0.013401857 | G7: 44293 | H7: 14819.05 | I7: =(H7-H6)/H6 -> 0.009231437 | L7: SUMMARY OUTPUT
B8: 44294 | C8: 357.71 | D8: 355.17 | E8: =(D8-D7)/D7 -> -0.0048751786 | G8: 44294 | H8: 14873.8 | I8: =(H8-H7)/H7 -> 0.0036945689
B9: 44295 | C9: 352.53 | D9: 358.35 | E9: =(D9-D8)/D8 -> 0.0089534589 | G9: 44295 | H9: 14834.85 | I9: =(H9-H8)/H8 -> -0.0026187118 | L9: Regression Statistics
B10: 44298 | C10: 349.99 | D10: 347.05 | E10: =(D10-D9)/D9 -> -0.031533417 | G10: 44298 | H10: 14310.8 | I10: =(H10-H9)/H9 -> -0.035325589 | L10: Multiple R | M10: 0.58706256
B11: 44299 | C11: 347.71 | D11: 353.69 | E11: =(D11-D10)/D10 -> 0.01913269 | G11: 44299 | H11: 14504.8 | I11: =(H11-H10)/H10 -> 0.013556196 | L11: R Square | M11: 0.34464245
B12: 44301 | C12: 358.5 | D12: 353.17 | E12: =(D12-D11)/D11 -> -0.001470214 | G12: 44301 | H12: 14581.45 | I12: =(H12-H11)/H11 -> 0.0052844846 | L12: Adjusted R Square | M12: 0.34411007
B13: 44302 | C13: 353.32 | D13: 351.35 | E13: =(D13-D12)/D12 -> -0.0051533256 | G13: 44302 | H13: 14617.85 | I13: =(H13-H12)/H12 -> 0.0024962822 | L13: Standard Error | M13: 0.01167144
B14: 44305 | C14: 342.57 | D14: 338.73 | E14: =(D14-D13)/D13 -> -0.0359186 | G14: 44305 | H14: 14359.45 | I14: =(H14-H13)/H13 -> -0.017676979 | L14: Observations | M14: 1233
B15: 44306 | C15: 343.56 | D15: 338.13 | E15: =(D15-D14)/D14 -> -0.0017713223 | G15: 44306 | H15: 14296.4 | I15: =(H15-H14)/H14 -> -0.004390823
B16: 44308 | C16: 336.54 | D16: 345.77 | E16: =(D16-D15)/D15 -> 0.02259486 | G16: 44308 | H16: 14406.15 | I16: =(H16-H15)/H15 -> 0.0076767576 | L16: ANOVA
B17: 44309 | C17: 345.34 | D17: 345.4 | E17: =(D17-D16)/D16 -> -0.0010700755 | G17: 44309 | H17: 14341.35 | I17: =(H17-H16)/H16 -> -0.0044981331 | M17: df | N17: SS | O17: MS | P17: F | Q17: Significance F
B18: 44312 | C18: 346.55 | D18: 350.47 | E18: =(D18-D17)/D17 -> 0.014678633 | G18: 44312 | H18: 14485 | I18: =(H18-H17)/H17 -> 0.010016518 | L18: Regression | M18: 1 | N18: 0.08818554 | O18: 0.08818554 | P18: 647.36395 | Q18: 4.2635427e-115
B19: 44313 | C19: 348.54 | D19: 348.6 | E19: =(D19-D18)/D18 -> -0.0053356921 | G19: 44313 | H19: 14653.05 | I19: =(H19-H18)/H18 -> 0.011601643 | L19: Residual | M19: 1231 | N19: 0.16768991 | O19: 0.00013622251
B20: 44314 | C20: 351.03 | D20: 360.78 | E20: =(D20-D19)/D19 -> 0.034939759 | G20: 44314 | H20: 14864.55 | I20: =(H20-H19)/H19 -> 0.014433855 | L20: Total | M20: 1232 | N20: 0.25587545
B21: 44315 | C21: 363.5 | D21: 359.5 | E21: =(D21-D20)/D20 -> -0.0035478685 | G21: 44315 | H21: 14894.9 | I21: =(H21-H20)/H20 -> 0.00204181
B22: 44316 | C22: 354.52 | D22: 348.3 | E22: =(D22-D21)/D21 -> -0.031154381 | G22: 44316 | H22: 14631.1 | I22: =(H22-H21)/H21 -> -0.017710812 | M22: Coefficients | N22: Standard Error | O22: t Stat | P22: P-value | Q22: Lower 95% | R22: Upper 95% | S22: Lower 95.0% | T22: Upper 95.0%
B23: 44319 | C23: 345.56 | D23: 343.65 | E23: =(D23-D22)/D22 -> -0.01335056 | G23: 44319 | H23: 14634.15 | I23: =(H23-H22)/H22 -> 0.00020851346 | L23: Intercept | M23: -0.00026836264 | N23: 0.00033268498 | O23: -0.80665691 | P23: 0.42001999 | Q23: -0.00092105497 | R23: 0.00038432969 | S23: -0.00092105497 | T23: 0.00038432969
B24: 44320 | C24: 348.74 | D24: 345.09 | E24: =(D24-D23)/D23 -> 0.0041903099 | G24: 44320 | H24: 14496.5 | I24: =(H24-H23)/H23 -> -0.0094061074 | L24: X Variable 1 | M24: 0.97558336 | N24: 0.038343357 | O24: 25.443348 | P24: 4.2635427e-115 | Q24: 0.9003578 | R24: 1.0508089 | S24: 0.9003578 | T24: 1.0508089
B25: 44321 | C25: 346.75 | D25: 352.68 | E25: =(D25-D24)/D24 -> 0.021994262 | G25: 44321 | H25: 14617.85 | I25: =(H25-H24)/H24 -> 0.0083709592
B26: 44322 | C26: 354.86 | D26: 356.16 | E26: =(D26-D25)/D25 -> 0.0098673018 | G26: 44322 | H26: 14724.8 | I26: =(H26-H25)/H25 -> 0.007316411
B27: 44323 | C27: 357.71 | D27: 354.59 | E27: =(D27-D26)/D26 -> -0.0044081312 | G27: 44323 | H27: 14823.15 | I27: =(H27-H26)/H26 -> 0.0066792477
B28: 44326 | C28: 360.29 | D28: 360.36 | E28: =(D28-D27)/D27 -> 0.016272315 | G28: 44326 | H28: 14942.35 | I28: =(H28-H27)/H27 -> 0.0080414227
B29: 44327 | C29: 353.84 | D29: 349.63 | E29: =(D29-D28)/D28 -> -0.02977578 | G29: 44327 | H29: 14850.75 | I29: =(H29-H28)/H28 -> -0.0061302012
B30: 44328 | C30: 349.34 | D30: 342.34 | E30: =(D30-D29)/D29 -> -0.020850614 | G30: 44328 | H30: 14696.5 | I30: =(H30-H29)/H29 -> -0.010386681
B31: 44330 | C31: 344.34 | D31: 339.91 | E31: =(D31-D30)/D30 -> -0.0070982065 | G31: 44330 | H31: 14677.8 | I31: =(H31-H30)/H30 -> -0.0012724251
B32: 44333 | C32: 341.97 | D32: 347.38 | E32: =(D32-D31)/D31 -> 0.021976406 | G32: 44333 | H32: 14923.15 | I32: =(H32-H31)/H31 -> 0.01671576
B33: 44334 | C33: 352.13 | D33: 349.56 | E33: =(D33-D32)/D32 -> 0.0062755484 | G33: 44334 | H33: 15108.1 | I33: =(H33-H32)/H32 -> 0.012393443
B34: 44335 | C34: 348.14 | D34: 344.67 | E34: =(D34-D33)/D33 -> -0.013989015 | G34: 44335 | H34: 15030.15 | I34: =(H34-H33)/H33 -> -0.0051594324
B35: 44336 | C35: 344.96 | D35: 340.22 | E35: =(D35-D34)/D34 -> -0.0129109 | G35: 44336 | H35: 14906.05 | I35: =(H35-H34)/H34 -> -0.0082567761
B36: 44337 | C36: 341.67 | D36: 350.07 | E36: =(D36-D35)/D35 -> 0.028951855 | G36: 44337 | H36: 15175.3 | I36: =(H36-H35)/H35 -> 0.018063136
... B1237: 46111 | C1237: 361 | D1237: 353.4 | E1237: =(D1237-D1236)/D1236 -> -0.034821794 | G1237: 46111 | H1237: 22331.4 | I1237: =(H1237-H1236)/H1236 -> -0.021393856

Sheet WACC
B1: Weighted Average Cost of Capital
B4: Capital Structure
B5: Total Debt | C5: ='Consolidated FS'!P8 -> 97622.03
B6: Total Equity | C6: =SUM('Consolidated FS'!P4:P6) -> 157489.35
B7: Total Mix | C7: =SUM(C5:C6) -> 255111.38
B8: % of Debt | C8: =C5/C7 -> 0.38266435
B9: % of Equity | C9: =C6/C7 -> 0.61733565
B10: Debt to Equity | C10: =C5/C6 -> 0.61986433
B14: Cost of Equity | E14: Cost of Debt
B15: Risk free rate(Rf) | C15: 0.066
B16: Beta | C16: ='BETA '!L5 -> 0.97558336 | E16: Cost of debt* | F16: ='Consolidated FS'!G9/(AVERAGE(SUM('Consolidated FS'!O7:O8),SUM('Consolidated FS'!P7:P8))) -> 0.050821338
B17: Market risk premium | C17: 0.07 | E17: Tax rate | F17: 0.25
B18: Cost of equity | C18: =C15+C16*C17 -> 0.13429084 | E18: Cost of Debt after tax | F18: =F16*(1-F17) -> 0.038116004
B21: WACC
B22: Source | C22: Weight | D22: Cost | E22: Weighted Cost
B23: Debt | C23: =C8 -> 0.38266435 | D23: =F18 -> 0.038116004 | E23: =C23*D23 -> 0.014585636
B24: Equity | C24: =C9 -> 0.61733565 | D24: =C18 -> 0.13429084 | E24: =C24*D24 -> 0.08290252
B25: WACC | E25: =SUM(E23:E24) -> 0.097488156

Sheet Relative Valuation 
B2: Relative Valuation - Alkem Labs
B4: Figures in Crore
B5: Comparable Company Valuation
B7: Company Name | C7: Market Data | J7: Financials | O7: Valuation
C8: No. of shares | D8: Share Price | E8: Equity value | F8: Debt | G8: cash | H8: Enterprises value | J8: Revenue | K8: EBITDA | L8: Net Profit | M8: EPS | O8: EV/Revenue | P8: EV/EBITDA | Q8: P/E Ratio
B9: HDFC Bank | C9: 1539.76 | D9: 738.65 | E9: =IFERROR(C9*D9,0) -> 1137343.7 | F9: 3688122.8 | G9: 200707.11 | H9: =IFERROR(E9+F9-G9,0) -> 4624759.5 | J9: 348615.15 | K9: 287632.68 | L9: 79219.46 | M9: =IFERROR(L9/C9,0) -> 51.449226 | O9: =IFERROR(H9/J9,0) -> 13.266089 | P9: =IFERROR(H9/K9,0) -> 16.0787 | Q9: =IFERROR(D9/M9,0) -> 14.356873
B10: ICICI Bank | C10: 717.18 | D10: 1250.2 | E10: =IFERROR(C10*D10,0) -> 896618.44 | F10: 2050284.4 | G10: 121237.19 | H10: =IFERROR(E10+F10-G10,0) -> 2825665.6 | J10: 195218.46 | K10: 166085.91 | L10: 57936.25 | M10: =IFERROR(L10/C10,0) -> 80.783416 | O10: =IFERROR(H10/J10,0) -> 14.474377 | P10: =IFERROR(H10/K10,0) -> 17.013277 | Q10: =IFERROR(D10/M10,0) -> 15.475949
B11: Axis Bank | C11: 311.01 | D11: 1268.1 | E11: =IFERROR(C11*D11,0) -> 394391.78 | F11: 1614302.1 | G11: 78627.37 | H11: =IFERROR(E11+F11-G11,0) -> 1930066.5 | J11: 132538.24 | K11: 106368.46 | L11: 26547.91 | M11: =IFERROR(L11/C11,0) -> 85.36031 | O11: =IFERROR(H11/J11,0) -> 14.562337 | P11: =IFERROR(H11/K11,0) -> 18.145101 | Q11: =IFERROR(D11/M11,0) -> 14.85585
B12: Kotak Mah. Bank | C12: 994.65 | D12: 377.1 | E12: =IFERROR(C12*D12,0) -> 375082.52 | F12: 662333.86 | G12: 51281.74 | H12: =IFERROR(E12+F12-G12,0) -> 986134.64 | J12: 69781.21 | K12: 55244.9 | L12: 19287.9 | M12: =IFERROR(L12/C12,0) -> 19.391645 | O12: =IFERROR(H12/J12,0) -> 14.131808 | P12: =IFERROR(H12/K12,0) -> 17.850238 | Q12: =IFERROR(D12/M12,0) -> 19.446519
B13: IDBI Bank | C13: 1075.24 | D13: 71.85 | E13: =IFERROR(C13*D13,0) -> 77255.994 | F13: 374879.89 | G13: 33230.47 | H13: =IFERROR(E13+F13-G13,0) -> 418905.41 | J13: 29019.59 | K13: 27132.49 | L13: 9236.62 | M13: =IFERROR(L13/C13,0) -> 8.5902868 | O13: =IFERROR(H13/J13,0) -> 14.435263 | P13: =IFERROR(H13/K13,0) -> 15.439254 | Q13: =IFERROR(D13/M13,0) -> 8.3640979
B15: Max | O15: =IFERROR(MAX(O9:O13),0) -> 14.562337 | P15: =IFERROR(MAX(P9:P13),0) -> 18.145101 | Q15: =IFERROR(MAX(Q9:Q13),0) -> 19.446519
B16: 75th Percentile | O16: =IFERROR(QUARTILE(O9:O13,3),0) -> 14.474377 | P16: =IFERROR(QUARTILE(P9:P13,3),0) -> 17.850238 | Q16: =IFERROR(QUARTILE(Q9:Q13,3),0) -> 15.475949
B17: Average | O17: =IFERROR(AVERAGE(O9:O13),0) -> 14.173975 | P17: =IFERROR(AVERAGE(P9:P13),0) -> 16.905314 | Q17: =IFERROR(AVERAGE(Q9:Q13),0) -> 14.499858
B18: median | O18: =IFERROR(MEDIAN(O9:O13),0) -> 14.435263 | P18: =IFERROR(MEDIAN(P9:P13),0) -> 17.013277 | Q18: =IFERROR(MEDIAN(Q9:Q13),0) -> 14.85585
B19: 25th Percentile | O19: =IFERROR(QUARTILE(O9:O13,1),0) -> 14.131808 | P19: =IFERROR(QUARTILE(P9:P13,1),0) -> 16.0787 | Q19: =IFERROR(QUARTILE(Q9:Q13,1),0) -> 14.356873
B20: Min. | O20: =IFERROR(MIN(O9:O13),0) -> 13.266089 | P20: =IFERROR(MIN(P9:P13),0) -> 15.439254 | Q20: =IFERROR(MIN(Q9:Q13),0) -> 8.3640979
B22: M&M Industry Comparable comps | O22: EV/Revenue | P22: EV/EBITDA | Q22: P/E Ratio
B23: Implied Enterprise Value | O23: =O18*J12 -> 1007310.1 | P23: =P18*K12 -> 939896.8 | Q23: =SUM(Q25+Q24) -> 897590.28
B24: Net Debt | O24: =F12-G12 -> 611052.12 | P24: =O24 -> 611052.12 | Q24: =P24 -> 611052.12
B25: Implied Market Value | O25: =O23-O24 -> 396258 | P25: =P23-P24 -> 328844.68 | Q25: =Q18*L12 -> 286538.16
B26: Share Outstanding | O26: =C12 -> 994.65 | P26: =O26 -> 994.65 | Q26: =P26 -> 994.65
B28: Implied Value per Share | O28: =O25/O26 -> 398.38938 | P28: =P25/P26 -> 330.61347 | Q28: =Q25/Q26 -> 288.07938
