Workbook

Sheet Hero
A1: GOLDMAN SACHS EQUITY RESEARCH
A2: Suzlon Energy Ltd (SUZLON.NS)
A3: Recommendation: BUY
A4: Target Price: ₹88.00
A5: Current Price: ₹53.62
A6: Upside: 64.1%
A8: INVESTMENT THESIS:
A9: We reiterate our BUY rating on Suzlon Energy as the company emerges as a primary beneficiary of India's aggressive renewable energy targets. With a deleveraged balance sheet and a robust order book of over 5.6 GW, Suzlon is well-positioned to capture the surging demand in the wind energy sector.
A11: KEY DRIVERS:
A12: 1. Market Leadership: Suzlon maintains a ~32% market share in India's wind turbine market.
A13: 2. Financial Turnaround: Successful debt reduction and capital infusion have significantly improved the ROCE to 32.5%.
A14: 3. Order Book Visibility: Record order book of 5.6 GW provides strong revenue visibility for the next 24-36 months.
... A20: 3. Competition from global players like GE Vernova and Siemens Energy.

Sheet About
J5: Suzlon Energy Limited (NSE: SUZLON | BSE: 532667 | CIN: L40101PN1995PLC085963) is one of the leading global renewable energy solutions providers. Incorporated in 1995, it is a vertically integrated wind turbine generator (WTG) manufacturer. Headquartered in Pune, India, Suzlon has a presence in 17 countries across Asia, Australia, Europe, Africa, and the Americas. The company has installed over 20.5 GW of wind energy capacity globally. It operates 14 manufacturing facilities in India and has a strong R&D presence in Germany, Denmark, and the Netherlands. Key subsidiaries include SE Forge Limited and Suzlon Global Services Limited. Vision: Powering a greener tomorrow. Mission: To be the world's leading renewable energy solutions provider.

Sheet Shareholding 
C2: 45717 | D2: 46082
B3: Promoters - | C3: 0.1325 | D3: 0.1173
B4: Sugati Holdings Pvt. Ltd.
B5: Tanti Holdings Private Limited | C5: 5.14 | D5: 4.63
B6: Samanvaya Holdings Private Limited | C6: 2.68 | D6: 2.67
B7: Rambhaben Ukabhai | C7: 3.47 | D7: 3.25
B8: Girish R.Tanti | C8: 0.73 | D8: 0.73
B9: Sangita V.Tanti | C9: 0 | D9: 0
B10: Lina J.Tanti | C10: 0 | D10: 0
B11: Tulsi R.Tanti J/w. Vinod R.Tanti J/w. Jitendra R.Tanti
B12: Tulsi R.Tanti as karta of Ranchhodbhai Ramjibhai HUF
B13: Gita T.Tanti | C13: 0.04 | D13: 0.04
B14: Pranav T.Tanti | C14: 0 | D14: 0
B15: Tulsi R.Tanti J/w. Vinod R.Tanti J/w. Jitendra R.T...
B16: Brij J.Tanti | C16: 0 | D16: 0
B17: Vinod R.Tanti as karta of Ranchhodbhai Ramjibhai HUF | C17: 0.39
B18: Vinod R.Tanti J/w. Jitendra R.Tanti as trustees of... | C18: 0.39
B19: Tulsi R.Tanti as karta of Tulsi Ranchhodbhai HUF
B20: Vinod R.Tanti | C20: 0.22 | D20: 0.22
B21: Rajan V.Tanti | C21: 0 | D21: 0
B22: Jitendra R.Tanti | C22: 0.07 | D22: 0.07
B23: Trisha J.Tanti | C23: 0 | D23: 0
B24: Vinod R.Tanti as karta of Vinod Ranchhodbhai HUF | C24: 0
B25: Jitendra R.Tanti as karta of Jitendra Ranchhodbhai HUF | C25: 0
B26: Pranav T.Tanti as karta of Tulsi Ranchhodbhai HUF | C26: 0.13 | D26: 0.13
B27: Tulsi R.Tanti
B28: Nidhi T.Tanti | C28: 0 | D28: 0
B29: The Tanti Trust (through its Trustee Mr. Vinod Ran...
B30: The Tanti Trust (its Trustee Vinod R.Tanti, Girish... | C30: 0
B31: FIIs - | C31: 0.2304 | D31: 0.2385
B32: Cowell & Lee Investment (Mauritius) Limited
B33: Ishares Ii Public Limited Company - Ishares Global
B34: Vanguard Total International Stock Index Fund | C34: 1.23 | D34: 1.16
B35: Vanguard Emerging Markets Stock Index Fund, A Seri | C35: 1.11 | D35: 1.09
B36: Blackrock Global Funds Asian Dragon Fund
B37: Elm Park Fund Limited
B38: DIIs - | C38: 0.0873 | D38: 0.0918
B39: State Bank Of India
B40: Tor Asia Credit Master Fund Lp
B41: Belgrave Investment Fund .
...

Sheet Consolidated FS
B2: Particulars (₹ in Crores) | C2: FY 2020-21 | D2: FY 2021-22 | E2: FY 2022-23 | F2: FY 2023-24 | G2: FY 2024-25 | J2: Consolidated Balance Sheet | K2: 2021 | L2: 2022 | M2: 2023 | N2: 2024 | O2: 2025 | Q2: Consolidated Cash Flow Statement | R2: 2021 | S2: 2022 | T2: 2023 | U2: 2024 | V2: 2025
B3: Income | J3: ASSETS | Q3: Cash flow from operating activities
B4: Revenue from operations | C4: 3294.65 | D4: 6519.95 | E4: 5946.84 | F4: 6496.84 | G4: 10851.32 | J4: Non-current assets | Q4: Profit / (loss) before tax | R4: 1020.15 | S4: -210.45 | T4: 2825.4 | U4: 1338.1 | V4: 2368.4
B5: Other operating income | C5: 51.07 | D5: 61.83 | E5: 23.69 | F5: 32.25 | G5: 38.42 | J5: Property, plant and equipment | K5: 1161.76 | L5: 984.71 | M5: 943.15 | N5: 1021.4 | O5: 1451.6 | Q5: Adjustments for:
B6: Other income | C6: 19.87 | D6: 22.19 | E6: 19.63 | F6: 38.42 | G6: 103.39 | J6: Capital work-in-progress | K6: 114.5 | L6: 85.2 | M6: 42.1 | N6: 96.3 | O6: 110.4 | Q6: Depreciation and amortisation | R6: 256.4 | S6: 242.15 | T6: 254.12 | U6: 252.4 | V6: 268.15
B7: Total Income (I) | C7: 3365.59 | D7: 6603.97 | E7: 5990.16 | F7: 6567.51 | G7: 10993.13 | J7: Investment property | K7: 11.9 | L7: 11.8 | M7: 11.5 | N7: 11.1 | O7: 10.8 | Q7: Finance costs | R7: 410.12 | S7: 712.4 | T7: 415.16 | U7: 128.15 | V7: 172.4
J8: Goodwill | K8: 56.12 | L8: 38.45 | M8: 38.45 | N8: 38.45 | O8: 115.6 | Q8: Interest income | R8: -18.45 | S8: -24.15 | T8: -31.12 | U8: -45.12 | V8: -58.6
B9: Expenses | J9: Other intangible assets | K9: 85.4 | L9: 76.1 | M9: 69.15 | N9: 106.85 | O9: 169.2 | Q9: (Gain) / loss on disposal of property | R9: -4.15 | S9: 8.4 | T9: -11.45 | U9: -6.15 | V9: -12.4
B10: Cost of raw materials, components and services consumed | C10: 1610.75 | D10: 4091.95 | E10: 3626.76 | F10: 4018.65 | G10: 7139.17 | J10: Intangible assets under development | K10: 6.8 | L10: 1.1 | M10: 0 | N10: 12.4 | O10: 24.5 | Q10: Unrealised foreign exchange (gain) / loss | R10: -12.1 | S10: 31.15 | T10: -42.15 | U10: -12.4 | V10: 24.5
B11: Changes in inventories of finished goods, etc. | C11: -33.48 | D11: 239.61 | E11: 155.9 | F11: -36.52 | G11: -252.57 | J11: Financial assets | Q11: Bad debts and allowances for doubtful debts | R11: 112.1 | S11: 125.4 | T11: 98.5 | U11: 65.12 | V11: 84.15
B12: Employee benefits expense | C12: 553.21 | D12: 545.36 | E12: 609.22 | F12: 702.9 | G12: 941.53 | J12: (i) Investments | K12: 240.15 | L12: 115.2 | M12: 112.45 | N12: 145.6 | O12: 168.9 | Q12: Exceptional items items adjustment | R12: -1610.4 | S12: -701.12 | T12: -2674.9 | U12: 0 | V12: 0
B13: Finance costs | C13: 996.26 | D13: 734.52 | E13: 420.76 | F13: 164.32 | G13: 254.8 | J13: (ii) Trade receivables | K13: 185.6 | L13: 142.1 | M13: 120.6 | N13: 184.2 | O13: 210.5 | Q13: Operating profit before working capital changes | R13: 153.67 | S13: 183.88 | T13: 833.56 | U13: 1590.1 | V13: 2636.6
B14: Depreciation and amortisation expenses | C14: 258.38 | D14: 259.84 | E14: 259.68 | F14: 189.6 | G14: 259.19 | J14: (iii) Loans | K14: 38.5 | L14: 24.15 | M14: 11.2 | N14: 15.6 | O14: 18.4 | Q14: Movements in working capital:
B15: Other expenses | C15: 680.96 | D15: 815.41 | E15: 746.73 | F15: 815.18 | G15: 1204.38 | J15: (iv) Other financial assets | K15: 260.4 | L15: 281.3 | M15: 298.5 | N15: 421.4 | O15: 435.1 | Q15: Decrease / (increase) in inventories | R15: -35.7 | S15: -229.6 | T15: -329.72 | U15: -430.38 | V15: -739.9
B16: Total Expenses (II) | C16: 4066.08 | D16: 6686.69 | E16: 5819.05 | F16: 5854.13 | G16: 9546.5 | J16: Deferred tax assets (net) | K16: 22.1 | L16: 24.5 | M16: 28.4 | N16: 34.15 | O16: 38.2 | Q16: Decrease / (increase) in trade receivables | R16: 95.5 | S16: -165.25 | T16: -170.2 | U16: -230.05 | V16: -559.75
J17: Other non-current assets | K17: 38.4 | L17: 38.2 | M17: 38.3 | N17: 44.15 | O17: 57.2 | Q17: Decrease / (increase) in financial and other assets | R17: 54.12 | S17: -32.15 | T17: -54.15 | U17: -140.25 | V17: -110.15
B18: Profit / (loss) before exceptional items and tax | C18: -700.49 | D18: -82.72 | E18: 171.11 | F18: 713.38 | G18: 1446.63 | J18: Total non-current assets | K18: 2167.53 | L18: 1793.16 | M18: 1712.55 | N18: 2065.25 | O18: 2714.9 | Q18: Increase / (decrease) in trade payables | R18: -549.42 | S18: 132.27 | T18: 115.16 | U18: -373.15 | V18: 384.5
B19: Exceptional items (net) | C19: -805.46 | D19: -83.12 | E19: -2720.6 | F19: 53.89 | G19: - | J19: Current assets | Q19: Increase / (decrease) in financial and other liabilities | R19: 198.4 | S19: 185.15 | T19: 31.15 | U19: 25.4 | V19: 110.25
B20: Profit / (loss) before tax | C20: 104.97 | D20: 0.4 | E20: 2891.71 | F20: 659.49 | G20: 1446.63 | J20: Inventories | K20: 1420.8 | L20: 1650.4 | M20: 1980.12 | N20: 2410.5 | O20: 3150.4 | Q20: Increase / (decrease) in provisions | R20: 27.15 | S20: 34.15 | T20: -4.15 | U20: -66.25 | V20: 25.1
J21: Financial assets | Q21: Cash generated from operations | R21: -56.28 | S21: 308.45 | T21: 421.65 | U21: 975.42 | V21: 1746.65
B22: Tax expense | J22: (i) Investments | K22: 45.1 | L22: 82.3 | M22: 124.5 | N22: 245.6 | O22: 310.2 | Q22: Direct taxes paid (net of refunds) | R22: -5.4 | S22: -18.15 | T22: -24.5 | U22: -312.4 | V22: -485.4
B23: Current tax | C23: 4.63 | D23: 184.07 | E23: 4.61 | F23: 2.9 | G23: 14.42 | J23: (ii) Trade receivables | K23: 1114.9 | L23: 1280.15 | M23: 1450.35 | N23: 1680.4 | O23: 2240.15 | Q23: Net cash flow from operating activities (A) | R23: -61.68 | S23: 290.3 | T23: 397.15 | U23: 663.02 | V23: 1261.25
B24: Deferred tax | C24: - | D24: -17.48 | E24: -0.19 | F24: -3.76 | G24: -639.42 | J24: (iii) Cash and cash equivalents | K24: 245.2 | L24: 310.12 | M24: 520.4 | N24: 1150.25 | O24: 1850.4
B25: Total Tax Expense | C25: 4.63 | D25: 166.59 | E25: 4.42 | F25: -0.86 | G25: -625 | J25: (iv) Bank balances other than cash | K25: 240.15 | L25: 225.4 | M25: 312.15 | N25: 485.6 | O25: 560.15 | Q25: Cash flows from investing activities
J26: (v) Loans | K26: 10.5 | L26: 8.4 | M26: 6.2 | N26: 11.4 | O26: 15.6 | Q26: Purchase of property, plant and equipment | R26: -45.15 | S26: -98.5 | T26: -142.15 | U26: -382.4 | V26: -610.15
B27: Profit / (loss) after tax | C27: 100.34 | D27: -166.19 | E27: 2887.29 | F27: 660.35 | G27: 2071.63 | J27: (vi) Other financial assets | K27: 410.15 | L27: 452.1 | M27: 410.12 | N27: 512.4 | O27: 618.9 | Q27: Proceeds from sale of property, plant & equipment | R27: 21.4 | S27: 14.5 | T27: 38.4 | U27: 24.15 | V27: 18.4
B28: Share of profit / (loss) of associates and joint ventures | C28: 3.25 | D28: -10.36 | E28: - | F28: - | G28: - | J28: Other current assets | K28: 314.15 | L28: 276.5 | M28: 361.16 | N28: 174.25 | O28: 184.2 | Q28: Purchase of current/non-current investments | R28: -38.5 | S28: -76.15 | T28: -110.25 | U28: -185.6 | V28: -245.12
B29: Net Profit / (loss) for the year | C29: 103.59 | D29: -176.55 | E29: 2887.29 | F29: 660.35 | G29: 2071.63 | J29: Total current assets | K29: 3761 | L29: 4285.42 | M29: 5165.02 | N29: 6664.65 | O29: 8930.15 | Q29: Proceeds from sale/maturity of investments | R29: 24.15 | S29: 45.12 | T29: 64.5 | U29: 112.4 | V29: 184.2
J30: Total assets | K30: 5928.53 | L30: 6078.58 | M30: 6877.57 | N30: 8729.9 | O30: 11645.05 | Q30: Interest received | R30: 23.12 | S30: 39.8 | T30: 39.85 | U30: 85.9 | V30: 72.4
B31: Other Comprehensive Income / (loss) (OCI) | Q31: Net cash flow used in investing activities (B) | R31: -14.98 | S31: -75.23 | T31: -109.65 | U31: -345.55 | V31: -580.27
B32: Items that will not be reclassified to profit or loss | C32: -0.38 | D32: 3.33 | E32: -9.22 | F32: 3.17 | G32: 6.44 | J32: EQUITY AND LIABILITIES
B33: Items that will be reclassified to profit or loss | C33: 31.62 | D33: -85.16 | E33: -25.66 | F33: 63.3 | G33: -29.77 | J33: Equity | Q33: Cash flows from financing activities
B34: Other comprehensive income for the year, net of tax | C34: 31.24 | D34: -81.83 | E34: -34.88 | F34: 66.47 | G34: -23.33 | J34: Equity share capital | K34: 1695.12 | L34: 1842.15 | M34: 2456.12 | N34: 2715.6 | O34: 2715.6 | Q34: Proceeds from issuance of equity shares | R34: 633.92 | S34: 147.03 | T34: 613.97 | U34: 259.48 | V34: 0
J35: Other equity | K35: -4510.4 | L35: -3425.1 | M35: 1120.15 | N35: 3450.4 | O35: 5810.2 | Q35: Proceeds from long-term borrowings | R35: 412.15 | S35: 185.4 | T35: 0 | U35: 0 | V35: 84.15
B36: Total Comprehensive Income for the year | C36: 134.83 | D36: -258.38 | E36: 2852.41 | F36: 726.82 | G36: 2048.3 | J36: Equity attributable to owners | K36: -2815.28 | L36: -1582.95 | M36: 3576.27 | N36: 6166 | O36: 8525.8 | Q36: Repayment of long-term borrowings | R36: -615.4 | S36: -452.12 | T36: -210.45 | U36: -80 | V36: -19.12
J37: Non-controlling interests | K37: -11.4 | L37: -15.6 | M37: 1.1 | N37: 1.4 | O37: 2.4 | Q37: Net movement in short-term borrowings | R37: -110.15 | S37: -125.4 | T37: -52.15 | U37: -12.4 | V37: 30.25
B38: Profit / (loss) for the year attributable to: | J38: Total equity | K38: -2826.68 | L38: -1598.55 | M38: 3577.37 | N38: 6167.4 | O38: 8528.2 | Q38: Payment of lease liabilities | R38: -12.15 | S38: -16.5 | T38: -14.15 | U38: -11.2 | V38: -14.5
B39: Owners of the Company | C39: 104.18 | D39: -199.59 | E39: 2849.01 | F39: 660.35 | G39: 2071.63 | J39: LIABILITIES | Q39: Finance costs paid | R39: -168.4 | S39: -88.4 | T39: -414.2 | U39: -124.15 | V39: -60.4
B40: Non-controlling interest | C40: -0.59 | D40: 23.04 | E40: 38.28 | F40: - | G40: - | J40: Non-current liabilities | Q40: Net cash flow from / (used in) financing activities (C) | R40: 139.97 | S40: -149.99 | T40: -76.98 | U40: 31.73 | V40: 20.38
J41: Financial liabilities
...

Sheet Quaterly Results 
B1: SUZLON ENERGY LIMITED
B2: Consolidated Financial Results for the Quarters of 2025
B3: (₹ in Crores)
B5: Particulars | C5: Quarter ended December 31, 2025 (Unaudited) | D5: Quarter ended September 30, 2025 (Unaudited) | E5: Quarter ended June 30, 2025 (Unaudited)
B6: 1. Income
B7: a) Revenue from operations | C7: 4228.18 | D7: 3865.54 | E7: 3117.33
B8: b) Other operating income | C8: 7.91 | D8: 5.24 | E8: 14.39
B9: c) Other income | C9: 22.52 | D9: 26.55 | E9: 33.47
B10: Total Income | C10: 4258.61 | D10: 3897.33 | E10: 3165.19
B11: 2. Expenses
B12: a) Consumption of raw materials, components consumed and services rendered | C12: 3015.66 | D12: 2428.27 | E12: 2463.68
B13: b) Purchase of stock-in-trade | C13: 0 | D13: 0 | E13: 0
B14: c) Changes in inventories of finished goods, semi-finished goods and work-in-progress | C14: -258.49 | D14: -1.59 | E14: -550
B15: d) Employee benefits expense | C15: 292.13 | D15: 291.33 | E15: 254.02
B16: e) Finance cost | C16: 114.26 | D16: 109.66 | E16: 103.07
B17: f) Depreciation and amortisation expense | C17: 80 | D17: 75.23 | E17: 70.24
B18: g) Foreign exchange loss / (gain) | C18: 2.65 | D18: 6.47 | E18: 3.8
B19: h) Other expenses | C19: 445.65 | D19: 425.46 | E19: 361.15
B20: Total Expenses | C20: 3691.86 | D20: 3334.83 | E20: 2705.96
B21: 3. Profit before exceptional items and tax (1 - 2) | C21: 566.75 | D21: 562.5 | E21: 459.23
B22: 4. Exceptional items loss / (gain) | C22: 0 | D22: 0 | E22: 0
B23: 5. Profit before tax (3 - 4) | C23: 566.75 | D23: 562.5 | E23: 459.23
B24: 6. Tax expenses
B25: a) Current tax | C25: 2.3 | D25: 1.24 | E25: 0.81
B26: b) Deferred tax | C26: 119.17 | D26: -718.18 | E26: 134.1
B27: 7. Net profit after tax (5 - 6) | C27: 445.28 | D27: 1279.44 | E27: 324.32
B28: 8. Share of profit/ (loss) of associate and joint ventures | C28: 0 | D28: 0 | E28: 0
B29: 9. Net profit for the period (7 + 8) | C29: 445.28 | D29: 1279.44 | E29: 324.32
B30: 10. Other comprehensive income/ (loss), net of tax
B31: a) Items that will not be reclassified to profit and loss | C31: -0.49 | D31: -2.16 | E31: -1.15
B32: b) Items that will be reclassified to profit and loss | C32: 0.47 | D32: 0.38 | E32: 6.19
B33: 11. Total comprehensive income, net of tax (9 + 10) | C33: 445.26 | D33: 1277.66 | E33: 329.36
B34: 12. Net profit for the period attributable to:
B35: - Owners of the Company | C35: 445.28 | D35: 1279.44 | E35: 324.32
B36: - Non-controlling interest | C36: 0 | D36: 0 | E36: 0
B37: Total comprehensive income for the period attributable to:
B38: - Owners of the Company | C38: 445.26 | D38: 1277.66 | E38: 329.36
B39: - Non-controlling interest | C39: 0 | D39: 0 | E39: 0
B40: 13. Paid up equity share capital (Face value of ₹ 2/- each) | C40: 2744.51 | D40: 2743.76 | E40: 2741.83
B41: 14. Earnings per equity share (EPS) (*not annualised)
...

Sheet WACC
B1: Weighted Average Cost of Capital
B4: Capital Structure
B5: Total Debt | C5: ='Consolidated FS'!O42 -> 110.25
B6: Total Equity | C6: ='Consolidated FS'!O38 -> 8528.2
B7: Total Mix | C7: =SUM(C5:C6) -> 8638.45
B8: % of Debt | C8: =C5/C7 -> 0.012762706
B9: % of Equity | C9: =C6/C7 -> 0.98723729
B10: Debt to Equity | C10: =C5/C6 -> 0.012927699
B14: Cost of Equity | E14: Cost of Debt
B15: Risk free rate(Rf) | C15: 0.066 | E15: Source | F15: Cost
B16: Beta | C16: =BETA!K4 -> 0.93650857 | E16: Cost of debt* | F16: ='Consolidated FS'!G13/('Consolidated FS'!O42+'Consolidated FS'!O43+'Consolidated FS'!O44+'Consolidated FS'!O51+'Consolidated FS'!O56) -> 0.54118347
B17: Market risk premium | C17: 0.07 | E17: Tax rate | F17: 0.25
B18: Cost of equity | C18: =C15+C16*C17 -> 0.1315556 | E18: Cost of Debt after tax | F18: =F16*(1+F17) -> 0.67647933
B21: WACC
B22: Source | C22: Weight | D22: Cost | E22: Weighted Cost
B23: Debt | C23: =C8 -> 0.012762706 | D23: =F18 -> 0.67647933 | E23: =C23*D23 -> 0.008633707
B24: Equity | C24: =C9 -> 0.98723729 | D24: =C18 -> 0.1315556 | E24: =C24*D24 -> 0.12987659
B25: WACC | E25: =SUM(E23:E24) -> 0.1385103

Sheet BETA
F2: NIFTY | K2: BETA
B3: Date | C3: Closing Price | F3: Date | G3: Close
B4: 43922 | C4: 1.836427 | F4: 43922 | G4: 8253.7998 | K4: =SLOPE(D5:D1485,H5:H1485) -> 0.93650857
B5: 43924 | C5: 1.928249 | D5: =(C5-C4)/C4 -> 0.05000037 | F5: 43924 | G5: 8083.7998 | H5: =(G5-G4)/G4 -> -0.020596574
B6: 43928 | C6: 2.0200701 | D6: =(C6-C5)/C5 -> 0.047618889 | F6: 43928 | G6: 8792.2002 | H6: =(G6-G5)/G5 -> 0.087632105 | K6: =(_xlfn.COVARIANCE.S(D5:D1485,H5:H1485)/_xlfn.VAR.S(H5:H1485)) -> 0.93650857
B7: 43929 | C7: 2.111892 | D7: =(C7-C6)/C6 -> 0.045454814 | F7: 43929 | G7: 8748.75 | H7: =(G7-G6)/G6 -> -0.0049419024
B8: 43930 | C8: 2.2037129 | D8: =(C8-C7)/C7 -> 0.043478055 | F8: 43930 | G8: 9111.9004 | H8: =(G8-G7)/G7 -> 0.041508832
B9: 43934 | C9: 2.2955339 | D9: =(C9-C8)/C8 -> 0.041666477 | F9: 43934 | G9: 8993.8496 | H9: =(G9-G8)/G8 -> -0.012955671 | K9: SUMMARY OUTPUT
B10: 43936 | C10: 2.387356 | D10: =(C10-C9)/C9 -> 0.040000345 | F10: 43936 | G10: 8925.2998 | H10: =(G10-G9)/G9 -> -0.0076218536
B11: 43937 | C11: 2.479177 | D11: =(C11-C10)/C10 -> 0.038461358 | F11: 43937 | G11: 8992.7998 | H11: =(G11-G10)/G10 -> 0.0075627712 | K11: Regression Statistics
B12: 43938 | C12: 2.5709989 | D12: =(C12-C11)/C11 -> 0.037037254 | F12: 43938 | G12: 9266.75 | H12: =(G12-G11)/G11 -> 0.030463282 | K12: Multiple R | L12: 0.2746704
B13: 43941 | C13: 2.6628201 | D13: =(C13-C12)/C12 -> 0.03571421 | F13: 43941 | G13: 9261.8496 | H13: =(G13-G12)/G12 -> -0.00052881438 | K13: R Square | L13: 0.075443828
B14: 43942 | C14: 2.7546411 | D14: =(C14-C13)/C13 -> 0.034482598 | F14: 43942 | G14: 8981.4502 | H14: =(G14-G13)/G13 -> -0.030274667 | K14: Adjusted R Square | L14: 0.074818705
B15: 43943 | C15: 2.616909 | D15: =(C15-C14)/C14 -> -0.049999991 | F15: 43943 | G15: 9187.2998 | H15: =(G15-G14)/G14 -> 0.022919418 | K15: Standard Error | L15: 0.032131646
B16: 43944 | C16: 2.5250881 | D16: =(C16-C15)/C15 -> -0.035087561 | F16: 43944 | G16: 9313.9004 | H16: =(G16-G15)/G15 -> 0.013779956 | K16: Observations | L16: 1481
B17: 43945 | C17: 2.4332671 | D17: =(C17-C16)/C16 -> -0.036363466 | F17: 43945 | G17: 9154.4004 | H17: =(G17-G16)/G16 -> -0.017124942
B18: 43948 | C18: 2.4332671 | D18: =(C18-C17)/C17 -> 0 | F18: 43948 | G18: 9282.2998 | H18: =(G18-G17)/G17 -> 0.013971359 | K18: ANOVA
B19: 43949 | C19: 2.479177 | D19: =(C19-C18)/C18 -> 0.018867588 | F19: 43949 | G19: 9380.9004 | H19: =(G19-G18)/G18 -> 0.010622431 | L19: df | M19: SS | N19: MS | O19: F | P19: Significance F
B20: 43950 | C20: 2.4332671 | D20: =(C20-C19)/C19 -> -0.018518194 | F20: 43950 | G20: 9553.3496 | H20: =(G20-G19)/G19 -> 0.018383014 | K20: Regression | L20: 1 | M20: 0.12460186 | N20: 0.12460186 | O20: 120.68647 | P20: 4.8108907e-27
B21: 43951 | C21: 2.387356 | D21: =(C21-C20)/C20 -> -0.018868078 | F21: 43951 | G21: 9859.9004 | H21: =(G21-G20)/G20 -> 0.032088303 | K21: Residual | L21: 1479 | M21: 1.5269828 | N21: 0.0010324427
B22: 43955 | C22: 2.2955339 | D22: =(C22-C21)/C21 -> -0.038461857 | F22: 43955 | G22: 9293.5 | H22: =(G22-G21)/G21 -> -0.057444839 | K22: Total | L22: 1480 | M22: 1.6515846
B23: 43956 | C23: 2.249624 | D23: =(C23-C22)/C22 -> -0.019999653 | F23: 43956 | G23: 9205.5996 | H23: =(G23-G22)/G22 -> -0.0094582655
B24: 43957 | C24: 2.1578021 | D24: =(C24-C23)/C23 -> -0.040816558 | F24: 43957 | G24: 9270.9004 | H24: =(G24-G23)/G23 -> 0.0070935935 | L24: Coefficients | M24: Standard Error | N24: t Stat | O24: P-value | P24: Lower 95% | Q24: Upper 95% | R24: Lower 95.0% | S24: Upper 95.0%
B25: 43958 | C25: 2.249624 | D25: =(C25-C24)/C24 -> 0.042553443 | F25: 43958 | G25: 9199.0498 | H25: =(G25-G24)/G24 -> -0.0077501195 | K25: Intercept | L25: 0.0019493729 | M25: 0.00083719474 | N25: 2.3284581 | O25: 0.020022001 | P25: 0.0003071574 | Q25: 0.0035915883 | R25: 0.0003071574 | S25: 0.0035915883
B26: 43959 | C26: 2.341445 | D26: =(C26-C25)/C25 -> 0.040816134 | F26: 43959 | G26: 9251.5 | H26: =(G26-G25)/G25 -> 0.0057016971 | K26: X Variable 1 | L26: 0.93650857 | M26: 0.08524766 | N26: 10.985739 | O26: 4.8108907e-27 | P26: 0.76928938 | Q26: 1.1037278 | R26: 0.76928938 | S26: 1.1037278
B27: 43962 | C27: 2.387356 | D27: =(C27-C26)/C26 -> 0.019608009 | F27: 43962 | G27: 9239.2002 | H27: =(G27-G26)/G26 -> -0.001329493
B28: 43963 | C28: 2.341445 | D28: =(C28-C27)/C27 -> -0.019230929 | F28: 43963 | G28: 9196.5498 | H28: =(G28-G27)/G27 -> -0.0046162427
B29: 43964 | C29: 2.387356 | D29: =(C29-C28)/C28 -> 0.019608009 | F29: 43964 | G29: 9383.5498 | H29: =(G29-G28)/G28 -> 0.020333713
B30: 43965 | C30: 2.4332671 | D30: =(C30-C29)/C29 -> 0.019230929 | F30: 43965 | G30: 9142.75 | H30: =(G30-G29)/G29 -> -0.025661909
B31: 43966 | C31: 2.387356 | D31: =(C31-C30)/C30 -> -0.018868078 | F31: 43966 | G31: 9136.8496 | H31: =(G31-G30)/G30 -> -0.00064536279
B32: 43969 | C32: 2.2955339 | D32: =(C32-C31)/C31 -> -0.038461857 | F32: 43969 | G32: 8823.25 | H32: =(G32-G31)/G31 -> -0.03432251
B33: 43970 | C33: 2.387356 | D33: =(C33-C32)/C32 -> 0.040000345 | F33: 43970 | G33: 8879.0996 | H33: =(G33-G32)/G32 -> 0.0063298228
B34: 43971 | C34: 2.479177 | D34: =(C34-C33)/C33 -> 0.038461358 | F34: 43971 | G34: 9066.5498 | H34: =(G34-G33)/G33 -> 0.021111397
B35: 43972 | C35: 2.5709989 | D35: =(C35-C34)/C34 -> 0.037037254 | F35: 43972 | G35: 9106.25 | H35: =(G35-G34)/G34 -> 0.0043787545
B36: 43973 | C36: 2.5250881 | D36: =(C36-C35)/C35 -> -0.017857198 | F36: 43973 | G36: 9039.25 | H36: =(G36-G35)/G35 -> -0.0073575841
B37: 43977 | C37: 2.479177 | D37: =(C37-C36)/C36 -> -0.018181969 | F37: 43977 | G37: 9029.0498 | H37: =(G37-G36)/G36 -> -0.0011284338
B38: 43978 | C38: 2.5709989 | D38: =(C38-C37)/C37 -> 0.037037254 | F38: 43978 | G38: 9314.9502 | H38: =(G38-G37)/G37 -> 0.031664505
... B1485: 46111 | C1485: 39.560001 | D1485: =(C1485-C1484)/C1484 -> -0.030867181 | F1485: 46111 | G1485: 22331.4 | H1485: =(G1485-G1484)/G1484 -> -0.021393856

Sheet Assumptions
C2: [ | D2: Suzlon Energy
D3: Consolidated Profit & Loss account
E4: 44256 | F4: 44621 | G4: 44986 | H4: 45352 | I4: Mar 25
C5: Particulars
C6: Revenue From Operations [Net] | E6: ='Consolidated FS'!C4+'Consolidated FS'!C5 -> 3345.72 | F6: ='Consolidated FS'!D4+'Consolidated FS'!D5 -> 6581.78 | G6: ='Consolidated FS'!E4+'Consolidated FS'!E5 -> 5970.53 | H6: ='Consolidated FS'!F4+'Consolidated FS'!F5 -> 6529.09 | I6: ='Consolidated FS'!G4+'Consolidated FS'!G5 -> 10889.74
C7: revenue growth | F7: =(F6-E6)/E6 -> 0.9672238 | G7: =(G6-F6)/F6 -> -0.092870014 | H7: =(H6-G6)/G6 -> 0.093552834 | I7: =(I6-H6)/H6 -> 0.66788021
C9: less: Material Consumed | E9: ='Consolidated FS'!C10+'Consolidated FS'!C11 -> 1577.27 | F9: ='Consolidated FS'!D10+'Consolidated FS'!D11 -> 4331.56 | G9: ='Consolidated FS'!E10+'Consolidated FS'!E11 -> 3782.66 | H9: ='Consolidated FS'!F10+'Consolidated FS'!F11 -> 3982.13 | I9: ='Consolidated FS'!G10+'Consolidated FS'!G11 -> 6886.6
C10: less: Employee Cost | E10: ='Consolidated FS'!C12 -> 553.21 | F10: ='Consolidated FS'!D12 -> 545.36 | G10: ='Consolidated FS'!E12 -> 609.22 | H10: ='Consolidated FS'!F12 -> 702.9 | I10: ='Consolidated FS'!G12 -> 941.53
C11: less: Other Expenses | E11: ='Consolidated FS'!C15 -> 680.96 | F11: ='Consolidated FS'!D15 -> 815.41 | G11: ='Consolidated FS'!E15 -> 746.73 | H11: ='Consolidated FS'!F15 -> 815.18 | I11: ='Consolidated FS'!G15 -> 1204.38
C12: Total Expenses | E12: =SUM(E9:E11) -> 2811.44 | F12: =SUM(F9:F11) -> 5692.33 | G12: =SUM(G9:G11) -> 5138.61 | H12: =SUM(H9:H11) -> 5500.21 | I12: =SUM(I9:I11) -> 9032.51
C14: EBITDA | E14: =E6-E12 -> 534.28 | F14: =F6-F12 -> 889.45 | G14: =G6-G12 -> 831.92 | H14: =H6-H12 -> 1028.88 | I14: =I6-I12 -> 1857.23
C16: less: Depreciation & Amortization | E16: ='Consolidated FS'!C14 -> 258.38 | F16: ='Consolidated FS'!D14 -> 259.84 | G16: ='Consolidated FS'!E14 -> 259.68 | H16: ='Consolidated FS'!F14 -> 189.6 | I16: ='Consolidated FS'!G14 -> 259.19
C18: EBIT | E18: =E14-E16 -> 275.9 | F18: =F14-F16 -> 629.61 | G18: =G14-G16 -> 572.24 | H18: =H14-H16 -> 839.28 | I18: =I14-I16 -> 1598.04
C20: add: Other income | E20: ='Consolidated FS'!C6 -> 19.87 | F20: ='Consolidated FS'!D6 -> 22.19 | G20: ='Consolidated FS'!E6 -> 19.63 | H20: ='Consolidated FS'!F6 -> 38.42 | I20: ='Consolidated FS'!G6 -> 103.39
C21: less: Interest Expense | E21: ='Consolidated FS'!C13 -> 996.26 | F21: ='Consolidated FS'!D13 -> 734.52 | G21: ='Consolidated FS'!E13 -> 420.76 | H21: ='Consolidated FS'!F13 -> 164.32 | I21: ='Consolidated FS'!G13 -> 254.8
C23: EBT | E23: =E18+E20-E21 -> -700.49 | F23: =F18+F20-F21 -> -82.72 | G23: =G18+G20-G21 -> 171.11 | H23: =H18+H20-H21 -> 713.38 | I23: =I18+I20-I21 -> 1446.63
C25: less: Tax | E25: =SUM('Consolidated FS'!C23:C24) -> 4.63 | F25: =SUM('Consolidated FS'!D23:D24) -> 166.59 | G25: =SUM('Consolidated FS'!E23:E24) -> 4.42 | H25: =SUM('Consolidated FS'!F23:F24) -> -0.86 | I25: =SUM('Consolidated FS'!G23:G24) -> -625
C26: less: Non Controlling interest | E26: ='Consolidated FS'!K37 -> -11.4 | F26: ='Consolidated FS'!L37 -> -15.6 | G26: ='Consolidated FS'!M37 -> 1.1 | H26: ='Consolidated FS'!N37 -> 1.4 | I26: ='Consolidated FS'!O37 -> 2.4
C28: PAT | E28: =E23-E25-E26 -> -693.72 | F28: =F23-F25-F26 -> -233.71 | G28: =G23-G25-G26 -> 165.59 | H28: =H23-H25-H26 -> 712.84 | I28: =I23-I25-I26 -> 2069.23
C30: Historical Growth
C31: Average Growth | E31: =AVERAGE(F7:I7) -> 0.40894671
C32: CAGR | E32: =(I6/E6)^(1/4)-1 -> 0.34317308 | F32: =_xlfn.RRI(4,E6,I6) -> 0.34317308
C34: Margin Analysis
C35: EBITDA Margin | E35: =E14/E6 -> 0.15969059 | F35: =F14/F6 -> 0.13513821 | G35: =G14/G6 -> 0.13933771 | H35: =H14/H6 -> 0.15758398 | I35: =I14/I6 -> 0.17054861
C36: EBIT Margin | E36: =E18/E6 -> 0.082463565 | F36: =F18/F6 -> 0.095659533 | G36: =G18/G6 -> 0.095844088 | H36: =H18/H6 -> 0.12854471 | I36: =I18/I6 -> 0.14674731
C37: EBT Margin | E37: =E23/E6 -> -0.20936898 | F37: =F23/F6 -> -0.012568029 | G37: =G23/G6 -> 0.028659097 | H37: =H23/H6 -> 0.10926178 | I37: =I23/I6 -> 0.13284339
C38: PAT Margin | E38: =E28/E6 -> -0.2073455 | F38: =F28/F6 -> -0.035508631 | G38: =G28/G6 -> 0.027734556 | H38: =H28/H6 -> 0.10917907 | I38: =I28/I6 -> 0.19001647
C40: Tax Rate
C41: Effective Tax Rate | D41: =E25/E23 -> -0.006609659 | E41: =F25/F23 -> -2.0139023 | F41: =G25/G23 -> 0.025831337 | G41: =H25/H23 -> -0.0012055286 | H41: =I25/I23 -> -0.4320386
C42: Marginal Tax Rate | D42: 0.25 | E42: 0.25 | F42: 0.25 | G42: 0.25 | H42: 0.25
C44: Return on Capital
C45: EBIT(1-t) | D45: =E18*(1-D42) -> 206.925 | E45: =F18*(1-E42) -> 472.2075 | F45: =G18*(1-F42) -> 429.18 | G45: =H18*(1-G42) -> 629.46 | H45: =I18*(1-H42) -> 1198.53
C46: Book Equity | D46: ='Consolidated FS'!K34 -> 1695.12 | E46: ='Consolidated FS'!L34 -> 1842.15 | F46: ='Consolidated FS'!M34 -> 2456.12 | G46: ='Consolidated FS'!N34 -> 2715.6 | H46: ='Consolidated FS'!O34 -> 2715.6
C47: Book Debt | D47: ='Consolidated FS'!K42+'Consolidated FS'!K51 -> 6270.27 | E47: ='Consolidated FS'!L42+'Consolidated FS'!L51 -> 5060.52 | F47: ='Consolidated FS'!M42+'Consolidated FS'!M51 -> 375.3 | G47: ='Consolidated FS'!N42+'Consolidated FS'!N51 -> 110.27 | H47: ='Consolidated FS'!O42+'Consolidated FS'!O51 -> 205.65
C48: Cash and Cash Equivalent | D48: ='Consolidated FS'!K24 -> 245.2 | E48: ='Consolidated FS'!L24 -> 310.12 | F48: ='Consolidated FS'!M24 -> 520.4 | G48: ='Consolidated FS'!N24 -> 1150.25 | H48: ='Consolidated FS'!O24 -> 1850.4
C49: Capital Employed | D49: =D46+D47-D48 -> 7720.19 | E49: =E46+E47-E48 -> 6592.55 | F49: =F46+F47-F48 -> 2311.02 | G49: =G46+G47-G48 -> 1675.62 | H49: =H46+H47-H48 -> 1070.85
C51: Pre Tax Return on Capital | D51: =E18/D49 -> 0.035737462 | E51: =F18/E49 -> 0.095503257 | F51: =G18/F49 -> 0.24761361 | G51: =H18/G49 -> 0.50087729 | H51: =I18/H49 -> 1.4923098
C52: Post Tax Return on Capital | D52: =D45/D49 -> 0.026803097 | E52: =E45/E49 -> 0.071627443 | F52: =F45/F49 -> 0.18571021 | G52: =G45/G49 -> 0.37565797 | H52: =H45/H49 -> 1.1192324
C54: EBIT Growth | D54: =H52*FCFF!C13 -> 0.014795412

Sheet Fixed Asset Schedule 
B1: Varun Beverages "Fixed Asset Schedule "
B2: Particular | C2: 44256 | D2: 44621 | E2: 44986 | F2: 45352 | G2: 45717
B3: Beginning balance | D3: =C7 -> 1173.66 | E3: =D7 -> 996.51 | F3: =E7 -> 954.65 | G3: =F7 -> 1032.5
B4: Add: Net Purchases | D4: =D5-D3 -> 82.69 | E4: =E5-E3 -> 217.82 | F4: =F5-F3 -> 267.45 | G4: =G5-G3 -> 689.09
B5: Total Fixed Assets | C5: =C6+C7 -> 1432.04 | D5: =D6+D7 -> 1256.35 | E5: =E6+E7 -> 1214.33 | F5: =F6+F7 -> 1222.1 | G5: =G6+G7 -> 1721.59
B6: Less: Depreciation | C6: ='Consolidated FS'!C14 -> 258.38 | D6: ='Consolidated FS'!D14 -> 259.84 | E6: ='Consolidated FS'!E14 -> 259.68 | F6: ='Consolidated FS'!F14 -> 189.6 | G6: ='Consolidated FS'!G14 -> 259.19
B7: Closing Balance(Fixed Asests ) | C7: ='Consolidated FS'!K5+'Consolidated FS'!K7 -> 1173.66 | D7: ='Consolidated FS'!L5+'Consolidated FS'!L7 -> 996.51 | E7: ='Consolidated FS'!M5+'Consolidated FS'!M7 -> 954.65 | F7: ='Consolidated FS'!N5+'Consolidated FS'!N7 -> 1032.5 | G7: ='Consolidated FS'!O5+'Consolidated FS'!O7 -> 1462.4
B9: Net Capital expenditure | D9: =D4-D6 -> -177.15 | E9: =E4-E6 -> -41.86 | F9: =F4-F6 -> 77.85 | G9: =G4-G6 -> 429.9
B10: Net Capital expenditure / Sales percentage | D10: =IFERROR(D9/D3,0) -> -0.15093809 | E10: =IFERROR(E9/E3,0) -> -0.042006603 | F10: =IFERROR(F9/F3,0) -> 0.081548211 | G10: =IFERROR(G9/G3,0) -> 0.41636804
B12: Median Capital expenditure /Sales percentage | C12: =MEDIAN(D10:G10) -> 0.019770804
B13: Average Capital expenditure /Sales percentage | C13: =AVERAGE(D10:G10) -> 0.076242889

Sheet Change in Working Capital 
B1: "Change in Working Capital "
B2: Particular | C2: 44256 | D2: 44621 | E2: 44986 | F2: 45352 | G2: 45717
B3: Inventory | C3: ='Consolidated FS'!K20 -> 1420.8 | D3: ='Consolidated FS'!L20 -> 1650.4 | E3: ='Consolidated FS'!M20 -> 1980.12 | F3: ='Consolidated FS'!N20 -> 2410.5 | G3: ='Consolidated FS'!O20 -> 3150.4
B4: Trade Receivables | C4: ='Consolidated FS'!K13 -> 185.6 | D4: ='Consolidated FS'!L13 -> 142.1 | E4: ='Consolidated FS'!M13 -> 120.6 | F4: ='Consolidated FS'!N13 -> 184.2 | G4: ='Consolidated FS'!O13 -> 210.5
B5: Trade Payable | C5: ='Consolidated FS'!K54+'Consolidated FS'!K55 -> 1850.25 | D5: ='Consolidated FS'!L54+'Consolidated FS'!L55 -> 1980.52 | E5: ='Consolidated FS'!M54+'Consolidated FS'!M55 -> 2110.1 | F5: ='Consolidated FS'!N54+'Consolidated FS'!N55 -> 1680.25 | G5: ='Consolidated FS'!O54+'Consolidated FS'!O55 -> 2010.55
B6: Non Cash working Capital | C6: =C3+C4-C5 -> -243.85 | D6: =D3+D4-D5 -> -188.02 | E6: =E3+E4-E5 -> -9.38 | F6: =F3+F4-F5 -> 914.45 | G6: =G3+G4-G5 -> 1350.35
B7: Change in Working Capital | D7: =D6-C6 -> 55.83 | E7: =E6-D6 -> 178.64 | F7: =F6-E6 -> 923.83 | G7: =G6-F6 -> 435.9
B8: changein working Capital /percentage of sales | D8: =D7/'Consolidated FS'!D4 -> 0.0085629491 | E8: =E7/'Consolidated FS'!E4 -> 0.030039483 | F8: =F7/'Consolidated FS'!F4 -> 0.14219682 | G8: =G7/'Consolidated FS'!G4 -> 0.040170228
B10: Median Non Cash working Capital /Sales percentage | C10: =MEDIAN(D8:G8) -> 0.035104856
B11: Average Non Cash working Capital /Sales percentage | C11: =AVERAGE(C8:G8) -> 0.055242371

Sheet FCFF
B1: Suzlon Energy "Free Cash Flow "
B2: Particular | C2: 44256 | D2: 44621 | E2: 44986 | F2: 45352 | G2: 45717
B3: EBIT | C3: =Assumptions!E18 -> 275.9 | D3: =Assumptions!F18 -> 629.61 | E3: =Assumptions!G18 -> 572.24 | F3: =Assumptions!H18 -> 839.28 | G3: =Assumptions!I18 -> 1598.04
B4: Less: Tax on EBIT | C4: =25%*C3 -> 68.975 | D4: =25%*D3 -> 157.4025 | E4: =25%*E3 -> 143.06 | F4: =25%*F3 -> 209.82 | G4: =25%*G3 -> 399.51
B5: EBIT * (1- Tax) | C5: =C3-C4 -> 206.925 | D5: =D3-D4 -> 472.2075 | E5: =E3-E4 -> 429.18 | F5: =F3-F4 -> 629.46 | G5: =G3-G4 -> 1198.53
B6: Less: Net Capital expenditure | C6: 0 | D6: ='Fixed Asset Schedule '!D9 -> -177.15 | E6: ='Fixed Asset Schedule '!E9 -> -41.86 | F6: ='Fixed Asset Schedule '!F9 -> 77.85 | G6: ='Fixed Asset Schedule '!G9 -> 429.9
B7: Less: Net Change in working Capital | C7: ='Change in Working Capital '!C8 -> 0 | D7: ='Change in Working Capital '!D8 -> 0.0085629491 | E7: ='Change in Working Capital '!E8 -> 0.030039483 | F7: ='Change in Working Capital '!F8 -> 0.14219682 | G7: ='Change in Working Capital '!G8 -> 0.040170228
B8: Reinvestment | C8: =SUM(C6:C7) -> 0 | D8: =SUM(D6:D7) -> -177.14144 | E8: =SUM(E6:E7) -> -41.829961 | F8: =SUM(F6:F7) -> 77.992197 | G8: =SUM(G6:G7) -> 429.94017
B9: Free Cash Flow | C9: =C5-C8 -> 206.925 | D9: =D5-D8 -> 649.34894 | E9: =E5-E8 -> 471.00996 | F9: =F5-F8 -> 551.4678 | G9: =G5-G8 -> 768.58983
B11: Reinvestment Rate | C11: 0 | D11: =D8/D5 -> -0.37513474 | E11: =E8/E5 -> -0.097464841 | F11: =F8/F5 -> 0.12390334 | G11: =G8/G5 -> 0.35872291
B13: Median Reinvestment rate /Sales percentage | C13: =MEDIAN(D11:G11) -> 0.01321925
B14: Average Reinvestment rate /Sales percentage | C14: =AVERAGE(D11:G11) -> 0.0025066679

Sheet Growth Scenario
B2: Radico Khaitan "Growth Scenarios"
B4: Scenario 1: High Growth
B5: INR Cr. | C5: LTM | D5: Y1E | E5: Y2E | F5: Y3E | G5: Y4W | H5: Y5E | I5: Y6E | J5: Y7E | K5: Y8E | L5: Y9E | M5: Y10E
B6: Sales | C6: ='Consolidated FS'!G4 -> 10851.32 | D6: =C6*(1+D7) -> 14982.597 | E6: =D6*(1+E7) -> 20162.8 | F6: =E6*(1+F7) -> 26428.985 | G6: =F6*(1+G7) -> 33718.39 | H6: =G6*(1+H7) -> 41839.212 | I6: =H6*(1+I7) -> 50452.819 | J6: =I6*(1+J7) -> 59075.483 | K6: =J6*(1+K7) -> 67106.028 | ... M6: =L6*(1+M7) -> 78757.81 | O6: Risk Free Rate | P6: 0.066
B7: Sales Growth % | D7: =N7 -> 0.38071652 | E7: =D7-$P$9 -> 0.34574802 | F7: =E7-$P$9 -> 0.31077952 | G7: =F7-$P$9 -> 0.27581101 | H7: =G7-$P$9 -> 0.24084251 | I7: =H7-$P$9 -> 0.20587401 | J7: =I7-$P$9 -> 0.17090551 | K7: =J7-$P$9 -> 0.135937 | L7: =K7-$P$9 -> 0.1009685 | M7: =L7-$P$9 -> 0.066 | N7: =MEDIAN(Assumptions!F7:I7) -> 0.38071652
B9: Scenario 2: Average Growth | O9: =N7-P6 -> 0.31471652 | P9: =O9/9 -> 0.034968502
B10: INR Cr. | C10: LTM | D10: Y1E | E10: Y2E | F10: Y3E | G10: Y4W | H10: Y5E | I10: Y6E | J10: Y7E | K10: Y8E | L10: Y9E | M10: Y10E
B11: Sales | C11: =C6 -> 10851.32 | D11: =C11*(1+D12) -> 15288.932 | E11: =D11*(1+E12) -> 20961.25 | F11: =E11*(1+F12) -> 27942.807 | G11: =F11*(1+G12) -> 36189.599 | H11: =G11*(1+H12) -> 45497.297 | I11: =H11*(1+I12) -> 55472.765 | J11: =I11*(1+J12) -> 65530.841 | K11: =J11*(1+K12) -> 74926.46 | ... M11: =L11*(1+M12) -> 88417.39
B12: Sales Growth % | D12: =AVERAGE(Assumptions!F7:I7) -> 0.40894671 | E12: =D12-O12 -> 0.37100818 | F12: =E12-O12 -> 0.33306966 | G12: =F12-O12 -> 0.29513114 | H12: =G12-O12 -> 0.25719261 | I12: =H12-O12 -> 0.21925409 | J12: =I12-O12 -> 0.18131557 | K12: =J12-O12 -> 0.14337705 | L12: =K12-O12 -> 0.10543852 | M12: 0.0675 | N12: =D12-M12 -> 0.34144671 | O12: =N12/9 -> 0.037938523
B14: Scenario 3: EBIT Growth
B15: INR Cr. | C15: LTM | D15: Y1E | E15: Y2E | F15: Y3E | G15: Y4W | H15: Y5E | I15: Y6E | J15: Y7E | K15: Y8E | L15: Y9E | M15: Y10E
B16: Sales | C16: =C11 -> 10851.32 | D16: =C16*(1+D17) -> 11011.87 | E16: =D16*(1+E17) -> 11239.281 | F16: =E16*(1+F17) -> 11537.207 | G16: =F16*(1+G17) -> 11910.593 | H16: =G16*(1+H17) -> 12365.811 | I16: =H16*(1+I17) -> 12910.844 | J16: =I16*(1+J17) -> 13555.505 | K16: =J16*(1+K17) -> 14311.738 | ... M16: =L16*(1+M17) -> 16219.563
B17: Sales Growth % | D17: =Assumptions!D54 -> 0.014795412 | E17: =D17-$O$17 -> 0.020651478 | F17: =E17-$O$17 -> 0.026507543 | G17: =F17-$O$17 -> 0.032363608 | H17: =G17-$O$17 -> 0.038219674 | I17: =H17-$O$17 -> 0.044075739 | J17: =I17-$O$17 -> 0.049931804 | K17: =J17-$O$17 -> 0.055787869 | L17: =K17-$O$17 -> 0.061643935 | M17: 0.0675 | N17: =D17-M17 -> -0.052704588 | O17: =N17/9 -> -0.0058560653
B19: Live Scenario | C19: 2
B20: INR Cr. | C20: LTM | D20: Y1E | E20: Y2E | F20: Y3E | G20: Y4W | H20: Y5E | I20: Y6E | J20: Y7E | K20: Y8E | L20: Y9E | M20: Y10E
B21: Sales | C21: =C6 -> 10851.32 | D21: =C21*(1+D22) -> 15288.932 | E21: =D21*(1+E22) -> 20961.25 | F21: =E21*(1+F22) -> 27942.807 | G21: =F21*(1+G22) -> 36189.599 | H21: =G21*(1+H22) -> 45497.297 | I21: =H21*(1+I22) -> 55472.765 | J21: =I21*(1+J22) -> 65530.841 | K21: =J21*(1+K22) -> 74926.46 | ... M21: =L21*(1+M22) -> 88417.39
B22: Sales Growth % | D22: =CHOOSE($C$19,D7,D12,D17) -> 0.40894671 | E22: =CHOOSE($C$19,E7,E12,E17) -> 0.37100818 | F22: =CHOOSE($C$19,F7,F12,F17) -> 0.33306966 | G22: =CHOOSE($C$19,G7,G12,G17) -> 0.29513114 | H22: =CHOOSE($C$19,H7,H12,H17) -> 0.25719261 | I22: =CHOOSE($C$19,I7,I12,I17) -> 0.21925409 | J22: =CHOOSE($C$19,J7,J12,J17) -> 0.18131557 | K22: =CHOOSE($C$19,K7,K12,K17) -> 0.14337705 | ... M22: =CHOOSE($C$19,M7,M12,M17) -> 0.0675

Sheet Valuation 
B1: Suzlon Energy- "VALUATION"
D2: 1 | E2: 2 | F2: 3 | G2: 4 | H2: 5 | I2: 6 | J2: 7 | K2: 8 | L2: 9 | M2: 10
B3: INR Cr | C3: LTM | D3: Y1E | E3: Y2E | F3: Y3E | G3: Y4W | H3: Y5E | I3: Y6E | J3: Y7E | K3: Y8E | L3: Y9E | M3: Y10E | O3: Terminal Year | Q3: Terminal growth rate % | R3: 0.15
B4: Sales | C4: ='Growth Scenario'!C21 -> 10851.32 | D4: ='Growth Scenario'!D21 -> 15288.932 | E4: ='Growth Scenario'!E21 -> 20961.25 | F4: ='Growth Scenario'!F21 -> 27942.807 | G4: ='Growth Scenario'!G21 -> 36189.599 | H4: ='Growth Scenario'!H21 -> 45497.297 | I4: ='Growth Scenario'!I21 -> 55472.765 | J4: ='Growth Scenario'!J21 -> 65530.841 | ... M4: ='Growth Scenario'!M21 -> 88417.39 | O4: =M4*(1+R3) -> 101680 | Q4: Cost of Capital % | R4: =WACC!E25 -> 0.1385103
B5: Sales Growth | D5: ='Growth Scenario'!D22 -> 0.40894671 | E5: ='Growth Scenario'!E22 -> 0.37100818 | F5: ='Growth Scenario'!F22 -> 0.33306966 | G5: ='Growth Scenario'!G22 -> 0.29513114 | H5: ='Growth Scenario'!H22 -> 0.25719261 | I5: ='Growth Scenario'!I22 -> 0.21925409 | J5: ='Growth Scenario'!J22 -> 0.18131557 | K5: ='Growth Scenario'!K22 -> 0.14337705 | ... M5: ='Growth Scenario'!M22 -> 0.0675 | O5: =R3 -> 0.15 | Q5: Terminal reinvestment rate % | R5: =R3*R4 -> 0.020776545
B6: EBIT | D6: =D7*D4 -> 142.46088 | E6: =E7*E4 -> 195.31503 | F6: =F7*F4 -> 260.36854 | G6: =G7*G4 -> 337.2114 | H6: =H7*H4 -> 423.93969 | I6: =I7*I4 -> 516.8902 | J6: =J7*J4 -> 610.61044 | K6: =K7*K4 -> 698.15796 | ... M6: =M7*M4 -> 823.86523 | O6: =O7*O4 -> 947.44501
B7: EBIT Margin % | D7: =AVERAGE(Ratios!C13:G13) -> 0.0093179093 | E7: =D7 -> 0.0093179093 | F7: =E7 -> 0.0093179093 | G7: =F7 -> 0.0093179093 | H7: =G7 -> 0.0093179093 | I7: =H7 -> 0.0093179093 | J7: =I7 -> 0.0093179093 | K7: =J7 -> 0.0093179093 | L7: =K7 -> 0.0093179093 | M7: =L7 -> 0.0093179093 | O7: =M7 -> 0.0093179093 | Q7: Enterprise value = Equity Value + Minority interest
B8: Less: Tax on EBIT | D8: =25%*D6 -> 35.61522 | E8: =25%*E6 -> 48.828757 | F8: =25%*F6 -> 65.092135 | G8: =25%*G6 -> 84.302851 | H8: =25%*H6 -> 105.98492 | I8: =25%*I6 -> 129.22255 | J8: =25%*J6 -> 152.65261 | K8: =25%*K6 -> 174.53949 | ... M8: =25%*M6 -> 205.96631 | O8: =25%*O6 -> 236.86125
B9: EBIT(1-T) | D9: =D6-D8 -> 106.84566 | E9: =E6-E8 -> 146.48627 | F9: =F6-F8 -> 195.27641 | G9: =G6-G8 -> 252.90855 | H9: =H6-H8 -> 317.95477 | I9: =I6-I8 -> 387.66765 | J9: =J6-J8 -> 457.95783 | K9: =K6-K8 -> 523.61847 | ... M9: =M6-M8 -> 617.89892 | O9: =O6-O8 -> 710.58376
B10: Less: Net Capital Expenditure | D10: ='Fixed Asset Schedule '!$C$12*'Valuation '!D4 -> 302.27447 | E10: ='Fixed Asset Schedule '!$C$12*'Valuation '!E4 -> 414.42078 | F10: ='Fixed Asset Schedule '!$C$12*'Valuation '!F4 -> 552.45176 | G10: ='Fixed Asset Schedule '!$C$12*'Valuation '!G4 -> 715.49748 | H10: ='Fixed Asset Schedule '!$C$12*'Valuation '!H4 -> 899.51815 | I10: ='Fixed Asset Schedule '!$C$12*'Valuation '!I4 -> 1096.7412 | J10: ='Fixed Asset Schedule '!$C$12*'Valuation '!J4 -> 1295.5974 | K10: ='Fixed Asset Schedule '!$C$12*'Valuation '!K4 -> 1481.3564 | ... M10: ='Fixed Asset Schedule '!$C$12*'Valuation '!M4 -> 1748.0829
B11: Non Cash Working Capital | C11: ='Change in Working Capital '!G7 -> 435.9 | D11: ='Change in Working Capital '!$C$11*'Valuation '!D4 -> 844.59682 | E11: ='Change in Working Capital '!$C$11*'Valuation '!E4 -> 1157.9492 | F11: ='Change in Working Capital '!$C$11*'Valuation '!F4 -> 1543.6269 | G11: ='Change in Working Capital '!$C$11*'Valuation '!G4 -> 1999.1992 | H11: ='Change in Working Capital '!$C$11*'Valuation '!H4 -> 2513.3785 | I11: ='Change in Working Capital '!$C$11*'Valuation '!I4 -> 3064.4471 | J11: ='Change in Working Capital '!$C$11*'Valuation '!J4 -> 3620.079 | K11: ='Change in Working Capital '!$C$11*'Valuation '!K4 -> 4139.1153 | ... M11: ='Change in Working Capital '!$C$11*'Valuation '!M4 -> 4884.3862
B12: Less: Change in Working Capital | D12: =D11-C11 -> 408.69682 | E12: =E11-D11 -> 313.35233 | F12: =F11-E11 -> 385.67773 | G12: =G11-F11 -> 455.57236 | H12: =H11-G11 -> 514.17928 | I12: =I11-H11 -> 551.06853 | J12: =J11-I11 -> 555.63196 | K12: =K11-J11 -> 519.03624 | ... M12: =M11-L11 -> 308.84878
B13: Reinvestment | D13: =D10+D12 -> 710.9713 | E13: =E10+E12 -> 727.77311 | F13: =F10+F12 -> 938.12949 | G13: =G10+G12 -> 1171.0698 | H13: =H10+H12 -> 1413.6974 | I13: =I10+I12 -> 1647.8097 | J13: =J10+J12 -> 1851.2294 | K13: =K10+K12 -> 2000.3926 | ... M13: =M10+M12 -> 2056.9317 | O13: =O9*O15 -> 14.763476
B14: Free Cash Flow To Firm (FCFF) | D14: =D9-D13 -> -604.12564 | E14: =E9-E13 -> -581.28684 | F14: =F9-F13 -> -742.85309 | G14: =G9-G13 -> -918.16129 | H14: =H9-H13 -> -1095.7427 | I14: =I9-I13 -> -1260.1421 | J14: =J9-J13 -> -1393.2716 | K14: =K9-K13 -> -1476.7741 | ... M14: =M9-M13 -> -1439.0328 | O14: =O9-O13 -> 695.82028
B15: Implied Reinvestment rate % | D15: =D13/D9 -> 6.6541898 | E15: =E13/E9 -> 4.9682001 | F15: =F13/F9 -> 4.8041108 | G15: =G13/G9 -> 4.6304082 | H15: =H13/H9 -> 4.4462219 | I15: =I13/I9 -> 4.2505732 | J15: =J13/J9 -> 4.0423578 | K15: =K13/K9 -> 3.8203248 | ... M15: =M13/M9 -> 3.3289129 | O15: =R5 -> 0.020776545
B17: Terminal Value | M17: =M14*(1+R3)/(R4-R3) -> 144032.3
B19: Present Value Interest Factor(PVIF) | D19: =1/(1+$R$4)^D2 -> 0.87834076 | E19: =1/(1+$R$4)^E2 -> 0.77148249 | F19: =1/(1+$R$4)^F2 -> 0.67762451 | G19: =1/(1+$R$4)^G2 -> 0.59518522 | H19: =1/(1+$R$4)^H2 -> 0.52277544 | I19: =1/(1+$R$4)^I2 -> 0.45917498 | J19: =1/(1+$R$4)^J2 -> 0.4033121 | K19: =1/(1+$R$4)^K2 -> 0.35424545 | ... M19: =1/(1+$R$4)^M2 -> 0.27329416
B21: Present value of FCFF | D21: =SUMPRODUCT(D14:M14,D19:M19) -> -5123.9393
B22: Present value of Terminal value | D22: =M17*M19 -> 39363.187
I23: Calculation of Sensitivity Analysis
B24: Value of operating assets | D24: =D21+D22 -> 34239.247 | I24: =D31 -> 26.365905 | J24: =K24-1% -> 0.1285103 | K24: =R4 -> 0.1385103 | L24: =K24+1% -> 0.1485103 | M24: =L24+1% -> 0.1585103
B25: Add: Cash | D25: ='Consolidated FS'!O24 -> 1850.4 | I25: =I26-1% -> 0.047 | J25: 647.64581 | K25: 647.64581 | L25: 525.46011 | M25: 380.7948
B26: Less: Debt | D26: ='Consolidated FS'!O42+'Consolidated FS'!O51 -> 205.65 | I26: =I27-1% -> 0.057 | J26: 488.12563 | K26: 488.12563 | L26: 411.63691 | M26: 313.33096
B27: Less: Minority Interest | I27: 0.067 | J27: 384.07289 | K27: 384.07289 | L27: 332.97385 | M27: 263.15813
B28: Equity Value | D28: =D24+D25-D26-D27 -> 35883.997 | I28: =I27+1% -> 0.077 | J28: 311.961 | K28: 311.961 | L28: 276.13091 | M28: 224.78524
I29: =I28+1% -> 0.087 | J29: 259.70008 | K29: 259.70008 | L29: 233.60488 | M29: 194.74248
B30: No. of Shares outstanding (Cr) | D30: 1361
B31: intrinsic value per share | D31: =D28/D30 -> 26.365905 | F31: Current | G31: 26.5

Sheet Ratios
B2: Ratio Analysis
B3: Years | C3: 46102 | D3: 46103 | E3: 46104 | F3: 46105 | G3: 46106 | H3: Trend
B5: SalesGrowth | D5: =('Consolidated FS'!D4/'Consolidated FS'!C4)-1 -> 0.97895072 | E5: =('Consolidated FS'!E4/'Consolidated FS'!D4)-1 -> -0.087900981 | F5: =('Consolidated FS'!F4/'Consolidated FS'!E4)-1 -> 0.092486093 | G5: =('Consolidated FS'!G4/'Consolidated FS'!F4)-1 -> 0.67024584
B6: EBITDA Growth | D6: =(('Consolidated FS'!D20+'Consolidated FS'!D13+'Consolidated FS'!D14+'Consolidated FS'!D25)-('Consolidated FS'!C20+'Consolidated FS'!C13+'Consolidated FS'!C14+'Consolidated FS'!C25))/('Consolidated FS'!C20+'Consolidated FS'!C13+'Consolidated FS'!C14+'Consolidated FS'!C25) -> -0.14872017 | E6: =(('Consolidated FS'!E20+'Consolidated FS'!E13+'Consolidated FS'!E14+'Consolidated FS'!E25)-('Consolidated FS'!D20+'Consolidated FS'!D13+'Consolidated FS'!D14+'Consolidated FS'!D25))/('Consolidated FS'!D20+'Consolidated FS'!D13+'Consolidated FS'!D14+'Consolidated FS'!D25) -> 2.0796659 | F6: =(('Consolidated FS'!F20+'Consolidated FS'!F13+'Consolidated FS'!F14+'Consolidated FS'!F25)-('Consolidated FS'!E20+'Consolidated FS'!E13+'Consolidated FS'!E14+'Consolidated FS'!E25))/('Consolidated FS'!E20+'Consolidated FS'!E13+'Consolidated FS'!E14+'Consolidated FS'!E25) -> -0.71689356 | G6: =(('Consolidated FS'!G20+'Consolidated FS'!G13+'Consolidated FS'!G14+'Consolidated FS'!G25)-('Consolidated FS'!F20+'Consolidated FS'!F13+'Consolidated FS'!F14+'Consolidated FS'!F25))/('Consolidated FS'!F20+'Consolidated FS'!F13+'Consolidated FS'!F14+'Consolidated FS'!F25) -> 0.31906573
B7: EBIT Growth | D7: =(('Consolidated FS'!D18)-('Consolidated FS'!C18))/('Consolidated FS'!C18) -> -0.88191123 | E7: =(('Consolidated FS'!E18)-('Consolidated FS'!D18))/('Consolidated FS'!D18) -> -3.0685445 | F7: =(('Consolidated FS'!F18)-('Consolidated FS'!E18))/('Consolidated FS'!E18) -> 3.169131 | G7: =(('Consolidated FS'!G18)-('Consolidated FS'!F18))/('Consolidated FS'!F18) -> 1.0278533
B8: Net Profit Growth | D8: =(('Consolidated FS'!D29)-('Consolidated FS'!C29))/('Consolidated FS'!C29) -> -2.7043151 | E8: =(('Consolidated FS'!E29)-('Consolidated FS'!D29))/('Consolidated FS'!D29) -> -17.353951 | F8: =(('Consolidated FS'!F29)-('Consolidated FS'!E29))/('Consolidated FS'!E29) -> -0.77129073 | G8: =(('Consolidated FS'!G29)-('Consolidated FS'!F29))/('Consolidated FS'!F29) -> 2.1371697
B9: Dividend Growth
B11: Gross Margin | C11: =('Consolidated FS'!C4-('Consolidated FS'!C10+'Consolidated FS'!C11))/('Consolidated FS'!C4) -> 0.52126326 | D11: =('Consolidated FS'!D4-('Consolidated FS'!D10+'Consolidated FS'!D11))/('Consolidated FS'!D4) -> 0.33564521 | E11: =('Consolidated FS'!E4-('Consolidated FS'!E10+'Consolidated FS'!E11))/('Consolidated FS'!E4) -> 0.36392101 | F11: =('Consolidated FS'!F4-('Consolidated FS'!F10+'Consolidated FS'!F11))/('Consolidated FS'!F4) -> 0.38706664 | G11: =('Consolidated FS'!G4-('Consolidated FS'!G10+'Consolidated FS'!G11))/('Consolidated FS'!G4) -> 0.36536753
B12: EBITDA Margin | C12: =('Consolidated FS'!C20+'Consolidated FS'!C13+'Consolidated FS'!C14+'Consolidated FS'!C25)/'Consolidated FS'!C4 -> 0.41407737 | D12: =('Consolidated FS'!D20+'Consolidated FS'!D13+'Consolidated FS'!D14+'Consolidated FS'!D25)/'Consolidated FS'!D4 -> 0.17812253 | E12: =('Consolidated FS'!E20+'Consolidated FS'!E13+'Consolidated FS'!E14+'Consolidated FS'!E25)/'Consolidated FS'!E4 -> 0.60142361 | F12: =('Consolidated FS'!F20+'Consolidated FS'!F13+'Consolidated FS'!F14+'Consolidated FS'!F25)/'Consolidated FS'!F4 -> 0.15585269 | G12: =('Consolidated FS'!G20+'Consolidated FS'!G13+'Consolidated FS'!G14+'Consolidated FS'!G25)/'Consolidated FS'!G4 -> 0.12308364
B13: EBIT Margin | C13: ='Consolidated FS'!C18/'Consolidated FS'!C4 -> -0.21261439 | D13: ='Consolidated FS'!D18/'Consolidated FS'!D4 -> -0.012687214 | E13: ='Consolidated FS'!E18/'Consolidated FS'!E4 -> 0.028773264 | F13: ='Consolidated FS'!F18/'Consolidated FS'!F4 -> 0.10980415 | G13: ='Consolidated FS'!G18/'Consolidated FS'!G4 -> 0.13331374
B14: EBT Margin | C14: ='Consolidated FS'!C20/'Consolidated FS'!C4 -> 0.031860744 | D14: ='Consolidated FS'!D20/'Consolidated FS'!D4 -> 6.1350164e-05 | E14: ='Consolidated FS'!E20/'Consolidated FS'!E4 -> 0.48625993 | F14: ='Consolidated FS'!F20/'Consolidated FS'!F4 -> 0.10150935 | G14: ='Consolidated FS'!G20/'Consolidated FS'!G4 -> 0.13331374
B15: Net Profit Margin | C15: ='Consolidated FS'!C29/'Consolidated FS'!C4 -> 0.031441883 | D15: ='Consolidated FS'!D29/'Consolidated FS'!D4 -> -0.027078429 | E15: ='Consolidated FS'!E29/'Consolidated FS'!E4 -> 0.48551668 | F15: ='Consolidated FS'!F29/'Consolidated FS'!F4 -> 0.10164172 | G15: ='Consolidated FS'!G29/'Consolidated FS'!G4 -> 0.19091041
B17: SalesExpenses%Sales | C17: =('Consolidated FS'!C12+'Consolidated FS'!C15)/'Consolidated FS'!C4 -> 0.37459821 | D17: =('Consolidated FS'!D12+'Consolidated FS'!D15)/'Consolidated FS'!D4 -> 0.20870866 | E17: =('Consolidated FS'!E12+'Consolidated FS'!E15)/'Consolidated FS'!E4 -> 0.22801185 | F17: =('Consolidated FS'!F12+'Consolidated FS'!F15)/'Consolidated FS'!F4 -> 0.23366437 | G17: =('Consolidated FS'!G12+'Consolidated FS'!G15)/'Consolidated FS'!G4 -> 0.19775566
B18: Depreciation%Sales | C18: ='Consolidated FS'!C14/'Consolidated FS'!C4 -> 0.078424112 | D18: ='Consolidated FS'!D14/'Consolidated FS'!D4 -> 0.039853066 | E18: ='Consolidated FS'!E14/'Consolidated FS'!E4 -> 0.043666889 | F18: ='Consolidated FS'!F14/'Consolidated FS'!F4 -> 0.029183418 | G18: ='Consolidated FS'!G14/'Consolidated FS'!G4 -> 0.023885573
B19: OperatingIncome%Sales | C19: ='Consolidated FS'!C18/'Consolidated FS'!C4 -> -0.21261439 | D19: ='Consolidated FS'!D18/'Consolidated FS'!D4 -> -0.012687214 | E19: ='Consolidated FS'!E18/'Consolidated FS'!E4 -> 0.028773264 | F19: ='Consolidated FS'!F18/'Consolidated FS'!F4 -> 0.10980415 | G19: ='Consolidated FS'!G18/'Consolidated FS'!G4 -> 0.13331374
B21: Return on Capital Employed | C21: ='Consolidated FS'!C18/('Consolidated FS'!K38+'Consolidated FS'!K40) -> 0.24781369 | D21: ='Consolidated FS'!D18/(('Consolidated FS'!K38+'Consolidated FS'!K40+('Consolidated FS'!L38+'Consolidated FS'!L40))/2) -> 0.037385627 | E21: ='Consolidated FS'!E18/(('Consolidated FS'!L38+'Consolidated FS'!L40+('Consolidated FS'!M38+'Consolidated FS'!M40))/2) -> 0.17294145 | F21: ='Consolidated FS'!F18/(('Consolidated FS'!M38+'Consolidated FS'!M40+('Consolidated FS'!N38+'Consolidated FS'!N40))/2) -> 0.1464129 | G21: ='Consolidated FS'!G18/(('Consolidated FS'!N38+'Consolidated FS'!N40+('Consolidated FS'!O38+'Consolidated FS'!O40))/2) -> 0.19687934
B22: Retained Earnings%
B23: Return on Equity% | C23: ='Consolidated FS'!C29/'Consolidated FS'!K38 -> -0.036647233 | D23: ='Consolidated FS'!D29/(('Consolidated FS'!K38+'Consolidated FS'!L38)/2) -> 0.079792463 | E23: ='Consolidated FS'!E29/(('Consolidated FS'!L38+'Consolidated FS'!M38)/2) -> 2.9181937 | F23: ='Consolidated FS'!F29/(('Consolidated FS'!M38+'Consolidated FS'!N38)/2) -> 0.13552911 | G23: ='Consolidated FS'!G29/(('Consolidated FS'!N38+'Consolidated FS'!O38)/2) -> 0.28193881
B24: Self Sustained Growth Rate
B25: Interest Coverage Ratio | C25: ='Consolidated FS'!C18/'Consolidated FS'!C13 -> -0.70311967 | D25: ='Consolidated FS'!D18/'Consolidated FS'!D13 -> -0.11261776 | E25: ='Consolidated FS'!E18/'Consolidated FS'!E13 -> 0.40666888 | F25: ='Consolidated FS'!F18/'Consolidated FS'!F13 -> 4.341407 | G25: ='Consolidated FS'!G18/'Consolidated FS'!G13 -> 5.6775118
B27: Debtor Turnover Ratio | C27: ='Consolidated FS'!C4/'Consolidated FS'!K23 -> 2.9551081 | D27: ='Consolidated FS'!D4/(('Consolidated FS'!K23+'Consolidated FS'!L23)/2) -> 5.444521 | E27: ='Consolidated FS'!E4/(('Consolidated FS'!L23+'Consolidated FS'!M23)/2) -> 4.3558616 | F27: ='Consolidated FS'!F4/(('Consolidated FS'!M23+'Consolidated FS'!N23)/2) -> 4.150341 | G27: ='Consolidated FS'!G4/(('Consolidated FS'!N23+'Consolidated FS'!O23)/2) -> 5.5356111
B28: Creditor Turnover Ratio | C28: =('Consolidated FS'!C10+'Consolidated FS'!C12+'Consolidated FS'!C13)/'Consolidated FS'!K54 -> 22.239409 | D28: =('Consolidated FS'!D10+'Consolidated FS'!D12+'Consolidated FS'!D13)/(('Consolidated FS'!K54+'Consolidated FS'!L54)/2) -> 34.938732 | E28: =('Consolidated FS'!E10+'Consolidated FS'!E12+'Consolidated FS'!E13)/(('Consolidated FS'!L54+'Consolidated FS'!M54)/2) -> 26.640389 | F28: =('Consolidated FS'!F10+'Consolidated FS'!F12+'Consolidated FS'!F13)/(('Consolidated FS'!M54+'Consolidated FS'!N54)/2) -> 29.942516 | G28: =('Consolidated FS'!G10+'Consolidated FS'!G12+'Consolidated FS'!G13)/(('Consolidated FS'!N54+'Consolidated FS'!O54)/2) -> 52.498819
B29: Inventory Turnover | C29: =('Consolidated FS'!C10+'Consolidated FS'!C11)/'Consolidated FS'!K20 -> 1.1101281 | D29: =('Consolidated FS'!D10+'Consolidated FS'!D11)/(('Consolidated FS'!K20+'Consolidated FS'!L20)/2) -> 2.8207606 | E29: =('Consolidated FS'!E10+'Consolidated FS'!E11)/(('Consolidated FS'!L20+'Consolidated FS'!M20)/2) -> 2.0838117 | F29: =('Consolidated FS'!F10+'Consolidated FS'!F11)/(('Consolidated FS'!M20+'Consolidated FS'!N20)/2) -> 1.8139261 | G29: =('Consolidated FS'!G10+'Consolidated FS'!G11)/(('Consolidated FS'!N20+'Consolidated FS'!O20)/2) -> 2.4767933
B30: Fixed Asset Turnover | C30: ='Consolidated FS'!C4/'Consolidated FS'!K18 -> 1.520002 | D30: ='Consolidated FS'!D4/(('Consolidated FS'!K18+'Consolidated FS'!L18)/2) -> 3.2923304 | E30: ='Consolidated FS'!E4/(('Consolidated FS'!L18+'Consolidated FS'!M18)/2) -> 3.3926594 | F30: ='Consolidated FS'!F4/(('Consolidated FS'!M18+'Consolidated FS'!N18)/2) -> 3.4394833 | G30: ='Consolidated FS'!G4/(('Consolidated FS'!N18+'Consolidated FS'!O18)/2) -> 4.5401588
B31: Capital Turnover Ratio | C31: ='Consolidated FS'!C4/('Consolidated FS'!K38+'Consolidated FS'!K40) -> -1.1655546 | D31: ='Consolidated FS'!D4/(((('Consolidated FS'!K38+'Consolidated FS'!K40)+('Consolidated FS'!L38+'Consolidated FS'!L40))/2)) -> -2.9467169 | E31: ='Consolidated FS'!E4/(((('Consolidated FS'!L38+'Consolidated FS'!L40)+('Consolidated FS'!M38+'Consolidated FS'!M40))/2)) -> 6.0104911 | F31: ='Consolidated FS'!F4/(((('Consolidated FS'!M38+'Consolidated FS'!M40)+('Consolidated FS'!N38+'Consolidated FS'!N40))/2)) -> 1.3334004 | G31: ='Consolidated FS'!G4/(((('Consolidated FS'!N38+'Consolidated FS'!N40)+('Consolidated FS'!O38+'Consolidated FS'!O40))/2)) -> 1.4768121
B33: Debtor Days | C33: =365/C27 -> 123.51494 | D33: =365/D27 -> 67.039874 | E33: =365/E27 -> 83.795133 | F33: =365/F27 -> 87.944582 | G33: =365/G27 -> 65.936713
B34: Payable Days | C34: =365/C28 -> 16.412307 | D34: =365/D28 -> 10.446859 | E34: =365/E28 -> 13.701001 | F34: =365/F28 -> 12.190024 | G34: =365/G28 -> 6.9525373
B35: Inventory Days | C35: =365/C29 -> 328.79089 | D35: =365/D29 -> 129.39772 | E35: =365/E29 -> 175.15978 | F35: =365/F29 -> 201.22099 | G35: =365/G29 -> 147.36797
B36: Cash Conversion Cycle (in days) | C36: =C33+C35-C34 -> 435.89352 | D36: =D33+D35-D34 -> 185.99074 | E36: =E33+E35-E34 -> 245.25391 | F36: =F33+F35-F34 -> 276.97555 | G36: =G33+G35-G34 -> 206.35214

Sheet Raw Data Relative Valuation 
B2: S.No. | C2: Name | D2: CMP Rs. | E2: Net Profit | F2: No. Eq. Shares Cr. | G2: Mar Cap Rs.Cr. | H2: Cash End Rs.Cr. | I2: Debt Rs.Cr. | J2: Sales Rs.Cr. | K2: EV / EBITDA | L2: EBIDT Ann Rs.Cr.
B3: 1 | C3: A B B | D3: 6605 | E3: 2977.28 | F3: 21.19 | G3: 140030.75 | H3: 5834.87 | I3: 84.82 | J3: 13093.38 | K3: 60.76 | L3: 2397.26
B4: 2 | C4: CG Power & Ind | D4: 853.25 | E4: 1198.68 | F4: 157.49 | G4: 134414.29 | H4: 1027.56 | I4: 118.39 | J4: 12417.95 | K4: 71.41 | L4: 1869.56
B5: 3 | C5: Siemens Ener.Ind | D5: 3459.6 | E5: 1309.8 | F5: 35.61 | G5: 123178.14 | H5: 3462 | I5: 215.7 | J5: 8735.3 | K5: 61.18 | L5: 1637.2
B6: 4 | C6: GE Vernova T&D | D6: 4679.4 | E6: 1233.25 | F6: 25.6 | G6: 119826.97 | H6: 1527.72 | I6: 24 | J6: 6206.31 | K6: 66.68 | L6: 1774.47
B7: 5 | C7: Suzlon Energy | D7: 52.57 | E7: 3230.02 | F7: 1360.53 | G7: 71495.95 | H7: 1112.83 | I7: 397 | J7: 15028.53 | K7: 24.81 | L7: 1966.42

Sheet Relative Valuation 
B2: Relative Valuation - Radico Khaitan
B4: Figures in Crore
B5: Comparable Company Valuation
B7: Company Name | C7: Ticker Name | D7: Market Data | K7: Financials | P7: Valuation
D8: No. of shares | E8: Share Price | F8: Equity value | G8: Debt | H8: cash | I8: Enterprises value | K8: Revenue | L8: EBITDA | M8: Net Profit | N8: EPS | P8: EV/Revenue | Q8: EV/EBITDA | R8: P/E Ratio
B9: A B B | D9: 21.19 | E9: 6605 | F9: =IFERROR(D9*E9,0) -> 139959.95 | G9: 84.82 | H9: 5834.87 | I9: =IFERROR(F9+G9-H9,0) -> 134209.9 | K9: 13093.38 | L9: 2397.26 | M9: 2977.28 | N9: =IFERROR(M9/D9,0) -> 140.50401 | P9: =IFERROR(I9/K9,0) -> 10.25021 | Q9: =IFERROR(I9/L9,0) -> 55.984708 | R9: =IFERROR(E9/N9,0) -> 47.009334
B10: CG Power & Ind | D10: 157.49 | E10: 853.25 | F10: =IFERROR(D10*E10,0) -> 134378.34 | G10: 118.39 | H10: 1027.56 | I10: =IFERROR(F10+G10-H10,0) -> 133469.17 | K10: 12417.95 | L10: 1869.56 | M10: 1198.68 | N10: =IFERROR(M10/D10,0) -> 7.6111499 | P10: =IFERROR(I10/K10,0) -> 10.748084 | Q10: =IFERROR(I10/L10,0) -> 71.390687 | R10: =IFERROR(E10/N10,0) -> 112.10527
B11: Siemens Ener.Ind | D11: 35.61 | E11: 3459.6 | F11: =IFERROR(D11*E11,0) -> 123196.36 | G11: 215.7 | H11: 3462 | I11: =IFERROR(F11+G11-H11,0) -> 119950.06 | K11: 8735.3 | L11: 1637.2 | M11: 1309.8 | N11: =IFERROR(M11/D11,0) -> 36.781803 | P11: =IFERROR(I11/K11,0) -> 13.731647 | Q11: =IFERROR(I11/L11,0) -> 73.265365 | R11: =IFERROR(E11/N11,0) -> 94.05738
B12: GE Vernova T&D | D12: 25.6 | E12: 4679.4 | F12: =IFERROR(D12*E12,0) -> 119792.64 | G12: 24 | H12: 1527.72 | I12: =IFERROR(F12+G12-H12,0) -> 118288.92 | K12: 6206.31 | L12: 1774.47 | M12: 1233.25 | N12: =IFERROR(M12/D12,0) -> 48.173828 | P12: =IFERROR(I12/K12,0) -> 19.05946 | Q12: =IFERROR(I12/L12,0) -> 66.66155 | R12: =IFERROR(E12/N12,0) -> 97.135731
B13: Suzlon Energy | D13: 1360.53 | E13: 52.57 | F13: =IFERROR(D13*E13,0) -> 71523.062 | G13: 397 | H13: 1112.83 | I13: =IFERROR(F13+G13-H13,0) -> 70807.232 | K13: 15028.53 | L13: 1966.42 | M13: 3230.02 | N13: =IFERROR(M13/D13,0) -> 2.3740895 | P13: =IFERROR(I13/K13,0) -> 4.7115208 | Q13: =IFERROR(I13/L13,0) -> 36.008194 | R13: =IFERROR(E13/N13,0) -> 22.143226
B15: Max | P15: =IFERROR(MAX(P9:P13),0) -> 19.05946 | Q15: =IFERROR(MAX(Q9:Q13),0) -> 73.265365 | R15: =IFERROR(MAX(R9:R13),0) -> 112.10527
B16: 75th Percentile | P16: =IFERROR(QUARTILE(P9:P13,3),0) -> 13.731647 | Q16: =IFERROR(QUARTILE(Q9:Q13,3),0) -> 71.390687 | R16: =IFERROR(QUARTILE(R9:R13,3),0) -> 97.135731
B17: Average | P17: =IFERROR(AVERAGE(P9:P13),0) -> 11.700185 | Q17: =IFERROR(AVERAGE(Q9:Q13),0) -> 60.662101 | R17: =IFERROR(AVERAGE(R9:R13),0) -> 74.490188
B18: median | P18: =IFERROR(MEDIAN(P9:P13),0) -> 10.748084 | Q18: =IFERROR(MEDIAN(Q9:Q13),0) -> 66.66155 | R18: =IFERROR(MEDIAN(R9:R13),0) -> 94.05738
B19: 25th Percentile | P19: =IFERROR(QUARTILE(P9:P13,1),0) -> 10.25021 | Q19: =IFERROR(QUARTILE(Q9:Q13,1),0) -> 55.984708 | R19: =IFERROR(QUARTILE(R9:R13,1),0) -> 47.009334
B20: Min. | P20: =IFERROR(MIN(P9:P13),0) -> 4.7115208 | Q20: =IFERROR(MIN(Q9:Q13),0) -> 36.008194 | R20: =IFERROR(MIN(R9:R13),0) -> 22.143226
B22: M&M Industry Comparable comps | P22: EV/Revenue | Q22: EV/EBITDA | R22: P/E Ratio
P23: Overvalued | Q23: Overvalued | R23: Overvalued
B24: Implied Enterprise Value | P24: =P18*K12 -> 66705.943 | Q24: =Q18*L12 -> 118288.92 | R24: =SUM(R26+R25) -> 114492.54
B25: Net Debt | P25: =G12-H12 -> -1503.72 | Q25: =P25 -> -1503.72 | R25: =Q25 -> -1503.72
