Workbook

Sheet About
K3: ABOUT
K4: Varun Beverages Limited (VBL) is one of the largest franchise bottlers of PepsiCo beverages globally outside the United States. The company manufactures, bottles, distributes, and sells a wide range of carbonated soft drinks, fruit-based beverages, packaged drinking water, sports drinks, and juice products under well-known PepsiCo brands such as Pepsi, Mountain Dew, Mirinda, 7UP, Sting, Slice, Tropicana, and Aquafina. Headquartered in Gurugram, Haryana, Varun Beverages operates an extensive manufacturing and distribution network across India and several international markets in Asia and Africa. The company benefits from strong brand partnerships, a wide retail reach, and increasing beverage consumption trends, making it a key player in the fast-growing beverage industry.
F26: Subsidiary Name
F27: Varun Beverages (Nepal) Pvt. Ltd.,Kathmandu Nepal
F28: Varun Beverages Morocco SA,Casablanca Morocco
F29: Varun Beverages Zambia Ltd.,Lusaka Zambia
F30: Varun Beverages Zimbabwe (Pvt.) Ltd.,Harare Zimbabwe
F31: Varun Beverages Mozambique SA,Maputo Mozambique
F32: Lunarmech Technologies Pvt. Ltd.,India

Sheet Promoter 
B2: Varun Beverages | Promoter Shareholding Pattern
B3: Category of shareholder | C3: Entity Type | D3: Nos. of shareholders | E3: Total nos. shares held | F3: Shareholding as a %
B6: A3) Indian | D6: - | E6: - | F6: 0
B7: Individuals/Hindu undivided Family | D7: 10 | E7: 1,15,51,35,704 | F7: 34.15
B8: Ravi Kant Jaipuria | C8: Promoter | D8: 1 | E8: 56,50,86,222 | F8: 16.71
B9: Varun Jaipuria | C9: Promoter | D9: 1 | E9: 52,18,59,870 | F9: 15.43
B10: Devyani Jaipuria | C10: Promoter Group | D10: 1 | E10: 6,57,79,775 | F10: 1.94
B11: Vivek Gupta | C11: Promoter Group | D11: 1 | E11: 23,26,500 | F11: 0.07
B12: Dhara Jaipuria | C12: Promoter Group | D12: 1 | E12: 33995 | F12: 0
B13: Vivek Gupta (HUF) | C13: Promoter Group | D13: 1 | E13: 33750 | F13: 0
B14: Madhav Hansraj Mariwala (HUF) | C14: Promoter Group | D14: - | E14: - | F14: 0
B15: Madhav H Mariwala | C15: Promoter Group | D15: 1 | E15: 11710 | F15: 0
B16: Nandini Madhav Mariwala | C16: Promoter Group | D16: 1 | E16: 1250 | F16: 0
B17: Bela Jyotikumar Saha | C17: Promoter Group | D17: 1 | E17: 2500 | F17: 0
B18: Madhu Rajendra Jindal | C18: Promoter Group | D18: 1 | E18: 132 | F18: 0
B19: Aishwarya M Mariwala | C19: Promoter Group | D19: - | E19: - | F19: 0
B20: Kimaya Jaipuria | C20: Promoter Group | D20: - | E20: - | F20: 0
B21: Any Other (specify) | D21: 4 | E21: 85,50,82,025 | F21: 25.28
B22: RJ Corp Limited | C22: Promoter | D22: 1 | E22: 85,50,41,916 | F22: 25.28
B23: SFT Technologies Private Limited | C23: Promoter Group | D23: 1 | E23: 19074 | F23: 0
B24: Lotus Holdings | C24: Promoter Group | D24: 1 | E24: 18850 | F24: 0
B25: Marison Finvest Private Limited | C25: Promoter Group | D25: 1 | E25: 2185 | F25: 0
B26: Devyani Jaipuria Sports Academy Private Limited | C26: Promoter Group | D26: - | E26: - | F26: Subsidiary Name
B27: Cryoviva Life Sciences Private Limited | C27: Promoter Group | D27: - | E27: - | F27: Varun Beverages (Nepal) Pvt. Ltd.,Kathmandu Nepal
B28: SFT Syscon Private Limited | C28: Promoter Group | D28: - | E28: - | F28: Varun Beverages Morocco SA,Casablanca Morocco
B29: Sara Ferrous Private Limited | C29: Promoter Group | D29: - | E29: - | F29: Varun Beverages Zambia Ltd.,Lusaka Zambia
B30: Gee Kay Builder And Development Services Private Limited | C30: Promoter Group | D30: - | E30: - | F30: Varun Beverages Zimbabwe (Pvt.) Ltd.,Harare Zimbabwe
B31: Chanda Exports Private Limited | C31: Promoter Group | D31: - | E31: - | F31: Varun Beverages Mozambique SA,Maputo Mozambique
B32: Manog Securities Private Limited | C32: Promoter Group | D32: - | E32: - | F32: Lunarmech Technologies Pvt. Ltd.,India
B33: Lineage Healthcare Limited | C33: Promoter Group | D33: - | E33: - | F33: 0
B34: Jacore Energy Private Limited | C34: Promoter Group | D34: - | E34: - | F34: 0
B35: KV Retail Private Limited | C35: Promoter Group | D35: - | E35: - | F35: 0
B36: Empire Stocks Private Limited | C36: Promoter Group | D36: - | E36: - | F36: 0
B37: Capital Infracon Private Limited | C37: Promoter Group | D37: - | E37: - | F37: 0
B38: CV Biotech Private Limited | C38: Promoter Group | D38: - | E38: - | F38: 0
B39: S V S India Private Limited | C39: Promoter Group | D39: - | E39: - | F39: 0
B40: Modern Montessori International (India) Private Limited | C40: Promoter Group | D40: - | E40: - | F40: 0
B41: Cryoviva Biotech Private Limited | C41: Promoter Group | D41: - | E41: - | F41: 0
B42: Accor Realcon Private Limited | C42: Promoter Group | D42: - | E42: - | F42: 0
B43: Devyani International Limited | C43: Promoter Group | D43: - | E43: - | F43: 0
...

Sheet Public 
B2: Varun Beverages | Public Shareholding Pattern
C3: Category & Name of the Shareholders | D3: No. of shareholder | E3: Total no. shares held | F3: Shareholding %
C6: Institutions | D6: - | E6: - | F6: 0
C7: B1) Institutions (Domestic) | D7: - | E7: - | F7: 0
C8: Mutual Funds/ | D8: 40 | E8: 28,08,38,227 | F8: 8.3
C9: NIPPON LIFE INDIA TRUSTEE LTD-A/C NIPPON INDIA ARB | D9: 1 | E9: 5,91,57,638 | F9: 1.75
C10: SBI ARBITRAGE OPPORTUNITIES FUND | D10: 1 | E10: 3,78,64,460 | F10: 1.12
C11: Alternate Investment Funds | D11: 37 | E11: 81,35,193 | F11: 0.24
C12: Banks | D12: 1 | E12: 645 | F12: 0
C13: Insurance Companies | D13: 26 | E13: 15,83,46,326 | F13: 4.68
C14: LICI INDEX PLUS FLEXI GROWTH FUND | D14: 1 | E14: 7,31,23,131 | F14: 2.16
C15: Provident Funds/ Pension Funds | D15: 1 | E15: 3,82,46,040 | F15: 1.13
C16: NPS TRUST A/C - SBI PENSION FUND - UPS - CG SCHEM | D16: 1 | E16: 3,82,46,040 | F16: 1.13
C17: Sovereign Wealth Funds | D17: 2 | E17: 14,32,645 | F17: 0.04
C18: NBFCs registered with RBI | D18: 14 | E18: 1,42,547 | F18: 0
C19: Sub Total B1 | D19: 121 | E19: 48,71,41,623 | F19: 14.4
C20: B14) Institutions (Foreign) | D20: - | E20: - | F20: 0
C21: Foreign Portfolio Investors Category I | D21: 778 | E21: 63,87,80,636 | F21: 18.89
C22: GOVERNMENT OF SINGAPORE | D22: 1 | E22: 4,63,03,882 | F22: 1.37
C23: GOVERNMENT PENSION FUND GLOBAL | D23: 1 | E23: 6,23,23,233 | F23: 1.84
C24: Foreign Portfolio Investors Category II | D24: 53 | E24: 2,09,19,503 | F24: 0.62
C25: Sub Total B2 | D25: 831 | E25: 65,97,00,139 | F25: 19.51
C26: B20) Central Government/ State Government(s)/ President of India | D26: - | E26: - | F26: Subsidiary Name
C27: Central Government / President of India | D27: 1 | E27: 87 | F27: Varun Beverages (Nepal) Pvt. Ltd.,Kathmandu Nepal
C28: Sub Total B3 | D28: 1 | E28: 87 | F28: Varun Beverages Morocco SA,Casablanca Morocco
C29: B23) Non-Institutions | D29: - | E29: - | F29: Varun Beverages Zambia Ltd.,Lusaka Zambia
C30: Directors and their relatives (excluding independent directors and nominee directors) | D30: 3 | E30: 70,48,037 | F30: Varun Beverages Zimbabwe (Pvt.) Ltd.,Harare Zimbabwe
C31: Key Managerial Personnel | D31: 1 | E31: 11250 | F31: Varun Beverages Mozambique SA,Maputo Mozambique
C32: Investor Education and Protection Fund (IEPF) | D32: 1 | E32: 4374 | F32: Lunarmech Technologies Pvt. Ltd.,India
C33: Resident Individuals holding nominal share capital up to Rs. 2 lakhs | D33: 8,51,098 | E33: 14,80,32,380 | F33: 4.38
C34: Resident Individuals holding nominal share capital in excess of Rs. 2 lakhs | D34: 51 | E34: 2,83,63,193 | F34: 0.84
C35: Non Resident Indians (NRIs) | D35: 15755 | E35: 1,13,63,493 | F35: 0.34
C36: Bodies Corporate | D36: 2110 | E36: 2,66,99,216 | F36: 0.79
C37: Any Other (specify) | D37: 7618 | E37: 35,12,873 | F37: 0.1
C38: Clearing Members | D38: 4 | E38: 261 | F38: 0
C39: HUF | D39: 7595 | E39: 34,96,442 | F39: 0.1
C40: Trusts | D40: 19 | E40: 16170 | F40: 0
C41: ESOP or ESOS or ESPS | D41: - | E41: - | F41: 0
C42: Sub Total B4 | D42: 8,76,637 | E42: 22,50,34,816 | F42: 6.65
C43: B=B1+B2+B3+B4 | D43: 8,77,590 | E43: 1,37,18,76,665 | F43: 40.56

Sheet Consolidated QTR
B2: Varun Beverages | Consolidated Quarterly P&L | (₹ Crores)
D3: 45657 | E3: 45747 | F3: 45838 | G3: 45930 | H3: 46022
C4: Net Sales/Income from operations | D4: 3688 | E4: 5566 | F4: 7017 | G4: 4896 | H4: 4204
C5: Other Operating Income | D5: -- | E5: -- | F5: -- | G5: -- | H5: --
C6: Total Income From Operations | D6: 3688 | E6: 5566 | F6: 7017 | G6: 4896 | H6: 4204
C7: EXPENDITURE
C8: Consumption of Raw Materials | D8: 1705 | E8: 2671 | F8: 2845 | G8: 1898 | H8: 1922
C9: Purchase of Traded Goods | D9: 144 | E9: 71 | F9: 99 | G9: 88 | H9: 110
C10: Increase/Decrease in Stocks | D10: -229 | E10: -213 | F10: 246 | G10: 131 | H10: -156
C11: Power & Fuel | D11: -- | E11: -- | F11: -- | G11: -- | H11: --
C12: Employees Cost | D12: 479 | E12: 511 | F12: 549 | G12: 553 | H12: 586
C13: Depreciation | D13: 260 | E13: 272 | F13: 306 | G13: 307 | H13: 330
C14: Excise Duty | D14: -- | E14: -- | F14: -- | G14: -- | H14: --
C15: Admin. And Selling Expenses | D15: -- | E15: -- | F15: -- | G15: -- | H15: --
C16: R & D Expenses | D16: -- | E16: -- | F16: -- | G16: -- | H16: --
C17: Provisions And Contingencies | D17: -- | E17: -- | F17: -- | G17: -- | H17: --
C18: Exp. Capitalised | D18: -- | E18: -- | F18: -- | G18: -- | H18: --
C19: Other Expenses | D19: 1009 | E19: 1262 | F19: 1277 | G19: 1076 | H19: 1102
C20: P/L Before Other Inc., Int., Excpt. Items & Tax | D20: 319 | E20: 991 | F20: 1692 | G20: 839 | H20: 309
C21: Other Income | D21: 44 | E21: 28 | F21: 77 | G21: 148 | H21: 99
C22: P/L Before Int., Excpt. Items & Tax | D22: 363 | E22: 1019 | F22: 1769 | G22: 987 | H22: 408
C23: Interest | D23: 109 | E23: 41 | F23: 36 | G23: 45 | H23: 46
C24: P/L Before Exceptional Items & Tax | D24: 254 | E24: 978 | F24: 1733 | G24: 942 | H24: 361
C25: Exceptional Items | D25: -- | E25: -- | F25: -- | G25: -- | H25: --
C26: P/L Before Tax | D26: 254 | E26: 978 | F26: 1732 | G26: 942 | H26: 361
C27: Tax | D27: 58 | E27: 246 | F27: 1325 | G27: 195 | H27: 98
C28: P/L After Tax from Ordinary Activities | D28: 196 | E28: 731 | G28: 746 | H28: 262
C29: Prior Year Adjustments | D29: -- | E29: -- | G29: -- | H29: --
C30: Extra Ordinary Items | D30: -- | E30: -- | G30: -- | H30: --
C31: Net Profit/(Loss) For the Period | D31: 196 | E31: 731 | G31: 746 | H31: 262

Sheet Consolidated BS
B4: Varun Beverages | C4: Previous Years �
B5: Consolidated Balance Sheet | C5: ------------------- in Rs. Cr. -------------------
C6: Dec '22 | D6: Dec '23 | E6: Dec '24 | F6: Dec '25 | G6: Mar '25
B7: #VALUE!
B8: #VALUE!
B9: Sources Of Funds
B10: Total Share Capital | C10: 649.55 | D10: 649.61 | E10: 676.3 | F10: 676.4 | G10: 676.4
B11: Equity Share Capital | C11: 649.55 | D11: 649.61 | E11: 676.3 | F11: 676.4 | G11: 676.4
B12: Share Application Money | C12: 0 | D12: 0.35 | E12: 0 | F12: 0.27 | G12: 0.27
B13: Reserves | C13: 4452.83 | D13: 6286.54 | E13: 15933.53 | F13: 18902.03 | G13: 18902.03
B14: Networth | C14: 5102.38 | D14: 6936.5 | E14: 16609.83 | F14: 19578.7 | G14: 19578.7
B15: Secured Loans | C15: 3694.81 | D15: 5194.39 | E15: 2364.27 | F15: 2024.12 | G15: 2024.12
B16: Total Debt | C16: 3694.81 | D16: 5194.39 | E16: 2364.27 | F16: 2024.12 | G16: 2024.12
B17: Minority Interest | C17: 113.11 | D17: 148.16 | E17: 129.81 | F17: 162.25 | G17: 162.25
B18: Total Liabilities | C18: 8910.3 | D18: 12279.05 | E18: 19103.91 | F18: 21765.07 | G18: 21765.07
C19: Dec '22 | D19: Dec '23 | E19: Dec '24 | F19: Dec '25 | G19: Mar '25
B20: #VALUE!
B21: #VALUE!
B22: Application Of Funds
B23: Gross Block | C23: 10243.19 | D23: 12208.09 | E23: 18526.73 | F23: 23253.35 | G23: 23253.35
B24: Less: Accum. Depreciation | C24: 3310.97 | D24: 3798.92 | E24: 5124.99 | F24: 6494.42 | G24: 6494.42
B25: Net Block | C25: 6932.22 | D25: 8409.17 | E25: 13401.74 | F25: 16758.93 | G25: 16758.93
B26: Capital Work in Progress | C26: 606.63 | D26: 1922.22 | E26: 1166.71 | F26: Subsidiary Name | G26: 270.79
B27: Investments | C27: 0.01 | D27: 21.08 | E27: 59.5 | F27: Varun Beverages (Nepal) Pvt. Ltd.,Kathmandu Nepal | G27: 174.28
B28: Inventories | C28: 1993.89 | D28: 2150.53 | E28: 2791.23 | F28: Varun Beverages Morocco SA,Casablanca Morocco | G28: 2951.79
B29: Sundry Debtors | C29: 299.34 | D29: 359.39 | E29: 845.84 | F29: Varun Beverages Zambia Ltd.,Lusaka Zambia | G29: 1249.03
B30: Cash and Bank Balance | C30: 285.27 | D30: 459.86 | E30: 2450.05 | F30: Varun Beverages Zimbabwe (Pvt.) Ltd.,Harare Zimbabwe | G30: 1998.49
B31: Total Current Assets | C31: 2578.5 | D31: 2969.78 | E31: 6087.12 | F31: Varun Beverages Mozambique SA,Maputo Mozambique | G31: 6199.31
B32: Loans and Advances | C32: 1500.9 | D32: 1864.93 | E32: 2428.83 | F32: Lunarmech Technologies Pvt. Ltd.,India | G32: 2161.85
B33: Total CA, Loans & Advances | C33: 4079.4 | D33: 4834.71 | E33: 8515.95 | F33: 8361.16 | G33: 8361.16
B34: Current Liabilities | C34: 2474.64 | D34: 2612.96 | E34: 3776.68 | F34: 3559.1 | G34: 3559.1
B35: Provisions | C35: 233.3 | D35: 295.19 | E35: 263.33 | F35: 240.99 | G35: 240.99
B36: Total CL & Provisions | C36: 2707.94 | D36: 2908.15 | E36: 4040.01 | F36: 3800.09 | G36: 3800.09
B37: Net Current Assets | C37: 1371.46 | D37: 1926.56 | E37: 4475.94 | F37: 4561.07 | G37: 4561.07
B38: Total Assets | C38: 8910.32 | D38: 12279.03 | E38: 19103.89 | F38: 21765.07 | G38: 21765.07
B39: #VALUE!
B40: Contingent Liabilities | C40: 1910.47 | D40: 3298.1 | E40: 2993.26 | F40: 3489.54 | G40: 3489.54
B41: Book Value (Rs) | C41: 78.55 | D41: 53.39 | E41: 49.12 | F41: 57.89 | G41: 57.89

Sheet Standalone BS
B2: Varun Beverages | Standalone Balance Sheet | (₹ Crores)
B3: Standalone Balance Sheet | C3: ------------------- in Rs. Cr. -------------------
C4: Dec '21 | D4: Dec '22 | E4: Dec '23 | F4: Dec '24 | G4: Dec '25
B5: #VALUE!
C6: 12 mths | D6: 12 mths | E6: 12 mths | F6: 12 mths | G6: 12 mths
B7: #VALUE!
B8: Sources Of Funds
B9: Total Share Capital | C9: 433.03 | D9: 649.55 | E9: 649.61 | F9: 676.3 | G9: 676.4
B10: Equity Share Capital | C10: 433.03 | D10: 649.55 | E10: 649.61 | F10: 676.3 | G10: 676.4
B11: Share Application Money | C11: 0 | D11: 0 | E11: 0.35 | F11: 0 | G11: 0.27
B12: Reserves | C12: 3965.59 | D12: 4867.85 | E12: 6425.85 | F12: 15882.4 | G12: 18088.13
B13: Networth | C13: 4398.62 | D13: 5517.4 | E13: 7075.81 | F13: 16558.7 | G13: 18764.8
B14: Secured Loans | C14: 2272.97 | D14: 3471.85 | E14: 4760.11 | F14: 831.54 | G14: 376.07
B15: Total Debt | C15: 2272.97 | D15: 3471.85 | E15: 4760.11 | F15: 831.54 | G15: 376.07
B16: Total Liabilities | C16: 6671.59 | D16: 8989.25 | E16: 11835.92 | F16: 17390.24 | G16: 19140.87
C17: Dec '21 | D17: Dec '22 | E17: Dec '23 | F17: Dec '24 | G17: Dec '25
B18: #VALUE!
C19: 12 mths | D19: 12 mths | E19: 12 mths | F19: 12 mths | G19: 12 mths
B20: #VALUE!
B21: Application Of Funds
B22: Gross Block | C22: 7259.91 | D22: 8390.14 | E22: 9951.46 | F22: 12804.1 | G22: 15130.38
B23: Less: Accum. Depreciation | C23: 2248.3 | D23: 2638.27 | E23: 3013.25 | F23: 3623 | G23: 4293.44
B24: Net Block | C24: 5011.61 | D24: 5751.87 | E24: 6938.21 | F24: 9181.1 | G24: 10836.94
B25: Capital Work in Progress | C25: 477.95 | D25: 539.95 | E25: 1576 | F25: 960.03 | G25: 140.73
B26: Investments | C26: 1352.24 | D26: 1354.32 | E26: 1449.95 | F26: Subsidiary Name | G26: 3770.46
B27: Inventories | C27: 1066.27 | D27: 1426.15 | E27: 1535.87 | F27: Varun Beverages (Nepal) Pvt. Ltd.,Kathmandu Nepal | G27: 1659.03
B28: Sundry Debtors | C28: 132.07 | D28: 150.24 | E28: 212.94 | F28: Varun Beverages Morocco SA,Casablanca Morocco | G28: 266.21
B29: Cash and Bank Balance | C29: 24.24 | D29: 47.49 | E29: 52.31 | F29: Varun Beverages Zambia Ltd.,Lusaka Zambia | G29: 1599.94
B30: Total Current Assets | C30: 1222.58 | D30: 1623.88 | E30: 1801.12 | F30: Varun Beverages Zimbabwe (Pvt.) Ltd.,Harare Zimbabwe | G30: 3525.18
B31: Loans and Advances | C31: 1001.24 | D31: 1798.93 | E31: 2244.17 | F31: Varun Beverages Mozambique SA,Maputo Mozambique | G31: 2726.97
B32: Total CA, Loans & Advances | C32: 2223.82 | D32: 3422.81 | E32: 4045.29 | F32: Lunarmech Technologies Pvt. Ltd.,India | G32: 6252.15
B33: Current Liabilities | C33: 2145.64 | D33: 1853.72 | E33: 1886.35 | F33: 1851.23 | G33: 1648.92
B34: Provisions | C34: 248.4 | D34: 225.97 | E34: 287.2 | F34: 242.49 | G34: 210.48
B35: Total CL & Provisions | C35: 2394.04 | D35: 2079.69 | E35: 2173.55 | F35: 2093.72 | G35: 1859.4
B36: Net Current Assets | C36: -170.22 | D36: 1343.12 | E36: 1871.74 | F36: 5153.12 | G36: 4392.75
B37: Total Assets | C37: 6671.58 | D37: 8989.26 | E37: 11835.9 | F37: 17390.26 | G37: 19140.88
B38: #VALUE!
B39: Contingent Liabilities | C39: 700.47 | D39: 2051.21 | E39: 3262.02 | F39: 4257.8 | G39: 4277.24
B40: Book Value (Rs) | C40: 101.58 | D40: 84.94 | E40: 54.46 | F40: 48.97 | G40: 55.48

Sheet Consolidated PL
B2: Varun Beverages | Consolidated Profit & Loss | (₹ Crores)
C3: Consolidated Profit & Loss account | D3: ------------------- in Rs. Cr. -------------------
D4: 44286 | E4: 44651 | F4: 45016 | G4: 45382 | H4: 45747
C5: #VALUE!
D6: 12 mths | E6: 12 mths | F6: 12 mths | G6: 12 mths | H6: 12 mths
C7: #VALUE!
C8: INCOME
C9: Revenue From Operations [Gross] | D9: 8777.41 | E9: 13138.47 | F9: 15900.22 | G9: 19918.72 | H9: 21374.81
C10: Less: Excise/Sevice Tax/Other Levies | D10: 135.06 | E10: 217.42 | F10: 278.48 | G10: 473.68 | H10: 540.21
C11: Revenue From Operations [Net] | D11: 8642.35 | E11: 12921.05 | F11: 15621.74 | G11: 19445.05 | H11: 20834.6
C12: Other Operating Revenues | D12: 180.88 | E12: 252.09 | F12: 420.84 | G12: 562.6 | H12: 850.78
C13: Total Operating Revenues | D13: 8823.23 | E13: 13173.14 | F13: 16042.58 | G13: 20007.65 | H13: 21685.38
C14: Other Income | D14: 67.93 | E14: 38.85 | F14: 79.36 | G14: 121.27 | H14: 352.35
C15: Total Revenue | D15: 8891.16 | E15: 13211.99 | F15: 16121.94 | G15: 20128.92 | H15: 22037.73
C16: EXPENSES
C17: Cost Of Materials Consumed | D17: 3968.91 | E17: 6417.09 | F17: 7026.46 | G17: 8293.74 | H17: 9337.06
C18: Purchase Of Stock-In Trade | D18: 165.47 | E18: 188.57 | F18: 462.7 | G18: 685.92 | H18: 369.45
C19: Changes In Inventories Of FG,WIP And Stock-In Trade | D19: -99.72 | E19: -344.51 | F19: -84.27 | G19: -74.94 | H19: 8.91
C20: Employee Benefit Expenses | D20: 1007.7 | E20: 1216.64 | F20: 1446.59 | G20: 1885.03 | H20: 2200.74
C21: Finance Costs | D21: 184.7 | E21: 186.12 | F21: 268.1 | G21: 450.39 | H21: 169.58
C22: Depreciation And Amortisation Expenses | D22: 531.26 | E22: 617.19 | F22: 680.91 | G22: 947.39 | H22: 1216.46
C23: Other Expenses | D23: 2126.23 | E23: 2907.24 | F23: 3581.62 | G23: 4506.83 | H23: 4719.84
C24: Total Expenses | D24: 7884.55 | E24: 11188.35 | F24: 13382.1 | G24: 16694.35 | H24: 18022.05
C25: Profit/Loss Before Exceptional, ExtraOrdinary Items And Tax | D25: 1006.61 | E25: 2023.64 | F25: 2739.84 | G25: 3434.57 | H25: 4015.68
C26: Profit/Loss Before Tax | D26: 1006.61 | E26: 2023.64 | F26: Subsidiary Name | G26: 3434.57 | H26: 4015.68
C27: Tax Expenses-Continued Operations | F27: Varun Beverages (Nepal) Pvt. Ltd.,Kathmandu Nepal
C28: Current Tax | D28: 134.2 | E28: 425.87 | F28: Varun Beverages Morocco SA,Casablanca Morocco | G28: 750.21 | H28: 838.91
C29: Deferred Tax | D29: 91.35 | E29: 24.97 | F29: Varun Beverages Zambia Ltd.,Lusaka Zambia | G29: 48.07 | H29: 107.01
C30: Tax For Earlier Years | D30: 35.01 | E30: 22.69 | F30: Varun Beverages Zimbabwe (Pvt.) Ltd.,Harare Zimbabwe | G30: 0.53 | H30: 1.69
C31: Total Tax Expenses | D31: 260.56 | E31: 473.52 | F31: Varun Beverages Mozambique SA,Maputo Mozambique | G31: 798.8 | H31: 947.61
C32: Profit/Loss After Tax And Before ExtraOrdinary Items | D32: 746.05 | E32: 1550.12 | F32: Lunarmech Technologies Pvt. Ltd.,India | G32: 2635.76 | H32: 3068.07
C33: Profit/Loss From Continuing Operations | D33: 746.05 | E33: 1550.12 | F33: 2102.29 | G33: 2635.76 | H33: 3068.07
C34: Profit/Loss For The Period | D34: 746.05 | E34: 1550.12 | F34: 2102.29 | G34: 2635.76 | H34: 3068.07
C35: Minority Interest | D35: -52 | E35: -52.68 | F35: -45.89 | G35: -39.65 | H35: -25.55
C36: Share Of Profit/Loss Of Associates | D36: 0 | E36: -0.01 | F36: -0.48 | G36: -1.48 | H36: -6.03
C37: Consolidated Profit/Loss After MI And Associates | D37: 694.05 | E37: 1497.43 | F37: 2055.92 | G37: 2594.63 | H37: 3036.49
C38: OTHER ADDITIONAL INFORMATION
C39: EARNINGS PER SHARE
C40: Basic EPS (Rs.) | D40: 16 | E40: 23 | F40: 16 | G40: 8 | H40: 9
C41: Diluted EPS (Rs.) | D41: 16 | E41: 23 | F41: 16 | G41: 8 | H41: 9
...

Sheet Ratios
B2: Ratio Analysis
B3: Years | C3: 46102 | D3: 46103 | E3: 46104 | F3: 46105 | G3: 46106 | H3: Trend | I3: Mean | J3: Median
B5: SalesGrowth | D5: =('Consolidated PL'!E9-'Consolidated PL'!D9)/'Consolidated PL'!D9 -> 0.49685044 | E5: =('Consolidated PL'!F9-'Consolidated PL'!E9)/'Consolidated PL'!E9 -> 0.21020332 | F5: =('Consolidated PL'!G9-'Consolidated PL'!F9)/'Consolidated PL'!F9 -> 0.25273235 | G5: =('Consolidated PL'!H9-'Consolidated PL'!G9)/'Consolidated PL'!G9 -> 0.073101585
B6: EBITDA Growth | D6: =('Assumptions '!F14-'Assumptions '!E14)/'Assumptions '!E14 -> 0.72078222 | E6: =('Assumptions '!G14-'Assumptions '!F14)/'Assumptions '!F14 -> 0.25734024 | F6: =('Assumptions '!H14-'Assumptions '!G14)/'Assumptions '!G14 -> 0.30101548 | G6: =('Assumptions '!I14-'Assumptions '!H14)/'Assumptions '!H14 -> 0.012083973
B7: EBIT Growth | D7: =('Assumptions '!F18-'Assumptions '!E18)/'Assumptions '!E18 -> 1.0358939 | E7: =('Assumptions '!G18-'Assumptions '!F18)/'Assumptions '!F18 -> 0.30690577 | F7: =('Assumptions '!H18-'Assumptions '!G18)/'Assumptions '!G18 -> 0.27648511 | G7: =('Assumptions '!I18-'Assumptions '!H18)/'Assumptions '!H18 -> -0.068395666
B8: Net Profit Growth | D8: =('Assumptions '!F28-'Assumptions '!E28)/'Assumptions '!E28 -> #VALUE! | E8: =('Assumptions '!G28-'Assumptions '!F28)/'Assumptions '!F28 -> #VALUE! | F8: =('Assumptions '!H28-'Assumptions '!G28)/'Assumptions '!G28 -> #VALUE! | G8: =('Assumptions '!I28-'Assumptions '!H28)/'Assumptions '!H28 -> 0.017230475
B9: Dividend Growth
B11: Gross Margin | C11: =('Assumptions '!E6-'Assumptions '!E9)/'Assumptions '!E6 -> 0.53315244 | D11: =('Assumptions '!F6-'Assumptions '!F9)/'Assumptions '!F6 -> 0.51543025 | E11: =('Assumptions '!G6-'Assumptions '!G9)/'Assumptions '!G6 -> 0.52598814 | F11: =('Assumptions '!H6-'Assumptions '!H9)/'Assumptions '!H6 -> 0.54205723 | G11: =('Assumptions '!I6-'Assumptions '!I9)/'Assumptions '!I6 -> 0.53368819
B12: EBITDA Margin | C12: ='Assumptions '!E14/'Assumptions '!E6 -> 0.17052769 | D12: ='Assumptions '!F14/'Assumptions '!F6 -> 0.19627043 | E12: ='Assumptions '!G14/'Assumptions '!G6 -> 0.20411555 | F12: ='Assumptions '!H14/'Assumptions '!H6 -> 0.21334324 | G12: ='Assumptions '!I14/'Assumptions '!I6 -> 0.20152055
B13: EBIT Margin | C13: ='Assumptions '!E18/'Assumptions '!E6 -> 0.10905599 | D13: ='Assumptions '!F18/'Assumptions '!F6 -> 0.14850419 | E13: ='Assumptions '!G18/'Assumptions '!G6 -> 0.16052821 | F13: ='Assumptions '!H18/'Assumptions '!H6 -> 0.16462184 | G13: ='Assumptions '!I18/'Assumptions '!I6 -> 0.14313402
B14: EBT Margin | C14: ='Assumptions '!E23/'Assumptions '!E6 -> 0.333709 | D14: ='Assumptions '!F23/'Assumptions '!F6 -> 0.35910007 | E14: ='Assumptions '!G23/'Assumptions '!G6 -> 0.37263775 | F14: ='Assumptions '!H23/'Assumptions '!H6 -> 0.37323226 | G14: ='Assumptions '!I23/'Assumptions '!I6 -> 0.36153322
B15: Net Profit Margin | C15: ='Assumptions '!E28/'Assumptions '!E6 -> 0.30957668 | D15: ='Assumptions '!F28/'Assumptions '!F6 -> #VALUE! | E15: ='Assumptions '!G28/'Assumptions '!G6 -> #VALUE! | F15: ='Assumptions '!H28/'Assumptions '!H6 -> 0.33419148 | G15: ='Assumptions '!I28/'Assumptions '!I6 -> 0.31727703
B17: Return on Capital Employed | C17: ='Assumptions '!E18/('Consolidated BS'!C10+'Consolidated BS'!C15) -> 0.21694795 | D17: ='Assumptions '!F18/('Consolidated BS'!D10+'Consolidated BS'!D15) -> 0.32834189 | E17: ='Assumptions '!G18/('Consolidated BS'!E10+'Consolidated BS'!E15) -> 0.82475654 | F17: ='Assumptions '!H18/('Consolidated BS'!F10+'Consolidated BS'!F15) -> 1.1853569 | G17: ='Assumptions '!I18/('Consolidated BS'!G10+'Consolidated BS'!G15) -> 1.1042836
B18: Retained Earnings% | C18: =('Consolidated PL'!D37-'Consolidated PL'!D43)/'Consolidated PL'!D37 -> 0.844017 | D18: =('Consolidated PL'!E37-'Consolidated PL'!E43)/'Consolidated PL'!E37 -> 0.8915542 | E18: =('Consolidated PL'!F37-'Consolidated PL'!F43)/'Consolidated PL'!F37 -> 0.8894169 | F18: =('Consolidated PL'!G37-'Consolidated PL'!G43)/'Consolidated PL'!G37 -> 0.87479525 | G18: =('Consolidated PL'!H37-'Consolidated PL'!H43)/'Consolidated PL'!H37 -> 0.83293869
B19: Return on Equity% | C19: ='Assumptions '!E28/('Consolidated BS'!C10+'Consolidated BS'!C13) -> 0.52435726 | D19: ='Assumptions '!F28/('Consolidated BS'!D10+'Consolidated BS'!D13) -> #VALUE! | E19: ='Assumptions '!G28/('Consolidated BS'!E10+'Consolidated BS'!E13) -> #VALUE! | F19: ='Assumptions '!H28/('Consolidated BS'!F10+'Consolidated BS'!F13) -> 0.33191477 | G19: ='Assumptions '!I28/('Consolidated BS'!G10+'Consolidated BS'!G13) -> 0.33763381
B20: Self Sustained Growth Rate | C20: =C19*C18 -> 0.44256644 | D20: =D19*D18 -> #VALUE! | E20: =E19*E18 -> #VALUE! | F20: =F19*F18 -> 0.29035746 | G20: =G19*G18 -> 0.28122827
B21: Interest Coverage Ratio | C21: ='Consolidated PL'!D21/'Assumptions '!E18 -> 0.19596817 | D21: ='Consolidated PL'!E21/'Assumptions '!F18 -> 0.096996607 | E21: ='Consolidated PL'!F21/'Assumptions '!G18 -> 0.10690944 | F21: ='Consolidated PL'!G21/'Assumptions '!H18 -> 0.14069939 | G21: ='Consolidated PL'!H21/'Assumptions '!I18 -> 0.056865204
B23: Debtor Turnover Ratio | D23: ='Consolidated PL'!E11/(AVERAGE('Consolidated BS'!D29,'Consolidated BS'!C29)) -> 39.230185 | E23: ='Consolidated PL'!F11/(AVERAGE('Consolidated BS'!E29,'Consolidated BS'!D29)) -> 25.923251 | F23: ='Consolidated PL'!G11/(AVERAGE('Consolidated BS'!F29,'Consolidated BS'!E29)) -> 22.98904 | G23: ='Consolidated PL'!H11/(AVERAGE('Consolidated BS'!G29,'Consolidated BS'!F29)) -> 16.680624
B24: Inventory Turnover | D24: =('Consolidated PL'!E17+'Consolidated PL'!E18+'Consolidated BS'!D28-'Consolidated BS'!C28)/AVERAGE('Standalone BS'!C27:D27) -> 5.4262925 | E24: =('Consolidated PL'!F17+'Consolidated PL'!F18+'Consolidated BS'!E28-'Consolidated BS'!D28)/AVERAGE('Standalone BS'!D27:E27) -> 5.4894025 | F24: =('Consolidated PL'!G17+'Consolidated PL'!G18+'Consolidated BS'!F28-'Consolidated BS'!E28)/AVERAGE('Standalone BS'!E27:F27) -> #VALUE! | G24: =('Consolidated PL'!H17+'Consolidated PL'!H18+'Consolidated BS'!G28-'Consolidated BS'!F28)/AVERAGE('Standalone BS'!F27:G27) -> #VALUE!
B25: Fixed Asset Turnover | D25: ='Consolidated PL'!E11/AVERAGE('Consolidated BS'!D25,'Consolidated BS'!C25) -> 1.6844693 | E25: ='Consolidated PL'!F11/AVERAGE('Consolidated BS'!E25,'Consolidated BS'!D25) -> 1.4324703 | F25: ='Consolidated PL'!G11/AVERAGE('Consolidated BS'!F25,'Consolidated BS'!E25) -> 1.2894309 | G25: ='Consolidated PL'!H11/AVERAGE('Consolidated BS'!G25,'Consolidated BS'!F25) -> 1.2431939
B26: Capital Turnover Ratio | D26: ='Consolidated PL'!E11/AVERAGE('Consolidated BS'!D11,'Consolidated BS'!D15) -> 4.4219884 | E26: ='Consolidated PL'!F11/AVERAGE('Consolidated BS'!E11,'Consolidated BS'!E15) -> 10.275534 | F26: Subsidiary Name | G26: ='Consolidated PL'!H11/AVERAGE('Consolidated BS'!G11,'Consolidated BS'!G15) -> 15.430065
F27: Varun Beverages (Nepal) Pvt. Ltd.,Kathmandu Nepal
B28: Debtor Days | F28: Varun Beverages Morocco SA,Casablanca Morocco
B29: Payable Days | F29: Varun Beverages Zambia Ltd.,Lusaka Zambia
B30: Inventory Days | F30: Varun Beverages Zimbabwe (Pvt.) Ltd.,Harare Zimbabwe
B31: Cash Conversion Cycle (in days) | F31: Varun Beverages Mozambique SA,Maputo Mozambique
F32: Lunarmech Technologies Pvt. Ltd.,India
B33: CFO/Sales
B34: CFO/Total Assets
B35: CFO/Total Debt

Sheet Standalone PL
B2: Varun Beverages | Standalone Profit & Loss | (₹ Crores)
B4: (₹ Crores) | C4: Dec '21 | D4: Dec '22 | E4: Dec '23 | F4: Dec '24 | G4: Dec '25
B5: #VALUE!
B6: #VALUE!
B7: Income
B8: Sales Turnover | C8: 6595.74 | D8: 10595.83 | E8: 12632.83 | F8: 14348.6 | G8: 14556.82
B9: Net Sales | C9: 6595.74 | D9: 10595.83 | E9: 12632.83 | F9: 14348.6 | G9: 14556.82
B10: Other Income | C10: 62.93 | D10: 151.82 | E10: 144.06 | F10: 374.75 | G10: 534.16
B11: Stock Adjustments | C11: 76.07 | D11: 302.35 | E11: 61.82 | F11: -38.84 | G11: -12.97
B12: Total Income | C12: 6734.74 | D12: 11050 | E12: 12838.71 | F12: 14684.51 | G12: 15078.01
B13: Expenditure
B14: Raw Materials | C14: 3268.52 | D14: 5683.1 | E14: 6158.07 | F14: 6691.53 | G14: 6866.68
B15: Power & Fuel Cost | C15: 258.39 | D15: 388.97 | E15: 436.94 | F15: 475.66 | G15: 474.54
B16: Employee Cost | C16: 741.12 | D16: 920.47 | E16: 1036.8 | F16: 1177.55 | G16: 1260.22
B17: Selling and Admin Expenses | C17: 59.51 | D17: 72.55 | E17: 100.34 | F17: 93.92 | G17: 111.27
B18: Miscellaneous Expenses | C18: 1165.08 | D18: 1654.96 | E18: 1981.05 | F18: 2187.54 | G18: 2067.17
B19: Total Expenses | C19: 5492.62 | D19: 8720.05 | E19: 9713.2 | F19: 10626.2 | G19: 10779.88
C20: Dec '21 | D20: Dec '22 | E20: Dec '23 | F20: Dec '24 | G20: Dec '25
B21: #VALUE!
C22: 12 mths | D22: 12 mths | E22: 12 mths | F22: 12 mths | G22: 12 mths
B23: #VALUE!
B24: Operating Profit | C24: 1179.19 | D24: 2178.13 | E24: 2981.45 | F24: 3683.56 | G24: 3763.97
B25: PBDIT | C25: 1242.12 | D25: 2329.95 | E25: 3125.51 | F25: 4058.31 | G25: 4298.13
B26: Interest | C26: 155.14 | D26: 154.26 | E26: 241.1 | F26: Subsidiary Name | G26: 32.24
B27: PBDT | C27: 1086.98 | D27: 2175.69 | E27: 2884.41 | F27: Varun Beverages (Nepal) Pvt. Ltd.,Kathmandu Nepal | G27: 4265.89
B28: Depreciation | C28: 399.83 | D28: 483.13 | E28: 518.33 | F28: Varun Beverages Morocco SA,Casablanca Morocco | G28: 702.42
B29: Profit Before Tax | C29: 687.15 | D29: 1692.56 | E29: 2366.08 | F29: Varun Beverages Zambia Ltd.,Lusaka Zambia | G29: 3563.47
B30: PBT (Post Extra-ord Items) | C30: 687.15 | D30: 1692.56 | E30: 2366.08 | F30: Varun Beverages Zimbabwe (Pvt.) Ltd.,Harare Zimbabwe | G30: 3563.47
B31: Tax | C31: 192.04 | D31: 414.3 | E31: 593.04 | F31: Varun Beverages Mozambique SA,Maputo Mozambique | G31: 866.6
B32: Reported Net Profit | C32: 489.49 | D32: 1270.2 | E32: 1775.13 | F32: Lunarmech Technologies Pvt. Ltd.,India | G32: 2676.64
B33: Total Value Addition | C33: 2224.09 | D33: 3036.94 | E33: 3555.13 | F33: 3934.67 | G33: 3913.2
B34: Equity Dividend | C34: 108.26 | D34: 162.39 | E34: 227.35 | F34: 324.86 | G34: 507.28
B35: Per share data (annualised)
B36: Shares in issue (lakhs) | C36: 4330.33 | D36: 6495.5 | E36: 12992.15 | F36: 33815.1 | G36: 33819.89
B37: Earning Per Share (Rs) | C37: 11.3 | D37: 19.56 | E37: 13.66 | F37: 6.86 | G37: 7.91
B38: Equity Dividend (%) | C38: 25 | D38: 35 | E38: 50 | F38: 50 | G38: 75
B39: Book Value (Rs) | C39: 101.58 | D39: 84.94 | E39: 54.46 | F39: 48.97 | G39: 55.48

Sheet Peers
B2: Varun Beverages | Peer Comparison
B4: VBL | C4: Varun Beverages Ltd is one of the largest franchisees of PepsiCo in the world, producing and distributing carbonated soft drinks (Pepsi, Mountain Dew, 7UP, Mirinda, Sting), non-carbonated beverages (Tropicana, Slice, Gatorade) and packaged drinking water (Aquafina). Operations span India and 6+ international geographies (Nepal, Sri Lanka, Morocco, Zambia, Zimbabwe, South Africa). FY Dec.
B9: TATACONSUM | C9: Tata Consumer Products Ltd is one of the leading Tata Group companies in food & beverages, both in India and internationally. It is the second largest tea company globally and ranks among India's top 10 FMCG companies. Key brands include Tata Tea, Tetley, Tata Salt, Tata Sampann, Himalayan (mineral water), Eight O'Clock Coffee and Tata Soulfull. FY Mar.
B14: BRITANNIA | C14: Britannia Industries Ltd is one of India's leading food companies with a 100-year legacy and revenues over Rs.16,000 Cr. Britannia is among India's most trusted food brands with products including biscuits (Good Day, Tiger, NutriChoice, Milk Bikis, Marie Gold, Bourbon), bread, cakes, rusk, and dairy (cheese, milk, yoghurt, beverages). Part of Wadia Group. FY Mar.
B19: GODREJCP | C19: Godrej Consumer Products Ltd is an Indian FMCG company manufacturing and marketing household and personal care products. Top brands (~70% of revenue) include GoodKnight (mosquito repellents), HIT (pest control), Cinthol (premium personal care), Godrej Expert (hair color), Godrej No.1 (soaps), Darling (hair extensions in Africa), Aer (air fresheners). Geographic mix: India, Indonesia, Africa. FY Mar.
B24: Attribute | C24: LTP (₹) | D24: Change (%) | E24: Sales (₹ Cr) | F24: PAT (₹ Cr) | G24: Equity (₹ Cr) | H24: OPM % | I24: NPM % | J24: EPS (₹) | K24: CEPS (₹)
B25: VBL (Dec 2025) | C25: 388 | D25: -0.28 | E25: 21685 | F25: 3062 | G25: 676 | H25: 23 | I25: =F25/E25*100 -> 14.12036 | J25: 8.98 | K25: =(F25+1216)/(G25/2) -> 12.656805
B26: TATACONSUM (Mar 2025) | C26: 1179 | D26: 3.2 | E26: 17618 | F26: Subsidiary Name | G26: 99 | H26: 14 | I26: =F26/E26*100 -> #VALUE! | J26: 12.92 | K26: =(F26+601)/(G26/1) -> #VALUE!
B27: BRITANNIA (Mar 2025) | C27: 5983 | D27: 0.34 | E27: 17943 | F27: Varun Beverages (Nepal) Pvt. Ltd.,Kathmandu Nepal | G27: 24 | H27: 18 | I27: =F27/E27*100 -> #VALUE! | J27: 90.45 | K27: =(F27+313)/(G27/1) -> #VALUE!
B28: GODREJCP (Mar 2025) | C28: 1161 | D28: 0.61 | E28: 14364 | F28: Varun Beverages Morocco SA,Casablanca Morocco | G28: 102 | H28: 21 | I28: =F28/E28*100 -> #VALUE! | J28: 18.11 | K28: =(F28+234)/(G28/1) -> #VALUE!
F29: Varun Beverages Zambia Ltd.,Lusaka Zambia
F30: Varun Beverages Zimbabwe (Pvt.) Ltd.,Harare Zimbabwe
F31: Varun Beverages Mozambique SA,Maputo Mozambique
B32: VBL | F32: Lunarmech Technologies Pvt. Ltd.,India | G32: TATACONSUM
B33: Metric | C33: 45261 | D33: 45627 | E33: 45992 | G33: Metric | H33: 44986 | I33: 45352 | J33: 45717
B34: Debtor Days | C34: 8 | D34: 15 | E34: 21 | G34: Debtor Days | H34: 21 | I34: 22 | J34: 18
B35: Inventory Days | C35: 106 | D35: 114 | E35: 111 | G35: Inventory Days | H35: 144 | I35: 140 | J35: 152
B36: Days Payable | C36: 37 | D36: 64 | E36: 53 | G36: Days Payable | H36: 125 | I36: 136 | J36: 148
B37: Cash Conversion Cycle | C37: 77 | D37: 66 | E37: 79 | G37: Cash Conversion Cycle | H37: 40 | I37: 25 | J37: 22
B38: Working Capital Days | C38: -9 | D38: 16 | E38: 31 | G38: Working Capital Days | H38: 22 | I38: -35 | J38: 0
B39: ROCE % | C39: 0.29 | D39: 0.25 | E39: 0.2 | G39: ROCE % | H39: 0.09 | I39: 0.11 | J39: 0.09
B41: BRITANNIA | G41: GODREJCP
B42: Metric | C42: 44986 | D42: 45352 | E42: 45717 | G42: Metric | H42: 44986 | I42: 45352 | J42: 45717
B43: Debtor Days | C43: 7 | D43: 9 | E43: 9 | G43: Debtor Days | H43: 34 | I43: 40 | J43: 46
B44: Inventory Days | C44: 45 | D44: 45 | E44: 43 | G44: Inventory Days | H44: 84 | I44: 73 | J44: 79
B45: Days Payable | C45: 55 | D45: 63 | E45: 60 | G45: Days Payable | H45: 99 | I45: 97 | J45: 120
B46: Cash Conversion Cycle | C46: -2 | D46: -9 | E46: -9 | G46: Cash Conversion Cycle | H46: 19 | I46: 16 | J46: 6
B47: Working Capital Days | C47: -31 | D47: -30 | E47: -23 | G47: Working Capital Days | H47: -2 | I47: -60 | J47: -81
B48: ROCE % | C48: 0.49 | D48: 0.49 | E48: 0.53 | G48: ROCE % | H48: 0.17 | I48: 0.19 | J48: 0.19

Sheet Stock Analysis
B2: VARUN BEVERAGES LTD — STOCK ANALYSIS
K3: Recommendation
P4: ACCUMULATE ON DIPS. Varun Beverages trades at ₹520 (P/E 55.1x), having recovered ~34% from the ₹381 low but still ~9% below the 52-week high of ₹568. Operating fundamentals remain strong: CY25 revenue ₹21,685 Cr (+8.4% YoY), PAT ₹3,062 Cr (+16.3% YoY), 5-yr profit CAGR 50%, ROCE 19.7%, ROE 16.2%. At 55x P/E and ~9x book, the stock is no longer cheap, so accumulate selectively rather than chase. Add aggressively below ₹450 where margin of safety improves; outright BUY only on a re-rating event or earnings beat that compresses the multiple toward 45x.
P7: Thesis: VBL is the world's 2nd-largest PepsiCo bottler outside the US and the dominant CSD/NCB franchise in India, Nepal, Sri Lanka, Morocco, and now sub-Saharan Africa (post BevCo, Twizza, Crickley Dairy). The CY25 print confirms the operating model is intact: sales ₹21,685 Cr (+8.4%), PAT ₹3,062 Cr (+16.3%), OPM held at 23%. Strategic pivot to low/no-sugar (now 59% of mix) reduces regulatory risk. 5-yr compounded profit growth at 50% CAGR is among the best in Indian FMCG. Valuation reality: at ₹520 the stock trades 55.1x TTM P/E and ~9x book, near the upper end of its historical range. Dividend yield 0.26% offers no margin of safety. Mkt cap ₹1.75 lakh Cr. The recovery from ₹381 low to ₹520 (+36%) has run ahead of fundamentals, requiring earnings to grow into the multiple. ROCE compression to 19.7% (from 28%+) is real, driven by the capex-heavy Africa/DRC build-out. Returns should normalize as new plants ramp. Catalysts (positive): (1) Twizza/Crickley Dairy synergy, with SA being Africa's largest soft-drinks market; (2) DRC greenfield ramp + Morocco snack distribution scale-up; (3) summer demand season + favorable monsoon supporting India volumes; (4) borrowings down to ₹2,508 Cr in CY25 from ₹5,431 Cr in CY23, balance sheet de-risked. Risks: (1) further P/E de-rating if growth slows below 12%; (2) margin pressure from PET/sugar/aluminum; (3) integration drag from Twizza in early quarters; (4) climate/weather disruptions to peak season.
Q16: Financial Year | R16: Revenue (₹ Cr) | S16: PAT (₹ Cr) | T16: Revenue Change (%) | U16: PAT Change (%) | V16: Nifty 50 Change (%)
Q17: 45992 | R17: 21685 | S17: 3062 | T17: =R17/R18-1 -> 0.083816473 | U17: =S17/S18-1 -> 0.16249051 | V17: 0.007
Q18: 45627 | R18: 20008 | S18: 2634 | T18: =R18/R19-1 -> 0.24714829 | U18: =S18/S19-1 -> 0.25309229 | V18: 0.27
Q19: 45261 | R19: 16043 | S19: 2102 | T19: =R19/R20-1 -> 0.21786989 | U19: =S19/S20-1 -> 0.35612903 | V19: 0.2
Q20: 44896 | R20: 13173 | S20: 1550 | T20: =R20/R21-1 -> 0.49302958 | U20: =S20/S21-1 -> 1.077748 | V20: 0.043
B21: Metric | C21: Value | Q21: 44531 | R21: 8823 | S21: 746 | T21: - | U21: - | V21: 0.24
B22: Market Cap | C22: ₹ 1,75,373 Cr.
B23: Current Price | C23: 520
B24: High / Low | C24: ₹ 568 / ₹ 381
B25: Stock P/E | C25: 55.1
B26: Book Value | C26: 57.9 | F26: Subsidiary Name
B27: Dividend Yield | C27: 0.0026 | F27: Varun Beverages (Nepal) Pvt. Ltd.,Kathmandu Nepal
B28: ROCE | C28: 0.197 | F28: Varun Beverages Morocco SA,Casablanca Morocco
B29: ROE | C29: 0.162 | F29: Varun Beverages Zambia Ltd.,Lusaka Zambia
B30: Face Value | C30: 2 | F30: Varun Beverages Zimbabwe (Pvt.) Ltd.,Harare Zimbabwe
F31: Varun Beverages Mozambique SA,Maputo Mozambique
F32: Lunarmech Technologies Pvt. Ltd.,India
B34: Source: Screener.in (https://www.screener.in/company/VBL/consolidated/)
B42: All financial and stock data on this sheet is sourced from Screener.in for Varun Beverages Ltd (consolidated).

Sheet BETA
B1: VBL & NIFTY 50 - DAILY PRICES (Apr 2020 - Mar 2026)
B2: Varun Beverages Ltd | F2: Nifty 50
B3: Date | C3: Close (₹) | D3: Daily Return | F3: Date | G3: Close | H3: Daily Return
B4: 43922 | C4: 46.97 | F4: 43922 | G4: 8253.7998
B5: 43924 | C5: 46.97 | D5: =(C5-C4)/C4 -> 0 | F5: 43924 | G5: 8083.7998 | H5: =(G5-G4)/G4 -> -0.020596574 | K5: BETA | L5: =SLOPE(D5:D1485,H5:H1485) -> 0.65919938
B6: 43928 | C6: 46.48 | D6: =(C6-C5)/C5 -> -0.010432191 | F6: 43928 | G6: 8792.2002 | H6: =(G6-G5)/G5 -> 0.087632105 | L6: =_xlfn.COVARIANCE.S(D5:D1485,H5:H1485)/_xlfn.VAR.S(H5:H1485) -> 0.65919938
B7: 43929 | C7: 47.45 | D7: =(C7-C6)/C6 -> 0.020869191 | F7: 43929 | G7: 8748.75 | H7: =(G7-G6)/G6 -> -0.0049419024
B8: 43930 | C8: 50.51 | D8: =(C8-C7)/C7 -> 0.064488936 | F8: 43930 | G8: 9111.9004 | H8: =(G8-G7)/G7 -> 0.041508832 | L8: SUMMARY OUTPUT
B9: 43934 | C9: 48.53 | D9: =(C9-C8)/C8 -> -0.039200158 | F9: 43934 | G9: 8993.8496 | H9: =(G9-G8)/G8 -> -0.012955671
B10: 43936 | C10: 49.58 | D10: =(C10-C9)/C9 -> 0.021636101 | F10: 43936 | G10: 8925.2998 | H10: =(G10-G9)/G9 -> -0.0076218536 | L10: Regression Statistics | Y10: 0.0007202242
B11: 43937 | C11: 50.45 | D11: =(C11-C10)/C10 -> 0.017547398 | F11: 43937 | G11: 8992.7998 | H11: =(G11-G10)/G10 -> 0.0075627712 | L11: Multiple R | M11: 0.28727264 | Y11: 0.00025459046
B12: 43938 | C12: 52.88 | D12: =(C12-C11)/C11 -> 0.048166501 | F12: 43938 | G12: 9266.75 | H12: =(G12-G11)/G11 -> 0.030463282 | L12: R Square | M12: 0.082525569 | Y12: 0.00089289295
B13: 43941 | C13: 56.85 | D13: =(C13-C12)/C12 -> 0.075075643 | F13: 43941 | G13: 9261.8496 | H13: =(G13-G12)/G12 -> -0.00052881438 | L13: Adjusted R Square | M13: 0.081905235 | Y13: #N/A
B14: 43942 | C14: 53.06 | D14: =(C14-C13)/C13 -> -0.066666667 | F14: 43942 | G14: 8981.4502 | H14: =(G14-G13)/G13 -> -0.030274667 | L14: Standard Error | M14: 0.021541996 | Y14: 0.0097975989
B15: 43943 | C15: 56.92 | D15: =(C15-C14)/C14 -> 0.072747833 | F15: 43943 | G15: 9187.2998 | H15: =(G15-G14)/G14 -> 0.022919418 | L15: Observations | M15: 1481 | Y15: 9.5992945e-05
B16: 43944 | C16: 54.44 | D16: =(C16-C15)/C15 -> -0.043569923 | F16: 43944 | G16: 9313.9004 | H16: =(G16-G15)/G15 -> 0.013779956 | Y16: 7.3387766
B17: 43945 | C17: 56.9 | D17: =(C17-C16)/C16 -> 0.045187362 | F17: 43945 | G17: 9154.4004 | H17: =(G17-G16)/G16 -> -0.017124942 | L17: ANOVA | Y17: 0.04110201
B18: 43948 | C18: 56.43 | D18: =(C18-C17)/C17 -> -0.0082601054 | F18: 43948 | G18: 9282.2998 | H18: =(G18-G17)/G17 -> 0.013971359 | M18: df | N18: SS | O18: MS | P18: F | Q18: Significance F | Y18: 0.1469257
B19: 43949 | C19: 57.87 | D19: =(C19-C18)/C18 -> 0.025518341 | F19: 43949 | G19: 9380.9004 | H19: =(G19-G18)/G18 -> 0.010622431 | L19: Regression | M19: 1 | N19: 0.061735449 | O19: 0.061735449 | P19: 133.03403 | Q19: 1.5618079e-29 | Y19: -0.059293599
B20: 43950 | C20: 57.55 | D20: =(C20-C19)/C19 -> -0.0055296354 | F20: 43950 | G20: 9553.3496 | H20: =(G20-G19)/G19 -> 0.018383014 | L20: Residual | M20: 1479 | N20: 0.68634117 | O20: 0.00046405758 | Y20: 0.087632105
B21: 43951 | C21: 58.51 | D21: =(C21-C20)/C20 -> 0.016681147 | F21: 43951 | G21: 9859.9004 | H21: =(G21-G20)/G20 -> 0.032088303 | L21: Total | M21: 1480 | N21: 0.74807662 | Y21: 1.066652
B22: 43955 | C22: 53.89 | D22: =(C22-C21)/C21 -> -0.078960861 | F22: 43955 | G22: 9293.5 | H22: =(G22-G21)/G21 -> -0.057444839 | Y22: 1481
B23: 43956 | C23: 54.21 | D23: =(C23-C22)/C22 -> 0.0059380219 | F23: 43956 | G23: 9205.5996 | H23: =(G23-G22)/G22 -> -0.0094582655 | M23: Coefficients | N23: Standard Error | O23: t Stat | P23: P-value | Q23: Lower 95% | R23: Upper 95% | S23: Lower 95.0% | T23: Upper 95.0%
B24: 43957 | C24: 53.83 | D24: =(C24-C23)/C23 -> -0.0070097768 | F24: 43957 | G24: 9270.9004 | H24: =(G24-G23)/G23 -> 0.0070935935 | L24: Intercept | M24: 0.0011952093 | N24: 0.00056127985 | O24: 2.1294357 | P24: 0.03338299 | Q24: 9.4220036e-05 | R24: 0.0022961986 | S24: 9.4220036e-05 | T24: 0.0022961986
B25: 43958 | C25: 52.43 | D25: =(C25-C24)/C24 -> -0.026007802 | F25: 43958 | G25: 9199.0498 | H25: =(G25-G24)/G24 -> -0.0077501195 | L25: X Variable 1 | M25: 0.65919938 | N25: 0.057152525 | O25: 11.534038 | P25: 1.5618079e-29 | Q25: 0.54709074 | R25: 0.77130802 | S25: 0.54709074 | T25: 0.77130802
B26: 43959 | C26: 54.22 | D26: =(C26-C25)/C25 -> 0.034140759 | F26: Subsidiary Name | G26: 9251.5 | H26: =(G26-G25)/G25 -> 0.0057016971
B27: 43962 | C27: 53.94 | D27: =(C27-C26)/C26 -> -0.0051641461 | F27: Varun Beverages (Nepal) Pvt. Ltd.,Kathmandu Nepal | G27: 9239.2002 | H27: =(G27-G26)/G26 -> -0.001329493
B28: 43963 | C28: 54.51 | D28: =(C28-C27)/C27 -> 0.010567297 | F28: Varun Beverages Morocco SA,Casablanca Morocco | G28: 9196.5498 | H28: =(G28-G27)/G27 -> -0.0046162427
B29: 43964 | C29: 57.68 | D29: =(C29-C28)/C28 -> 0.058154467 | F29: Varun Beverages Zambia Ltd.,Lusaka Zambia | G29: 9383.5498 | H29: =(G29-G28)/G28 -> 0.020333713
B30: 43965 | C30: 56.23 | D30: =(C30-C29)/C29 -> -0.025138696 | F30: Varun Beverages Zimbabwe (Pvt.) Ltd.,Harare Zimbabwe | G30: 9142.75 | H30: =(G30-G29)/G29 -> -0.025661909
B31: 43966 | C31: 55.31 | D31: =(C31-C30)/C30 -> -0.016361373 | F31: Varun Beverages Mozambique SA,Maputo Mozambique | G31: 9136.8496 | H31: =(G31-G30)/G30 -> -0.00064536279
B32: 43969 | C32: 54.77 | D32: =(C32-C31)/C31 -> -0.0097631531 | F32: Lunarmech Technologies Pvt. Ltd.,India | G32: 8823.25 | H32: =(G32-G31)/G31 -> -0.03432251
B33: 43970 | C33: 53.83 | D33: =(C33-C32)/C32 -> -0.01716268 | F33: 43970 | G33: 8879.0996 | H33: =(G33-G32)/G32 -> 0.0063298228
B34: 43971 | C34: 52.68 | D34: =(C34-C33)/C33 -> -0.021363552 | F34: 43971 | G34: 9066.5498 | H34: =(G34-G33)/G33 -> 0.021111397
B35: 43972 | C35: 50.69 | D35: =(C35-C34)/C34 -> -0.037775247 | F35: 43972 | G35: 9106.25 | H35: =(G35-G34)/G34 -> 0.0043787545
B36: 43973 | C36: 50.92 | D36: =(C36-C35)/C35 -> 0.0045373841 | F36: 43973 | G36: 9039.25 | H36: =(G36-G35)/G35 -> -0.0073575841
B37: 43977 | C37: 51.88 | D37: =(C37-C36)/C36 -> 0.018853103 | F37: 43977 | G37: 9029.0498 | H37: =(G37-G36)/G36 -> -0.0011284338
B38: 43978 | C38: 51.97 | D38: =(C38-C37)/C37 -> 0.0017347726 | F38: 43978 | G38: 9314.9502 | H38: =(G38-G37)/G37 -> 0.031664505
B39: 43979 | C39: 53.49 | D39: =(C39-C38)/C38 -> 0.029247643 | F39: 43979 | G39: 9490.0996 | H39: =(G39-G38)/G38 -> 0.018803044
B40: 43980 | C40: 55.2 | D40: =(C40-C39)/C39 -> 0.031968592 | F40: 43980 | G40: 9580.2998 | H40: =(G40-G39)/G39 -> 0.0095046627
...

Sheet Assumptions 
C2: [ | D2: Varun Beverages
D3: Consolidated Profit & Loss account
E4: 44256 | F4: 44621 | G4: 44986 | H4: 45352 | I4: Mar 25
C5: Particulars
C6: Revenue From Operations [Net] | E6: ='Consolidated PL'!D11 -> 8642.35 | F6: ='Consolidated PL'!E11 -> 12921.05 | G6: ='Consolidated PL'!F11 -> 15621.74 | H6: ='Consolidated PL'!G11 -> 19445.05 | I6: ='Consolidated PL'!H11 -> 20834.6
C7: revenue growth | F7: =(F6-E6)/E6 -> 0.49508525 | G7: =(G6-F6)/F6 -> 0.20901475 | H7: =(H6-G6)/G6 -> 0.2447429 | I7: =(I6-H6)/H6 -> 0.071460346
C9: less: Material Consumed | E9: ='Consolidated PL'!D17+'Consolidated PL'!D18+'Consolidated PL'!D19 -> 4034.66 | F9: ='Consolidated PL'!E17+'Consolidated PL'!E18+'Consolidated PL'!E19 -> 6261.15 | G9: ='Consolidated PL'!F17+'Consolidated PL'!F18+'Consolidated PL'!F19 -> 7404.89 | H9: ='Consolidated PL'!G17+'Consolidated PL'!G18+'Consolidated PL'!G19 -> 8904.72 | I9: ='Consolidated PL'!H17+'Consolidated PL'!H18+'Consolidated PL'!H19 -> 9715.42
C10: less: Employee Cost | E10: ='Consolidated PL'!D20 -> 1007.7 | F10: ='Consolidated PL'!E20 -> 1216.64 | G10: ='Consolidated PL'!F20 -> 1446.59 | H10: ='Consolidated PL'!G20 -> 1885.03 | I10: ='Consolidated PL'!H20 -> 2200.74
C11: less: Other Expenses | E11: ='Consolidated PL'!D23 -> 2126.23 | F11: ='Consolidated PL'!E23 -> 2907.24 | G11: ='Consolidated PL'!F23 -> 3581.62 | H11: ='Consolidated PL'!G23 -> 4506.83 | I11: ='Consolidated PL'!H23 -> 4719.84
C12: Total Expenses | E12: =SUM('Assumptions '!E9:E11) -> 7168.59 | F12: =SUM('Assumptions '!F9:F11) -> 10385.03 | G12: =SUM('Assumptions '!G9:G11) -> 12433.1 | H12: =SUM('Assumptions '!H9:H11) -> 15296.58 | I12: =SUM('Assumptions '!I9:I11) -> 16636
C14: EBITDA | E14: =E6-E12 -> 1473.76 | F14: =F6-F12 -> 2536.02 | G14: =G6-G12 -> 3188.64 | H14: =H6-H12 -> 4148.47 | I14: =I6-I12 -> 4198.6
C16: less: Depreciation & Amortization | E16: ='Consolidated PL'!D22 -> 531.26 | F16: ='Consolidated PL'!E22 -> 617.19 | G16: ='Consolidated PL'!F22 -> 680.91 | H16: ='Consolidated PL'!G22 -> 947.39 | I16: ='Consolidated PL'!H22 -> 1216.46
C18: EBIT | E18: =E14-E16 -> 942.5 | F18: =F14-F16 -> 1918.83 | G18: =G14-G16 -> 2507.73 | H18: =H14-H16 -> 3201.08 | I18: =I14-I16 -> 2982.14
C20: add: Other income | E20: ='Consolidated PL'!D23 -> 2126.23 | F20: ='Consolidated PL'!E23 -> 2907.24 | G20: ='Consolidated PL'!F23 -> 3581.62 | H20: ='Consolidated PL'!G23 -> 4506.83 | I20: ='Consolidated PL'!H23 -> 4719.84
C21: less: Interest Expense | E21: ='Consolidated PL'!D21 -> 184.7 | F21: ='Consolidated PL'!E21 -> 186.12 | G21: ='Consolidated PL'!F21 -> 268.1 | H21: ='Consolidated PL'!G21 -> 450.39 | I21: ='Consolidated PL'!H21 -> 169.58
C23: EBT | E23: =E18+E20-E21 -> 2884.03 | F23: =F18+F20-F21 -> 4639.95 | G23: =G18+G20-G21 -> 5821.25 | H23: =H18+H20-H21 -> 7257.52 | I23: =I18+I20-I21 -> 7532.4
C25: less: Tax | E25: ='Consolidated PL'!D31 -> 260.56 | F25: ='Consolidated PL'!E31 -> 473.52 | G25: ='Consolidated PL'!F31 -> Varun Beverages Mozambique SA,Maputo Mozambique | H25: ='Consolidated PL'!G31 -> 798.8 | I25: ='Consolidated PL'!H31 -> 947.61
C26: less: Non Controlling interest | E26: ='Consolidated PL'!D35 -> -52 | F26: Subsidiary Name | G26: ='Consolidated PL'!F35 -> -45.89 | H26: ='Consolidated PL'!G35 -> -39.65 | I26: ='Consolidated PL'!H35 -> -25.55
F27: Varun Beverages (Nepal) Pvt. Ltd.,Kathmandu Nepal
C28: PAT | E28: =E23-E25-E26 -> 2675.47 | F28: Varun Beverages Morocco SA,Casablanca Morocco | G28: =G23-G25-G26 -> #VALUE! | H28: =H23-H25-H26 -> 6498.37 | I28: =I23-I25-I26 -> 6610.34
F29: Varun Beverages Zambia Ltd.,Lusaka Zambia
C30: Historical Growth | F30: Varun Beverages Zimbabwe (Pvt.) Ltd.,Harare Zimbabwe
C31: Average Growth | E31: =AVERAGE(F7:I7) -> 0.25507581 | F31: Varun Beverages Mozambique SA,Maputo Mozambique
C32: CAGR | E32: =(I6/E6)^(1/4)-1 -> 0.2460582 | F32: Lunarmech Technologies Pvt. Ltd.,India
C34: Margin Analysis
C35: EBITDA Margin | E35: =E14/E6 -> 0.17052769 | F35: =F14/F6 -> 0.19627043 | G35: =G14/G6 -> 0.20411555 | H35: =H14/H6 -> 0.21334324 | I35: =I14/I6 -> 0.20152055
C36: EBIT Margin | E36: =E18/E6 -> 0.10905599 | F36: =F18/F6 -> 0.14850419 | G36: =G18/G6 -> 0.16052821 | H36: =H18/H6 -> 0.16462184 | I36: =I18/I6 -> 0.14313402
C37: EBT Margin | E37: =E23/E6 -> 0.333709 | F37: =F23/F6 -> 0.35910007 | G37: =G23/G6 -> 0.37263775 | H37: =H23/H6 -> 0.37323226 | I37: =I23/I6 -> 0.36153322
C38: PAT Margin | E38: =E28/E6 -> 0.30957668 | F38: =F28/F6 -> #VALUE! | G38: =G28/G6 -> #VALUE! | H38: =H28/H6 -> 0.33419148 | I38: =I28/I6 -> 0.31727703
C40: Tax Rate
C41: Effective Tax Rate | D41: =E25/E23 -> 0.090345801 | E41: =F25/F23 -> 0.10205282 | F41: =G25/G23 -> #VALUE! | G41: =H25/H23 -> 0.11006515 | H41: =I25/I23 -> 0.12580452
C42: Marginal Tax Rate | D42: 0.25 | E42: 0.25 | F42: 0.25 | G42: 0.25 | H42: 0.25
C44: Return on Capital
C45: EBIT(1-t) | D45: =E18*(1-D42) -> 706.875 | E45: =F18*(1-E42) -> 1439.1225 | F45: =G18*(1-F42) -> 1880.7975 | G45: =H18*(1-G42) -> 2400.81 | H45: =I18*(1-H42) -> 2236.605
C46: Book Equity | D46: ='Consolidated BS'!C10 -> 649.55 | E46: ='Consolidated BS'!D10 -> 649.61 | F46: ='Consolidated BS'!E10 -> 676.3 | G46: ='Consolidated BS'!F10 -> 676.4 | H46: ='Consolidated BS'!G10 -> 676.4
C47: Book Debt | D47: ='Consolidated BS'!C16 -> 3694.81 | E47: ='Consolidated BS'!D16 -> 5194.39 | F47: ='Consolidated BS'!E16 -> 2364.27 | G47: ='Consolidated BS'!F16 -> 2024.12 | H47: ='Consolidated BS'!G16 -> 2024.12
C48: Cash and Cash Equivalent | D48: ='Consolidated BS'!C30 -> 285.27 | E48: ='Consolidated BS'!D30 -> 459.86 | F48: ='Consolidated BS'!E30 -> 2450.05 | G48: ='Consolidated BS'!F30 -> Varun Beverages Zimbabwe (Pvt.) Ltd.,Harare Zimbabwe | H48: ='Consolidated BS'!G30 -> 1998.49
C49: Capital Employed | D49: =D46+D47-D48 -> 4059.09 | E49: =E46+E47-E48 -> 5384.14 | F49: =F46+F47-F48 -> 590.52 | G49: =G46+G47-G48 -> #VALUE! | H49: =H46+H47-H48 -> 702.03
C51: Pre Tax Return on Capital | D51: =E18/D49 -> 0.2321949 | E51: =F18/E49 -> 0.35638561 | F51: =G18/F49 -> 4.246647 | G51: =H18/G49 -> #VALUE! | H51: =I18/H49 -> 4.2478811
C52: Post Tax Return on Capital | D52: =D45/D49 -> 0.17414618 | E52: =E45/E49 -> 0.2672892 | F52: =F45/F49 -> 3.1849853 | G52: =G45/G49 -> #VALUE! | H52: =H45/H49 -> 3.1859109
...

Sheet Fixed Asset Schedule 
B1: Varun Beverages — Fixed Asset Schedule
B2: Particulars | C2: 44256 | D2: 44621 | E2: 44986 | F2: 45352 | G2: 45717
B3: Beginning Balance | D3: =C7 -> 6932.22 | E3: =D7 -> 8409.17 | F3: =E7 -> 13401.74 | G3: =F7 -> 16758.93
B4: Add: Net Purchases | D4: =D5-D3 -> 2094.14 | E4: =E5-E3 -> 5673.48 | F4: =F5-F3 -> 4304.58 | G4: =G5-G3 -> 1216.46
B5: Total Fixed Assets | C5: =C6+C7 -> 7463.48 | D5: =D6+D7 -> 9026.36 | E5: =E6+E7 -> 14082.65 | F5: =F6+F7 -> 17706.32 | G5: =G6+G7 -> 17975.39
B6: Less: Depreciation | C6: ='Consolidated PL'!D22 -> 531.26 | D6: ='Consolidated PL'!E22 -> 617.19 | E6: ='Consolidated PL'!F22 -> 680.91 | F6: ='Consolidated PL'!G22 -> 947.39 | G6: ='Consolidated PL'!H22 -> 1216.46
B7: Closing Balance (Fixed Assets) | C7: ='Consolidated BS'!C25 -> 6932.22 | D7: ='Consolidated BS'!D25 -> 8409.17 | E7: ='Consolidated BS'!E25 -> 13401.74 | F7: ='Consolidated BS'!F25 -> 16758.93 | G7: ='Consolidated BS'!G25 -> 16758.93
B9: Net Capital Expenditure | D9: =D4-D6 -> 1476.95 | E9: =E4-E6 -> 4992.57 | F9: =F4-F6 -> 3357.19 | G9: =G4-G6 -> 0
B10: Net Capex / Sales (%) | D10: =IFERROR(D9/D3,0) -> 0.21305585 | E10: =IFERROR(E9/E3,0) -> 0.59370544 | F10: =IFERROR(F9/F3,0) -> 0.25050404 | G10: =IFERROR(G9/G3,0) -> 0
B12: Median Capex / Sales (%) | C12: =MEDIAN(C10:G10) -> 0.23177994
B13: Average Capex / Sales (%) | C13: =AVERAGE(C10:G10) -> 0.26431633
F26: Subsidiary Name
F27: Varun Beverages (Nepal) Pvt. Ltd.,Kathmandu Nepal
F28: Varun Beverages Morocco SA,Casablanca Morocco
F29: Varun Beverages Zambia Ltd.,Lusaka Zambia
F30: Varun Beverages Zimbabwe (Pvt.) Ltd.,Harare Zimbabwe
F31: Varun Beverages Mozambique SA,Maputo Mozambique
F32: Lunarmech Technologies Pvt. Ltd.,India

Sheet Change in Working Capital
B1: "Change in Working Capital "
B2: Particular | C2: 44256 | D2: 44621 | E2: 44986 | F2: 45352 | G2: 45717
B3: Inventory | C3: ='Consolidated BS'!C28 -> 1993.89 | D3: ='Consolidated BS'!D28 -> 2150.53 | E3: ='Consolidated BS'!E28 -> 2791.23 | F3: ='Consolidated BS'!F28 -> Varun Beverages Morocco SA,Casablanca Morocco | G3: ='Consolidated BS'!G28 -> 2951.79
B4: Trade Receivables | C4: ='Consolidated BS'!C29 -> 299.34 | D4: ='Consolidated BS'!D29 -> 359.39 | E4: ='Consolidated BS'!E29 -> 845.84 | F4: ='Consolidated BS'!F29 -> Varun Beverages Zambia Ltd.,Lusaka Zambia | G4: ='Consolidated BS'!G29 -> 1249.03
B5: Trade Payable | C5: ='Consolidated BS'!C34 -> 2474.64 | D5: ='Consolidated BS'!D34 -> 2612.96 | E5: ='Consolidated BS'!E34 -> 3776.68 | F5: ='Consolidated BS'!F34 -> 3559.1 | G5: ='Consolidated BS'!G34 -> 3559.1
B6: Non Cash working Capital | C6: =C3+C4-C5 -> -181.41 | D6: =D3+D4-D5 -> -103.04 | E6: =E3+E4-E5 -> -139.61 | F6: =F3+F4-F5 -> #VALUE! | G6: =G3+G4-G5 -> 641.72
B7: Change in Working Capital | D7: =D6-C6 -> 78.37 | E7: =E6-D6 -> -36.57 | F7: =F6-E6 -> #VALUE! | G7: =G6-F6 -> #VALUE!
B8: changein working Capital /percentage of sales | D8: =D7/'Consolidated PL'!D11 -> 0.0090681354 | E8: =E7/'Consolidated PL'!E11 -> -0.0028302653 | F8: =F7/'Consolidated PL'!F11 -> #VALUE! | G8: =G7/'Consolidated PL'!G11 -> #VALUE!
B10: Median Non Cash working Capital /Sales percentage | C10: =MEDIAN(D8:G8) -> #VALUE!
B11: Average Non Cash working Capital /Sales percentage | C11: =AVERAGE(C8:G8) -> #VALUE!
F26: Subsidiary Name
F27: Varun Beverages (Nepal) Pvt. Ltd.,Kathmandu Nepal
F28: Varun Beverages Morocco SA,Casablanca Morocco
F29: Varun Beverages Zambia Ltd.,Lusaka Zambia
F30: Varun Beverages Zimbabwe (Pvt.) Ltd.,Harare Zimbabwe
F31: Varun Beverages Mozambique SA,Maputo Mozambique
F32: Lunarmech Technologies Pvt. Ltd.,India

Sheet FCFF
B1: Varun Beverages "Free Cash Flow "
B2: Particular | C2: 44256 | D2: 44621 | E2: 44986 | F2: 45352 | G2: 45717
B3: EBIT | C3: ='Assumptions '!E18 -> 942.5 | D3: ='Assumptions '!F18 -> 1918.83 | E3: ='Assumptions '!G18 -> 2507.73 | F3: ='Assumptions '!H18 -> 3201.08 | G3: ='Assumptions '!I18 -> 2982.14
B4: Less: Tax on EBIT | C4: {=MEDIAN('Assumptions '!$D$41:H41*C3)} -> #VALUE! | D4: {=MEDIAN('Assumptions '!$D$41:I41*D3)} -> #VALUE! | E4: {=MEDIAN('Assumptions '!$D$41:J41*E3)} -> #VALUE! | F4: {=MEDIAN('Assumptions '!$D$41:K41*F3)} -> #VALUE! | G4: {=MEDIAN('Assumptions '!$D$41:L41*G3)} -> #VALUE!
B5: EBIT * (1- Tax) | C5: =C3-C4 -> #VALUE! | D5: =D3-D4 -> #VALUE! | E5: =E3-E4 -> #VALUE! | F5: =F3-F4 -> #VALUE! | G5: =G3-G4 -> #VALUE!
B6: Less: Net Capital expenditure | C6: ='Fixed Asset Schedule '!C9 -> 0 | D6: ='Fixed Asset Schedule '!D9 -> 1476.95 | E6: ='Fixed Asset Schedule '!E9 -> 4992.57 | F6: ='Fixed Asset Schedule '!F9 -> 3357.19 | G6: ='Fixed Asset Schedule '!G9 -> 0
B7: Less: Net Change in working Capital | C7: ='Change in Working Capital'!C7 -> 0 | D7: ='Change in Working Capital'!D7 -> 78.37 | E7: ='Change in Working Capital'!E7 -> -36.57 | F7: ='Change in Working Capital'!F7 -> #VALUE! | G7: ='Change in Working Capital'!G7 -> #VALUE!
B8: Reinvestment | C8: =SUM(C6:C7) -> 0 | D8: =SUM(D6:D7) -> 1555.32 | E8: =SUM(E6:E7) -> 4956 | F8: =SUM(F6:F7) -> #VALUE! | G8: =SUM(G6:G7) -> #VALUE!
B9: Free Cash Flow | C9: =C5-C8 -> #VALUE! | D9: =D5-D8 -> #VALUE! | E9: =E5-E8 -> #VALUE! | F9: =F5-F8 -> #VALUE! | G9: =G5-G8 -> #VALUE!
B11: Reinvestment Rate | C11: =C8/FCFF!C5 -> #VALUE! | D11: =D8/FCFF!D5 -> #VALUE! | E11: =E8/FCFF!E5 -> #VALUE! | F11: =F8/FCFF!F5 -> #VALUE! | G11: =G8/FCFF!G5 -> #VALUE!
B13: Median Reinvestment rate /Sales percentage | C13: =MEDIAN(C11:G11) -> #VALUE!
B14: Average Reinvestment rate /Sales percentage | C14: =AVERAGE(C11:G11) -> #VALUE!
F26: Subsidiary Name
F27: Varun Beverages (Nepal) Pvt. Ltd.,Kathmandu Nepal
F28: Varun Beverages Morocco SA,Casablanca Morocco
F29: Varun Beverages Zambia Ltd.,Lusaka Zambia
F30: Varun Beverages Zimbabwe (Pvt.) Ltd.,Harare Zimbabwe
F31: Varun Beverages Mozambique SA,Maputo Mozambique
F32: Lunarmech Technologies Pvt. Ltd.,India

Sheet Cost of Capital 
B1: Weighted Average Cost of Capital
B4: Capital Structure
B5: Total Debt | C5: ='Consolidated BS'!C16 -> 3694.81
B6: Total Equity | C6: ='Consolidated BS'!C10 -> 649.55
B7: Total Mix | C7: =SUM(C5:C6) -> 4344.36
B8: % of Debt | C8: =C5/C7 -> 0.85048431
B9: % of Equity | C9: =C6/C7 -> 0.14951569
B10: Debt to Equity | C10: =C5/C6 -> 5.6882611
B14: Cost of Equity | E14: Cost of Debt
B15: Risk free rate(Rf) | C15: 0.066 | E15: Source | F15: Cost
B16: Beta | C16: =BETA!L5 -> 0.65919938 | E16: Cost of debt* | F16: ='Consolidated PL'!H21/'Consolidated BS'!G16 -> 0.083779618
B17: Market risk premium | C17: 0.07 | E17: Tax rate | F17: ='Assumptions '!D42 -> 0.25
B18: Cost of equity | C18: =C15+C16*C17 -> 0.11214396 | E18: Cost of Debt after tax | F18: =F16*(1+F17) -> 0.10472452
B21: WACC
B22: Source | C22: Weight | D22: Cost | E22: Weighted Cost
B23: Debt | C23: =C8 -> 0.85048431 | D23: =F18 -> 0.10472452 | E23: =C23*D23 -> 0.089066563
B24: Equity | C24: =C9 -> 0.14951569 | D24: =C18 -> 0.11214396 | E24: =C24*D24 -> 0.016767281
B25: WACC | E25: =SUM(E23:E24) -> 0.10583384
F26: Subsidiary Name
F27: Varun Beverages (Nepal) Pvt. Ltd.,Kathmandu Nepal
F28: Varun Beverages Morocco SA,Casablanca Morocco
F29: Varun Beverages Zambia Ltd.,Lusaka Zambia
F30: Varun Beverages Zimbabwe (Pvt.) Ltd.,Harare Zimbabwe
F31: Varun Beverages Mozambique SA,Maputo Mozambique
F32: Lunarmech Technologies Pvt. Ltd.,India

Sheet Growth Scenario
B2: Radico Khaitan "Growth Scenarios"
B4: Scenario 1: High Growth
B5: INR Cr. | C5: LTM | D5: Y1E | E5: Y2E | F5: Y3E | G5: Y4W | H5: Y5E | I5: Y6E | J5: Y7E | K5: Y8E | L5: Y9E | M5: Y10E
B6: Sales | C6: ='Consolidated PL'!H9 -> 21374.81 | D6: =C6*(1+D7) -> 26224.302 | E6: =D6*(1+E7) -> 31705.27 | F6: =E6*(1+F7) -> 37765.034 | G6: =F6*(1+G7) -> 44307.923 | H6: =G6*(1+H7) -> 51192.36 | I6: =H6*(1+I7) -> 58231.397 | J6: =I6*(1+J7) -> 65197.402 | K6: =J6*(1+K7) -> 71831.293 | ... M6: =L6*(1+M7) -> 82994.681 | O6: Risk Free Rate | P6: 0.066
B7: Sales Growth % | D7: =N7 -> 0.22687883 | E7: =D7-$P$9 -> 0.2090034 | F7: =E7-$P$9 -> 0.19112798 | G7: =F7-$P$9 -> 0.17325255 | H7: =G7-$P$9 -> 0.15537713 | I7: =H7-$P$9 -> 0.1375017 | J7: =I7-$P$9 -> 0.11962628 | K7: =J7-$P$9 -> 0.10175085 | L7: =K7-$P$9 -> 0.083875425 | M7: =L7-$P$9 -> 0.066 | N7: =MEDIAN('Assumptions '!F7:I7) -> 0.22687883
B9: Scenario 2: Average Growth | O9: =N7-P6 -> 0.16087883 | P9: =O9/9 -> 0.017875425
B10: INR Cr. | C10: LTM | D10: Y1E | E10: Y2E | F10: Y3E | G10: Y4W | H10: Y5E | I10: Y6E | J10: Y7E | K10: Y8E | L10: Y9E | M10: Y10E
